<?xml version="1.0" ?>
<!-- =================================================================================== -->
<!-- |    This document was autogenerated by xacro from loop_size2.xacro               | -->
<!-- |    EDITING THIS FILE BY HAND IS NOT RECOMMENDED                                 | -->
<!-- =================================================================================== -->
<robot name="parallel_chain_exp_d5_l2" xmlns:xacro="http://ros.org/wiki/xacro">
  <link name="base"/>
  <link name="link_1_1">
    <inertial>
      <mass value="0.25"/>
      <origin rpy="0 0 0" xyz="0 0.5 0"/>
      <inertia ixx="0.01" ixy="0" ixz="0" iyy="0.1" iyz="0" izz="0.01"/>
    </inertial>
  </link>
  <joint independent="True" name="joint_1_1" type="revolute">
    <parent link="base"/>
    <child link="link_1_1"/>
    <origin xyz="0 0 0"/>
    <axis xyz="0 0 1"/>
    <limit effort="30" lower="-10" upper="10" velocity="1.0"/>
  </joint>
  <link name="link_2_1">
    <inertial>
      <mass value="0.25"/>
      <origin rpy="0 0 0" xyz="0 0.5 0"/>
      <inertia ixx="0.01" ixy="0" ixz="0" iyy="0.1" iyz="0" izz="0.01"/>
    </inertial>
  </link>
  <joint independent="False" name="joint_2_1" type="revolute">
    <parent link="base"/>
    <child link="link_2_1"/>
    <origin xyz="0 0 0"/>
    <axis xyz="0 0 1"/>
    <limit effort="30" lower="-10" upper="10" velocity="1.0"/>
  </joint>
  <constraint name="rolling_1" type="rolling">
    <predecessor link="link_1_1"/>
    <successor link="link_2_1"/>
    <ratio value="1"/>
  </constraint>
  <link name="link_1_2">
    <inertial>
      <mass value="0.25"/>
      <origin rpy="0 0 0" xyz="0 0.5 0"/>
      <inertia ixx="0.01" ixy="0" ixz="0" iyy="0.1" iyz="0" izz="0.01"/>
    </inertial>
  </link>
  <joint independent="True" name="joint_1_2" type="revolute">
    <parent link="link_1_1"/>
    <child link="link_1_2"/>
    <origin xyz="0 1.0 0"/>
    <axis xyz="0 0 1"/>
    <limit effort="30" lower="-10" upper="10" velocity="1.0"/>
  </joint>
  <link name="link_2_2">
    <inertial>
      <mass value="0.25"/>
      <origin rpy="0 0 0" xyz="0 0.5 0"/>
      <inertia ixx="0.01" ixy="0" ixz="0" iyy="0.1" iyz="0" izz="0.01"/>
    </inertial>
  </link>
  <joint independent="True" name="joint_2_2" type="revolute">
    <parent link="link_2_1"/>
    <child link="link_2_2"/>
    <origin xyz="0 1.0 0"/>
    <axis xyz="0 0 1"/>
    <limit effort="30" lower="-10" upper="10" velocity="1.0"/>
  </joint>
  <link name="link_1_3">
    <inertial>
      <mass value="0.25"/>
      <origin rpy="0 0 0" xyz="0 0.5 0"/>
      <inertia ixx="0.01" ixy="0" ixz="0" iyy="0.1" iyz="0" izz="0.01"/>
    </inertial>
  </link>
  <joint independent="True" name="joint_1_3" type="revolute">
    <parent link="link_1_2"/>
    <child link="link_1_3"/>
    <origin xyz="0 1.0 0"/>
    <axis xyz="0 0 1"/>
    <limit effort="30" lower="-10" upper="10" velocity="1.0"/>
  </joint>
  <link name="link_2_3">
    <inertial>
      <mass value="0.25"/>
      <origin rpy="0 0 0" xyz="0 0.5 0"/>
      <inertia ixx="0.01" ixy="0" ixz="0" iyy="0.1" iyz="0" izz="0.01"/>
    </inertial>
  </link>
  <joint independent="True" name="joint_2_3" type="revolute">
    <parent link="link_2_2"/>
    <child link="link_2_3"/>
    <origin xyz="0 1.0 0"/>
    <axis xyz="0 0 1"/>
    <limit effort="30" lower="-10" upper="10" velocity="1.0"/>
  </joint>
  <link name="link_1_4">
    <inertial>
      <mass value="0.25"/>
      <origin rpy="0 0 0" xyz="0 0.5 0"/>
      <inertia ixx="0.01" ixy="0" ixz="0" iyy="0.1" iyz="0" izz="0.01"/>
    </inertial>
  </link>
  <joint independent="True" name="joint_1_4" type="revolute">
    <parent link="link_1_3"/>
    <child link="link_1_4"/>
    <origin xyz="0 1.0 0"/>
    <axis xyz="0 0 1"/>
    <limit effort="30" lower="-10" upper="10" velocity="1.0"/>
  </joint>
  <link name="link_2_4">
    <inertial>
      <mass value="0.25"/>
      <origin rpy="0 0 0" xyz="0 0.5 0"/>
      <inertia ixx="0.01" ixy="0" ixz="0" iyy="0.1" iyz="0" izz="0.01"/>
    </inertial>
  </link>
  <joint independent="True" name="joint_2_4" type="revolute">
    <parent link="link_2_3"/>
    <child link="link_2_4"/>
    <origin xyz="0 1.0 0"/>
    <axis xyz="0 0 1"/>
    <limit effort="30" lower="-10" upper="10" velocity="1.0"/>
  </joint>
  <link name="link_1_5">
    <inertial>
      <mass value="0.25"/>
      <origin rpy="0 0 0" xyz="0 0.5 0"/>
      <inertia ixx="0.01" ixy="0" ixz="0" iyy="0.1" iyz="0" izz="0.01"/>
    </inertial>
  </link>
  <joint independent="True" name="joint_1_5" type="revolute">
    <parent link="link_1_4"/>
    <child link="link_1_5"/>
    <origin xyz="0 1.0 0"/>
    <axis xyz="0 0 1"/>
    <limit effort="30" lower="-10" upper="10" velocity="1.0"/>
  </joint>
  <link name="link_2_5">
    <inertial>
      <mass value="0.25"/>
      <origin rpy="0 0 0" xyz="0 0.5 0"/>
      <inertia ixx="0.01" ixy="0" ixz="0" iyy="0.1" iyz="0" izz="0.01"/>
    </inertial>
  </link>
  <joint independent="True" name="joint_2_5" type="revolute">
    <parent link="link_2_4"/>
    <child link="link_2_5"/>
    <origin xyz="0 1.0 0"/>
    <axis xyz="0 0 1"/>
    <limit effort="30" lower="-10" upper="10" velocity="1.0"/>
  </joint>
</robot>

