<?xml version="1.0" ?>
<!-- =================================================================================== -->
<!-- |    This document was autogenerated by xacro from approx_revolute_rotor_pair_branch.xacro | -->
<!-- |    EDITING THIS FILE BY HAND IS NOT RECOMMENDED                                 | -->
<!-- =================================================================================== -->
<robot name="variable_revolute_rotor_pair_branch">
  <link name="ground"/>
  <link name="Floating Base">
    <inertial>
      <mass value="5.0"/>
      <origin xyz="0. 0. 0."/>
      <inertia ixx="0.1" ixy="0." ixz="0." iyy="0.1" iyz="0." izz="0.1"/>
    </inertial>
  </link>
  <joint name="world_to_base" type="floating">
    <origin rpy="0 0 0" xyz="0 0 0"/>
    <parent link="ground"/>
    <child link="Floating Base"/>
  </joint>
  <joint independent="true" name="base_to_link_7" type="revolute">
    <parent link="Floating Base"/>
    <child link="link_7"/>
    <axis xyz="0 0 1"/>
    <origin xyz="1.0 0.0 0.0"/>
    <limit effort="30" lower="-10" upper="10" velocity="1.0"/>
  </joint>
  <link name="link_7">
    <inertial>
      <mass value="1"/>
      <origin rpy="0 0 0" xyz="0.5 0 0"/>
      <inertia ixx="1" ixy="0" ixz="0" iyy="1" iyz="0" izz="1"/>
    </inertial>
  </link>
  <joint independent="true" name="link_7_to_link_8" type="revolute">
    <parent link="link_7"/>
    <child link="link_8"/>
    <axis xyz="0 0 1"/>
    <origin xyz="1.0 0.0 0.0"/>
    <limit effort="30" lower="-10" upper="10" velocity="1.0"/>
  </joint>
  <link name="link_8">
    <inertial>
      <mass value="1"/>
      <origin rpy="0 0 0" xyz="0.5 0 0"/>
      <inertia ixx="1" ixy="0" ixz="0" iyy="1" iyz="0" izz="1"/>
    </inertial>
  </link>
  <joint independent="true" name="base_to_link_5" type="revolute">
    <parent link="Floating Base"/>
    <child link="link_5"/>
    <axis xyz="0 0 1"/>
    <origin xyz="1.0 0.0 0.0"/>
    <limit effort="30" lower="-10" upper="10" velocity="1.0"/>
  </joint>
  <link name="link_5">
    <inertial>
      <mass value="1"/>
      <origin rpy="0 0 0" xyz="0.5 0 0"/>
      <inertia ixx="1" ixy="0" ixz="0" iyy="1" iyz="0" izz="1"/>
    </inertial>
  </link>
  <joint independent="true" name="link_5_to_link_6" type="revolute">
    <parent link="link_5"/>
    <child link="link_6"/>
    <axis xyz="0 0 1"/>
    <origin xyz="1.0 0.0 0.0"/>
    <limit effort="30" lower="-10" upper="10" velocity="1.0"/>
  </joint>
  <link name="link_6">
    <inertial>
      <mass value="1"/>
      <origin rpy="0 0 0" xyz="0.5 0 0"/>
      <inertia ixx="1" ixy="0" ixz="0" iyy="1" iyz="0" izz="1"/>
    </inertial>
  </link>
  <joint independent="true" name="base_to_link_3" type="revolute">
    <parent link="Floating Base"/>
    <child link="link_3"/>
    <axis xyz="0 0 1"/>
    <origin xyz="1.0 0.0 0.0"/>
    <limit effort="30" lower="-10" upper="10" velocity="1.0"/>
  </joint>
  <link name="link_3">
    <inertial>
      <mass value="1"/>
      <origin rpy="0 0 0" xyz="0.5 0 0"/>
      <inertia ixx="1" ixy="0" ixz="0" iyy="1" iyz="0" izz="1"/>
    </inertial>
  </link>
  <joint independent="true" name="link_3_to_link_4" type="revolute">
    <parent link="link_3"/>
    <child link="link_4"/>
    <axis xyz="0 0 1"/>
    <origin xyz="1.0 0.0 0.0"/>
    <limit effort="30" lower="-10" upper="10" velocity="1.0"/>
  </joint>
  <link name="link_4">
    <inertial>
      <mass value="1"/>
      <origin rpy="0 0 0" xyz="0.5 0 0"/>
      <inertia ixx="1" ixy="0" ixz="0" iyy="1" iyz="0" izz="1"/>
    </inertial>
  </link>
  <joint independent="true" name="base_to_link_1" type="revolute">
    <parent link="Floating Base"/>
    <child link="link_1"/>
    <axis xyz="0 0 1"/>
    <origin xyz="1.0 0.0 0.0"/>
    <limit effort="30" lower="-10" upper="10" velocity="1.0"/>
  </joint>
  <link name="link_1">
    <inertial>
      <mass value="1"/>
      <origin rpy="0 0 0" xyz="0.5 0 0"/>
      <inertia ixx="1" ixy="0" ixz="0" iyy="1" iyz="0" izz="1"/>
    </inertial>
  </link>
  <joint independent="true" name="link_1_to_link_2" type="revolute">
    <parent link="link_1"/>
    <child link="link_2"/>
    <axis xyz="0 0 1"/>
    <origin xyz="1.0 0.0 0.0"/>
    <limit effort="30" lower="-10" upper="10" velocity="1.0"/>
  </joint>
  <link name="link_2">
    <inertial>
      <mass value="1"/>
      <origin rpy="0 0 0" xyz="0.5 0 0"/>
      <inertia ixx="1" ixy="0" ixz="0" iyy="1" iyz="0" izz="1"/>
    </inertial>
  </link>
  <joint independent="true" name="link_8_to_link_39" type="revolute">
    <parent link="link_8"/>
    <child link="link_39"/>
    <axis xyz="0 0 1"/>
    <origin xyz="1.0 0.0 0.0"/>
    <limit effort="30" lower="-10" upper="10" velocity="1.0"/>
  </joint>
  <link name="link_39">
    <inertial>
      <mass value="1"/>
      <origin rpy="0 0 0" xyz="0.5 0 0"/>
      <inertia ixx="1" ixy="0" ixz="0" iyy="1" iyz="0" izz="1"/>
    </inertial>
  </link>
  <joint independent="true" name="link_39_to_link_40" type="revolute">
    <parent link="link_39"/>
    <child link="link_40"/>
    <axis xyz="0 0 1"/>
    <origin xyz="1.0 0.0 0.0"/>
    <limit effort="30" lower="-10" upper="10" velocity="1.0"/>
  </joint>
  <link name="link_40">
    <inertial>
      <mass value="1"/>
      <origin rpy="0 0 0" xyz="0.5 0 0"/>
      <inertia ixx="1" ixy="0" ixz="0" iyy="1" iyz="0" izz="1"/>
    </inertial>
  </link>
  <joint independent="true" name="link_40_to_link_41" type="revolute">
    <parent link="link_40"/>
    <child link="link_41"/>
    <axis xyz="0 0 1"/>
    <origin xyz="1.0 0.0 0.0"/>
    <limit effort="30" lower="-10" upper="10" velocity="1.0"/>
  </joint>
  <link name="link_41">
    <inertial>
      <mass value="1"/>
      <origin rpy="0 0 0" xyz="0.5 0 0"/>
      <inertia ixx="1" ixy="0" ixz="0" iyy="1" iyz="0" izz="1"/>
    </inertial>
  </link>
  <joint independent="true" name="link_41_to_link_42" type="revolute">
    <parent link="link_41"/>
    <child link="link_42"/>
    <axis xyz="0 0 1"/>
    <origin xyz="1.0 0.0 0.0"/>
    <limit effort="30" lower="-10" upper="10" velocity="1.0"/>
  </joint>
  <link name="link_42">
    <inertial>
      <mass value="1"/>
      <origin rpy="0 0 0" xyz="0.5 0 0"/>
      <inertia ixx="1" ixy="0" ixz="0" iyy="1" iyz="0" izz="1"/>
    </inertial>
  </link>
  <joint independent="true" name="link_42_to_link_43" type="revolute">
    <parent link="link_42"/>
    <child link="link_43"/>
    <axis xyz="0 0 1"/>
    <origin xyz="1.0 0.0 0.0"/>
    <limit effort="30" lower="-10" upper="10" velocity="1.0"/>
  </joint>
  <link name="link_43">
    <inertial>
      <mass value="1"/>
      <origin rpy="0 0 0" xyz="0.5 0 0"/>
      <inertia ixx="1" ixy="0" ixz="0" iyy="1" iyz="0" izz="1"/>
    </inertial>
  </link>
  <joint independent="true" name="link_43_to_link_44" type="revolute">
    <parent link="link_43"/>
    <child link="link_44"/>
    <axis xyz="0 0 1"/>
    <origin xyz="1.0 0.0 0.0"/>
    <limit effort="30" lower="-10" upper="10" velocity="1.0"/>
  </joint>
  <link name="link_44">
    <inertial>
      <mass value="1"/>
      <origin rpy="0 0 0" xyz="0.5 0 0"/>
      <inertia ixx="1" ixy="0" ixz="0" iyy="1" iyz="0" izz="1"/>
    </inertial>
  </link>
  <joint independent="true" name="link_44_to_link_45" type="revolute">
    <parent link="link_44"/>
    <child link="link_45"/>
    <axis xyz="0 0 1"/>
    <origin xyz="1.0 0.0 0.0"/>
    <limit effort="30" lower="-10" upper="10" velocity="1.0"/>
  </joint>
  <link name="link_45">
    <inertial>
      <mass value="1"/>
      <origin rpy="0 0 0" xyz="0.5 0 0"/>
      <inertia ixx="1" ixy="0" ixz="0" iyy="1" iyz="0" izz="1"/>
    </inertial>
  </link>
  <joint independent="true" name="link_45_to_link_46" type="revolute">
    <parent link="link_45"/>
    <child link="link_46"/>
    <axis xyz="0 0 1"/>
    <origin xyz="1.0 0.0 0.0"/>
    <limit effort="30" lower="-10" upper="10" velocity="1.0"/>
  </joint>
  <link name="link_46">
    <inertial>
      <mass value="1"/>
      <origin rpy="0 0 0" xyz="0.5 0 0"/>
      <inertia ixx="1" ixy="0" ixz="0" iyy="1" iyz="0" izz="1"/>
    </inertial>
  </link>
  <joint independent="true" name="link_46_to_link_47" type="revolute">
    <parent link="link_46"/>
    <child link="link_47"/>
    <axis xyz="0 0 1"/>
    <origin xyz="1.0 0.0 0.0"/>
    <limit effort="30" lower="-10" upper="10" velocity="1.0"/>
  </joint>
  <link name="link_47">
    <inertial>
      <mass value="1"/>
      <origin rpy="0 0 0" xyz="0.5 0 0"/>
      <inertia ixx="1" ixy="0" ixz="0" iyy="1" iyz="0" izz="1"/>
    </inertial>
  </link>
  <joint independent="true" name="link_47_to_link_48" type="revolute">
    <parent link="link_47"/>
    <child link="link_48"/>
    <axis xyz="0 0 1"/>
    <origin xyz="1.0 0.0 0.0"/>
    <limit effort="30" lower="-10" upper="10" velocity="1.0"/>
  </joint>
  <link name="link_48">
    <inertial>
      <mass value="1"/>
      <origin rpy="0 0 0" xyz="0.5 0 0"/>
      <inertia ixx="1" ixy="0" ixz="0" iyy="1" iyz="0" izz="1"/>
    </inertial>
  </link>
  <joint independent="true" name="link_6_to_link_29" type="revolute">
    <parent link="link_6"/>
    <child link="link_29"/>
    <axis xyz="0 0 1"/>
    <origin xyz="1.0 0.0 0.0"/>
    <limit effort="30" lower="-10" upper="10" velocity="1.0"/>
  </joint>
  <link name="link_29">
    <inertial>
      <mass value="1"/>
      <origin rpy="0 0 0" xyz="0.5 0 0"/>
      <inertia ixx="1" ixy="0" ixz="0" iyy="1" iyz="0" izz="1"/>
    </inertial>
  </link>
  <joint independent="true" name="link_29_to_link_30" type="revolute">
    <parent link="link_29"/>
    <child link="link_30"/>
    <axis xyz="0 0 1"/>
    <origin xyz="1.0 0.0 0.0"/>
    <limit effort="30" lower="-10" upper="10" velocity="1.0"/>
  </joint>
  <link name="link_30">
    <inertial>
      <mass value="1"/>
      <origin rpy="0 0 0" xyz="0.5 0 0"/>
      <inertia ixx="1" ixy="0" ixz="0" iyy="1" iyz="0" izz="1"/>
    </inertial>
  </link>
  <joint independent="true" name="link_30_to_link_31" type="revolute">
    <parent link="link_30"/>
    <child link="link_31"/>
    <axis xyz="0 0 1"/>
    <origin xyz="1.0 0.0 0.0"/>
    <limit effort="30" lower="-10" upper="10" velocity="1.0"/>
  </joint>
  <link name="link_31">
    <inertial>
      <mass value="1"/>
      <origin rpy="0 0 0" xyz="0.5 0 0"/>
      <inertia ixx="1" ixy="0" ixz="0" iyy="1" iyz="0" izz="1"/>
    </inertial>
  </link>
  <joint independent="true" name="link_31_to_link_32" type="revolute">
    <parent link="link_31"/>
    <child link="link_32"/>
    <axis xyz="0 0 1"/>
    <origin xyz="1.0 0.0 0.0"/>
    <limit effort="30" lower="-10" upper="10" velocity="1.0"/>
  </joint>
  <link name="link_32">
    <inertial>
      <mass value="1"/>
      <origin rpy="0 0 0" xyz="0.5 0 0"/>
      <inertia ixx="1" ixy="0" ixz="0" iyy="1" iyz="0" izz="1"/>
    </inertial>
  </link>
  <joint independent="true" name="link_32_to_link_33" type="revolute">
    <parent link="link_32"/>
    <child link="link_33"/>
    <axis xyz="0 0 1"/>
    <origin xyz="1.0 0.0 0.0"/>
    <limit effort="30" lower="-10" upper="10" velocity="1.0"/>
  </joint>
  <link name="link_33">
    <inertial>
      <mass value="1"/>
      <origin rpy="0 0 0" xyz="0.5 0 0"/>
      <inertia ixx="1" ixy="0" ixz="0" iyy="1" iyz="0" izz="1"/>
    </inertial>
  </link>
  <joint independent="true" name="link_33_to_link_34" type="revolute">
    <parent link="link_33"/>
    <child link="link_34"/>
    <axis xyz="0 0 1"/>
    <origin xyz="1.0 0.0 0.0"/>
    <limit effort="30" lower="-10" upper="10" velocity="1.0"/>
  </joint>
  <link name="link_34">
    <inertial>
      <mass value="1"/>
      <origin rpy="0 0 0" xyz="0.5 0 0"/>
      <inertia ixx="1" ixy="0" ixz="0" iyy="1" iyz="0" izz="1"/>
    </inertial>
  </link>
  <joint independent="true" name="link_34_to_link_35" type="revolute">
    <parent link="link_34"/>
    <child link="link_35"/>
    <axis xyz="0 0 1"/>
    <origin xyz="1.0 0.0 0.0"/>
    <limit effort="30" lower="-10" upper="10" velocity="1.0"/>
  </joint>
  <link name="link_35">
    <inertial>
      <mass value="1"/>
      <origin rpy="0 0 0" xyz="0.5 0 0"/>
      <inertia ixx="1" ixy="0" ixz="0" iyy="1" iyz="0" izz="1"/>
    </inertial>
  </link>
  <joint independent="true" name="link_35_to_link_36" type="revolute">
    <parent link="link_35"/>
    <child link="link_36"/>
    <axis xyz="0 0 1"/>
    <origin xyz="1.0 0.0 0.0"/>
    <limit effort="30" lower="-10" upper="10" velocity="1.0"/>
  </joint>
  <link name="link_36">
    <inertial>
      <mass value="1"/>
      <origin rpy="0 0 0" xyz="0.5 0 0"/>
      <inertia ixx="1" ixy="0" ixz="0" iyy="1" iyz="0" izz="1"/>
    </inertial>
  </link>
  <joint independent="true" name="link_36_to_link_37" type="revolute">
    <parent link="link_36"/>
    <child link="link_37"/>
    <axis xyz="0 0 1"/>
    <origin xyz="1.0 0.0 0.0"/>
    <limit effort="30" lower="-10" upper="10" velocity="1.0"/>
  </joint>
  <link name="link_37">
    <inertial>
      <mass value="1"/>
      <origin rpy="0 0 0" xyz="0.5 0 0"/>
      <inertia ixx="1" ixy="0" ixz="0" iyy="1" iyz="0" izz="1"/>
    </inertial>
  </link>
  <joint independent="true" name="link_37_to_link_38" type="revolute">
    <parent link="link_37"/>
    <child link="link_38"/>
    <axis xyz="0 0 1"/>
    <origin xyz="1.0 0.0 0.0"/>
    <limit effort="30" lower="-10" upper="10" velocity="1.0"/>
  </joint>
  <link name="link_38">
    <inertial>
      <mass value="1"/>
      <origin rpy="0 0 0" xyz="0.5 0 0"/>
      <inertia ixx="1" ixy="0" ixz="0" iyy="1" iyz="0" izz="1"/>
    </inertial>
  </link>
  <joint independent="true" name="link_4_to_link_19" type="revolute">
    <parent link="link_4"/>
    <child link="link_19"/>
    <axis xyz="0 0 1"/>
    <origin xyz="1.0 0.0 0.0"/>
    <limit effort="30" lower="-10" upper="10" velocity="1.0"/>
  </joint>
  <link name="link_19">
    <inertial>
      <mass value="1"/>
      <origin rpy="0 0 0" xyz="0.5 0 0"/>
      <inertia ixx="1" ixy="0" ixz="0" iyy="1" iyz="0" izz="1"/>
    </inertial>
  </link>
  <joint independent="true" name="link_19_to_link_20" type="revolute">
    <parent link="link_19"/>
    <child link="link_20"/>
    <axis xyz="0 0 1"/>
    <origin xyz="1.0 0.0 0.0"/>
    <limit effort="30" lower="-10" upper="10" velocity="1.0"/>
  </joint>
  <link name="link_20">
    <inertial>
      <mass value="1"/>
      <origin rpy="0 0 0" xyz="0.5 0 0"/>
      <inertia ixx="1" ixy="0" ixz="0" iyy="1" iyz="0" izz="1"/>
    </inertial>
  </link>
  <joint independent="true" name="link_20_to_link_21" type="revolute">
    <parent link="link_20"/>
    <child link="link_21"/>
    <axis xyz="0 0 1"/>
    <origin xyz="1.0 0.0 0.0"/>
    <limit effort="30" lower="-10" upper="10" velocity="1.0"/>
  </joint>
  <link name="link_21">
    <inertial>
      <mass value="1"/>
      <origin rpy="0 0 0" xyz="0.5 0 0"/>
      <inertia ixx="1" ixy="0" ixz="0" iyy="1" iyz="0" izz="1"/>
    </inertial>
  </link>
  <joint independent="true" name="link_21_to_link_22" type="revolute">
    <parent link="link_21"/>
    <child link="link_22"/>
    <axis xyz="0 0 1"/>
    <origin xyz="1.0 0.0 0.0"/>
    <limit effort="30" lower="-10" upper="10" velocity="1.0"/>
  </joint>
  <link name="link_22">
    <inertial>
      <mass value="1"/>
      <origin rpy="0 0 0" xyz="0.5 0 0"/>
      <inertia ixx="1" ixy="0" ixz="0" iyy="1" iyz="0" izz="1"/>
    </inertial>
  </link>
  <joint independent="true" name="link_22_to_link_23" type="revolute">
    <parent link="link_22"/>
    <child link="link_23"/>
    <axis xyz="0 0 1"/>
    <origin xyz="1.0 0.0 0.0"/>
    <limit effort="30" lower="-10" upper="10" velocity="1.0"/>
  </joint>
  <link name="link_23">
    <inertial>
      <mass value="1"/>
      <origin rpy="0 0 0" xyz="0.5 0 0"/>
      <inertia ixx="1" ixy="0" ixz="0" iyy="1" iyz="0" izz="1"/>
    </inertial>
  </link>
  <joint independent="true" name="link_23_to_link_24" type="revolute">
    <parent link="link_23"/>
    <child link="link_24"/>
    <axis xyz="0 0 1"/>
    <origin xyz="1.0 0.0 0.0"/>
    <limit effort="30" lower="-10" upper="10" velocity="1.0"/>
  </joint>
  <link name="link_24">
    <inertial>
      <mass value="1"/>
      <origin rpy="0 0 0" xyz="0.5 0 0"/>
      <inertia ixx="1" ixy="0" ixz="0" iyy="1" iyz="0" izz="1"/>
    </inertial>
  </link>
  <joint independent="true" name="link_24_to_link_25" type="revolute">
    <parent link="link_24"/>
    <child link="link_25"/>
    <axis xyz="0 0 1"/>
    <origin xyz="1.0 0.0 0.0"/>
    <limit effort="30" lower="-10" upper="10" velocity="1.0"/>
  </joint>
  <link name="link_25">
    <inertial>
      <mass value="1"/>
      <origin rpy="0 0 0" xyz="0.5 0 0"/>
      <inertia ixx="1" ixy="0" ixz="0" iyy="1" iyz="0" izz="1"/>
    </inertial>
  </link>
  <joint independent="true" name="link_25_to_link_26" type="revolute">
    <parent link="link_25"/>
    <child link="link_26"/>
    <axis xyz="0 0 1"/>
    <origin xyz="1.0 0.0 0.0"/>
    <limit effort="30" lower="-10" upper="10" velocity="1.0"/>
  </joint>
  <link name="link_26">
    <inertial>
      <mass value="1"/>
      <origin rpy="0 0 0" xyz="0.5 0 0"/>
      <inertia ixx="1" ixy="0" ixz="0" iyy="1" iyz="0" izz="1"/>
    </inertial>
  </link>
  <joint independent="true" name="link_26_to_link_27" type="revolute">
    <parent link="link_26"/>
    <child link="link_27"/>
    <axis xyz="0 0 1"/>
    <origin xyz="1.0 0.0 0.0"/>
    <limit effort="30" lower="-10" upper="10" velocity="1.0"/>
  </joint>
  <link name="link_27">
    <inertial>
      <mass value="1"/>
      <origin rpy="0 0 0" xyz="0.5 0 0"/>
      <inertia ixx="1" ixy="0" ixz="0" iyy="1" iyz="0" izz="1"/>
    </inertial>
  </link>
  <joint independent="true" name="link_27_to_link_28" type="revolute">
    <parent link="link_27"/>
    <child link="link_28"/>
    <axis xyz="0 0 1"/>
    <origin xyz="1.0 0.0 0.0"/>
    <limit effort="30" lower="-10" upper="10" velocity="1.0"/>
  </joint>
  <link name="link_28">
    <inertial>
      <mass value="1"/>
      <origin rpy="0 0 0" xyz="0.5 0 0"/>
      <inertia ixx="1" ixy="0" ixz="0" iyy="1" iyz="0" izz="1"/>
    </inertial>
  </link>
  <joint independent="true" name="link_2_to_link_9" type="revolute">
    <parent link="link_2"/>
    <child link="link_9"/>
    <axis xyz="0 0 1"/>
    <origin xyz="1.0 0.0 0.0"/>
    <limit effort="30" lower="-10" upper="10" velocity="1.0"/>
  </joint>
  <link name="link_9">
    <inertial>
      <mass value="1"/>
      <origin rpy="0 0 0" xyz="0.5 0 0"/>
      <inertia ixx="1" ixy="0" ixz="0" iyy="1" iyz="0" izz="1"/>
    </inertial>
  </link>
  <joint independent="true" name="link_9_to_link_10" type="revolute">
    <parent link="link_9"/>
    <child link="link_10"/>
    <axis xyz="0 0 1"/>
    <origin xyz="1.0 0.0 0.0"/>
    <limit effort="30" lower="-10" upper="10" velocity="1.0"/>
  </joint>
  <link name="link_10">
    <inertial>
      <mass value="1"/>
      <origin rpy="0 0 0" xyz="0.5 0 0"/>
      <inertia ixx="1" ixy="0" ixz="0" iyy="1" iyz="0" izz="1"/>
    </inertial>
  </link>
  <joint independent="true" name="link_10_to_link_11" type="revolute">
    <parent link="link_10"/>
    <child link="link_11"/>
    <axis xyz="0 0 1"/>
    <origin xyz="1.0 0.0 0.0"/>
    <limit effort="30" lower="-10" upper="10" velocity="1.0"/>
  </joint>
  <link name="link_11">
    <inertial>
      <mass value="1"/>
      <origin rpy="0 0 0" xyz="0.5 0 0"/>
      <inertia ixx="1" ixy="0" ixz="0" iyy="1" iyz="0" izz="1"/>
    </inertial>
  </link>
  <joint independent="true" name="link_11_to_link_12" type="revolute">
    <parent link="link_11"/>
    <child link="link_12"/>
    <axis xyz="0 0 1"/>
    <origin xyz="1.0 0.0 0.0"/>
    <limit effort="30" lower="-10" upper="10" velocity="1.0"/>
  </joint>
  <link name="link_12">
    <inertial>
      <mass value="1"/>
      <origin rpy="0 0 0" xyz="0.5 0 0"/>
      <inertia ixx="1" ixy="0" ixz="0" iyy="1" iyz="0" izz="1"/>
    </inertial>
  </link>
  <joint independent="true" name="link_12_to_link_13" type="revolute">
    <parent link="link_12"/>
    <child link="link_13"/>
    <axis xyz="0 0 1"/>
    <origin xyz="1.0 0.0 0.0"/>
    <limit effort="30" lower="-10" upper="10" velocity="1.0"/>
  </joint>
  <link name="link_13">
    <inertial>
      <mass value="1"/>
      <origin rpy="0 0 0" xyz="0.5 0 0"/>
      <inertia ixx="1" ixy="0" ixz="0" iyy="1" iyz="0" izz="1"/>
    </inertial>
  </link>
  <joint independent="true" name="link_13_to_link_14" type="revolute">
    <parent link="link_13"/>
    <child link="link_14"/>
    <axis xyz="0 0 1"/>
    <origin xyz="1.0 0.0 0.0"/>
    <limit effort="30" lower="-10" upper="10" velocity="1.0"/>
  </joint>
  <link name="link_14">
    <inertial>
      <mass value="1"/>
      <origin rpy="0 0 0" xyz="0.5 0 0"/>
      <inertia ixx="1" ixy="0" ixz="0" iyy="1" iyz="0" izz="1"/>
    </inertial>
  </link>
  <joint independent="true" name="link_14_to_link_15" type="revolute">
    <parent link="link_14"/>
    <child link="link_15"/>
    <axis xyz="0 0 1"/>
    <origin xyz="1.0 0.0 0.0"/>
    <limit effort="30" lower="-10" upper="10" velocity="1.0"/>
  </joint>
  <link name="link_15">
    <inertial>
      <mass value="1"/>
      <origin rpy="0 0 0" xyz="0.5 0 0"/>
      <inertia ixx="1" ixy="0" ixz="0" iyy="1" iyz="0" izz="1"/>
    </inertial>
  </link>
  <joint independent="true" name="link_15_to_link_16" type="revolute">
    <parent link="link_15"/>
    <child link="link_16"/>
    <axis xyz="0 0 1"/>
    <origin xyz="1.0 0.0 0.0"/>
    <limit effort="30" lower="-10" upper="10" velocity="1.0"/>
  </joint>
  <link name="link_16">
    <inertial>
      <mass value="1"/>
      <origin rpy="0 0 0" xyz="0.5 0 0"/>
      <inertia ixx="1" ixy="0" ixz="0" iyy="1" iyz="0" izz="1"/>
    </inertial>
  </link>
  <joint independent="true" name="link_16_to_link_17" type="revolute">
    <parent link="link_16"/>
    <child link="link_17"/>
    <axis xyz="0 0 1"/>
    <origin xyz="1.0 0.0 0.0"/>
    <limit effort="30" lower="-10" upper="10" velocity="1.0"/>
  </joint>
  <link name="link_17">
    <inertial>
      <mass value="1"/>
      <origin rpy="0 0 0" xyz="0.5 0 0"/>
      <inertia ixx="1" ixy="0" ixz="0" iyy="1" iyz="0" izz="1"/>
    </inertial>
  </link>
  <joint independent="true" name="link_17_to_link_18" type="revolute">
    <parent link="link_17"/>
    <child link="link_18"/>
    <axis xyz="0 0 1"/>
    <origin xyz="1.0 0.0 0.0"/>
    <limit effort="30" lower="-10" upper="10" velocity="1.0"/>
  </joint>
  <link name="link_18">
    <inertial>
      <mass value="1"/>
      <origin rpy="0 0 0" xyz="0.5 0 0"/>
      <inertia ixx="1" ixy="0" ixz="0" iyy="1" iyz="0" izz="1"/>
    </inertial>
  </link>
</robot>
