<?xml version="1.0" ?>
<!-- =================================================================================== -->
<!-- |    This document was autogenerated by xacro from revolute_rotor_pair_branch.xacro | -->
<!-- |    EDITING THIS FILE BY HAND IS NOT RECOMMENDED                                 | -->
<!-- =================================================================================== -->
<robot name="variable_revolute_rotor_pair_branch">
  <link name="base"/>
  <joint independent="true" name="base_to_link_11" type="revolute">
    <parent link="base"/>
    <child link="link_11"/>
    <axis xyz="0 0 1"/>
    <origin xyz="1.0 0.0 0.0"/>
    <limit effort="30" lower="-10" upper="10" velocity="1.0"/>
  </joint>
  <link name="link_11">
    <inertial>
      <mass value="1"/>
      <origin rpy="0 0 0" xyz="0.5 0 0"/>
      <inertia ixx="1" ixy="0" ixz="0" iyy="1" iyz="0" izz="1"/>
    </inertial>
  </link>
  <joint independent="false" name="base_to_rotor_11" type="revolute">
    <parent link="base"/>
    <child link="rotor_11"/>
    <axis xyz="0 0 1"/>
    <origin xyz="1.0 0.0 0.0"/>
    <limit effort="30" lower="-10" upper="10" velocity="1.0"/>
  </joint>
  <link name="rotor_11">
    <inertial>
      <mass value="0"/>
      <origin rpy="0 0 0" xyz="0 0 0"/>
      <inertia ixx="1e-4" ixy="0" ixz="0" iyy="1e-4" iyz="0" izz="1e-4"/>
    </inertial>
  </link>
  <constraint name="transmission_11" type="rolling">
    <predecessor link="link_11"/>
    <successor link="rotor_11"/>
    <ratio value="6.0"/>
  </constraint>
  <joint independent="true" name="link_11_to_link_12" type="revolute">
    <parent link="link_11"/>
    <child link="link_12"/>
    <axis xyz="0 0 1"/>
    <origin xyz="1.0 0.0 0.0"/>
    <limit effort="30" lower="-10" upper="10" velocity="1.0"/>
  </joint>
  <link name="link_12">
    <inertial>
      <mass value="1"/>
      <origin rpy="0 0 0" xyz="0.5 0 0"/>
      <inertia ixx="1" ixy="0" ixz="0" iyy="1" iyz="0" izz="1"/>
    </inertial>
  </link>
  <joint independent="false" name="base_to_rotor_12" type="revolute">
    <parent link="base"/>
    <child link="rotor_12"/>
    <axis xyz="0 0 1"/>
    <origin xyz="1.0 0.0 0.0"/>
    <limit effort="30" lower="-10" upper="10" velocity="1.0"/>
  </joint>
  <link name="rotor_12">
    <inertial>
      <mass value="0"/>
      <origin rpy="0 0 0" xyz="0 0 0"/>
      <inertia ixx="1e-4" ixy="0" ixz="0" iyy="1e-4" iyz="0" izz="1e-4"/>
    </inertial>
  </link>
  <constraint name="transmission_12" type="rolling">
    <predecessor link="link_12"/>
    <successor link="rotor_12"/>
    <ratio value="6.0"/>
  </constraint>
  <joint independent="true" name="base_to_link_9" type="revolute">
    <parent link="base"/>
    <child link="link_9"/>
    <axis xyz="0 0 1"/>
    <origin xyz="1.0 0.0 0.0"/>
    <limit effort="30" lower="-10" upper="10" velocity="1.0"/>
  </joint>
  <link name="link_9">
    <inertial>
      <mass value="1"/>
      <origin rpy="0 0 0" xyz="0.5 0 0"/>
      <inertia ixx="1" ixy="0" ixz="0" iyy="1" iyz="0" izz="1"/>
    </inertial>
  </link>
  <joint independent="false" name="base_to_rotor_9" type="revolute">
    <parent link="base"/>
    <child link="rotor_9"/>
    <axis xyz="0 0 1"/>
    <origin xyz="1.0 0.0 0.0"/>
    <limit effort="30" lower="-10" upper="10" velocity="1.0"/>
  </joint>
  <link name="rotor_9">
    <inertial>
      <mass value="0"/>
      <origin rpy="0 0 0" xyz="0 0 0"/>
      <inertia ixx="1e-4" ixy="0" ixz="0" iyy="1e-4" iyz="0" izz="1e-4"/>
    </inertial>
  </link>
  <constraint name="transmission_9" type="rolling">
    <predecessor link="link_9"/>
    <successor link="rotor_9"/>
    <ratio value="6.0"/>
  </constraint>
  <joint independent="true" name="link_9_to_link_10" type="revolute">
    <parent link="link_9"/>
    <child link="link_10"/>
    <axis xyz="0 0 1"/>
    <origin xyz="1.0 0.0 0.0"/>
    <limit effort="30" lower="-10" upper="10" velocity="1.0"/>
  </joint>
  <link name="link_10">
    <inertial>
      <mass value="1"/>
      <origin rpy="0 0 0" xyz="0.5 0 0"/>
      <inertia ixx="1" ixy="0" ixz="0" iyy="1" iyz="0" izz="1"/>
    </inertial>
  </link>
  <joint independent="false" name="base_to_rotor_10" type="revolute">
    <parent link="base"/>
    <child link="rotor_10"/>
    <axis xyz="0 0 1"/>
    <origin xyz="1.0 0.0 0.0"/>
    <limit effort="30" lower="-10" upper="10" velocity="1.0"/>
  </joint>
  <link name="rotor_10">
    <inertial>
      <mass value="0"/>
      <origin rpy="0 0 0" xyz="0 0 0"/>
      <inertia ixx="1e-4" ixy="0" ixz="0" iyy="1e-4" iyz="0" izz="1e-4"/>
    </inertial>
  </link>
  <constraint name="transmission_10" type="rolling">
    <predecessor link="link_10"/>
    <successor link="rotor_10"/>
    <ratio value="6.0"/>
  </constraint>
  <joint independent="true" name="base_to_link_7" type="revolute">
    <parent link="base"/>
    <child link="link_7"/>
    <axis xyz="0 0 1"/>
    <origin xyz="1.0 0.0 0.0"/>
    <limit effort="30" lower="-10" upper="10" velocity="1.0"/>
  </joint>
  <link name="link_7">
    <inertial>
      <mass value="1"/>
      <origin rpy="0 0 0" xyz="0.5 0 0"/>
      <inertia ixx="1" ixy="0" ixz="0" iyy="1" iyz="0" izz="1"/>
    </inertial>
  </link>
  <joint independent="false" name="base_to_rotor_7" type="revolute">
    <parent link="base"/>
    <child link="rotor_7"/>
    <axis xyz="0 0 1"/>
    <origin xyz="1.0 0.0 0.0"/>
    <limit effort="30" lower="-10" upper="10" velocity="1.0"/>
  </joint>
  <link name="rotor_7">
    <inertial>
      <mass value="0"/>
      <origin rpy="0 0 0" xyz="0 0 0"/>
      <inertia ixx="1e-4" ixy="0" ixz="0" iyy="1e-4" iyz="0" izz="1e-4"/>
    </inertial>
  </link>
  <constraint name="transmission_7" type="rolling">
    <predecessor link="link_7"/>
    <successor link="rotor_7"/>
    <ratio value="6.0"/>
  </constraint>
  <joint independent="true" name="link_7_to_link_8" type="revolute">
    <parent link="link_7"/>
    <child link="link_8"/>
    <axis xyz="0 0 1"/>
    <origin xyz="1.0 0.0 0.0"/>
    <limit effort="30" lower="-10" upper="10" velocity="1.0"/>
  </joint>
  <link name="link_8">
    <inertial>
      <mass value="1"/>
      <origin rpy="0 0 0" xyz="0.5 0 0"/>
      <inertia ixx="1" ixy="0" ixz="0" iyy="1" iyz="0" izz="1"/>
    </inertial>
  </link>
  <joint independent="false" name="base_to_rotor_8" type="revolute">
    <parent link="base"/>
    <child link="rotor_8"/>
    <axis xyz="0 0 1"/>
    <origin xyz="1.0 0.0 0.0"/>
    <limit effort="30" lower="-10" upper="10" velocity="1.0"/>
  </joint>
  <link name="rotor_8">
    <inertial>
      <mass value="0"/>
      <origin rpy="0 0 0" xyz="0 0 0"/>
      <inertia ixx="1e-4" ixy="0" ixz="0" iyy="1e-4" iyz="0" izz="1e-4"/>
    </inertial>
  </link>
  <constraint name="transmission_8" type="rolling">
    <predecessor link="link_8"/>
    <successor link="rotor_8"/>
    <ratio value="6.0"/>
  </constraint>
  <joint independent="true" name="base_to_link_5" type="revolute">
    <parent link="base"/>
    <child link="link_5"/>
    <axis xyz="0 0 1"/>
    <origin xyz="1.0 0.0 0.0"/>
    <limit effort="30" lower="-10" upper="10" velocity="1.0"/>
  </joint>
  <link name="link_5">
    <inertial>
      <mass value="1"/>
      <origin rpy="0 0 0" xyz="0.5 0 0"/>
      <inertia ixx="1" ixy="0" ixz="0" iyy="1" iyz="0" izz="1"/>
    </inertial>
  </link>
  <joint independent="false" name="base_to_rotor_5" type="revolute">
    <parent link="base"/>
    <child link="rotor_5"/>
    <axis xyz="0 0 1"/>
    <origin xyz="1.0 0.0 0.0"/>
    <limit effort="30" lower="-10" upper="10" velocity="1.0"/>
  </joint>
  <link name="rotor_5">
    <inertial>
      <mass value="0"/>
      <origin rpy="0 0 0" xyz="0 0 0"/>
      <inertia ixx="1e-4" ixy="0" ixz="0" iyy="1e-4" iyz="0" izz="1e-4"/>
    </inertial>
  </link>
  <constraint name="transmission_5" type="rolling">
    <predecessor link="link_5"/>
    <successor link="rotor_5"/>
    <ratio value="6.0"/>
  </constraint>
  <joint independent="true" name="link_5_to_link_6" type="revolute">
    <parent link="link_5"/>
    <child link="link_6"/>
    <axis xyz="0 0 1"/>
    <origin xyz="1.0 0.0 0.0"/>
    <limit effort="30" lower="-10" upper="10" velocity="1.0"/>
  </joint>
  <link name="link_6">
    <inertial>
      <mass value="1"/>
      <origin rpy="0 0 0" xyz="0.5 0 0"/>
      <inertia ixx="1" ixy="0" ixz="0" iyy="1" iyz="0" izz="1"/>
    </inertial>
  </link>
  <joint independent="false" name="base_to_rotor_6" type="revolute">
    <parent link="base"/>
    <child link="rotor_6"/>
    <axis xyz="0 0 1"/>
    <origin xyz="1.0 0.0 0.0"/>
    <limit effort="30" lower="-10" upper="10" velocity="1.0"/>
  </joint>
  <link name="rotor_6">
    <inertial>
      <mass value="0"/>
      <origin rpy="0 0 0" xyz="0 0 0"/>
      <inertia ixx="1e-4" ixy="0" ixz="0" iyy="1e-4" iyz="0" izz="1e-4"/>
    </inertial>
  </link>
  <constraint name="transmission_6" type="rolling">
    <predecessor link="link_6"/>
    <successor link="rotor_6"/>
    <ratio value="6.0"/>
  </constraint>
  <joint independent="true" name="base_to_link_3" type="revolute">
    <parent link="base"/>
    <child link="link_3"/>
    <axis xyz="0 0 1"/>
    <origin xyz="1.0 0.0 0.0"/>
    <limit effort="30" lower="-10" upper="10" velocity="1.0"/>
  </joint>
  <link name="link_3">
    <inertial>
      <mass value="1"/>
      <origin rpy="0 0 0" xyz="0.5 0 0"/>
      <inertia ixx="1" ixy="0" ixz="0" iyy="1" iyz="0" izz="1"/>
    </inertial>
  </link>
  <joint independent="false" name="base_to_rotor_3" type="revolute">
    <parent link="base"/>
    <child link="rotor_3"/>
    <axis xyz="0 0 1"/>
    <origin xyz="1.0 0.0 0.0"/>
    <limit effort="30" lower="-10" upper="10" velocity="1.0"/>
  </joint>
  <link name="rotor_3">
    <inertial>
      <mass value="0"/>
      <origin rpy="0 0 0" xyz="0 0 0"/>
      <inertia ixx="1e-4" ixy="0" ixz="0" iyy="1e-4" iyz="0" izz="1e-4"/>
    </inertial>
  </link>
  <constraint name="transmission_3" type="rolling">
    <predecessor link="link_3"/>
    <successor link="rotor_3"/>
    <ratio value="6.0"/>
  </constraint>
  <joint independent="true" name="link_3_to_link_4" type="revolute">
    <parent link="link_3"/>
    <child link="link_4"/>
    <axis xyz="0 0 1"/>
    <origin xyz="1.0 0.0 0.0"/>
    <limit effort="30" lower="-10" upper="10" velocity="1.0"/>
  </joint>
  <link name="link_4">
    <inertial>
      <mass value="1"/>
      <origin rpy="0 0 0" xyz="0.5 0 0"/>
      <inertia ixx="1" ixy="0" ixz="0" iyy="1" iyz="0" izz="1"/>
    </inertial>
  </link>
  <joint independent="false" name="base_to_rotor_4" type="revolute">
    <parent link="base"/>
    <child link="rotor_4"/>
    <axis xyz="0 0 1"/>
    <origin xyz="1.0 0.0 0.0"/>
    <limit effort="30" lower="-10" upper="10" velocity="1.0"/>
  </joint>
  <link name="rotor_4">
    <inertial>
      <mass value="0"/>
      <origin rpy="0 0 0" xyz="0 0 0"/>
      <inertia ixx="1e-4" ixy="0" ixz="0" iyy="1e-4" iyz="0" izz="1e-4"/>
    </inertial>
  </link>
  <constraint name="transmission_4" type="rolling">
    <predecessor link="link_4"/>
    <successor link="rotor_4"/>
    <ratio value="6.0"/>
  </constraint>
  <joint independent="true" name="base_to_link_1" type="revolute">
    <parent link="base"/>
    <child link="link_1"/>
    <axis xyz="0 0 1"/>
    <origin xyz="1.0 0.0 0.0"/>
    <limit effort="30" lower="-10" upper="10" velocity="1.0"/>
  </joint>
  <link name="link_1">
    <inertial>
      <mass value="1"/>
      <origin rpy="0 0 0" xyz="0.5 0 0"/>
      <inertia ixx="1" ixy="0" ixz="0" iyy="1" iyz="0" izz="1"/>
    </inertial>
  </link>
  <joint independent="false" name="base_to_rotor_1" type="revolute">
    <parent link="base"/>
    <child link="rotor_1"/>
    <axis xyz="0 0 1"/>
    <origin xyz="1.0 0.0 0.0"/>
    <limit effort="30" lower="-10" upper="10" velocity="1.0"/>
  </joint>
  <link name="rotor_1">
    <inertial>
      <mass value="0"/>
      <origin rpy="0 0 0" xyz="0 0 0"/>
      <inertia ixx="1e-4" ixy="0" ixz="0" iyy="1e-4" iyz="0" izz="1e-4"/>
    </inertial>
  </link>
  <constraint name="transmission_1" type="rolling">
    <predecessor link="link_1"/>
    <successor link="rotor_1"/>
    <ratio value="6.0"/>
  </constraint>
  <joint independent="true" name="link_1_to_link_2" type="revolute">
    <parent link="link_1"/>
    <child link="link_2"/>
    <axis xyz="0 0 1"/>
    <origin xyz="1.0 0.0 0.0"/>
    <limit effort="30" lower="-10" upper="10" velocity="1.0"/>
  </joint>
  <link name="link_2">
    <inertial>
      <mass value="1"/>
      <origin rpy="0 0 0" xyz="0.5 0 0"/>
      <inertia ixx="1" ixy="0" ixz="0" iyy="1" iyz="0" izz="1"/>
    </inertial>
  </link>
  <joint independent="false" name="base_to_rotor_2" type="revolute">
    <parent link="base"/>
    <child link="rotor_2"/>
    <axis xyz="0 0 1"/>
    <origin xyz="1.0 0.0 0.0"/>
    <limit effort="30" lower="-10" upper="10" velocity="1.0"/>
  </joint>
  <link name="rotor_2">
    <inertial>
      <mass value="0"/>
      <origin rpy="0 0 0" xyz="0 0 0"/>
      <inertia ixx="1e-4" ixy="0" ixz="0" iyy="1e-4" iyz="0" izz="1e-4"/>
    </inertial>
  </link>
  <constraint name="transmission_2" type="rolling">
    <predecessor link="link_2"/>
    <successor link="rotor_2"/>
    <ratio value="6.0"/>
  </constraint>
  <joint independent="true" name="link_12_to_link_73" type="revolute">
    <parent link="link_12"/>
    <child link="link_73"/>
    <axis xyz="0 0 1"/>
    <origin xyz="1.0 0.0 0.0"/>
    <limit effort="30" lower="-10" upper="10" velocity="1.0"/>
  </joint>
  <link name="link_73">
    <inertial>
      <mass value="1"/>
      <origin rpy="0 0 0" xyz="0.5 0 0"/>
      <inertia ixx="1" ixy="0" ixz="0" iyy="1" iyz="0" izz="1"/>
    </inertial>
  </link>
  <joint independent="false" name="link_12_to_rotor_73" type="revolute">
    <parent link="link_12"/>
    <child link="rotor_73"/>
    <axis xyz="0 0 1"/>
    <origin xyz="1.0 0.0 0.0"/>
    <limit effort="30" lower="-10" upper="10" velocity="1.0"/>
  </joint>
  <link name="rotor_73">
    <inertial>
      <mass value="0"/>
      <origin rpy="0 0 0" xyz="0 0 0"/>
      <inertia ixx="1e-4" ixy="0" ixz="0" iyy="1e-4" iyz="0" izz="1e-4"/>
    </inertial>
  </link>
  <constraint name="transmission_73" type="rolling">
    <predecessor link="link_73"/>
    <successor link="rotor_73"/>
    <ratio value="6.0"/>
  </constraint>
  <joint independent="true" name="link_73_to_link_74" type="revolute">
    <parent link="link_73"/>
    <child link="link_74"/>
    <axis xyz="0 0 1"/>
    <origin xyz="1.0 0.0 0.0"/>
    <limit effort="30" lower="-10" upper="10" velocity="1.0"/>
  </joint>
  <link name="link_74">
    <inertial>
      <mass value="1"/>
      <origin rpy="0 0 0" xyz="0.5 0 0"/>
      <inertia ixx="1" ixy="0" ixz="0" iyy="1" iyz="0" izz="1"/>
    </inertial>
  </link>
  <joint independent="false" name="link_12_to_rotor_74" type="revolute">
    <parent link="link_12"/>
    <child link="rotor_74"/>
    <axis xyz="0 0 1"/>
    <origin xyz="1.0 0.0 0.0"/>
    <limit effort="30" lower="-10" upper="10" velocity="1.0"/>
  </joint>
  <link name="rotor_74">
    <inertial>
      <mass value="0"/>
      <origin rpy="0 0 0" xyz="0 0 0"/>
      <inertia ixx="1e-4" ixy="0" ixz="0" iyy="1e-4" iyz="0" izz="1e-4"/>
    </inertial>
  </link>
  <constraint name="transmission_74" type="rolling">
    <predecessor link="link_74"/>
    <successor link="rotor_74"/>
    <ratio value="6.0"/>
  </constraint>
  <joint independent="true" name="link_74_to_link_75" type="revolute">
    <parent link="link_74"/>
    <child link="link_75"/>
    <axis xyz="0 0 1"/>
    <origin xyz="1.0 0.0 0.0"/>
    <limit effort="30" lower="-10" upper="10" velocity="1.0"/>
  </joint>
  <link name="link_75">
    <inertial>
      <mass value="1"/>
      <origin rpy="0 0 0" xyz="0.5 0 0"/>
      <inertia ixx="1" ixy="0" ixz="0" iyy="1" iyz="0" izz="1"/>
    </inertial>
  </link>
  <joint independent="false" name="link_74_to_rotor_75" type="revolute">
    <parent link="link_74"/>
    <child link="rotor_75"/>
    <axis xyz="0 0 1"/>
    <origin xyz="1.0 0.0 0.0"/>
    <limit effort="30" lower="-10" upper="10" velocity="1.0"/>
  </joint>
  <link name="rotor_75">
    <inertial>
      <mass value="0"/>
      <origin rpy="0 0 0" xyz="0 0 0"/>
      <inertia ixx="1e-4" ixy="0" ixz="0" iyy="1e-4" iyz="0" izz="1e-4"/>
    </inertial>
  </link>
  <constraint name="transmission_75" type="rolling">
    <predecessor link="link_75"/>
    <successor link="rotor_75"/>
    <ratio value="6.0"/>
  </constraint>
  <joint independent="true" name="link_75_to_link_76" type="revolute">
    <parent link="link_75"/>
    <child link="link_76"/>
    <axis xyz="0 0 1"/>
    <origin xyz="1.0 0.0 0.0"/>
    <limit effort="30" lower="-10" upper="10" velocity="1.0"/>
  </joint>
  <link name="link_76">
    <inertial>
      <mass value="1"/>
      <origin rpy="0 0 0" xyz="0.5 0 0"/>
      <inertia ixx="1" ixy="0" ixz="0" iyy="1" iyz="0" izz="1"/>
    </inertial>
  </link>
  <joint independent="false" name="link_74_to_rotor_76" type="revolute">
    <parent link="link_74"/>
    <child link="rotor_76"/>
    <axis xyz="0 0 1"/>
    <origin xyz="1.0 0.0 0.0"/>
    <limit effort="30" lower="-10" upper="10" velocity="1.0"/>
  </joint>
  <link name="rotor_76">
    <inertial>
      <mass value="0"/>
      <origin rpy="0 0 0" xyz="0 0 0"/>
      <inertia ixx="1e-4" ixy="0" ixz="0" iyy="1e-4" iyz="0" izz="1e-4"/>
    </inertial>
  </link>
  <constraint name="transmission_76" type="rolling">
    <predecessor link="link_76"/>
    <successor link="rotor_76"/>
    <ratio value="6.0"/>
  </constraint>
  <joint independent="true" name="link_76_to_link_77" type="revolute">
    <parent link="link_76"/>
    <child link="link_77"/>
    <axis xyz="0 0 1"/>
    <origin xyz="1.0 0.0 0.0"/>
    <limit effort="30" lower="-10" upper="10" velocity="1.0"/>
  </joint>
  <link name="link_77">
    <inertial>
      <mass value="1"/>
      <origin rpy="0 0 0" xyz="0.5 0 0"/>
      <inertia ixx="1" ixy="0" ixz="0" iyy="1" iyz="0" izz="1"/>
    </inertial>
  </link>
  <joint independent="false" name="link_76_to_rotor_77" type="revolute">
    <parent link="link_76"/>
    <child link="rotor_77"/>
    <axis xyz="0 0 1"/>
    <origin xyz="1.0 0.0 0.0"/>
    <limit effort="30" lower="-10" upper="10" velocity="1.0"/>
  </joint>
  <link name="rotor_77">
    <inertial>
      <mass value="0"/>
      <origin rpy="0 0 0" xyz="0 0 0"/>
      <inertia ixx="1e-4" ixy="0" ixz="0" iyy="1e-4" iyz="0" izz="1e-4"/>
    </inertial>
  </link>
  <constraint name="transmission_77" type="rolling">
    <predecessor link="link_77"/>
    <successor link="rotor_77"/>
    <ratio value="6.0"/>
  </constraint>
  <joint independent="true" name="link_77_to_link_78" type="revolute">
    <parent link="link_77"/>
    <child link="link_78"/>
    <axis xyz="0 0 1"/>
    <origin xyz="1.0 0.0 0.0"/>
    <limit effort="30" lower="-10" upper="10" velocity="1.0"/>
  </joint>
  <link name="link_78">
    <inertial>
      <mass value="1"/>
      <origin rpy="0 0 0" xyz="0.5 0 0"/>
      <inertia ixx="1" ixy="0" ixz="0" iyy="1" iyz="0" izz="1"/>
    </inertial>
  </link>
  <joint independent="false" name="link_76_to_rotor_78" type="revolute">
    <parent link="link_76"/>
    <child link="rotor_78"/>
    <axis xyz="0 0 1"/>
    <origin xyz="1.0 0.0 0.0"/>
    <limit effort="30" lower="-10" upper="10" velocity="1.0"/>
  </joint>
  <link name="rotor_78">
    <inertial>
      <mass value="0"/>
      <origin rpy="0 0 0" xyz="0 0 0"/>
      <inertia ixx="1e-4" ixy="0" ixz="0" iyy="1e-4" iyz="0" izz="1e-4"/>
    </inertial>
  </link>
  <constraint name="transmission_78" type="rolling">
    <predecessor link="link_78"/>
    <successor link="rotor_78"/>
    <ratio value="6.0"/>
  </constraint>
  <joint independent="true" name="link_78_to_link_79" type="revolute">
    <parent link="link_78"/>
    <child link="link_79"/>
    <axis xyz="0 0 1"/>
    <origin xyz="1.0 0.0 0.0"/>
    <limit effort="30" lower="-10" upper="10" velocity="1.0"/>
  </joint>
  <link name="link_79">
    <inertial>
      <mass value="1"/>
      <origin rpy="0 0 0" xyz="0.5 0 0"/>
      <inertia ixx="1" ixy="0" ixz="0" iyy="1" iyz="0" izz="1"/>
    </inertial>
  </link>
  <joint independent="false" name="link_78_to_rotor_79" type="revolute">
    <parent link="link_78"/>
    <child link="rotor_79"/>
    <axis xyz="0 0 1"/>
    <origin xyz="1.0 0.0 0.0"/>
    <limit effort="30" lower="-10" upper="10" velocity="1.0"/>
  </joint>
  <link name="rotor_79">
    <inertial>
      <mass value="0"/>
      <origin rpy="0 0 0" xyz="0 0 0"/>
      <inertia ixx="1e-4" ixy="0" ixz="0" iyy="1e-4" iyz="0" izz="1e-4"/>
    </inertial>
  </link>
  <constraint name="transmission_79" type="rolling">
    <predecessor link="link_79"/>
    <successor link="rotor_79"/>
    <ratio value="6.0"/>
  </constraint>
  <joint independent="true" name="link_79_to_link_80" type="revolute">
    <parent link="link_79"/>
    <child link="link_80"/>
    <axis xyz="0 0 1"/>
    <origin xyz="1.0 0.0 0.0"/>
    <limit effort="30" lower="-10" upper="10" velocity="1.0"/>
  </joint>
  <link name="link_80">
    <inertial>
      <mass value="1"/>
      <origin rpy="0 0 0" xyz="0.5 0 0"/>
      <inertia ixx="1" ixy="0" ixz="0" iyy="1" iyz="0" izz="1"/>
    </inertial>
  </link>
  <joint independent="false" name="link_78_to_rotor_80" type="revolute">
    <parent link="link_78"/>
    <child link="rotor_80"/>
    <axis xyz="0 0 1"/>
    <origin xyz="1.0 0.0 0.0"/>
    <limit effort="30" lower="-10" upper="10" velocity="1.0"/>
  </joint>
  <link name="rotor_80">
    <inertial>
      <mass value="0"/>
      <origin rpy="0 0 0" xyz="0 0 0"/>
      <inertia ixx="1e-4" ixy="0" ixz="0" iyy="1e-4" iyz="0" izz="1e-4"/>
    </inertial>
  </link>
  <constraint name="transmission_80" type="rolling">
    <predecessor link="link_80"/>
    <successor link="rotor_80"/>
    <ratio value="6.0"/>
  </constraint>
  <joint independent="true" name="link_80_to_link_81" type="revolute">
    <parent link="link_80"/>
    <child link="link_81"/>
    <axis xyz="0 0 1"/>
    <origin xyz="1.0 0.0 0.0"/>
    <limit effort="30" lower="-10" upper="10" velocity="1.0"/>
  </joint>
  <link name="link_81">
    <inertial>
      <mass value="1"/>
      <origin rpy="0 0 0" xyz="0.5 0 0"/>
      <inertia ixx="1" ixy="0" ixz="0" iyy="1" iyz="0" izz="1"/>
    </inertial>
  </link>
  <joint independent="false" name="link_80_to_rotor_81" type="revolute">
    <parent link="link_80"/>
    <child link="rotor_81"/>
    <axis xyz="0 0 1"/>
    <origin xyz="1.0 0.0 0.0"/>
    <limit effort="30" lower="-10" upper="10" velocity="1.0"/>
  </joint>
  <link name="rotor_81">
    <inertial>
      <mass value="0"/>
      <origin rpy="0 0 0" xyz="0 0 0"/>
      <inertia ixx="1e-4" ixy="0" ixz="0" iyy="1e-4" iyz="0" izz="1e-4"/>
    </inertial>
  </link>
  <constraint name="transmission_81" type="rolling">
    <predecessor link="link_81"/>
    <successor link="rotor_81"/>
    <ratio value="6.0"/>
  </constraint>
  <joint independent="true" name="link_81_to_link_82" type="revolute">
    <parent link="link_81"/>
    <child link="link_82"/>
    <axis xyz="0 0 1"/>
    <origin xyz="1.0 0.0 0.0"/>
    <limit effort="30" lower="-10" upper="10" velocity="1.0"/>
  </joint>
  <link name="link_82">
    <inertial>
      <mass value="1"/>
      <origin rpy="0 0 0" xyz="0.5 0 0"/>
      <inertia ixx="1" ixy="0" ixz="0" iyy="1" iyz="0" izz="1"/>
    </inertial>
  </link>
  <joint independent="false" name="link_80_to_rotor_82" type="revolute">
    <parent link="link_80"/>
    <child link="rotor_82"/>
    <axis xyz="0 0 1"/>
    <origin xyz="1.0 0.0 0.0"/>
    <limit effort="30" lower="-10" upper="10" velocity="1.0"/>
  </joint>
  <link name="rotor_82">
    <inertial>
      <mass value="0"/>
      <origin rpy="0 0 0" xyz="0 0 0"/>
      <inertia ixx="1e-4" ixy="0" ixz="0" iyy="1e-4" iyz="0" izz="1e-4"/>
    </inertial>
  </link>
  <constraint name="transmission_82" type="rolling">
    <predecessor link="link_82"/>
    <successor link="rotor_82"/>
    <ratio value="6.0"/>
  </constraint>
  <joint independent="true" name="link_82_to_link_83" type="revolute">
    <parent link="link_82"/>
    <child link="link_83"/>
    <axis xyz="0 0 1"/>
    <origin xyz="1.0 0.0 0.0"/>
    <limit effort="30" lower="-10" upper="10" velocity="1.0"/>
  </joint>
  <link name="link_83">
    <inertial>
      <mass value="1"/>
      <origin rpy="0 0 0" xyz="0.5 0 0"/>
      <inertia ixx="1" ixy="0" ixz="0" iyy="1" iyz="0" izz="1"/>
    </inertial>
  </link>
  <joint independent="false" name="link_82_to_rotor_83" type="revolute">
    <parent link="link_82"/>
    <child link="rotor_83"/>
    <axis xyz="0 0 1"/>
    <origin xyz="1.0 0.0 0.0"/>
    <limit effort="30" lower="-10" upper="10" velocity="1.0"/>
  </joint>
  <link name="rotor_83">
    <inertial>
      <mass value="0"/>
      <origin rpy="0 0 0" xyz="0 0 0"/>
      <inertia ixx="1e-4" ixy="0" ixz="0" iyy="1e-4" iyz="0" izz="1e-4"/>
    </inertial>
  </link>
  <constraint name="transmission_83" type="rolling">
    <predecessor link="link_83"/>
    <successor link="rotor_83"/>
    <ratio value="6.0"/>
  </constraint>
  <joint independent="true" name="link_83_to_link_84" type="revolute">
    <parent link="link_83"/>
    <child link="link_84"/>
    <axis xyz="0 0 1"/>
    <origin xyz="1.0 0.0 0.0"/>
    <limit effort="30" lower="-10" upper="10" velocity="1.0"/>
  </joint>
  <link name="link_84">
    <inertial>
      <mass value="1"/>
      <origin rpy="0 0 0" xyz="0.5 0 0"/>
      <inertia ixx="1" ixy="0" ixz="0" iyy="1" iyz="0" izz="1"/>
    </inertial>
  </link>
  <joint independent="false" name="link_82_to_rotor_84" type="revolute">
    <parent link="link_82"/>
    <child link="rotor_84"/>
    <axis xyz="0 0 1"/>
    <origin xyz="1.0 0.0 0.0"/>
    <limit effort="30" lower="-10" upper="10" velocity="1.0"/>
  </joint>
  <link name="rotor_84">
    <inertial>
      <mass value="0"/>
      <origin rpy="0 0 0" xyz="0 0 0"/>
      <inertia ixx="1e-4" ixy="0" ixz="0" iyy="1e-4" iyz="0" izz="1e-4"/>
    </inertial>
  </link>
  <constraint name="transmission_84" type="rolling">
    <predecessor link="link_84"/>
    <successor link="rotor_84"/>
    <ratio value="6.0"/>
  </constraint>
  <joint independent="true" name="link_10_to_link_61" type="revolute">
    <parent link="link_10"/>
    <child link="link_61"/>
    <axis xyz="0 0 1"/>
    <origin xyz="1.0 0.0 0.0"/>
    <limit effort="30" lower="-10" upper="10" velocity="1.0"/>
  </joint>
  <link name="link_61">
    <inertial>
      <mass value="1"/>
      <origin rpy="0 0 0" xyz="0.5 0 0"/>
      <inertia ixx="1" ixy="0" ixz="0" iyy="1" iyz="0" izz="1"/>
    </inertial>
  </link>
  <joint independent="false" name="link_10_to_rotor_61" type="revolute">
    <parent link="link_10"/>
    <child link="rotor_61"/>
    <axis xyz="0 0 1"/>
    <origin xyz="1.0 0.0 0.0"/>
    <limit effort="30" lower="-10" upper="10" velocity="1.0"/>
  </joint>
  <link name="rotor_61">
    <inertial>
      <mass value="0"/>
      <origin rpy="0 0 0" xyz="0 0 0"/>
      <inertia ixx="1e-4" ixy="0" ixz="0" iyy="1e-4" iyz="0" izz="1e-4"/>
    </inertial>
  </link>
  <constraint name="transmission_61" type="rolling">
    <predecessor link="link_61"/>
    <successor link="rotor_61"/>
    <ratio value="6.0"/>
  </constraint>
  <joint independent="true" name="link_61_to_link_62" type="revolute">
    <parent link="link_61"/>
    <child link="link_62"/>
    <axis xyz="0 0 1"/>
    <origin xyz="1.0 0.0 0.0"/>
    <limit effort="30" lower="-10" upper="10" velocity="1.0"/>
  </joint>
  <link name="link_62">
    <inertial>
      <mass value="1"/>
      <origin rpy="0 0 0" xyz="0.5 0 0"/>
      <inertia ixx="1" ixy="0" ixz="0" iyy="1" iyz="0" izz="1"/>
    </inertial>
  </link>
  <joint independent="false" name="link_10_to_rotor_62" type="revolute">
    <parent link="link_10"/>
    <child link="rotor_62"/>
    <axis xyz="0 0 1"/>
    <origin xyz="1.0 0.0 0.0"/>
    <limit effort="30" lower="-10" upper="10" velocity="1.0"/>
  </joint>
  <link name="rotor_62">
    <inertial>
      <mass value="0"/>
      <origin rpy="0 0 0" xyz="0 0 0"/>
      <inertia ixx="1e-4" ixy="0" ixz="0" iyy="1e-4" iyz="0" izz="1e-4"/>
    </inertial>
  </link>
  <constraint name="transmission_62" type="rolling">
    <predecessor link="link_62"/>
    <successor link="rotor_62"/>
    <ratio value="6.0"/>
  </constraint>
  <joint independent="true" name="link_62_to_link_63" type="revolute">
    <parent link="link_62"/>
    <child link="link_63"/>
    <axis xyz="0 0 1"/>
    <origin xyz="1.0 0.0 0.0"/>
    <limit effort="30" lower="-10" upper="10" velocity="1.0"/>
  </joint>
  <link name="link_63">
    <inertial>
      <mass value="1"/>
      <origin rpy="0 0 0" xyz="0.5 0 0"/>
      <inertia ixx="1" ixy="0" ixz="0" iyy="1" iyz="0" izz="1"/>
    </inertial>
  </link>
  <joint independent="false" name="link_62_to_rotor_63" type="revolute">
    <parent link="link_62"/>
    <child link="rotor_63"/>
    <axis xyz="0 0 1"/>
    <origin xyz="1.0 0.0 0.0"/>
    <limit effort="30" lower="-10" upper="10" velocity="1.0"/>
  </joint>
  <link name="rotor_63">
    <inertial>
      <mass value="0"/>
      <origin rpy="0 0 0" xyz="0 0 0"/>
      <inertia ixx="1e-4" ixy="0" ixz="0" iyy="1e-4" iyz="0" izz="1e-4"/>
    </inertial>
  </link>
  <constraint name="transmission_63" type="rolling">
    <predecessor link="link_63"/>
    <successor link="rotor_63"/>
    <ratio value="6.0"/>
  </constraint>
  <joint independent="true" name="link_63_to_link_64" type="revolute">
    <parent link="link_63"/>
    <child link="link_64"/>
    <axis xyz="0 0 1"/>
    <origin xyz="1.0 0.0 0.0"/>
    <limit effort="30" lower="-10" upper="10" velocity="1.0"/>
  </joint>
  <link name="link_64">
    <inertial>
      <mass value="1"/>
      <origin rpy="0 0 0" xyz="0.5 0 0"/>
      <inertia ixx="1" ixy="0" ixz="0" iyy="1" iyz="0" izz="1"/>
    </inertial>
  </link>
  <joint independent="false" name="link_62_to_rotor_64" type="revolute">
    <parent link="link_62"/>
    <child link="rotor_64"/>
    <axis xyz="0 0 1"/>
    <origin xyz="1.0 0.0 0.0"/>
    <limit effort="30" lower="-10" upper="10" velocity="1.0"/>
  </joint>
  <link name="rotor_64">
    <inertial>
      <mass value="0"/>
      <origin rpy="0 0 0" xyz="0 0 0"/>
      <inertia ixx="1e-4" ixy="0" ixz="0" iyy="1e-4" iyz="0" izz="1e-4"/>
    </inertial>
  </link>
  <constraint name="transmission_64" type="rolling">
    <predecessor link="link_64"/>
    <successor link="rotor_64"/>
    <ratio value="6.0"/>
  </constraint>
  <joint independent="true" name="link_64_to_link_65" type="revolute">
    <parent link="link_64"/>
    <child link="link_65"/>
    <axis xyz="0 0 1"/>
    <origin xyz="1.0 0.0 0.0"/>
    <limit effort="30" lower="-10" upper="10" velocity="1.0"/>
  </joint>
  <link name="link_65">
    <inertial>
      <mass value="1"/>
      <origin rpy="0 0 0" xyz="0.5 0 0"/>
      <inertia ixx="1" ixy="0" ixz="0" iyy="1" iyz="0" izz="1"/>
    </inertial>
  </link>
  <joint independent="false" name="link_64_to_rotor_65" type="revolute">
    <parent link="link_64"/>
    <child link="rotor_65"/>
    <axis xyz="0 0 1"/>
    <origin xyz="1.0 0.0 0.0"/>
    <limit effort="30" lower="-10" upper="10" velocity="1.0"/>
  </joint>
  <link name="rotor_65">
    <inertial>
      <mass value="0"/>
      <origin rpy="0 0 0" xyz="0 0 0"/>
      <inertia ixx="1e-4" ixy="0" ixz="0" iyy="1e-4" iyz="0" izz="1e-4"/>
    </inertial>
  </link>
  <constraint name="transmission_65" type="rolling">
    <predecessor link="link_65"/>
    <successor link="rotor_65"/>
    <ratio value="6.0"/>
  </constraint>
  <joint independent="true" name="link_65_to_link_66" type="revolute">
    <parent link="link_65"/>
    <child link="link_66"/>
    <axis xyz="0 0 1"/>
    <origin xyz="1.0 0.0 0.0"/>
    <limit effort="30" lower="-10" upper="10" velocity="1.0"/>
  </joint>
  <link name="link_66">
    <inertial>
      <mass value="1"/>
      <origin rpy="0 0 0" xyz="0.5 0 0"/>
      <inertia ixx="1" ixy="0" ixz="0" iyy="1" iyz="0" izz="1"/>
    </inertial>
  </link>
  <joint independent="false" name="link_64_to_rotor_66" type="revolute">
    <parent link="link_64"/>
    <child link="rotor_66"/>
    <axis xyz="0 0 1"/>
    <origin xyz="1.0 0.0 0.0"/>
    <limit effort="30" lower="-10" upper="10" velocity="1.0"/>
  </joint>
  <link name="rotor_66">
    <inertial>
      <mass value="0"/>
      <origin rpy="0 0 0" xyz="0 0 0"/>
      <inertia ixx="1e-4" ixy="0" ixz="0" iyy="1e-4" iyz="0" izz="1e-4"/>
    </inertial>
  </link>
  <constraint name="transmission_66" type="rolling">
    <predecessor link="link_66"/>
    <successor link="rotor_66"/>
    <ratio value="6.0"/>
  </constraint>
  <joint independent="true" name="link_66_to_link_67" type="revolute">
    <parent link="link_66"/>
    <child link="link_67"/>
    <axis xyz="0 0 1"/>
    <origin xyz="1.0 0.0 0.0"/>
    <limit effort="30" lower="-10" upper="10" velocity="1.0"/>
  </joint>
  <link name="link_67">
    <inertial>
      <mass value="1"/>
      <origin rpy="0 0 0" xyz="0.5 0 0"/>
      <inertia ixx="1" ixy="0" ixz="0" iyy="1" iyz="0" izz="1"/>
    </inertial>
  </link>
  <joint independent="false" name="link_66_to_rotor_67" type="revolute">
    <parent link="link_66"/>
    <child link="rotor_67"/>
    <axis xyz="0 0 1"/>
    <origin xyz="1.0 0.0 0.0"/>
    <limit effort="30" lower="-10" upper="10" velocity="1.0"/>
  </joint>
  <link name="rotor_67">
    <inertial>
      <mass value="0"/>
      <origin rpy="0 0 0" xyz="0 0 0"/>
      <inertia ixx="1e-4" ixy="0" ixz="0" iyy="1e-4" iyz="0" izz="1e-4"/>
    </inertial>
  </link>
  <constraint name="transmission_67" type="rolling">
    <predecessor link="link_67"/>
    <successor link="rotor_67"/>
    <ratio value="6.0"/>
  </constraint>
  <joint independent="true" name="link_67_to_link_68" type="revolute">
    <parent link="link_67"/>
    <child link="link_68"/>
    <axis xyz="0 0 1"/>
    <origin xyz="1.0 0.0 0.0"/>
    <limit effort="30" lower="-10" upper="10" velocity="1.0"/>
  </joint>
  <link name="link_68">
    <inertial>
      <mass value="1"/>
      <origin rpy="0 0 0" xyz="0.5 0 0"/>
      <inertia ixx="1" ixy="0" ixz="0" iyy="1" iyz="0" izz="1"/>
    </inertial>
  </link>
  <joint independent="false" name="link_66_to_rotor_68" type="revolute">
    <parent link="link_66"/>
    <child link="rotor_68"/>
    <axis xyz="0 0 1"/>
    <origin xyz="1.0 0.0 0.0"/>
    <limit effort="30" lower="-10" upper="10" velocity="1.0"/>
  </joint>
  <link name="rotor_68">
    <inertial>
      <mass value="0"/>
      <origin rpy="0 0 0" xyz="0 0 0"/>
      <inertia ixx="1e-4" ixy="0" ixz="0" iyy="1e-4" iyz="0" izz="1e-4"/>
    </inertial>
  </link>
  <constraint name="transmission_68" type="rolling">
    <predecessor link="link_68"/>
    <successor link="rotor_68"/>
    <ratio value="6.0"/>
  </constraint>
  <joint independent="true" name="link_68_to_link_69" type="revolute">
    <parent link="link_68"/>
    <child link="link_69"/>
    <axis xyz="0 0 1"/>
    <origin xyz="1.0 0.0 0.0"/>
    <limit effort="30" lower="-10" upper="10" velocity="1.0"/>
  </joint>
  <link name="link_69">
    <inertial>
      <mass value="1"/>
      <origin rpy="0 0 0" xyz="0.5 0 0"/>
      <inertia ixx="1" ixy="0" ixz="0" iyy="1" iyz="0" izz="1"/>
    </inertial>
  </link>
  <joint independent="false" name="link_68_to_rotor_69" type="revolute">
    <parent link="link_68"/>
    <child link="rotor_69"/>
    <axis xyz="0 0 1"/>
    <origin xyz="1.0 0.0 0.0"/>
    <limit effort="30" lower="-10" upper="10" velocity="1.0"/>
  </joint>
  <link name="rotor_69">
    <inertial>
      <mass value="0"/>
      <origin rpy="0 0 0" xyz="0 0 0"/>
      <inertia ixx="1e-4" ixy="0" ixz="0" iyy="1e-4" iyz="0" izz="1e-4"/>
    </inertial>
  </link>
  <constraint name="transmission_69" type="rolling">
    <predecessor link="link_69"/>
    <successor link="rotor_69"/>
    <ratio value="6.0"/>
  </constraint>
  <joint independent="true" name="link_69_to_link_70" type="revolute">
    <parent link="link_69"/>
    <child link="link_70"/>
    <axis xyz="0 0 1"/>
    <origin xyz="1.0 0.0 0.0"/>
    <limit effort="30" lower="-10" upper="10" velocity="1.0"/>
  </joint>
  <link name="link_70">
    <inertial>
      <mass value="1"/>
      <origin rpy="0 0 0" xyz="0.5 0 0"/>
      <inertia ixx="1" ixy="0" ixz="0" iyy="1" iyz="0" izz="1"/>
    </inertial>
  </link>
  <joint independent="false" name="link_68_to_rotor_70" type="revolute">
    <parent link="link_68"/>
    <child link="rotor_70"/>
    <axis xyz="0 0 1"/>
    <origin xyz="1.0 0.0 0.0"/>
    <limit effort="30" lower="-10" upper="10" velocity="1.0"/>
  </joint>
  <link name="rotor_70">
    <inertial>
      <mass value="0"/>
      <origin rpy="0 0 0" xyz="0 0 0"/>
      <inertia ixx="1e-4" ixy="0" ixz="0" iyy="1e-4" iyz="0" izz="1e-4"/>
    </inertial>
  </link>
  <constraint name="transmission_70" type="rolling">
    <predecessor link="link_70"/>
    <successor link="rotor_70"/>
    <ratio value="6.0"/>
  </constraint>
  <joint independent="true" name="link_70_to_link_71" type="revolute">
    <parent link="link_70"/>
    <child link="link_71"/>
    <axis xyz="0 0 1"/>
    <origin xyz="1.0 0.0 0.0"/>
    <limit effort="30" lower="-10" upper="10" velocity="1.0"/>
  </joint>
  <link name="link_71">
    <inertial>
      <mass value="1"/>
      <origin rpy="0 0 0" xyz="0.5 0 0"/>
      <inertia ixx="1" ixy="0" ixz="0" iyy="1" iyz="0" izz="1"/>
    </inertial>
  </link>
  <joint independent="false" name="link_70_to_rotor_71" type="revolute">
    <parent link="link_70"/>
    <child link="rotor_71"/>
    <axis xyz="0 0 1"/>
    <origin xyz="1.0 0.0 0.0"/>
    <limit effort="30" lower="-10" upper="10" velocity="1.0"/>
  </joint>
  <link name="rotor_71">
    <inertial>
      <mass value="0"/>
      <origin rpy="0 0 0" xyz="0 0 0"/>
      <inertia ixx="1e-4" ixy="0" ixz="0" iyy="1e-4" iyz="0" izz="1e-4"/>
    </inertial>
  </link>
  <constraint name="transmission_71" type="rolling">
    <predecessor link="link_71"/>
    <successor link="rotor_71"/>
    <ratio value="6.0"/>
  </constraint>
  <joint independent="true" name="link_71_to_link_72" type="revolute">
    <parent link="link_71"/>
    <child link="link_72"/>
    <axis xyz="0 0 1"/>
    <origin xyz="1.0 0.0 0.0"/>
    <limit effort="30" lower="-10" upper="10" velocity="1.0"/>
  </joint>
  <link name="link_72">
    <inertial>
      <mass value="1"/>
      <origin rpy="0 0 0" xyz="0.5 0 0"/>
      <inertia ixx="1" ixy="0" ixz="0" iyy="1" iyz="0" izz="1"/>
    </inertial>
  </link>
  <joint independent="false" name="link_70_to_rotor_72" type="revolute">
    <parent link="link_70"/>
    <child link="rotor_72"/>
    <axis xyz="0 0 1"/>
    <origin xyz="1.0 0.0 0.0"/>
    <limit effort="30" lower="-10" upper="10" velocity="1.0"/>
  </joint>
  <link name="rotor_72">
    <inertial>
      <mass value="0"/>
      <origin rpy="0 0 0" xyz="0 0 0"/>
      <inertia ixx="1e-4" ixy="0" ixz="0" iyy="1e-4" iyz="0" izz="1e-4"/>
    </inertial>
  </link>
  <constraint name="transmission_72" type="rolling">
    <predecessor link="link_72"/>
    <successor link="rotor_72"/>
    <ratio value="6.0"/>
  </constraint>
  <joint independent="true" name="link_8_to_link_49" type="revolute">
    <parent link="link_8"/>
    <child link="link_49"/>
    <axis xyz="0 0 1"/>
    <origin xyz="1.0 0.0 0.0"/>
    <limit effort="30" lower="-10" upper="10" velocity="1.0"/>
  </joint>
  <link name="link_49">
    <inertial>
      <mass value="1"/>
      <origin rpy="0 0 0" xyz="0.5 0 0"/>
      <inertia ixx="1" ixy="0" ixz="0" iyy="1" iyz="0" izz="1"/>
    </inertial>
  </link>
  <joint independent="false" name="link_8_to_rotor_49" type="revolute">
    <parent link="link_8"/>
    <child link="rotor_49"/>
    <axis xyz="0 0 1"/>
    <origin xyz="1.0 0.0 0.0"/>
    <limit effort="30" lower="-10" upper="10" velocity="1.0"/>
  </joint>
  <link name="rotor_49">
    <inertial>
      <mass value="0"/>
      <origin rpy="0 0 0" xyz="0 0 0"/>
      <inertia ixx="1e-4" ixy="0" ixz="0" iyy="1e-4" iyz="0" izz="1e-4"/>
    </inertial>
  </link>
  <constraint name="transmission_49" type="rolling">
    <predecessor link="link_49"/>
    <successor link="rotor_49"/>
    <ratio value="6.0"/>
  </constraint>
  <joint independent="true" name="link_49_to_link_50" type="revolute">
    <parent link="link_49"/>
    <child link="link_50"/>
    <axis xyz="0 0 1"/>
    <origin xyz="1.0 0.0 0.0"/>
    <limit effort="30" lower="-10" upper="10" velocity="1.0"/>
  </joint>
  <link name="link_50">
    <inertial>
      <mass value="1"/>
      <origin rpy="0 0 0" xyz="0.5 0 0"/>
      <inertia ixx="1" ixy="0" ixz="0" iyy="1" iyz="0" izz="1"/>
    </inertial>
  </link>
  <joint independent="false" name="link_8_to_rotor_50" type="revolute">
    <parent link="link_8"/>
    <child link="rotor_50"/>
    <axis xyz="0 0 1"/>
    <origin xyz="1.0 0.0 0.0"/>
    <limit effort="30" lower="-10" upper="10" velocity="1.0"/>
  </joint>
  <link name="rotor_50">
    <inertial>
      <mass value="0"/>
      <origin rpy="0 0 0" xyz="0 0 0"/>
      <inertia ixx="1e-4" ixy="0" ixz="0" iyy="1e-4" iyz="0" izz="1e-4"/>
    </inertial>
  </link>
  <constraint name="transmission_50" type="rolling">
    <predecessor link="link_50"/>
    <successor link="rotor_50"/>
    <ratio value="6.0"/>
  </constraint>
  <joint independent="true" name="link_50_to_link_51" type="revolute">
    <parent link="link_50"/>
    <child link="link_51"/>
    <axis xyz="0 0 1"/>
    <origin xyz="1.0 0.0 0.0"/>
    <limit effort="30" lower="-10" upper="10" velocity="1.0"/>
  </joint>
  <link name="link_51">
    <inertial>
      <mass value="1"/>
      <origin rpy="0 0 0" xyz="0.5 0 0"/>
      <inertia ixx="1" ixy="0" ixz="0" iyy="1" iyz="0" izz="1"/>
    </inertial>
  </link>
  <joint independent="false" name="link_50_to_rotor_51" type="revolute">
    <parent link="link_50"/>
    <child link="rotor_51"/>
    <axis xyz="0 0 1"/>
    <origin xyz="1.0 0.0 0.0"/>
    <limit effort="30" lower="-10" upper="10" velocity="1.0"/>
  </joint>
  <link name="rotor_51">
    <inertial>
      <mass value="0"/>
      <origin rpy="0 0 0" xyz="0 0 0"/>
      <inertia ixx="1e-4" ixy="0" ixz="0" iyy="1e-4" iyz="0" izz="1e-4"/>
    </inertial>
  </link>
  <constraint name="transmission_51" type="rolling">
    <predecessor link="link_51"/>
    <successor link="rotor_51"/>
    <ratio value="6.0"/>
  </constraint>
  <joint independent="true" name="link_51_to_link_52" type="revolute">
    <parent link="link_51"/>
    <child link="link_52"/>
    <axis xyz="0 0 1"/>
    <origin xyz="1.0 0.0 0.0"/>
    <limit effort="30" lower="-10" upper="10" velocity="1.0"/>
  </joint>
  <link name="link_52">
    <inertial>
      <mass value="1"/>
      <origin rpy="0 0 0" xyz="0.5 0 0"/>
      <inertia ixx="1" ixy="0" ixz="0" iyy="1" iyz="0" izz="1"/>
    </inertial>
  </link>
  <joint independent="false" name="link_50_to_rotor_52" type="revolute">
    <parent link="link_50"/>
    <child link="rotor_52"/>
    <axis xyz="0 0 1"/>
    <origin xyz="1.0 0.0 0.0"/>
    <limit effort="30" lower="-10" upper="10" velocity="1.0"/>
  </joint>
  <link name="rotor_52">
    <inertial>
      <mass value="0"/>
      <origin rpy="0 0 0" xyz="0 0 0"/>
      <inertia ixx="1e-4" ixy="0" ixz="0" iyy="1e-4" iyz="0" izz="1e-4"/>
    </inertial>
  </link>
  <constraint name="transmission_52" type="rolling">
    <predecessor link="link_52"/>
    <successor link="rotor_52"/>
    <ratio value="6.0"/>
  </constraint>
  <joint independent="true" name="link_52_to_link_53" type="revolute">
    <parent link="link_52"/>
    <child link="link_53"/>
    <axis xyz="0 0 1"/>
    <origin xyz="1.0 0.0 0.0"/>
    <limit effort="30" lower="-10" upper="10" velocity="1.0"/>
  </joint>
  <link name="link_53">
    <inertial>
      <mass value="1"/>
      <origin rpy="0 0 0" xyz="0.5 0 0"/>
      <inertia ixx="1" ixy="0" ixz="0" iyy="1" iyz="0" izz="1"/>
    </inertial>
  </link>
  <joint independent="false" name="link_52_to_rotor_53" type="revolute">
    <parent link="link_52"/>
    <child link="rotor_53"/>
    <axis xyz="0 0 1"/>
    <origin xyz="1.0 0.0 0.0"/>
    <limit effort="30" lower="-10" upper="10" velocity="1.0"/>
  </joint>
  <link name="rotor_53">
    <inertial>
      <mass value="0"/>
      <origin rpy="0 0 0" xyz="0 0 0"/>
      <inertia ixx="1e-4" ixy="0" ixz="0" iyy="1e-4" iyz="0" izz="1e-4"/>
    </inertial>
  </link>
  <constraint name="transmission_53" type="rolling">
    <predecessor link="link_53"/>
    <successor link="rotor_53"/>
    <ratio value="6.0"/>
  </constraint>
  <joint independent="true" name="link_53_to_link_54" type="revolute">
    <parent link="link_53"/>
    <child link="link_54"/>
    <axis xyz="0 0 1"/>
    <origin xyz="1.0 0.0 0.0"/>
    <limit effort="30" lower="-10" upper="10" velocity="1.0"/>
  </joint>
  <link name="link_54">
    <inertial>
      <mass value="1"/>
      <origin rpy="0 0 0" xyz="0.5 0 0"/>
      <inertia ixx="1" ixy="0" ixz="0" iyy="1" iyz="0" izz="1"/>
    </inertial>
  </link>
  <joint independent="false" name="link_52_to_rotor_54" type="revolute">
    <parent link="link_52"/>
    <child link="rotor_54"/>
    <axis xyz="0 0 1"/>
    <origin xyz="1.0 0.0 0.0"/>
    <limit effort="30" lower="-10" upper="10" velocity="1.0"/>
  </joint>
  <link name="rotor_54">
    <inertial>
      <mass value="0"/>
      <origin rpy="0 0 0" xyz="0 0 0"/>
      <inertia ixx="1e-4" ixy="0" ixz="0" iyy="1e-4" iyz="0" izz="1e-4"/>
    </inertial>
  </link>
  <constraint name="transmission_54" type="rolling">
    <predecessor link="link_54"/>
    <successor link="rotor_54"/>
    <ratio value="6.0"/>
  </constraint>
  <joint independent="true" name="link_54_to_link_55" type="revolute">
    <parent link="link_54"/>
    <child link="link_55"/>
    <axis xyz="0 0 1"/>
    <origin xyz="1.0 0.0 0.0"/>
    <limit effort="30" lower="-10" upper="10" velocity="1.0"/>
  </joint>
  <link name="link_55">
    <inertial>
      <mass value="1"/>
      <origin rpy="0 0 0" xyz="0.5 0 0"/>
      <inertia ixx="1" ixy="0" ixz="0" iyy="1" iyz="0" izz="1"/>
    </inertial>
  </link>
  <joint independent="false" name="link_54_to_rotor_55" type="revolute">
    <parent link="link_54"/>
    <child link="rotor_55"/>
    <axis xyz="0 0 1"/>
    <origin xyz="1.0 0.0 0.0"/>
    <limit effort="30" lower="-10" upper="10" velocity="1.0"/>
  </joint>
  <link name="rotor_55">
    <inertial>
      <mass value="0"/>
      <origin rpy="0 0 0" xyz="0 0 0"/>
      <inertia ixx="1e-4" ixy="0" ixz="0" iyy="1e-4" iyz="0" izz="1e-4"/>
    </inertial>
  </link>
  <constraint name="transmission_55" type="rolling">
    <predecessor link="link_55"/>
    <successor link="rotor_55"/>
    <ratio value="6.0"/>
  </constraint>
  <joint independent="true" name="link_55_to_link_56" type="revolute">
    <parent link="link_55"/>
    <child link="link_56"/>
    <axis xyz="0 0 1"/>
    <origin xyz="1.0 0.0 0.0"/>
    <limit effort="30" lower="-10" upper="10" velocity="1.0"/>
  </joint>
  <link name="link_56">
    <inertial>
      <mass value="1"/>
      <origin rpy="0 0 0" xyz="0.5 0 0"/>
      <inertia ixx="1" ixy="0" ixz="0" iyy="1" iyz="0" izz="1"/>
    </inertial>
  </link>
  <joint independent="false" name="link_54_to_rotor_56" type="revolute">
    <parent link="link_54"/>
    <child link="rotor_56"/>
    <axis xyz="0 0 1"/>
    <origin xyz="1.0 0.0 0.0"/>
    <limit effort="30" lower="-10" upper="10" velocity="1.0"/>
  </joint>
  <link name="rotor_56">
    <inertial>
      <mass value="0"/>
      <origin rpy="0 0 0" xyz="0 0 0"/>
      <inertia ixx="1e-4" ixy="0" ixz="0" iyy="1e-4" iyz="0" izz="1e-4"/>
    </inertial>
  </link>
  <constraint name="transmission_56" type="rolling">
    <predecessor link="link_56"/>
    <successor link="rotor_56"/>
    <ratio value="6.0"/>
  </constraint>
  <joint independent="true" name="link_56_to_link_57" type="revolute">
    <parent link="link_56"/>
    <child link="link_57"/>
    <axis xyz="0 0 1"/>
    <origin xyz="1.0 0.0 0.0"/>
    <limit effort="30" lower="-10" upper="10" velocity="1.0"/>
  </joint>
  <link name="link_57">
    <inertial>
      <mass value="1"/>
      <origin rpy="0 0 0" xyz="0.5 0 0"/>
      <inertia ixx="1" ixy="0" ixz="0" iyy="1" iyz="0" izz="1"/>
    </inertial>
  </link>
  <joint independent="false" name="link_56_to_rotor_57" type="revolute">
    <parent link="link_56"/>
    <child link="rotor_57"/>
    <axis xyz="0 0 1"/>
    <origin xyz="1.0 0.0 0.0"/>
    <limit effort="30" lower="-10" upper="10" velocity="1.0"/>
  </joint>
  <link name="rotor_57">
    <inertial>
      <mass value="0"/>
      <origin rpy="0 0 0" xyz="0 0 0"/>
      <inertia ixx="1e-4" ixy="0" ixz="0" iyy="1e-4" iyz="0" izz="1e-4"/>
    </inertial>
  </link>
  <constraint name="transmission_57" type="rolling">
    <predecessor link="link_57"/>
    <successor link="rotor_57"/>
    <ratio value="6.0"/>
  </constraint>
  <joint independent="true" name="link_57_to_link_58" type="revolute">
    <parent link="link_57"/>
    <child link="link_58"/>
    <axis xyz="0 0 1"/>
    <origin xyz="1.0 0.0 0.0"/>
    <limit effort="30" lower="-10" upper="10" velocity="1.0"/>
  </joint>
  <link name="link_58">
    <inertial>
      <mass value="1"/>
      <origin rpy="0 0 0" xyz="0.5 0 0"/>
      <inertia ixx="1" ixy="0" ixz="0" iyy="1" iyz="0" izz="1"/>
    </inertial>
  </link>
  <joint independent="false" name="link_56_to_rotor_58" type="revolute">
    <parent link="link_56"/>
    <child link="rotor_58"/>
    <axis xyz="0 0 1"/>
    <origin xyz="1.0 0.0 0.0"/>
    <limit effort="30" lower="-10" upper="10" velocity="1.0"/>
  </joint>
  <link name="rotor_58">
    <inertial>
      <mass value="0"/>
      <origin rpy="0 0 0" xyz="0 0 0"/>
      <inertia ixx="1e-4" ixy="0" ixz="0" iyy="1e-4" iyz="0" izz="1e-4"/>
    </inertial>
  </link>
  <constraint name="transmission_58" type="rolling">
    <predecessor link="link_58"/>
    <successor link="rotor_58"/>
    <ratio value="6.0"/>
  </constraint>
  <joint independent="true" name="link_58_to_link_59" type="revolute">
    <parent link="link_58"/>
    <child link="link_59"/>
    <axis xyz="0 0 1"/>
    <origin xyz="1.0 0.0 0.0"/>
    <limit effort="30" lower="-10" upper="10" velocity="1.0"/>
  </joint>
  <link name="link_59">
    <inertial>
      <mass value="1"/>
      <origin rpy="0 0 0" xyz="0.5 0 0"/>
      <inertia ixx="1" ixy="0" ixz="0" iyy="1" iyz="0" izz="1"/>
    </inertial>
  </link>
  <joint independent="false" name="link_58_to_rotor_59" type="revolute">
    <parent link="link_58"/>
    <child link="rotor_59"/>
    <axis xyz="0 0 1"/>
    <origin xyz="1.0 0.0 0.0"/>
    <limit effort="30" lower="-10" upper="10" velocity="1.0"/>
  </joint>
  <link name="rotor_59">
    <inertial>
      <mass value="0"/>
      <origin rpy="0 0 0" xyz="0 0 0"/>
      <inertia ixx="1e-4" ixy="0" ixz="0" iyy="1e-4" iyz="0" izz="1e-4"/>
    </inertial>
  </link>
  <constraint name="transmission_59" type="rolling">
    <predecessor link="link_59"/>
    <successor link="rotor_59"/>
    <ratio value="6.0"/>
  </constraint>
  <joint independent="true" name="link_59_to_link_60" type="revolute">
    <parent link="link_59"/>
    <child link="link_60"/>
    <axis xyz="0 0 1"/>
    <origin xyz="1.0 0.0 0.0"/>
    <limit effort="30" lower="-10" upper="10" velocity="1.0"/>
  </joint>
  <link name="link_60">
    <inertial>
      <mass value="1"/>
      <origin rpy="0 0 0" xyz="0.5 0 0"/>
      <inertia ixx="1" ixy="0" ixz="0" iyy="1" iyz="0" izz="1"/>
    </inertial>
  </link>
  <joint independent="false" name="link_58_to_rotor_60" type="revolute">
    <parent link="link_58"/>
    <child link="rotor_60"/>
    <axis xyz="0 0 1"/>
    <origin xyz="1.0 0.0 0.0"/>
    <limit effort="30" lower="-10" upper="10" velocity="1.0"/>
  </joint>
  <link name="rotor_60">
    <inertial>
      <mass value="0"/>
      <origin rpy="0 0 0" xyz="0 0 0"/>
      <inertia ixx="1e-4" ixy="0" ixz="0" iyy="1e-4" iyz="0" izz="1e-4"/>
    </inertial>
  </link>
  <constraint name="transmission_60" type="rolling">
    <predecessor link="link_60"/>
    <successor link="rotor_60"/>
    <ratio value="6.0"/>
  </constraint>
  <joint independent="true" name="link_6_to_link_37" type="revolute">
    <parent link="link_6"/>
    <child link="link_37"/>
    <axis xyz="0 0 1"/>
    <origin xyz="1.0 0.0 0.0"/>
    <limit effort="30" lower="-10" upper="10" velocity="1.0"/>
  </joint>
  <link name="link_37">
    <inertial>
      <mass value="1"/>
      <origin rpy="0 0 0" xyz="0.5 0 0"/>
      <inertia ixx="1" ixy="0" ixz="0" iyy="1" iyz="0" izz="1"/>
    </inertial>
  </link>
  <joint independent="false" name="link_6_to_rotor_37" type="revolute">
    <parent link="link_6"/>
    <child link="rotor_37"/>
    <axis xyz="0 0 1"/>
    <origin xyz="1.0 0.0 0.0"/>
    <limit effort="30" lower="-10" upper="10" velocity="1.0"/>
  </joint>
  <link name="rotor_37">
    <inertial>
      <mass value="0"/>
      <origin rpy="0 0 0" xyz="0 0 0"/>
      <inertia ixx="1e-4" ixy="0" ixz="0" iyy="1e-4" iyz="0" izz="1e-4"/>
    </inertial>
  </link>
  <constraint name="transmission_37" type="rolling">
    <predecessor link="link_37"/>
    <successor link="rotor_37"/>
    <ratio value="6.0"/>
  </constraint>
  <joint independent="true" name="link_37_to_link_38" type="revolute">
    <parent link="link_37"/>
    <child link="link_38"/>
    <axis xyz="0 0 1"/>
    <origin xyz="1.0 0.0 0.0"/>
    <limit effort="30" lower="-10" upper="10" velocity="1.0"/>
  </joint>
  <link name="link_38">
    <inertial>
      <mass value="1"/>
      <origin rpy="0 0 0" xyz="0.5 0 0"/>
      <inertia ixx="1" ixy="0" ixz="0" iyy="1" iyz="0" izz="1"/>
    </inertial>
  </link>
  <joint independent="false" name="link_6_to_rotor_38" type="revolute">
    <parent link="link_6"/>
    <child link="rotor_38"/>
    <axis xyz="0 0 1"/>
    <origin xyz="1.0 0.0 0.0"/>
    <limit effort="30" lower="-10" upper="10" velocity="1.0"/>
  </joint>
  <link name="rotor_38">
    <inertial>
      <mass value="0"/>
      <origin rpy="0 0 0" xyz="0 0 0"/>
      <inertia ixx="1e-4" ixy="0" ixz="0" iyy="1e-4" iyz="0" izz="1e-4"/>
    </inertial>
  </link>
  <constraint name="transmission_38" type="rolling">
    <predecessor link="link_38"/>
    <successor link="rotor_38"/>
    <ratio value="6.0"/>
  </constraint>
  <joint independent="true" name="link_38_to_link_39" type="revolute">
    <parent link="link_38"/>
    <child link="link_39"/>
    <axis xyz="0 0 1"/>
    <origin xyz="1.0 0.0 0.0"/>
    <limit effort="30" lower="-10" upper="10" velocity="1.0"/>
  </joint>
  <link name="link_39">
    <inertial>
      <mass value="1"/>
      <origin rpy="0 0 0" xyz="0.5 0 0"/>
      <inertia ixx="1" ixy="0" ixz="0" iyy="1" iyz="0" izz="1"/>
    </inertial>
  </link>
  <joint independent="false" name="link_38_to_rotor_39" type="revolute">
    <parent link="link_38"/>
    <child link="rotor_39"/>
    <axis xyz="0 0 1"/>
    <origin xyz="1.0 0.0 0.0"/>
    <limit effort="30" lower="-10" upper="10" velocity="1.0"/>
  </joint>
  <link name="rotor_39">
    <inertial>
      <mass value="0"/>
      <origin rpy="0 0 0" xyz="0 0 0"/>
      <inertia ixx="1e-4" ixy="0" ixz="0" iyy="1e-4" iyz="0" izz="1e-4"/>
    </inertial>
  </link>
  <constraint name="transmission_39" type="rolling">
    <predecessor link="link_39"/>
    <successor link="rotor_39"/>
    <ratio value="6.0"/>
  </constraint>
  <joint independent="true" name="link_39_to_link_40" type="revolute">
    <parent link="link_39"/>
    <child link="link_40"/>
    <axis xyz="0 0 1"/>
    <origin xyz="1.0 0.0 0.0"/>
    <limit effort="30" lower="-10" upper="10" velocity="1.0"/>
  </joint>
  <link name="link_40">
    <inertial>
      <mass value="1"/>
      <origin rpy="0 0 0" xyz="0.5 0 0"/>
      <inertia ixx="1" ixy="0" ixz="0" iyy="1" iyz="0" izz="1"/>
    </inertial>
  </link>
  <joint independent="false" name="link_38_to_rotor_40" type="revolute">
    <parent link="link_38"/>
    <child link="rotor_40"/>
    <axis xyz="0 0 1"/>
    <origin xyz="1.0 0.0 0.0"/>
    <limit effort="30" lower="-10" upper="10" velocity="1.0"/>
  </joint>
  <link name="rotor_40">
    <inertial>
      <mass value="0"/>
      <origin rpy="0 0 0" xyz="0 0 0"/>
      <inertia ixx="1e-4" ixy="0" ixz="0" iyy="1e-4" iyz="0" izz="1e-4"/>
    </inertial>
  </link>
  <constraint name="transmission_40" type="rolling">
    <predecessor link="link_40"/>
    <successor link="rotor_40"/>
    <ratio value="6.0"/>
  </constraint>
  <joint independent="true" name="link_40_to_link_41" type="revolute">
    <parent link="link_40"/>
    <child link="link_41"/>
    <axis xyz="0 0 1"/>
    <origin xyz="1.0 0.0 0.0"/>
    <limit effort="30" lower="-10" upper="10" velocity="1.0"/>
  </joint>
  <link name="link_41">
    <inertial>
      <mass value="1"/>
      <origin rpy="0 0 0" xyz="0.5 0 0"/>
      <inertia ixx="1" ixy="0" ixz="0" iyy="1" iyz="0" izz="1"/>
    </inertial>
  </link>
  <joint independent="false" name="link_40_to_rotor_41" type="revolute">
    <parent link="link_40"/>
    <child link="rotor_41"/>
    <axis xyz="0 0 1"/>
    <origin xyz="1.0 0.0 0.0"/>
    <limit effort="30" lower="-10" upper="10" velocity="1.0"/>
  </joint>
  <link name="rotor_41">
    <inertial>
      <mass value="0"/>
      <origin rpy="0 0 0" xyz="0 0 0"/>
      <inertia ixx="1e-4" ixy="0" ixz="0" iyy="1e-4" iyz="0" izz="1e-4"/>
    </inertial>
  </link>
  <constraint name="transmission_41" type="rolling">
    <predecessor link="link_41"/>
    <successor link="rotor_41"/>
    <ratio value="6.0"/>
  </constraint>
  <joint independent="true" name="link_41_to_link_42" type="revolute">
    <parent link="link_41"/>
    <child link="link_42"/>
    <axis xyz="0 0 1"/>
    <origin xyz="1.0 0.0 0.0"/>
    <limit effort="30" lower="-10" upper="10" velocity="1.0"/>
  </joint>
  <link name="link_42">
    <inertial>
      <mass value="1"/>
      <origin rpy="0 0 0" xyz="0.5 0 0"/>
      <inertia ixx="1" ixy="0" ixz="0" iyy="1" iyz="0" izz="1"/>
    </inertial>
  </link>
  <joint independent="false" name="link_40_to_rotor_42" type="revolute">
    <parent link="link_40"/>
    <child link="rotor_42"/>
    <axis xyz="0 0 1"/>
    <origin xyz="1.0 0.0 0.0"/>
    <limit effort="30" lower="-10" upper="10" velocity="1.0"/>
  </joint>
  <link name="rotor_42">
    <inertial>
      <mass value="0"/>
      <origin rpy="0 0 0" xyz="0 0 0"/>
      <inertia ixx="1e-4" ixy="0" ixz="0" iyy="1e-4" iyz="0" izz="1e-4"/>
    </inertial>
  </link>
  <constraint name="transmission_42" type="rolling">
    <predecessor link="link_42"/>
    <successor link="rotor_42"/>
    <ratio value="6.0"/>
  </constraint>
  <joint independent="true" name="link_42_to_link_43" type="revolute">
    <parent link="link_42"/>
    <child link="link_43"/>
    <axis xyz="0 0 1"/>
    <origin xyz="1.0 0.0 0.0"/>
    <limit effort="30" lower="-10" upper="10" velocity="1.0"/>
  </joint>
  <link name="link_43">
    <inertial>
      <mass value="1"/>
      <origin rpy="0 0 0" xyz="0.5 0 0"/>
      <inertia ixx="1" ixy="0" ixz="0" iyy="1" iyz="0" izz="1"/>
    </inertial>
  </link>
  <joint independent="false" name="link_42_to_rotor_43" type="revolute">
    <parent link="link_42"/>
    <child link="rotor_43"/>
    <axis xyz="0 0 1"/>
    <origin xyz="1.0 0.0 0.0"/>
    <limit effort="30" lower="-10" upper="10" velocity="1.0"/>
  </joint>
  <link name="rotor_43">
    <inertial>
      <mass value="0"/>
      <origin rpy="0 0 0" xyz="0 0 0"/>
      <inertia ixx="1e-4" ixy="0" ixz="0" iyy="1e-4" iyz="0" izz="1e-4"/>
    </inertial>
  </link>
  <constraint name="transmission_43" type="rolling">
    <predecessor link="link_43"/>
    <successor link="rotor_43"/>
    <ratio value="6.0"/>
  </constraint>
  <joint independent="true" name="link_43_to_link_44" type="revolute">
    <parent link="link_43"/>
    <child link="link_44"/>
    <axis xyz="0 0 1"/>
    <origin xyz="1.0 0.0 0.0"/>
    <limit effort="30" lower="-10" upper="10" velocity="1.0"/>
  </joint>
  <link name="link_44">
    <inertial>
      <mass value="1"/>
      <origin rpy="0 0 0" xyz="0.5 0 0"/>
      <inertia ixx="1" ixy="0" ixz="0" iyy="1" iyz="0" izz="1"/>
    </inertial>
  </link>
  <joint independent="false" name="link_42_to_rotor_44" type="revolute">
    <parent link="link_42"/>
    <child link="rotor_44"/>
    <axis xyz="0 0 1"/>
    <origin xyz="1.0 0.0 0.0"/>
    <limit effort="30" lower="-10" upper="10" velocity="1.0"/>
  </joint>
  <link name="rotor_44">
    <inertial>
      <mass value="0"/>
      <origin rpy="0 0 0" xyz="0 0 0"/>
      <inertia ixx="1e-4" ixy="0" ixz="0" iyy="1e-4" iyz="0" izz="1e-4"/>
    </inertial>
  </link>
  <constraint name="transmission_44" type="rolling">
    <predecessor link="link_44"/>
    <successor link="rotor_44"/>
    <ratio value="6.0"/>
  </constraint>
  <joint independent="true" name="link_44_to_link_45" type="revolute">
    <parent link="link_44"/>
    <child link="link_45"/>
    <axis xyz="0 0 1"/>
    <origin xyz="1.0 0.0 0.0"/>
    <limit effort="30" lower="-10" upper="10" velocity="1.0"/>
  </joint>
  <link name="link_45">
    <inertial>
      <mass value="1"/>
      <origin rpy="0 0 0" xyz="0.5 0 0"/>
      <inertia ixx="1" ixy="0" ixz="0" iyy="1" iyz="0" izz="1"/>
    </inertial>
  </link>
  <joint independent="false" name="link_44_to_rotor_45" type="revolute">
    <parent link="link_44"/>
    <child link="rotor_45"/>
    <axis xyz="0 0 1"/>
    <origin xyz="1.0 0.0 0.0"/>
    <limit effort="30" lower="-10" upper="10" velocity="1.0"/>
  </joint>
  <link name="rotor_45">
    <inertial>
      <mass value="0"/>
      <origin rpy="0 0 0" xyz="0 0 0"/>
      <inertia ixx="1e-4" ixy="0" ixz="0" iyy="1e-4" iyz="0" izz="1e-4"/>
    </inertial>
  </link>
  <constraint name="transmission_45" type="rolling">
    <predecessor link="link_45"/>
    <successor link="rotor_45"/>
    <ratio value="6.0"/>
  </constraint>
  <joint independent="true" name="link_45_to_link_46" type="revolute">
    <parent link="link_45"/>
    <child link="link_46"/>
    <axis xyz="0 0 1"/>
    <origin xyz="1.0 0.0 0.0"/>
    <limit effort="30" lower="-10" upper="10" velocity="1.0"/>
  </joint>
  <link name="link_46">
    <inertial>
      <mass value="1"/>
      <origin rpy="0 0 0" xyz="0.5 0 0"/>
      <inertia ixx="1" ixy="0" ixz="0" iyy="1" iyz="0" izz="1"/>
    </inertial>
  </link>
  <joint independent="false" name="link_44_to_rotor_46" type="revolute">
    <parent link="link_44"/>
    <child link="rotor_46"/>
    <axis xyz="0 0 1"/>
    <origin xyz="1.0 0.0 0.0"/>
    <limit effort="30" lower="-10" upper="10" velocity="1.0"/>
  </joint>
  <link name="rotor_46">
    <inertial>
      <mass value="0"/>
      <origin rpy="0 0 0" xyz="0 0 0"/>
      <inertia ixx="1e-4" ixy="0" ixz="0" iyy="1e-4" iyz="0" izz="1e-4"/>
    </inertial>
  </link>
  <constraint name="transmission_46" type="rolling">
    <predecessor link="link_46"/>
    <successor link="rotor_46"/>
    <ratio value="6.0"/>
  </constraint>
  <joint independent="true" name="link_46_to_link_47" type="revolute">
    <parent link="link_46"/>
    <child link="link_47"/>
    <axis xyz="0 0 1"/>
    <origin xyz="1.0 0.0 0.0"/>
    <limit effort="30" lower="-10" upper="10" velocity="1.0"/>
  </joint>
  <link name="link_47">
    <inertial>
      <mass value="1"/>
      <origin rpy="0 0 0" xyz="0.5 0 0"/>
      <inertia ixx="1" ixy="0" ixz="0" iyy="1" iyz="0" izz="1"/>
    </inertial>
  </link>
  <joint independent="false" name="link_46_to_rotor_47" type="revolute">
    <parent link="link_46"/>
    <child link="rotor_47"/>
    <axis xyz="0 0 1"/>
    <origin xyz="1.0 0.0 0.0"/>
    <limit effort="30" lower="-10" upper="10" velocity="1.0"/>
  </joint>
  <link name="rotor_47">
    <inertial>
      <mass value="0"/>
      <origin rpy="0 0 0" xyz="0 0 0"/>
      <inertia ixx="1e-4" ixy="0" ixz="0" iyy="1e-4" iyz="0" izz="1e-4"/>
    </inertial>
  </link>
  <constraint name="transmission_47" type="rolling">
    <predecessor link="link_47"/>
    <successor link="rotor_47"/>
    <ratio value="6.0"/>
  </constraint>
  <joint independent="true" name="link_47_to_link_48" type="revolute">
    <parent link="link_47"/>
    <child link="link_48"/>
    <axis xyz="0 0 1"/>
    <origin xyz="1.0 0.0 0.0"/>
    <limit effort="30" lower="-10" upper="10" velocity="1.0"/>
  </joint>
  <link name="link_48">
    <inertial>
      <mass value="1"/>
      <origin rpy="0 0 0" xyz="0.5 0 0"/>
      <inertia ixx="1" ixy="0" ixz="0" iyy="1" iyz="0" izz="1"/>
    </inertial>
  </link>
  <joint independent="false" name="link_46_to_rotor_48" type="revolute">
    <parent link="link_46"/>
    <child link="rotor_48"/>
    <axis xyz="0 0 1"/>
    <origin xyz="1.0 0.0 0.0"/>
    <limit effort="30" lower="-10" upper="10" velocity="1.0"/>
  </joint>
  <link name="rotor_48">
    <inertial>
      <mass value="0"/>
      <origin rpy="0 0 0" xyz="0 0 0"/>
      <inertia ixx="1e-4" ixy="0" ixz="0" iyy="1e-4" iyz="0" izz="1e-4"/>
    </inertial>
  </link>
  <constraint name="transmission_48" type="rolling">
    <predecessor link="link_48"/>
    <successor link="rotor_48"/>
    <ratio value="6.0"/>
  </constraint>
  <joint independent="true" name="link_4_to_link_25" type="revolute">
    <parent link="link_4"/>
    <child link="link_25"/>
    <axis xyz="0 0 1"/>
    <origin xyz="1.0 0.0 0.0"/>
    <limit effort="30" lower="-10" upper="10" velocity="1.0"/>
  </joint>
  <link name="link_25">
    <inertial>
      <mass value="1"/>
      <origin rpy="0 0 0" xyz="0.5 0 0"/>
      <inertia ixx="1" ixy="0" ixz="0" iyy="1" iyz="0" izz="1"/>
    </inertial>
  </link>
  <joint independent="false" name="link_4_to_rotor_25" type="revolute">
    <parent link="link_4"/>
    <child link="rotor_25"/>
    <axis xyz="0 0 1"/>
    <origin xyz="1.0 0.0 0.0"/>
    <limit effort="30" lower="-10" upper="10" velocity="1.0"/>
  </joint>
  <link name="rotor_25">
    <inertial>
      <mass value="0"/>
      <origin rpy="0 0 0" xyz="0 0 0"/>
      <inertia ixx="1e-4" ixy="0" ixz="0" iyy="1e-4" iyz="0" izz="1e-4"/>
    </inertial>
  </link>
  <constraint name="transmission_25" type="rolling">
    <predecessor link="link_25"/>
    <successor link="rotor_25"/>
    <ratio value="6.0"/>
  </constraint>
  <joint independent="true" name="link_25_to_link_26" type="revolute">
    <parent link="link_25"/>
    <child link="link_26"/>
    <axis xyz="0 0 1"/>
    <origin xyz="1.0 0.0 0.0"/>
    <limit effort="30" lower="-10" upper="10" velocity="1.0"/>
  </joint>
  <link name="link_26">
    <inertial>
      <mass value="1"/>
      <origin rpy="0 0 0" xyz="0.5 0 0"/>
      <inertia ixx="1" ixy="0" ixz="0" iyy="1" iyz="0" izz="1"/>
    </inertial>
  </link>
  <joint independent="false" name="link_4_to_rotor_26" type="revolute">
    <parent link="link_4"/>
    <child link="rotor_26"/>
    <axis xyz="0 0 1"/>
    <origin xyz="1.0 0.0 0.0"/>
    <limit effort="30" lower="-10" upper="10" velocity="1.0"/>
  </joint>
  <link name="rotor_26">
    <inertial>
      <mass value="0"/>
      <origin rpy="0 0 0" xyz="0 0 0"/>
      <inertia ixx="1e-4" ixy="0" ixz="0" iyy="1e-4" iyz="0" izz="1e-4"/>
    </inertial>
  </link>
  <constraint name="transmission_26" type="rolling">
    <predecessor link="link_26"/>
    <successor link="rotor_26"/>
    <ratio value="6.0"/>
  </constraint>
  <joint independent="true" name="link_26_to_link_27" type="revolute">
    <parent link="link_26"/>
    <child link="link_27"/>
    <axis xyz="0 0 1"/>
    <origin xyz="1.0 0.0 0.0"/>
    <limit effort="30" lower="-10" upper="10" velocity="1.0"/>
  </joint>
  <link name="link_27">
    <inertial>
      <mass value="1"/>
      <origin rpy="0 0 0" xyz="0.5 0 0"/>
      <inertia ixx="1" ixy="0" ixz="0" iyy="1" iyz="0" izz="1"/>
    </inertial>
  </link>
  <joint independent="false" name="link_26_to_rotor_27" type="revolute">
    <parent link="link_26"/>
    <child link="rotor_27"/>
    <axis xyz="0 0 1"/>
    <origin xyz="1.0 0.0 0.0"/>
    <limit effort="30" lower="-10" upper="10" velocity="1.0"/>
  </joint>
  <link name="rotor_27">
    <inertial>
      <mass value="0"/>
      <origin rpy="0 0 0" xyz="0 0 0"/>
      <inertia ixx="1e-4" ixy="0" ixz="0" iyy="1e-4" iyz="0" izz="1e-4"/>
    </inertial>
  </link>
  <constraint name="transmission_27" type="rolling">
    <predecessor link="link_27"/>
    <successor link="rotor_27"/>
    <ratio value="6.0"/>
  </constraint>
  <joint independent="true" name="link_27_to_link_28" type="revolute">
    <parent link="link_27"/>
    <child link="link_28"/>
    <axis xyz="0 0 1"/>
    <origin xyz="1.0 0.0 0.0"/>
    <limit effort="30" lower="-10" upper="10" velocity="1.0"/>
  </joint>
  <link name="link_28">
    <inertial>
      <mass value="1"/>
      <origin rpy="0 0 0" xyz="0.5 0 0"/>
      <inertia ixx="1" ixy="0" ixz="0" iyy="1" iyz="0" izz="1"/>
    </inertial>
  </link>
  <joint independent="false" name="link_26_to_rotor_28" type="revolute">
    <parent link="link_26"/>
    <child link="rotor_28"/>
    <axis xyz="0 0 1"/>
    <origin xyz="1.0 0.0 0.0"/>
    <limit effort="30" lower="-10" upper="10" velocity="1.0"/>
  </joint>
  <link name="rotor_28">
    <inertial>
      <mass value="0"/>
      <origin rpy="0 0 0" xyz="0 0 0"/>
      <inertia ixx="1e-4" ixy="0" ixz="0" iyy="1e-4" iyz="0" izz="1e-4"/>
    </inertial>
  </link>
  <constraint name="transmission_28" type="rolling">
    <predecessor link="link_28"/>
    <successor link="rotor_28"/>
    <ratio value="6.0"/>
  </constraint>
  <joint independent="true" name="link_28_to_link_29" type="revolute">
    <parent link="link_28"/>
    <child link="link_29"/>
    <axis xyz="0 0 1"/>
    <origin xyz="1.0 0.0 0.0"/>
    <limit effort="30" lower="-10" upper="10" velocity="1.0"/>
  </joint>
  <link name="link_29">
    <inertial>
      <mass value="1"/>
      <origin rpy="0 0 0" xyz="0.5 0 0"/>
      <inertia ixx="1" ixy="0" ixz="0" iyy="1" iyz="0" izz="1"/>
    </inertial>
  </link>
  <joint independent="false" name="link_28_to_rotor_29" type="revolute">
    <parent link="link_28"/>
    <child link="rotor_29"/>
    <axis xyz="0 0 1"/>
    <origin xyz="1.0 0.0 0.0"/>
    <limit effort="30" lower="-10" upper="10" velocity="1.0"/>
  </joint>
  <link name="rotor_29">
    <inertial>
      <mass value="0"/>
      <origin rpy="0 0 0" xyz="0 0 0"/>
      <inertia ixx="1e-4" ixy="0" ixz="0" iyy="1e-4" iyz="0" izz="1e-4"/>
    </inertial>
  </link>
  <constraint name="transmission_29" type="rolling">
    <predecessor link="link_29"/>
    <successor link="rotor_29"/>
    <ratio value="6.0"/>
  </constraint>
  <joint independent="true" name="link_29_to_link_30" type="revolute">
    <parent link="link_29"/>
    <child link="link_30"/>
    <axis xyz="0 0 1"/>
    <origin xyz="1.0 0.0 0.0"/>
    <limit effort="30" lower="-10" upper="10" velocity="1.0"/>
  </joint>
  <link name="link_30">
    <inertial>
      <mass value="1"/>
      <origin rpy="0 0 0" xyz="0.5 0 0"/>
      <inertia ixx="1" ixy="0" ixz="0" iyy="1" iyz="0" izz="1"/>
    </inertial>
  </link>
  <joint independent="false" name="link_28_to_rotor_30" type="revolute">
    <parent link="link_28"/>
    <child link="rotor_30"/>
    <axis xyz="0 0 1"/>
    <origin xyz="1.0 0.0 0.0"/>
    <limit effort="30" lower="-10" upper="10" velocity="1.0"/>
  </joint>
  <link name="rotor_30">
    <inertial>
      <mass value="0"/>
      <origin rpy="0 0 0" xyz="0 0 0"/>
      <inertia ixx="1e-4" ixy="0" ixz="0" iyy="1e-4" iyz="0" izz="1e-4"/>
    </inertial>
  </link>
  <constraint name="transmission_30" type="rolling">
    <predecessor link="link_30"/>
    <successor link="rotor_30"/>
    <ratio value="6.0"/>
  </constraint>
  <joint independent="true" name="link_30_to_link_31" type="revolute">
    <parent link="link_30"/>
    <child link="link_31"/>
    <axis xyz="0 0 1"/>
    <origin xyz="1.0 0.0 0.0"/>
    <limit effort="30" lower="-10" upper="10" velocity="1.0"/>
  </joint>
  <link name="link_31">
    <inertial>
      <mass value="1"/>
      <origin rpy="0 0 0" xyz="0.5 0 0"/>
      <inertia ixx="1" ixy="0" ixz="0" iyy="1" iyz="0" izz="1"/>
    </inertial>
  </link>
  <joint independent="false" name="link_30_to_rotor_31" type="revolute">
    <parent link="link_30"/>
    <child link="rotor_31"/>
    <axis xyz="0 0 1"/>
    <origin xyz="1.0 0.0 0.0"/>
    <limit effort="30" lower="-10" upper="10" velocity="1.0"/>
  </joint>
  <link name="rotor_31">
    <inertial>
      <mass value="0"/>
      <origin rpy="0 0 0" xyz="0 0 0"/>
      <inertia ixx="1e-4" ixy="0" ixz="0" iyy="1e-4" iyz="0" izz="1e-4"/>
    </inertial>
  </link>
  <constraint name="transmission_31" type="rolling">
    <predecessor link="link_31"/>
    <successor link="rotor_31"/>
    <ratio value="6.0"/>
  </constraint>
  <joint independent="true" name="link_31_to_link_32" type="revolute">
    <parent link="link_31"/>
    <child link="link_32"/>
    <axis xyz="0 0 1"/>
    <origin xyz="1.0 0.0 0.0"/>
    <limit effort="30" lower="-10" upper="10" velocity="1.0"/>
  </joint>
  <link name="link_32">
    <inertial>
      <mass value="1"/>
      <origin rpy="0 0 0" xyz="0.5 0 0"/>
      <inertia ixx="1" ixy="0" ixz="0" iyy="1" iyz="0" izz="1"/>
    </inertial>
  </link>
  <joint independent="false" name="link_30_to_rotor_32" type="revolute">
    <parent link="link_30"/>
    <child link="rotor_32"/>
    <axis xyz="0 0 1"/>
    <origin xyz="1.0 0.0 0.0"/>
    <limit effort="30" lower="-10" upper="10" velocity="1.0"/>
  </joint>
  <link name="rotor_32">
    <inertial>
      <mass value="0"/>
      <origin rpy="0 0 0" xyz="0 0 0"/>
      <inertia ixx="1e-4" ixy="0" ixz="0" iyy="1e-4" iyz="0" izz="1e-4"/>
    </inertial>
  </link>
  <constraint name="transmission_32" type="rolling">
    <predecessor link="link_32"/>
    <successor link="rotor_32"/>
    <ratio value="6.0"/>
  </constraint>
  <joint independent="true" name="link_32_to_link_33" type="revolute">
    <parent link="link_32"/>
    <child link="link_33"/>
    <axis xyz="0 0 1"/>
    <origin xyz="1.0 0.0 0.0"/>
    <limit effort="30" lower="-10" upper="10" velocity="1.0"/>
  </joint>
  <link name="link_33">
    <inertial>
      <mass value="1"/>
      <origin rpy="0 0 0" xyz="0.5 0 0"/>
      <inertia ixx="1" ixy="0" ixz="0" iyy="1" iyz="0" izz="1"/>
    </inertial>
  </link>
  <joint independent="false" name="link_32_to_rotor_33" type="revolute">
    <parent link="link_32"/>
    <child link="rotor_33"/>
    <axis xyz="0 0 1"/>
    <origin xyz="1.0 0.0 0.0"/>
    <limit effort="30" lower="-10" upper="10" velocity="1.0"/>
  </joint>
  <link name="rotor_33">
    <inertial>
      <mass value="0"/>
      <origin rpy="0 0 0" xyz="0 0 0"/>
      <inertia ixx="1e-4" ixy="0" ixz="0" iyy="1e-4" iyz="0" izz="1e-4"/>
    </inertial>
  </link>
  <constraint name="transmission_33" type="rolling">
    <predecessor link="link_33"/>
    <successor link="rotor_33"/>
    <ratio value="6.0"/>
  </constraint>
  <joint independent="true" name="link_33_to_link_34" type="revolute">
    <parent link="link_33"/>
    <child link="link_34"/>
    <axis xyz="0 0 1"/>
    <origin xyz="1.0 0.0 0.0"/>
    <limit effort="30" lower="-10" upper="10" velocity="1.0"/>
  </joint>
  <link name="link_34">
    <inertial>
      <mass value="1"/>
      <origin rpy="0 0 0" xyz="0.5 0 0"/>
      <inertia ixx="1" ixy="0" ixz="0" iyy="1" iyz="0" izz="1"/>
    </inertial>
  </link>
  <joint independent="false" name="link_32_to_rotor_34" type="revolute">
    <parent link="link_32"/>
    <child link="rotor_34"/>
    <axis xyz="0 0 1"/>
    <origin xyz="1.0 0.0 0.0"/>
    <limit effort="30" lower="-10" upper="10" velocity="1.0"/>
  </joint>
  <link name="rotor_34">
    <inertial>
      <mass value="0"/>
      <origin rpy="0 0 0" xyz="0 0 0"/>
      <inertia ixx="1e-4" ixy="0" ixz="0" iyy="1e-4" iyz="0" izz="1e-4"/>
    </inertial>
  </link>
  <constraint name="transmission_34" type="rolling">
    <predecessor link="link_34"/>
    <successor link="rotor_34"/>
    <ratio value="6.0"/>
  </constraint>
  <joint independent="true" name="link_34_to_link_35" type="revolute">
    <parent link="link_34"/>
    <child link="link_35"/>
    <axis xyz="0 0 1"/>
    <origin xyz="1.0 0.0 0.0"/>
    <limit effort="30" lower="-10" upper="10" velocity="1.0"/>
  </joint>
  <link name="link_35">
    <inertial>
      <mass value="1"/>
      <origin rpy="0 0 0" xyz="0.5 0 0"/>
      <inertia ixx="1" ixy="0" ixz="0" iyy="1" iyz="0" izz="1"/>
    </inertial>
  </link>
  <joint independent="false" name="link_34_to_rotor_35" type="revolute">
    <parent link="link_34"/>
    <child link="rotor_35"/>
    <axis xyz="0 0 1"/>
    <origin xyz="1.0 0.0 0.0"/>
    <limit effort="30" lower="-10" upper="10" velocity="1.0"/>
  </joint>
  <link name="rotor_35">
    <inertial>
      <mass value="0"/>
      <origin rpy="0 0 0" xyz="0 0 0"/>
      <inertia ixx="1e-4" ixy="0" ixz="0" iyy="1e-4" iyz="0" izz="1e-4"/>
    </inertial>
  </link>
  <constraint name="transmission_35" type="rolling">
    <predecessor link="link_35"/>
    <successor link="rotor_35"/>
    <ratio value="6.0"/>
  </constraint>
  <joint independent="true" name="link_35_to_link_36" type="revolute">
    <parent link="link_35"/>
    <child link="link_36"/>
    <axis xyz="0 0 1"/>
    <origin xyz="1.0 0.0 0.0"/>
    <limit effort="30" lower="-10" upper="10" velocity="1.0"/>
  </joint>
  <link name="link_36">
    <inertial>
      <mass value="1"/>
      <origin rpy="0 0 0" xyz="0.5 0 0"/>
      <inertia ixx="1" ixy="0" ixz="0" iyy="1" iyz="0" izz="1"/>
    </inertial>
  </link>
  <joint independent="false" name="link_34_to_rotor_36" type="revolute">
    <parent link="link_34"/>
    <child link="rotor_36"/>
    <axis xyz="0 0 1"/>
    <origin xyz="1.0 0.0 0.0"/>
    <limit effort="30" lower="-10" upper="10" velocity="1.0"/>
  </joint>
  <link name="rotor_36">
    <inertial>
      <mass value="0"/>
      <origin rpy="0 0 0" xyz="0 0 0"/>
      <inertia ixx="1e-4" ixy="0" ixz="0" iyy="1e-4" iyz="0" izz="1e-4"/>
    </inertial>
  </link>
  <constraint name="transmission_36" type="rolling">
    <predecessor link="link_36"/>
    <successor link="rotor_36"/>
    <ratio value="6.0"/>
  </constraint>
  <joint independent="true" name="link_2_to_link_13" type="revolute">
    <parent link="link_2"/>
    <child link="link_13"/>
    <axis xyz="0 0 1"/>
    <origin xyz="1.0 0.0 0.0"/>
    <limit effort="30" lower="-10" upper="10" velocity="1.0"/>
  </joint>
  <link name="link_13">
    <inertial>
      <mass value="1"/>
      <origin rpy="0 0 0" xyz="0.5 0 0"/>
      <inertia ixx="1" ixy="0" ixz="0" iyy="1" iyz="0" izz="1"/>
    </inertial>
  </link>
  <joint independent="false" name="link_2_to_rotor_13" type="revolute">
    <parent link="link_2"/>
    <child link="rotor_13"/>
    <axis xyz="0 0 1"/>
    <origin xyz="1.0 0.0 0.0"/>
    <limit effort="30" lower="-10" upper="10" velocity="1.0"/>
  </joint>
  <link name="rotor_13">
    <inertial>
      <mass value="0"/>
      <origin rpy="0 0 0" xyz="0 0 0"/>
      <inertia ixx="1e-4" ixy="0" ixz="0" iyy="1e-4" iyz="0" izz="1e-4"/>
    </inertial>
  </link>
  <constraint name="transmission_13" type="rolling">
    <predecessor link="link_13"/>
    <successor link="rotor_13"/>
    <ratio value="6.0"/>
  </constraint>
  <joint independent="true" name="link_13_to_link_14" type="revolute">
    <parent link="link_13"/>
    <child link="link_14"/>
    <axis xyz="0 0 1"/>
    <origin xyz="1.0 0.0 0.0"/>
    <limit effort="30" lower="-10" upper="10" velocity="1.0"/>
  </joint>
  <link name="link_14">
    <inertial>
      <mass value="1"/>
      <origin rpy="0 0 0" xyz="0.5 0 0"/>
      <inertia ixx="1" ixy="0" ixz="0" iyy="1" iyz="0" izz="1"/>
    </inertial>
  </link>
  <joint independent="false" name="link_2_to_rotor_14" type="revolute">
    <parent link="link_2"/>
    <child link="rotor_14"/>
    <axis xyz="0 0 1"/>
    <origin xyz="1.0 0.0 0.0"/>
    <limit effort="30" lower="-10" upper="10" velocity="1.0"/>
  </joint>
  <link name="rotor_14">
    <inertial>
      <mass value="0"/>
      <origin rpy="0 0 0" xyz="0 0 0"/>
      <inertia ixx="1e-4" ixy="0" ixz="0" iyy="1e-4" iyz="0" izz="1e-4"/>
    </inertial>
  </link>
  <constraint name="transmission_14" type="rolling">
    <predecessor link="link_14"/>
    <successor link="rotor_14"/>
    <ratio value="6.0"/>
  </constraint>
  <joint independent="true" name="link_14_to_link_15" type="revolute">
    <parent link="link_14"/>
    <child link="link_15"/>
    <axis xyz="0 0 1"/>
    <origin xyz="1.0 0.0 0.0"/>
    <limit effort="30" lower="-10" upper="10" velocity="1.0"/>
  </joint>
  <link name="link_15">
    <inertial>
      <mass value="1"/>
      <origin rpy="0 0 0" xyz="0.5 0 0"/>
      <inertia ixx="1" ixy="0" ixz="0" iyy="1" iyz="0" izz="1"/>
    </inertial>
  </link>
  <joint independent="false" name="link_14_to_rotor_15" type="revolute">
    <parent link="link_14"/>
    <child link="rotor_15"/>
    <axis xyz="0 0 1"/>
    <origin xyz="1.0 0.0 0.0"/>
    <limit effort="30" lower="-10" upper="10" velocity="1.0"/>
  </joint>
  <link name="rotor_15">
    <inertial>
      <mass value="0"/>
      <origin rpy="0 0 0" xyz="0 0 0"/>
      <inertia ixx="1e-4" ixy="0" ixz="0" iyy="1e-4" iyz="0" izz="1e-4"/>
    </inertial>
  </link>
  <constraint name="transmission_15" type="rolling">
    <predecessor link="link_15"/>
    <successor link="rotor_15"/>
    <ratio value="6.0"/>
  </constraint>
  <joint independent="true" name="link_15_to_link_16" type="revolute">
    <parent link="link_15"/>
    <child link="link_16"/>
    <axis xyz="0 0 1"/>
    <origin xyz="1.0 0.0 0.0"/>
    <limit effort="30" lower="-10" upper="10" velocity="1.0"/>
  </joint>
  <link name="link_16">
    <inertial>
      <mass value="1"/>
      <origin rpy="0 0 0" xyz="0.5 0 0"/>
      <inertia ixx="1" ixy="0" ixz="0" iyy="1" iyz="0" izz="1"/>
    </inertial>
  </link>
  <joint independent="false" name="link_14_to_rotor_16" type="revolute">
    <parent link="link_14"/>
    <child link="rotor_16"/>
    <axis xyz="0 0 1"/>
    <origin xyz="1.0 0.0 0.0"/>
    <limit effort="30" lower="-10" upper="10" velocity="1.0"/>
  </joint>
  <link name="rotor_16">
    <inertial>
      <mass value="0"/>
      <origin rpy="0 0 0" xyz="0 0 0"/>
      <inertia ixx="1e-4" ixy="0" ixz="0" iyy="1e-4" iyz="0" izz="1e-4"/>
    </inertial>
  </link>
  <constraint name="transmission_16" type="rolling">
    <predecessor link="link_16"/>
    <successor link="rotor_16"/>
    <ratio value="6.0"/>
  </constraint>
  <joint independent="true" name="link_16_to_link_17" type="revolute">
    <parent link="link_16"/>
    <child link="link_17"/>
    <axis xyz="0 0 1"/>
    <origin xyz="1.0 0.0 0.0"/>
    <limit effort="30" lower="-10" upper="10" velocity="1.0"/>
  </joint>
  <link name="link_17">
    <inertial>
      <mass value="1"/>
      <origin rpy="0 0 0" xyz="0.5 0 0"/>
      <inertia ixx="1" ixy="0" ixz="0" iyy="1" iyz="0" izz="1"/>
    </inertial>
  </link>
  <joint independent="false" name="link_16_to_rotor_17" type="revolute">
    <parent link="link_16"/>
    <child link="rotor_17"/>
    <axis xyz="0 0 1"/>
    <origin xyz="1.0 0.0 0.0"/>
    <limit effort="30" lower="-10" upper="10" velocity="1.0"/>
  </joint>
  <link name="rotor_17">
    <inertial>
      <mass value="0"/>
      <origin rpy="0 0 0" xyz="0 0 0"/>
      <inertia ixx="1e-4" ixy="0" ixz="0" iyy="1e-4" iyz="0" izz="1e-4"/>
    </inertial>
  </link>
  <constraint name="transmission_17" type="rolling">
    <predecessor link="link_17"/>
    <successor link="rotor_17"/>
    <ratio value="6.0"/>
  </constraint>
  <joint independent="true" name="link_17_to_link_18" type="revolute">
    <parent link="link_17"/>
    <child link="link_18"/>
    <axis xyz="0 0 1"/>
    <origin xyz="1.0 0.0 0.0"/>
    <limit effort="30" lower="-10" upper="10" velocity="1.0"/>
  </joint>
  <link name="link_18">
    <inertial>
      <mass value="1"/>
      <origin rpy="0 0 0" xyz="0.5 0 0"/>
      <inertia ixx="1" ixy="0" ixz="0" iyy="1" iyz="0" izz="1"/>
    </inertial>
  </link>
  <joint independent="false" name="link_16_to_rotor_18" type="revolute">
    <parent link="link_16"/>
    <child link="rotor_18"/>
    <axis xyz="0 0 1"/>
    <origin xyz="1.0 0.0 0.0"/>
    <limit effort="30" lower="-10" upper="10" velocity="1.0"/>
  </joint>
  <link name="rotor_18">
    <inertial>
      <mass value="0"/>
      <origin rpy="0 0 0" xyz="0 0 0"/>
      <inertia ixx="1e-4" ixy="0" ixz="0" iyy="1e-4" iyz="0" izz="1e-4"/>
    </inertial>
  </link>
  <constraint name="transmission_18" type="rolling">
    <predecessor link="link_18"/>
    <successor link="rotor_18"/>
    <ratio value="6.0"/>
  </constraint>
  <joint independent="true" name="link_18_to_link_19" type="revolute">
    <parent link="link_18"/>
    <child link="link_19"/>
    <axis xyz="0 0 1"/>
    <origin xyz="1.0 0.0 0.0"/>
    <limit effort="30" lower="-10" upper="10" velocity="1.0"/>
  </joint>
  <link name="link_19">
    <inertial>
      <mass value="1"/>
      <origin rpy="0 0 0" xyz="0.5 0 0"/>
      <inertia ixx="1" ixy="0" ixz="0" iyy="1" iyz="0" izz="1"/>
    </inertial>
  </link>
  <joint independent="false" name="link_18_to_rotor_19" type="revolute">
    <parent link="link_18"/>
    <child link="rotor_19"/>
    <axis xyz="0 0 1"/>
    <origin xyz="1.0 0.0 0.0"/>
    <limit effort="30" lower="-10" upper="10" velocity="1.0"/>
  </joint>
  <link name="rotor_19">
    <inertial>
      <mass value="0"/>
      <origin rpy="0 0 0" xyz="0 0 0"/>
      <inertia ixx="1e-4" ixy="0" ixz="0" iyy="1e-4" iyz="0" izz="1e-4"/>
    </inertial>
  </link>
  <constraint name="transmission_19" type="rolling">
    <predecessor link="link_19"/>
    <successor link="rotor_19"/>
    <ratio value="6.0"/>
  </constraint>
  <joint independent="true" name="link_19_to_link_20" type="revolute">
    <parent link="link_19"/>
    <child link="link_20"/>
    <axis xyz="0 0 1"/>
    <origin xyz="1.0 0.0 0.0"/>
    <limit effort="30" lower="-10" upper="10" velocity="1.0"/>
  </joint>
  <link name="link_20">
    <inertial>
      <mass value="1"/>
      <origin rpy="0 0 0" xyz="0.5 0 0"/>
      <inertia ixx="1" ixy="0" ixz="0" iyy="1" iyz="0" izz="1"/>
    </inertial>
  </link>
  <joint independent="false" name="link_18_to_rotor_20" type="revolute">
    <parent link="link_18"/>
    <child link="rotor_20"/>
    <axis xyz="0 0 1"/>
    <origin xyz="1.0 0.0 0.0"/>
    <limit effort="30" lower="-10" upper="10" velocity="1.0"/>
  </joint>
  <link name="rotor_20">
    <inertial>
      <mass value="0"/>
      <origin rpy="0 0 0" xyz="0 0 0"/>
      <inertia ixx="1e-4" ixy="0" ixz="0" iyy="1e-4" iyz="0" izz="1e-4"/>
    </inertial>
  </link>
  <constraint name="transmission_20" type="rolling">
    <predecessor link="link_20"/>
    <successor link="rotor_20"/>
    <ratio value="6.0"/>
  </constraint>
  <joint independent="true" name="link_20_to_link_21" type="revolute">
    <parent link="link_20"/>
    <child link="link_21"/>
    <axis xyz="0 0 1"/>
    <origin xyz="1.0 0.0 0.0"/>
    <limit effort="30" lower="-10" upper="10" velocity="1.0"/>
  </joint>
  <link name="link_21">
    <inertial>
      <mass value="1"/>
      <origin rpy="0 0 0" xyz="0.5 0 0"/>
      <inertia ixx="1" ixy="0" ixz="0" iyy="1" iyz="0" izz="1"/>
    </inertial>
  </link>
  <joint independent="false" name="link_20_to_rotor_21" type="revolute">
    <parent link="link_20"/>
    <child link="rotor_21"/>
    <axis xyz="0 0 1"/>
    <origin xyz="1.0 0.0 0.0"/>
    <limit effort="30" lower="-10" upper="10" velocity="1.0"/>
  </joint>
  <link name="rotor_21">
    <inertial>
      <mass value="0"/>
      <origin rpy="0 0 0" xyz="0 0 0"/>
      <inertia ixx="1e-4" ixy="0" ixz="0" iyy="1e-4" iyz="0" izz="1e-4"/>
    </inertial>
  </link>
  <constraint name="transmission_21" type="rolling">
    <predecessor link="link_21"/>
    <successor link="rotor_21"/>
    <ratio value="6.0"/>
  </constraint>
  <joint independent="true" name="link_21_to_link_22" type="revolute">
    <parent link="link_21"/>
    <child link="link_22"/>
    <axis xyz="0 0 1"/>
    <origin xyz="1.0 0.0 0.0"/>
    <limit effort="30" lower="-10" upper="10" velocity="1.0"/>
  </joint>
  <link name="link_22">
    <inertial>
      <mass value="1"/>
      <origin rpy="0 0 0" xyz="0.5 0 0"/>
      <inertia ixx="1" ixy="0" ixz="0" iyy="1" iyz="0" izz="1"/>
    </inertial>
  </link>
  <joint independent="false" name="link_20_to_rotor_22" type="revolute">
    <parent link="link_20"/>
    <child link="rotor_22"/>
    <axis xyz="0 0 1"/>
    <origin xyz="1.0 0.0 0.0"/>
    <limit effort="30" lower="-10" upper="10" velocity="1.0"/>
  </joint>
  <link name="rotor_22">
    <inertial>
      <mass value="0"/>
      <origin rpy="0 0 0" xyz="0 0 0"/>
      <inertia ixx="1e-4" ixy="0" ixz="0" iyy="1e-4" iyz="0" izz="1e-4"/>
    </inertial>
  </link>
  <constraint name="transmission_22" type="rolling">
    <predecessor link="link_22"/>
    <successor link="rotor_22"/>
    <ratio value="6.0"/>
  </constraint>
  <joint independent="true" name="link_22_to_link_23" type="revolute">
    <parent link="link_22"/>
    <child link="link_23"/>
    <axis xyz="0 0 1"/>
    <origin xyz="1.0 0.0 0.0"/>
    <limit effort="30" lower="-10" upper="10" velocity="1.0"/>
  </joint>
  <link name="link_23">
    <inertial>
      <mass value="1"/>
      <origin rpy="0 0 0" xyz="0.5 0 0"/>
      <inertia ixx="1" ixy="0" ixz="0" iyy="1" iyz="0" izz="1"/>
    </inertial>
  </link>
  <joint independent="false" name="link_22_to_rotor_23" type="revolute">
    <parent link="link_22"/>
    <child link="rotor_23"/>
    <axis xyz="0 0 1"/>
    <origin xyz="1.0 0.0 0.0"/>
    <limit effort="30" lower="-10" upper="10" velocity="1.0"/>
  </joint>
  <link name="rotor_23">
    <inertial>
      <mass value="0"/>
      <origin rpy="0 0 0" xyz="0 0 0"/>
      <inertia ixx="1e-4" ixy="0" ixz="0" iyy="1e-4" iyz="0" izz="1e-4"/>
    </inertial>
  </link>
  <constraint name="transmission_23" type="rolling">
    <predecessor link="link_23"/>
    <successor link="rotor_23"/>
    <ratio value="6.0"/>
  </constraint>
  <joint independent="true" name="link_23_to_link_24" type="revolute">
    <parent link="link_23"/>
    <child link="link_24"/>
    <axis xyz="0 0 1"/>
    <origin xyz="1.0 0.0 0.0"/>
    <limit effort="30" lower="-10" upper="10" velocity="1.0"/>
  </joint>
  <link name="link_24">
    <inertial>
      <mass value="1"/>
      <origin rpy="0 0 0" xyz="0.5 0 0"/>
      <inertia ixx="1" ixy="0" ixz="0" iyy="1" iyz="0" izz="1"/>
    </inertial>
  </link>
  <joint independent="false" name="link_22_to_rotor_24" type="revolute">
    <parent link="link_22"/>
    <child link="rotor_24"/>
    <axis xyz="0 0 1"/>
    <origin xyz="1.0 0.0 0.0"/>
    <limit effort="30" lower="-10" upper="10" velocity="1.0"/>
  </joint>
  <link name="rotor_24">
    <inertial>
      <mass value="0"/>
      <origin rpy="0 0 0" xyz="0 0 0"/>
      <inertia ixx="1e-4" ixy="0" ixz="0" iyy="1e-4" iyz="0" izz="1e-4"/>
    </inertial>
  </link>
  <constraint name="transmission_24" type="rolling">
    <predecessor link="link_24"/>
    <successor link="rotor_24"/>
    <ratio value="6.0"/>
  </constraint>
</robot>

