<?xml version="1.0" ?>
<!-- =================================================================================== -->
<!-- |    This document was autogenerated by xacro from approx_four_bar_branch.xacro   | -->
<!-- |    EDITING THIS FILE BY HAND IS NOT RECOMMENDED                                 | -->
<!-- =================================================================================== -->
<robot name="variable_four_bar_branch">
  <link name="ground"/>
  <link name="Floating Base">
    <inertial>
      <mass value="5.0"/>
      <origin xyz="0. 0. 0."/>
      <inertia ixx="0.1" ixy="0." ixz="0." iyy="0.1" iyz="0." izz="0.1"/>
    </inertial>
  </link>
  <joint name="world_to_base" type="floating">
    <origin rpy="0 0 0" xyz="0 0 0"/>
    <parent link="ground"/>
    <child link="Floating Base"/>
  </joint>
  <link name="link_5">
    <inertial>
      <mass value="3.3"/>
      <origin xyz="0.0 0.0 0.0"/>
      <inertia ixx="0.011253" ixy="0" ixz="0" iyy="0.036203" iyz="0" izz="0.042673"/>
    </inertial>
    <visual>
      <origin rpy="0 0 0" xyz="0.25 0 0"/>
      <geometry>
        <box size="0.5 0.05 0.05"/>
      </geometry>
      <material name="Red">
        <color rgba="0.8 0.1 0.1 1.0"/>
      </material>
    </visual>
  </link>
  <joint independent="true" name="base_to_link_5" type="revolute">
    <parent link="Floating Base"/>
    <child link="link_5"/>
    <origin xyz="0.0 0.0 0.0"/>
    <axis xyz="0 0 1"/>
    <limit effort="30" lower="-10" upper="10" velocity="1.0"/>
  </joint>
  <link name="link_2">
    <inertial>
      <mass value="3.3"/>
      <origin xyz="0.0 0.0 0.0"/>
      <inertia ixx="0.011253" ixy="0" ixz="0" iyy="0.036203" iyz="0" izz="0.042673"/>
    </inertial>
    <visual>
      <origin rpy="0 0 0" xyz="0.25 0 0"/>
      <geometry>
        <box size="0.5 0.05 0.05"/>
      </geometry>
      <material name="Red">
        <color rgba="0.8 0.1 0.1 1.0"/>
      </material>
    </visual>
  </link>
  <joint independent="true" name="base_to_link_2" type="revolute">
    <parent link="Floating Base"/>
    <child link="link_2"/>
    <origin xyz="0.0 0.0 0.0"/>
    <axis xyz="0 0 1"/>
    <limit effort="30" lower="-10" upper="10" velocity="1.0"/>
  </joint>
  <link name="link_35">
    <inertial>
      <mass value="3.3"/>
      <origin xyz="0.0 0.0 0.0"/>
      <inertia ixx="0.011253" ixy="0" ixz="0" iyy="0.036203" iyz="0" izz="0.042673"/>
    </inertial>
    <visual>
      <origin rpy="0 0 0" xyz="0.25 0 0"/>
      <geometry>
        <box size="0.5 0.05 0.05"/>
      </geometry>
      <material name="Red">
        <color rgba="0.8 0.1 0.1 1.0"/>
      </material>
    </visual>
  </link>
  <joint independent="true" name="link_5_to_link_35" type="revolute">
    <parent link="link_5"/>
    <child link="link_35"/>
    <origin xyz="0.0 0.0 0.0"/>
    <axis xyz="0 0 1"/>
    <limit effort="30" lower="-10" upper="10" velocity="1.0"/>
  </joint>
  <link name="link_38">
    <inertial>
      <mass value="3.3"/>
      <origin xyz="0.0 0.0 0.0"/>
      <inertia ixx="0.011253" ixy="0" ixz="0" iyy="0.036203" iyz="0" izz="0.042673"/>
    </inertial>
    <visual>
      <origin rpy="0 0 0" xyz="0.25 0 0"/>
      <geometry>
        <box size="0.5 0.05 0.05"/>
      </geometry>
      <material name="Red">
        <color rgba="0.8 0.1 0.1 1.0"/>
      </material>
    </visual>
  </link>
  <joint independent="true" name="link_35_to_link_38" type="revolute">
    <parent link="link_35"/>
    <child link="link_38"/>
    <origin xyz="0.0 0.0 0.0"/>
    <axis xyz="0 0 1"/>
    <limit effort="30" lower="-10" upper="10" velocity="1.0"/>
  </joint>
  <link name="link_41">
    <inertial>
      <mass value="3.3"/>
      <origin xyz="0.0 0.0 0.0"/>
      <inertia ixx="0.011253" ixy="0" ixz="0" iyy="0.036203" iyz="0" izz="0.042673"/>
    </inertial>
    <visual>
      <origin rpy="0 0 0" xyz="0.25 0 0"/>
      <geometry>
        <box size="0.5 0.05 0.05"/>
      </geometry>
      <material name="Red">
        <color rgba="0.8 0.1 0.1 1.0"/>
      </material>
    </visual>
  </link>
  <joint independent="true" name="link_38_to_link_41" type="revolute">
    <parent link="link_38"/>
    <child link="link_41"/>
    <origin xyz="0.0 0.0 0.0"/>
    <axis xyz="0 0 1"/>
    <limit effort="30" lower="-10" upper="10" velocity="1.0"/>
  </joint>
  <link name="link_44">
    <inertial>
      <mass value="3.3"/>
      <origin xyz="0.0 0.0 0.0"/>
      <inertia ixx="0.011253" ixy="0" ixz="0" iyy="0.036203" iyz="0" izz="0.042673"/>
    </inertial>
    <visual>
      <origin rpy="0 0 0" xyz="0.25 0 0"/>
      <geometry>
        <box size="0.5 0.05 0.05"/>
      </geometry>
      <material name="Red">
        <color rgba="0.8 0.1 0.1 1.0"/>
      </material>
    </visual>
  </link>
  <joint independent="true" name="link_41_to_link_44" type="revolute">
    <parent link="link_41"/>
    <child link="link_44"/>
    <origin xyz="0.0 0.0 0.0"/>
    <axis xyz="0 0 1"/>
    <limit effort="30" lower="-10" upper="10" velocity="1.0"/>
  </joint>
  <link name="link_47">
    <inertial>
      <mass value="3.3"/>
      <origin xyz="0.0 0.0 0.0"/>
      <inertia ixx="0.011253" ixy="0" ixz="0" iyy="0.036203" iyz="0" izz="0.042673"/>
    </inertial>
    <visual>
      <origin rpy="0 0 0" xyz="0.25 0 0"/>
      <geometry>
        <box size="0.5 0.05 0.05"/>
      </geometry>
      <material name="Red">
        <color rgba="0.8 0.1 0.1 1.0"/>
      </material>
    </visual>
  </link>
  <joint independent="true" name="link_44_to_link_47" type="revolute">
    <parent link="link_44"/>
    <child link="link_47"/>
    <origin xyz="0.0 0.0 0.0"/>
    <axis xyz="0 0 1"/>
    <limit effort="30" lower="-10" upper="10" velocity="1.0"/>
  </joint>
  <link name="link_50">
    <inertial>
      <mass value="3.3"/>
      <origin xyz="0.0 0.0 0.0"/>
      <inertia ixx="0.011253" ixy="0" ixz="0" iyy="0.036203" iyz="0" izz="0.042673"/>
    </inertial>
    <visual>
      <origin rpy="0 0 0" xyz="0.25 0 0"/>
      <geometry>
        <box size="0.5 0.05 0.05"/>
      </geometry>
      <material name="Red">
        <color rgba="0.8 0.1 0.1 1.0"/>
      </material>
    </visual>
  </link>
  <joint independent="true" name="link_47_to_link_50" type="revolute">
    <parent link="link_47"/>
    <child link="link_50"/>
    <origin xyz="0.0 0.0 0.0"/>
    <axis xyz="0 0 1"/>
    <limit effort="30" lower="-10" upper="10" velocity="1.0"/>
  </joint>
  <link name="link_53">
    <inertial>
      <mass value="3.3"/>
      <origin xyz="0.0 0.0 0.0"/>
      <inertia ixx="0.011253" ixy="0" ixz="0" iyy="0.036203" iyz="0" izz="0.042673"/>
    </inertial>
    <visual>
      <origin rpy="0 0 0" xyz="0.25 0 0"/>
      <geometry>
        <box size="0.5 0.05 0.05"/>
      </geometry>
      <material name="Red">
        <color rgba="0.8 0.1 0.1 1.0"/>
      </material>
    </visual>
  </link>
  <joint independent="true" name="link_50_to_link_53" type="revolute">
    <parent link="link_50"/>
    <child link="link_53"/>
    <origin xyz="0.0 0.0 0.0"/>
    <axis xyz="0 0 1"/>
    <limit effort="30" lower="-10" upper="10" velocity="1.0"/>
  </joint>
  <link name="link_56">
    <inertial>
      <mass value="3.3"/>
      <origin xyz="0.0 0.0 0.0"/>
      <inertia ixx="0.011253" ixy="0" ixz="0" iyy="0.036203" iyz="0" izz="0.042673"/>
    </inertial>
    <visual>
      <origin rpy="0 0 0" xyz="0.25 0 0"/>
      <geometry>
        <box size="0.5 0.05 0.05"/>
      </geometry>
      <material name="Red">
        <color rgba="0.8 0.1 0.1 1.0"/>
      </material>
    </visual>
  </link>
  <joint independent="true" name="link_53_to_link_56" type="revolute">
    <parent link="link_53"/>
    <child link="link_56"/>
    <origin xyz="0.0 0.0 0.0"/>
    <axis xyz="0 0 1"/>
    <limit effort="30" lower="-10" upper="10" velocity="1.0"/>
  </joint>
  <link name="link_59">
    <inertial>
      <mass value="3.3"/>
      <origin xyz="0.0 0.0 0.0"/>
      <inertia ixx="0.011253" ixy="0" ixz="0" iyy="0.036203" iyz="0" izz="0.042673"/>
    </inertial>
    <visual>
      <origin rpy="0 0 0" xyz="0.25 0 0"/>
      <geometry>
        <box size="0.5 0.05 0.05"/>
      </geometry>
      <material name="Red">
        <color rgba="0.8 0.1 0.1 1.0"/>
      </material>
    </visual>
  </link>
  <joint independent="true" name="link_56_to_link_59" type="revolute">
    <parent link="link_56"/>
    <child link="link_59"/>
    <origin xyz="0.0 0.0 0.0"/>
    <axis xyz="0 0 1"/>
    <limit effort="30" lower="-10" upper="10" velocity="1.0"/>
  </joint>
  <link name="link_8">
    <inertial>
      <mass value="3.3"/>
      <origin xyz="0.0 0.0 0.0"/>
      <inertia ixx="0.011253" ixy="0" ixz="0" iyy="0.036203" iyz="0" izz="0.042673"/>
    </inertial>
    <visual>
      <origin rpy="0 0 0" xyz="0.25 0 0"/>
      <geometry>
        <box size="0.5 0.05 0.05"/>
      </geometry>
      <material name="Red">
        <color rgba="0.8 0.1 0.1 1.0"/>
      </material>
    </visual>
  </link>
  <joint independent="true" name="link_2_to_link_8" type="revolute">
    <parent link="link_2"/>
    <child link="link_8"/>
    <origin xyz="0.0 0.0 0.0"/>
    <axis xyz="0 0 1"/>
    <limit effort="30" lower="-10" upper="10" velocity="1.0"/>
  </joint>
  <link name="link_11">
    <inertial>
      <mass value="3.3"/>
      <origin xyz="0.0 0.0 0.0"/>
      <inertia ixx="0.011253" ixy="0" ixz="0" iyy="0.036203" iyz="0" izz="0.042673"/>
    </inertial>
    <visual>
      <origin rpy="0 0 0" xyz="0.25 0 0"/>
      <geometry>
        <box size="0.5 0.05 0.05"/>
      </geometry>
      <material name="Red">
        <color rgba="0.8 0.1 0.1 1.0"/>
      </material>
    </visual>
  </link>
  <joint independent="true" name="link_8_to_link_11" type="revolute">
    <parent link="link_8"/>
    <child link="link_11"/>
    <origin xyz="0.0 0.0 0.0"/>
    <axis xyz="0 0 1"/>
    <limit effort="30" lower="-10" upper="10" velocity="1.0"/>
  </joint>
  <link name="link_14">
    <inertial>
      <mass value="3.3"/>
      <origin xyz="0.0 0.0 0.0"/>
      <inertia ixx="0.011253" ixy="0" ixz="0" iyy="0.036203" iyz="0" izz="0.042673"/>
    </inertial>
    <visual>
      <origin rpy="0 0 0" xyz="0.25 0 0"/>
      <geometry>
        <box size="0.5 0.05 0.05"/>
      </geometry>
      <material name="Red">
        <color rgba="0.8 0.1 0.1 1.0"/>
      </material>
    </visual>
  </link>
  <joint independent="true" name="link_11_to_link_14" type="revolute">
    <parent link="link_11"/>
    <child link="link_14"/>
    <origin xyz="0.0 0.0 0.0"/>
    <axis xyz="0 0 1"/>
    <limit effort="30" lower="-10" upper="10" velocity="1.0"/>
  </joint>
  <link name="link_17">
    <inertial>
      <mass value="3.3"/>
      <origin xyz="0.0 0.0 0.0"/>
      <inertia ixx="0.011253" ixy="0" ixz="0" iyy="0.036203" iyz="0" izz="0.042673"/>
    </inertial>
    <visual>
      <origin rpy="0 0 0" xyz="0.25 0 0"/>
      <geometry>
        <box size="0.5 0.05 0.05"/>
      </geometry>
      <material name="Red">
        <color rgba="0.8 0.1 0.1 1.0"/>
      </material>
    </visual>
  </link>
  <joint independent="true" name="link_14_to_link_17" type="revolute">
    <parent link="link_14"/>
    <child link="link_17"/>
    <origin xyz="0.0 0.0 0.0"/>
    <axis xyz="0 0 1"/>
    <limit effort="30" lower="-10" upper="10" velocity="1.0"/>
  </joint>
  <link name="link_20">
    <inertial>
      <mass value="3.3"/>
      <origin xyz="0.0 0.0 0.0"/>
      <inertia ixx="0.011253" ixy="0" ixz="0" iyy="0.036203" iyz="0" izz="0.042673"/>
    </inertial>
    <visual>
      <origin rpy="0 0 0" xyz="0.25 0 0"/>
      <geometry>
        <box size="0.5 0.05 0.05"/>
      </geometry>
      <material name="Red">
        <color rgba="0.8 0.1 0.1 1.0"/>
      </material>
    </visual>
  </link>
  <joint independent="true" name="link_17_to_link_20" type="revolute">
    <parent link="link_17"/>
    <child link="link_20"/>
    <origin xyz="0.0 0.0 0.0"/>
    <axis xyz="0 0 1"/>
    <limit effort="30" lower="-10" upper="10" velocity="1.0"/>
  </joint>
  <link name="link_23">
    <inertial>
      <mass value="3.3"/>
      <origin xyz="0.0 0.0 0.0"/>
      <inertia ixx="0.011253" ixy="0" ixz="0" iyy="0.036203" iyz="0" izz="0.042673"/>
    </inertial>
    <visual>
      <origin rpy="0 0 0" xyz="0.25 0 0"/>
      <geometry>
        <box size="0.5 0.05 0.05"/>
      </geometry>
      <material name="Red">
        <color rgba="0.8 0.1 0.1 1.0"/>
      </material>
    </visual>
  </link>
  <joint independent="true" name="link_20_to_link_23" type="revolute">
    <parent link="link_20"/>
    <child link="link_23"/>
    <origin xyz="0.0 0.0 0.0"/>
    <axis xyz="0 0 1"/>
    <limit effort="30" lower="-10" upper="10" velocity="1.0"/>
  </joint>
  <link name="link_26">
    <inertial>
      <mass value="3.3"/>
      <origin xyz="0.0 0.0 0.0"/>
      <inertia ixx="0.011253" ixy="0" ixz="0" iyy="0.036203" iyz="0" izz="0.042673"/>
    </inertial>
    <visual>
      <origin rpy="0 0 0" xyz="0.25 0 0"/>
      <geometry>
        <box size="0.5 0.05 0.05"/>
      </geometry>
      <material name="Red">
        <color rgba="0.8 0.1 0.1 1.0"/>
      </material>
    </visual>
  </link>
  <joint independent="true" name="link_23_to_link_26" type="revolute">
    <parent link="link_23"/>
    <child link="link_26"/>
    <origin xyz="0.0 0.0 0.0"/>
    <axis xyz="0 0 1"/>
    <limit effort="30" lower="-10" upper="10" velocity="1.0"/>
  </joint>
  <link name="link_29">
    <inertial>
      <mass value="3.3"/>
      <origin xyz="0.0 0.0 0.0"/>
      <inertia ixx="0.011253" ixy="0" ixz="0" iyy="0.036203" iyz="0" izz="0.042673"/>
    </inertial>
    <visual>
      <origin rpy="0 0 0" xyz="0.25 0 0"/>
      <geometry>
        <box size="0.5 0.05 0.05"/>
      </geometry>
      <material name="Red">
        <color rgba="0.8 0.1 0.1 1.0"/>
      </material>
    </visual>
  </link>
  <joint independent="true" name="link_26_to_link_29" type="revolute">
    <parent link="link_26"/>
    <child link="link_29"/>
    <origin xyz="0.0 0.0 0.0"/>
    <axis xyz="0 0 1"/>
    <limit effort="30" lower="-10" upper="10" velocity="1.0"/>
  </joint>
  <link name="link_32">
    <inertial>
      <mass value="3.3"/>
      <origin xyz="0.0 0.0 0.0"/>
      <inertia ixx="0.011253" ixy="0" ixz="0" iyy="0.036203" iyz="0" izz="0.042673"/>
    </inertial>
    <visual>
      <origin rpy="0 0 0" xyz="0.25 0 0"/>
      <geometry>
        <box size="0.5 0.05 0.05"/>
      </geometry>
      <material name="Red">
        <color rgba="0.8 0.1 0.1 1.0"/>
      </material>
    </visual>
  </link>
  <joint independent="true" name="link_29_to_link_32" type="revolute">
    <parent link="link_29"/>
    <child link="link_32"/>
    <origin xyz="0.0 0.0 0.0"/>
    <axis xyz="0 0 1"/>
    <limit effort="30" lower="-10" upper="10" velocity="1.0"/>
  </joint>
</robot>
