<?xml version="1.0" ?>
<!-- =================================================================================== -->
<!-- |    This document was autogenerated by xacro from four_bar_branch.xacro          | -->
<!-- |    EDITING THIS FILE BY HAND IS NOT RECOMMENDED                                 | -->
<!-- =================================================================================== -->
<robot name="variable_four_bar_branch">
  <link name="ground"/>
  <link name="Floating Base">
    <inertial>
      <mass value="5.0"/>
      <origin xyz="0. 0. 0."/>
      <inertia ixx="0.1" ixy="0." ixz="0." iyy="0.1" iyz="0." izz="0.1"/>
    </inertial>
  </link>
  <joint name="world_to_base" type="floating">
    <origin rpy="0 0 0" xyz="0 0 0"/>
    <parent link="ground"/>
    <child link="Floating Base"/>
  </joint>
  <link name="link_1">
    <inertial>
      <mass value="3.3"/>
      <origin xyz="0.0 0.0 0.0"/>
      <inertia ixx="0.011253" ixy="0" ixz="0" iyy="0.036203" iyz="0" izz="0.042673"/>
    </inertial>
    <visual>
      <origin rpy="0 0 0" xyz="0.25 0 0"/>
      <geometry>
        <box size="0.5 0.05 0.05"/>
      </geometry>
      <material name="Blue">
        <color rgba="0.1 0 0.8 1.0"/>
      </material>
    </visual>
  </link>
  <link name="link_2">
    <inertial>
      <mass value="3.3"/>
      <origin xyz="0.0 0.0 0.0"/>
      <inertia ixx="0.011253" ixy="0" ixz="0" iyy="0.036203" iyz="0" izz="0.042673"/>
    </inertial>
    <visual>
      <origin rpy="0 0 0" xyz="0.25 0 0"/>
      <geometry>
        <box size="0.5 0.05 0.05"/>
      </geometry>
      <material name="Red">
        <color rgba="0.8 0.1 0.1 1.0"/>
      </material>
    </visual>
  </link>
  <link name="link_3">
    <inertial>
      <mass value="3.3"/>
      <origin xyz="0.0 0.0 0.0"/>
      <inertia ixx="0.011253" ixy="0" ixz="0" iyy="0.036203" iyz="0" izz="0.042673"/>
    </inertial>
    <visual>
      <origin rpy="0 0 0" xyz="0.5 0 0"/>
      <geometry>
        <box size="1.0 0.05 0.05"/>
      </geometry>
      <material name="Green2">
        <color rgba="0.1 0.8 0 1.0"/>
      </material>
    </visual>
  </link>
  <joint independent="false" name="base_to_link_1" type="revolute">
    <parent link="Floating Base"/>
    <child link="link_1"/>
    <origin xyz="1.0 0.0 0.0"/>
    <axis xyz="0 0 1"/>
    <limit effort="30" lower="-10" upper="10" velocity="1.0"/>
  </joint>
  <joint independent="true" name="base_to_link_2" type="revolute">
    <parent link="Floating Base"/>
    <child link="link_2"/>
    <origin xyz="0.0 0.0 0.0"/>
    <axis xyz="0 0 1"/>
    <limit effort="30" lower="-10" upper="10" velocity="1.0"/>
  </joint>
  <joint independent="false" name="link_2_to_link_3" type="revolute">
    <parent link="link_2"/>
    <child link="link_3"/>
    <origin xyz="0.5 0.0 0.0"/>
    <axis xyz="0 0 1"/>
    <limit effort="30" lower="-10" upper="10" velocity="1.0"/>
  </joint>
  <loop name="constraint_1" type="revolute">
    <predecessor link="link_1">
      <origin xyz="0.5 0.0 0.0"/>
    </predecessor>
    <successor link="link_3">
      <origin xyz="1.0 0.0 0.0"/>
    </successor>
    <axis xyz="0 0 1"/>
  </loop>
  <link name="link_4">
    <inertial>
      <mass value="3.3"/>
      <origin xyz="0.0 0.0 0.0"/>
      <inertia ixx="0.011253" ixy="0" ixz="0" iyy="0.036203" iyz="0" izz="0.042673"/>
    </inertial>
    <visual>
      <origin rpy="0 0 0" xyz="0.25 0 0"/>
      <geometry>
        <box size="0.5 0.05 0.05"/>
      </geometry>
      <material name="Blue">
        <color rgba="0.1 0 0.8 1.0"/>
      </material>
    </visual>
  </link>
  <link name="link_5">
    <inertial>
      <mass value="3.3"/>
      <origin xyz="0.0 0.0 0.0"/>
      <inertia ixx="0.011253" ixy="0" ixz="0" iyy="0.036203" iyz="0" izz="0.042673"/>
    </inertial>
    <visual>
      <origin rpy="0 0 0" xyz="0.25 0 0"/>
      <geometry>
        <box size="0.5 0.05 0.05"/>
      </geometry>
      <material name="Red">
        <color rgba="0.8 0.1 0.1 1.0"/>
      </material>
    </visual>
  </link>
  <link name="link_6">
    <inertial>
      <mass value="3.3"/>
      <origin xyz="0.0 0.0 0.0"/>
      <inertia ixx="0.011253" ixy="0" ixz="0" iyy="0.036203" iyz="0" izz="0.042673"/>
    </inertial>
    <visual>
      <origin rpy="0 0 0" xyz="0.5 0 0"/>
      <geometry>
        <box size="1.0 0.05 0.05"/>
      </geometry>
      <material name="Green2">
        <color rgba="0.1 0.8 0 1.0"/>
      </material>
    </visual>
  </link>
  <joint independent="false" name="link_1_to_link_4" type="revolute">
    <parent link="link_1"/>
    <child link="link_4"/>
    <origin xyz="1.0 0.0 0.0"/>
    <axis xyz="0 0 1"/>
    <limit effort="30" lower="-10" upper="10" velocity="1.0"/>
  </joint>
  <joint independent="true" name="link_1_to_link_5" type="revolute">
    <parent link="link_1"/>
    <child link="link_5"/>
    <origin xyz="0.0 0.0 0.0"/>
    <axis xyz="0 0 1"/>
    <limit effort="30" lower="-10" upper="10" velocity="1.0"/>
  </joint>
  <joint independent="false" name="link_5_to_link_6" type="revolute">
    <parent link="link_5"/>
    <child link="link_6"/>
    <origin xyz="0.5 0.0 0.0"/>
    <axis xyz="0 0 1"/>
    <limit effort="30" lower="-10" upper="10" velocity="1.0"/>
  </joint>
  <loop name="constraint_4" type="revolute">
    <predecessor link="link_4">
      <origin xyz="0.5 0.0 0.0"/>
    </predecessor>
    <successor link="link_6">
      <origin xyz="1.0 0.0 0.0"/>
    </successor>
    <axis xyz="0 0 1"/>
  </loop>
  <link name="link_7">
    <inertial>
      <mass value="3.3"/>
      <origin xyz="0.0 0.0 0.0"/>
      <inertia ixx="0.011253" ixy="0" ixz="0" iyy="0.036203" iyz="0" izz="0.042673"/>
    </inertial>
    <visual>
      <origin rpy="0 0 0" xyz="0.25 0 0"/>
      <geometry>
        <box size="0.5 0.05 0.05"/>
      </geometry>
      <material name="Blue">
        <color rgba="0.1 0 0.8 1.0"/>
      </material>
    </visual>
  </link>
  <link name="link_8">
    <inertial>
      <mass value="3.3"/>
      <origin xyz="0.0 0.0 0.0"/>
      <inertia ixx="0.011253" ixy="0" ixz="0" iyy="0.036203" iyz="0" izz="0.042673"/>
    </inertial>
    <visual>
      <origin rpy="0 0 0" xyz="0.25 0 0"/>
      <geometry>
        <box size="0.5 0.05 0.05"/>
      </geometry>
      <material name="Red">
        <color rgba="0.8 0.1 0.1 1.0"/>
      </material>
    </visual>
  </link>
  <link name="link_9">
    <inertial>
      <mass value="3.3"/>
      <origin xyz="0.0 0.0 0.0"/>
      <inertia ixx="0.011253" ixy="0" ixz="0" iyy="0.036203" iyz="0" izz="0.042673"/>
    </inertial>
    <visual>
      <origin rpy="0 0 0" xyz="0.5 0 0"/>
      <geometry>
        <box size="1.0 0.05 0.05"/>
      </geometry>
      <material name="Green2">
        <color rgba="0.1 0.8 0 1.0"/>
      </material>
    </visual>
  </link>
  <joint independent="false" name="link_4_to_link_7" type="revolute">
    <parent link="link_4"/>
    <child link="link_7"/>
    <origin xyz="1.0 0.0 0.0"/>
    <axis xyz="0 0 1"/>
    <limit effort="30" lower="-10" upper="10" velocity="1.0"/>
  </joint>
  <joint independent="true" name="link_4_to_link_8" type="revolute">
    <parent link="link_4"/>
    <child link="link_8"/>
    <origin xyz="0.0 0.0 0.0"/>
    <axis xyz="0 0 1"/>
    <limit effort="30" lower="-10" upper="10" velocity="1.0"/>
  </joint>
  <joint independent="false" name="link_8_to_link_9" type="revolute">
    <parent link="link_8"/>
    <child link="link_9"/>
    <origin xyz="0.5 0.0 0.0"/>
    <axis xyz="0 0 1"/>
    <limit effort="30" lower="-10" upper="10" velocity="1.0"/>
  </joint>
  <loop name="constraint_7" type="revolute">
    <predecessor link="link_7">
      <origin xyz="0.5 0.0 0.0"/>
    </predecessor>
    <successor link="link_9">
      <origin xyz="1.0 0.0 0.0"/>
    </successor>
    <axis xyz="0 0 1"/>
  </loop>
  <link name="link_10">
    <inertial>
      <mass value="3.3"/>
      <origin xyz="0.0 0.0 0.0"/>
      <inertia ixx="0.011253" ixy="0" ixz="0" iyy="0.036203" iyz="0" izz="0.042673"/>
    </inertial>
    <visual>
      <origin rpy="0 0 0" xyz="0.25 0 0"/>
      <geometry>
        <box size="0.5 0.05 0.05"/>
      </geometry>
      <material name="Blue">
        <color rgba="0.1 0 0.8 1.0"/>
      </material>
    </visual>
  </link>
  <link name="link_11">
    <inertial>
      <mass value="3.3"/>
      <origin xyz="0.0 0.0 0.0"/>
      <inertia ixx="0.011253" ixy="0" ixz="0" iyy="0.036203" iyz="0" izz="0.042673"/>
    </inertial>
    <visual>
      <origin rpy="0 0 0" xyz="0.25 0 0"/>
      <geometry>
        <box size="0.5 0.05 0.05"/>
      </geometry>
      <material name="Red">
        <color rgba="0.8 0.1 0.1 1.0"/>
      </material>
    </visual>
  </link>
  <link name="link_12">
    <inertial>
      <mass value="3.3"/>
      <origin xyz="0.0 0.0 0.0"/>
      <inertia ixx="0.011253" ixy="0" ixz="0" iyy="0.036203" iyz="0" izz="0.042673"/>
    </inertial>
    <visual>
      <origin rpy="0 0 0" xyz="0.5 0 0"/>
      <geometry>
        <box size="1.0 0.05 0.05"/>
      </geometry>
      <material name="Green2">
        <color rgba="0.1 0.8 0 1.0"/>
      </material>
    </visual>
  </link>
  <joint independent="false" name="link_7_to_link_10" type="revolute">
    <parent link="link_7"/>
    <child link="link_10"/>
    <origin xyz="1.0 0.0 0.0"/>
    <axis xyz="0 0 1"/>
    <limit effort="30" lower="-10" upper="10" velocity="1.0"/>
  </joint>
  <joint independent="true" name="link_7_to_link_11" type="revolute">
    <parent link="link_7"/>
    <child link="link_11"/>
    <origin xyz="0.0 0.0 0.0"/>
    <axis xyz="0 0 1"/>
    <limit effort="30" lower="-10" upper="10" velocity="1.0"/>
  </joint>
  <joint independent="false" name="link_11_to_link_12" type="revolute">
    <parent link="link_11"/>
    <child link="link_12"/>
    <origin xyz="0.5 0.0 0.0"/>
    <axis xyz="0 0 1"/>
    <limit effort="30" lower="-10" upper="10" velocity="1.0"/>
  </joint>
  <loop name="constraint_10" type="revolute">
    <predecessor link="link_10">
      <origin xyz="0.5 0.0 0.0"/>
    </predecessor>
    <successor link="link_12">
      <origin xyz="1.0 0.0 0.0"/>
    </successor>
    <axis xyz="0 0 1"/>
  </loop>
  <link name="link_13">
    <inertial>
      <mass value="3.3"/>
      <origin xyz="0.0 0.0 0.0"/>
      <inertia ixx="0.011253" ixy="0" ixz="0" iyy="0.036203" iyz="0" izz="0.042673"/>
    </inertial>
    <visual>
      <origin rpy="0 0 0" xyz="0.25 0 0"/>
      <geometry>
        <box size="0.5 0.05 0.05"/>
      </geometry>
      <material name="Blue">
        <color rgba="0.1 0 0.8 1.0"/>
      </material>
    </visual>
  </link>
  <link name="link_14">
    <inertial>
      <mass value="3.3"/>
      <origin xyz="0.0 0.0 0.0"/>
      <inertia ixx="0.011253" ixy="0" ixz="0" iyy="0.036203" iyz="0" izz="0.042673"/>
    </inertial>
    <visual>
      <origin rpy="0 0 0" xyz="0.25 0 0"/>
      <geometry>
        <box size="0.5 0.05 0.05"/>
      </geometry>
      <material name="Red">
        <color rgba="0.8 0.1 0.1 1.0"/>
      </material>
    </visual>
  </link>
  <link name="link_15">
    <inertial>
      <mass value="3.3"/>
      <origin xyz="0.0 0.0 0.0"/>
      <inertia ixx="0.011253" ixy="0" ixz="0" iyy="0.036203" iyz="0" izz="0.042673"/>
    </inertial>
    <visual>
      <origin rpy="0 0 0" xyz="0.5 0 0"/>
      <geometry>
        <box size="1.0 0.05 0.05"/>
      </geometry>
      <material name="Green2">
        <color rgba="0.1 0.8 0 1.0"/>
      </material>
    </visual>
  </link>
  <joint independent="false" name="link_10_to_link_13" type="revolute">
    <parent link="link_10"/>
    <child link="link_13"/>
    <origin xyz="1.0 0.0 0.0"/>
    <axis xyz="0 0 1"/>
    <limit effort="30" lower="-10" upper="10" velocity="1.0"/>
  </joint>
  <joint independent="true" name="link_10_to_link_14" type="revolute">
    <parent link="link_10"/>
    <child link="link_14"/>
    <origin xyz="0.0 0.0 0.0"/>
    <axis xyz="0 0 1"/>
    <limit effort="30" lower="-10" upper="10" velocity="1.0"/>
  </joint>
  <joint independent="false" name="link_14_to_link_15" type="revolute">
    <parent link="link_14"/>
    <child link="link_15"/>
    <origin xyz="0.5 0.0 0.0"/>
    <axis xyz="0 0 1"/>
    <limit effort="30" lower="-10" upper="10" velocity="1.0"/>
  </joint>
  <loop name="constraint_13" type="revolute">
    <predecessor link="link_13">
      <origin xyz="0.5 0.0 0.0"/>
    </predecessor>
    <successor link="link_15">
      <origin xyz="1.0 0.0 0.0"/>
    </successor>
    <axis xyz="0 0 1"/>
  </loop>
  <link name="link_16">
    <inertial>
      <mass value="3.3"/>
      <origin xyz="0.0 0.0 0.0"/>
      <inertia ixx="0.011253" ixy="0" ixz="0" iyy="0.036203" iyz="0" izz="0.042673"/>
    </inertial>
    <visual>
      <origin rpy="0 0 0" xyz="0.25 0 0"/>
      <geometry>
        <box size="0.5 0.05 0.05"/>
      </geometry>
      <material name="Blue">
        <color rgba="0.1 0 0.8 1.0"/>
      </material>
    </visual>
  </link>
  <link name="link_17">
    <inertial>
      <mass value="3.3"/>
      <origin xyz="0.0 0.0 0.0"/>
      <inertia ixx="0.011253" ixy="0" ixz="0" iyy="0.036203" iyz="0" izz="0.042673"/>
    </inertial>
    <visual>
      <origin rpy="0 0 0" xyz="0.25 0 0"/>
      <geometry>
        <box size="0.5 0.05 0.05"/>
      </geometry>
      <material name="Red">
        <color rgba="0.8 0.1 0.1 1.0"/>
      </material>
    </visual>
  </link>
  <link name="link_18">
    <inertial>
      <mass value="3.3"/>
      <origin xyz="0.0 0.0 0.0"/>
      <inertia ixx="0.011253" ixy="0" ixz="0" iyy="0.036203" iyz="0" izz="0.042673"/>
    </inertial>
    <visual>
      <origin rpy="0 0 0" xyz="0.5 0 0"/>
      <geometry>
        <box size="1.0 0.05 0.05"/>
      </geometry>
      <material name="Green2">
        <color rgba="0.1 0.8 0 1.0"/>
      </material>
    </visual>
  </link>
  <joint independent="false" name="link_13_to_link_16" type="revolute">
    <parent link="link_13"/>
    <child link="link_16"/>
    <origin xyz="1.0 0.0 0.0"/>
    <axis xyz="0 0 1"/>
    <limit effort="30" lower="-10" upper="10" velocity="1.0"/>
  </joint>
  <joint independent="true" name="link_13_to_link_17" type="revolute">
    <parent link="link_13"/>
    <child link="link_17"/>
    <origin xyz="0.0 0.0 0.0"/>
    <axis xyz="0 0 1"/>
    <limit effort="30" lower="-10" upper="10" velocity="1.0"/>
  </joint>
  <joint independent="false" name="link_17_to_link_18" type="revolute">
    <parent link="link_17"/>
    <child link="link_18"/>
    <origin xyz="0.5 0.0 0.0"/>
    <axis xyz="0 0 1"/>
    <limit effort="30" lower="-10" upper="10" velocity="1.0"/>
  </joint>
  <loop name="constraint_16" type="revolute">
    <predecessor link="link_16">
      <origin xyz="0.5 0.0 0.0"/>
    </predecessor>
    <successor link="link_18">
      <origin xyz="1.0 0.0 0.0"/>
    </successor>
    <axis xyz="0 0 1"/>
  </loop>
</robot>
