<?xml version="1.0" ?>
<!-- =================================================================================== -->
<!-- |    This document was autogenerated by xacro from four_bar_branch.xacro          | -->
<!-- |    EDITING THIS FILE BY HAND IS NOT RECOMMENDED                                 | -->
<!-- =================================================================================== -->
<robot name="variable_four_bar_branch">
  <link name="base"/>
  <link name="link_4">
    <inertial>
      <mass value="3.3"/>
      <origin xyz="0.0 0.0 0.0"/>
      <inertia ixx="0.011253" ixy="0" ixz="0" iyy="0.036203" iyz="0" izz="0.042673"/>
    </inertial>
    <visual>
      <origin rpy="0 0 0" xyz="0.25 0 0"/>
      <geometry>
        <box size="0.5 0.05 0.05"/>
      </geometry>
      <material name="Blue">
        <color rgba="0.1 0 0.8 1.0"/>
      </material>
    </visual>
  </link>
  <link name="link_5">
    <inertial>
      <mass value="3.3"/>
      <origin xyz="0.0 0.0 0.0"/>
      <inertia ixx="0.011253" ixy="0" ixz="0" iyy="0.036203" iyz="0" izz="0.042673"/>
    </inertial>
    <visual>
      <origin rpy="0 0 0" xyz="0.25 0 0"/>
      <geometry>
        <box size="0.5 0.05 0.05"/>
      </geometry>
      <material name="Red">
        <color rgba="0.8 0.1 0.1 1.0"/>
      </material>
    </visual>
  </link>
  <link name="link_6">
    <inertial>
      <mass value="3.3"/>
      <origin xyz="0.0 0.0 0.0"/>
      <inertia ixx="0.011253" ixy="0" ixz="0" iyy="0.036203" iyz="0" izz="0.042673"/>
    </inertial>
    <visual>
      <origin rpy="0 0 0" xyz="0.5 0 0"/>
      <geometry>
        <box size="1.0 0.05 0.05"/>
      </geometry>
      <material name="Green2">
        <color rgba="0.1 0.8 0 1.0"/>
      </material>
    </visual>
  </link>
  <joint independent="false" name="base_to_link_4" type="revolute">
    <parent link="base"/>
    <child link="link_4"/>
    <origin xyz="1.0 0.0 0.0"/>
    <axis xyz="0 0 1"/>
    <limit effort="30" lower="-10" upper="10" velocity="1.0"/>
  </joint>
  <joint independent="true" name="base_to_link_5" type="revolute">
    <parent link="base"/>
    <child link="link_5"/>
    <origin xyz="0.0 0.0 0.0"/>
    <axis xyz="0 0 1"/>
    <limit effort="30" lower="-10" upper="10" velocity="1.0"/>
  </joint>
  <joint independent="false" name="link_5_to_link_6" type="revolute">
    <parent link="link_5"/>
    <child link="link_6"/>
    <origin xyz="0.5 0.0 0.0"/>
    <axis xyz="0 0 1"/>
    <limit effort="30" lower="-10" upper="10" velocity="1.0"/>
  </joint>
  <loop name="constraint_4" type="revolute">
    <predecessor link="link_4">
      <origin xyz="0.5 0.0 0.0"/>
    </predecessor>
    <successor link="link_6">
      <origin xyz="1.0 0.0 0.0"/>
    </successor>
    <axis xyz="0 0 1"/>
  </loop>
  <link name="link_1">
    <inertial>
      <mass value="3.3"/>
      <origin xyz="0.0 0.0 0.0"/>
      <inertia ixx="0.011253" ixy="0" ixz="0" iyy="0.036203" iyz="0" izz="0.042673"/>
    </inertial>
    <visual>
      <origin rpy="0 0 0" xyz="0.25 0 0"/>
      <geometry>
        <box size="0.5 0.05 0.05"/>
      </geometry>
      <material name="Blue">
        <color rgba="0.1 0 0.8 1.0"/>
      </material>
    </visual>
  </link>
  <link name="link_2">
    <inertial>
      <mass value="3.3"/>
      <origin xyz="0.0 0.0 0.0"/>
      <inertia ixx="0.011253" ixy="0" ixz="0" iyy="0.036203" iyz="0" izz="0.042673"/>
    </inertial>
    <visual>
      <origin rpy="0 0 0" xyz="0.25 0 0"/>
      <geometry>
        <box size="0.5 0.05 0.05"/>
      </geometry>
      <material name="Red">
        <color rgba="0.8 0.1 0.1 1.0"/>
      </material>
    </visual>
  </link>
  <link name="link_3">
    <inertial>
      <mass value="3.3"/>
      <origin xyz="0.0 0.0 0.0"/>
      <inertia ixx="0.011253" ixy="0" ixz="0" iyy="0.036203" iyz="0" izz="0.042673"/>
    </inertial>
    <visual>
      <origin rpy="0 0 0" xyz="0.5 0 0"/>
      <geometry>
        <box size="1.0 0.05 0.05"/>
      </geometry>
      <material name="Green2">
        <color rgba="0.1 0.8 0 1.0"/>
      </material>
    </visual>
  </link>
  <joint independent="false" name="base_to_link_1" type="revolute">
    <parent link="base"/>
    <child link="link_1"/>
    <origin xyz="1.0 0.0 0.0"/>
    <axis xyz="0 0 1"/>
    <limit effort="30" lower="-10" upper="10" velocity="1.0"/>
  </joint>
  <joint independent="true" name="base_to_link_2" type="revolute">
    <parent link="base"/>
    <child link="link_2"/>
    <origin xyz="0.0 0.0 0.0"/>
    <axis xyz="0 0 1"/>
    <limit effort="30" lower="-10" upper="10" velocity="1.0"/>
  </joint>
  <joint independent="false" name="link_2_to_link_3" type="revolute">
    <parent link="link_2"/>
    <child link="link_3"/>
    <origin xyz="0.5 0.0 0.0"/>
    <axis xyz="0 0 1"/>
    <limit effort="30" lower="-10" upper="10" velocity="1.0"/>
  </joint>
  <loop name="constraint_1" type="revolute">
    <predecessor link="link_1">
      <origin xyz="0.5 0.0 0.0"/>
    </predecessor>
    <successor link="link_3">
      <origin xyz="1.0 0.0 0.0"/>
    </successor>
    <axis xyz="0 0 1"/>
  </loop>
  <link name="link_31">
    <inertial>
      <mass value="3.3"/>
      <origin xyz="0.0 0.0 0.0"/>
      <inertia ixx="0.011253" ixy="0" ixz="0" iyy="0.036203" iyz="0" izz="0.042673"/>
    </inertial>
    <visual>
      <origin rpy="0 0 0" xyz="0.25 0 0"/>
      <geometry>
        <box size="0.5 0.05 0.05"/>
      </geometry>
      <material name="Blue">
        <color rgba="0.1 0 0.8 1.0"/>
      </material>
    </visual>
  </link>
  <link name="link_32">
    <inertial>
      <mass value="3.3"/>
      <origin xyz="0.0 0.0 0.0"/>
      <inertia ixx="0.011253" ixy="0" ixz="0" iyy="0.036203" iyz="0" izz="0.042673"/>
    </inertial>
    <visual>
      <origin rpy="0 0 0" xyz="0.25 0 0"/>
      <geometry>
        <box size="0.5 0.05 0.05"/>
      </geometry>
      <material name="Red">
        <color rgba="0.8 0.1 0.1 1.0"/>
      </material>
    </visual>
  </link>
  <link name="link_33">
    <inertial>
      <mass value="3.3"/>
      <origin xyz="0.0 0.0 0.0"/>
      <inertia ixx="0.011253" ixy="0" ixz="0" iyy="0.036203" iyz="0" izz="0.042673"/>
    </inertial>
    <visual>
      <origin rpy="0 0 0" xyz="0.5 0 0"/>
      <geometry>
        <box size="1.0 0.05 0.05"/>
      </geometry>
      <material name="Green2">
        <color rgba="0.1 0.8 0 1.0"/>
      </material>
    </visual>
  </link>
  <joint independent="false" name="link_4_to_link_31" type="revolute">
    <parent link="link_4"/>
    <child link="link_31"/>
    <origin xyz="1.0 0.0 0.0"/>
    <axis xyz="0 0 1"/>
    <limit effort="30" lower="-10" upper="10" velocity="1.0"/>
  </joint>
  <joint independent="true" name="link_4_to_link_32" type="revolute">
    <parent link="link_4"/>
    <child link="link_32"/>
    <origin xyz="0.0 0.0 0.0"/>
    <axis xyz="0 0 1"/>
    <limit effort="30" lower="-10" upper="10" velocity="1.0"/>
  </joint>
  <joint independent="false" name="link_32_to_link_33" type="revolute">
    <parent link="link_32"/>
    <child link="link_33"/>
    <origin xyz="0.5 0.0 0.0"/>
    <axis xyz="0 0 1"/>
    <limit effort="30" lower="-10" upper="10" velocity="1.0"/>
  </joint>
  <loop name="constraint_31" type="revolute">
    <predecessor link="link_31">
      <origin xyz="0.5 0.0 0.0"/>
    </predecessor>
    <successor link="link_33">
      <origin xyz="1.0 0.0 0.0"/>
    </successor>
    <axis xyz="0 0 1"/>
  </loop>
  <link name="link_34">
    <inertial>
      <mass value="3.3"/>
      <origin xyz="0.0 0.0 0.0"/>
      <inertia ixx="0.011253" ixy="0" ixz="0" iyy="0.036203" iyz="0" izz="0.042673"/>
    </inertial>
    <visual>
      <origin rpy="0 0 0" xyz="0.25 0 0"/>
      <geometry>
        <box size="0.5 0.05 0.05"/>
      </geometry>
      <material name="Blue">
        <color rgba="0.1 0 0.8 1.0"/>
      </material>
    </visual>
  </link>
  <link name="link_35">
    <inertial>
      <mass value="3.3"/>
      <origin xyz="0.0 0.0 0.0"/>
      <inertia ixx="0.011253" ixy="0" ixz="0" iyy="0.036203" iyz="0" izz="0.042673"/>
    </inertial>
    <visual>
      <origin rpy="0 0 0" xyz="0.25 0 0"/>
      <geometry>
        <box size="0.5 0.05 0.05"/>
      </geometry>
      <material name="Red">
        <color rgba="0.8 0.1 0.1 1.0"/>
      </material>
    </visual>
  </link>
  <link name="link_36">
    <inertial>
      <mass value="3.3"/>
      <origin xyz="0.0 0.0 0.0"/>
      <inertia ixx="0.011253" ixy="0" ixz="0" iyy="0.036203" iyz="0" izz="0.042673"/>
    </inertial>
    <visual>
      <origin rpy="0 0 0" xyz="0.5 0 0"/>
      <geometry>
        <box size="1.0 0.05 0.05"/>
      </geometry>
      <material name="Green2">
        <color rgba="0.1 0.8 0 1.0"/>
      </material>
    </visual>
  </link>
  <joint independent="false" name="link_31_to_link_34" type="revolute">
    <parent link="link_31"/>
    <child link="link_34"/>
    <origin xyz="1.0 0.0 0.0"/>
    <axis xyz="0 0 1"/>
    <limit effort="30" lower="-10" upper="10" velocity="1.0"/>
  </joint>
  <joint independent="true" name="link_31_to_link_35" type="revolute">
    <parent link="link_31"/>
    <child link="link_35"/>
    <origin xyz="0.0 0.0 0.0"/>
    <axis xyz="0 0 1"/>
    <limit effort="30" lower="-10" upper="10" velocity="1.0"/>
  </joint>
  <joint independent="false" name="link_35_to_link_36" type="revolute">
    <parent link="link_35"/>
    <child link="link_36"/>
    <origin xyz="0.5 0.0 0.0"/>
    <axis xyz="0 0 1"/>
    <limit effort="30" lower="-10" upper="10" velocity="1.0"/>
  </joint>
  <loop name="constraint_34" type="revolute">
    <predecessor link="link_34">
      <origin xyz="0.5 0.0 0.0"/>
    </predecessor>
    <successor link="link_36">
      <origin xyz="1.0 0.0 0.0"/>
    </successor>
    <axis xyz="0 0 1"/>
  </loop>
  <link name="link_37">
    <inertial>
      <mass value="3.3"/>
      <origin xyz="0.0 0.0 0.0"/>
      <inertia ixx="0.011253" ixy="0" ixz="0" iyy="0.036203" iyz="0" izz="0.042673"/>
    </inertial>
    <visual>
      <origin rpy="0 0 0" xyz="0.25 0 0"/>
      <geometry>
        <box size="0.5 0.05 0.05"/>
      </geometry>
      <material name="Blue">
        <color rgba="0.1 0 0.8 1.0"/>
      </material>
    </visual>
  </link>
  <link name="link_38">
    <inertial>
      <mass value="3.3"/>
      <origin xyz="0.0 0.0 0.0"/>
      <inertia ixx="0.011253" ixy="0" ixz="0" iyy="0.036203" iyz="0" izz="0.042673"/>
    </inertial>
    <visual>
      <origin rpy="0 0 0" xyz="0.25 0 0"/>
      <geometry>
        <box size="0.5 0.05 0.05"/>
      </geometry>
      <material name="Red">
        <color rgba="0.8 0.1 0.1 1.0"/>
      </material>
    </visual>
  </link>
  <link name="link_39">
    <inertial>
      <mass value="3.3"/>
      <origin xyz="0.0 0.0 0.0"/>
      <inertia ixx="0.011253" ixy="0" ixz="0" iyy="0.036203" iyz="0" izz="0.042673"/>
    </inertial>
    <visual>
      <origin rpy="0 0 0" xyz="0.5 0 0"/>
      <geometry>
        <box size="1.0 0.05 0.05"/>
      </geometry>
      <material name="Green2">
        <color rgba="0.1 0.8 0 1.0"/>
      </material>
    </visual>
  </link>
  <joint independent="false" name="link_34_to_link_37" type="revolute">
    <parent link="link_34"/>
    <child link="link_37"/>
    <origin xyz="1.0 0.0 0.0"/>
    <axis xyz="0 0 1"/>
    <limit effort="30" lower="-10" upper="10" velocity="1.0"/>
  </joint>
  <joint independent="true" name="link_34_to_link_38" type="revolute">
    <parent link="link_34"/>
    <child link="link_38"/>
    <origin xyz="0.0 0.0 0.0"/>
    <axis xyz="0 0 1"/>
    <limit effort="30" lower="-10" upper="10" velocity="1.0"/>
  </joint>
  <joint independent="false" name="link_38_to_link_39" type="revolute">
    <parent link="link_38"/>
    <child link="link_39"/>
    <origin xyz="0.5 0.0 0.0"/>
    <axis xyz="0 0 1"/>
    <limit effort="30" lower="-10" upper="10" velocity="1.0"/>
  </joint>
  <loop name="constraint_37" type="revolute">
    <predecessor link="link_37">
      <origin xyz="0.5 0.0 0.0"/>
    </predecessor>
    <successor link="link_39">
      <origin xyz="1.0 0.0 0.0"/>
    </successor>
    <axis xyz="0 0 1"/>
  </loop>
  <link name="link_40">
    <inertial>
      <mass value="3.3"/>
      <origin xyz="0.0 0.0 0.0"/>
      <inertia ixx="0.011253" ixy="0" ixz="0" iyy="0.036203" iyz="0" izz="0.042673"/>
    </inertial>
    <visual>
      <origin rpy="0 0 0" xyz="0.25 0 0"/>
      <geometry>
        <box size="0.5 0.05 0.05"/>
      </geometry>
      <material name="Blue">
        <color rgba="0.1 0 0.8 1.0"/>
      </material>
    </visual>
  </link>
  <link name="link_41">
    <inertial>
      <mass value="3.3"/>
      <origin xyz="0.0 0.0 0.0"/>
      <inertia ixx="0.011253" ixy="0" ixz="0" iyy="0.036203" iyz="0" izz="0.042673"/>
    </inertial>
    <visual>
      <origin rpy="0 0 0" xyz="0.25 0 0"/>
      <geometry>
        <box size="0.5 0.05 0.05"/>
      </geometry>
      <material name="Red">
        <color rgba="0.8 0.1 0.1 1.0"/>
      </material>
    </visual>
  </link>
  <link name="link_42">
    <inertial>
      <mass value="3.3"/>
      <origin xyz="0.0 0.0 0.0"/>
      <inertia ixx="0.011253" ixy="0" ixz="0" iyy="0.036203" iyz="0" izz="0.042673"/>
    </inertial>
    <visual>
      <origin rpy="0 0 0" xyz="0.5 0 0"/>
      <geometry>
        <box size="1.0 0.05 0.05"/>
      </geometry>
      <material name="Green2">
        <color rgba="0.1 0.8 0 1.0"/>
      </material>
    </visual>
  </link>
  <joint independent="false" name="link_37_to_link_40" type="revolute">
    <parent link="link_37"/>
    <child link="link_40"/>
    <origin xyz="1.0 0.0 0.0"/>
    <axis xyz="0 0 1"/>
    <limit effort="30" lower="-10" upper="10" velocity="1.0"/>
  </joint>
  <joint independent="true" name="link_37_to_link_41" type="revolute">
    <parent link="link_37"/>
    <child link="link_41"/>
    <origin xyz="0.0 0.0 0.0"/>
    <axis xyz="0 0 1"/>
    <limit effort="30" lower="-10" upper="10" velocity="1.0"/>
  </joint>
  <joint independent="false" name="link_41_to_link_42" type="revolute">
    <parent link="link_41"/>
    <child link="link_42"/>
    <origin xyz="0.5 0.0 0.0"/>
    <axis xyz="0 0 1"/>
    <limit effort="30" lower="-10" upper="10" velocity="1.0"/>
  </joint>
  <loop name="constraint_40" type="revolute">
    <predecessor link="link_40">
      <origin xyz="0.5 0.0 0.0"/>
    </predecessor>
    <successor link="link_42">
      <origin xyz="1.0 0.0 0.0"/>
    </successor>
    <axis xyz="0 0 1"/>
  </loop>
  <link name="link_43">
    <inertial>
      <mass value="3.3"/>
      <origin xyz="0.0 0.0 0.0"/>
      <inertia ixx="0.011253" ixy="0" ixz="0" iyy="0.036203" iyz="0" izz="0.042673"/>
    </inertial>
    <visual>
      <origin rpy="0 0 0" xyz="0.25 0 0"/>
      <geometry>
        <box size="0.5 0.05 0.05"/>
      </geometry>
      <material name="Blue">
        <color rgba="0.1 0 0.8 1.0"/>
      </material>
    </visual>
  </link>
  <link name="link_44">
    <inertial>
      <mass value="3.3"/>
      <origin xyz="0.0 0.0 0.0"/>
      <inertia ixx="0.011253" ixy="0" ixz="0" iyy="0.036203" iyz="0" izz="0.042673"/>
    </inertial>
    <visual>
      <origin rpy="0 0 0" xyz="0.25 0 0"/>
      <geometry>
        <box size="0.5 0.05 0.05"/>
      </geometry>
      <material name="Red">
        <color rgba="0.8 0.1 0.1 1.0"/>
      </material>
    </visual>
  </link>
  <link name="link_45">
    <inertial>
      <mass value="3.3"/>
      <origin xyz="0.0 0.0 0.0"/>
      <inertia ixx="0.011253" ixy="0" ixz="0" iyy="0.036203" iyz="0" izz="0.042673"/>
    </inertial>
    <visual>
      <origin rpy="0 0 0" xyz="0.5 0 0"/>
      <geometry>
        <box size="1.0 0.05 0.05"/>
      </geometry>
      <material name="Green2">
        <color rgba="0.1 0.8 0 1.0"/>
      </material>
    </visual>
  </link>
  <joint independent="false" name="link_40_to_link_43" type="revolute">
    <parent link="link_40"/>
    <child link="link_43"/>
    <origin xyz="1.0 0.0 0.0"/>
    <axis xyz="0 0 1"/>
    <limit effort="30" lower="-10" upper="10" velocity="1.0"/>
  </joint>
  <joint independent="true" name="link_40_to_link_44" type="revolute">
    <parent link="link_40"/>
    <child link="link_44"/>
    <origin xyz="0.0 0.0 0.0"/>
    <axis xyz="0 0 1"/>
    <limit effort="30" lower="-10" upper="10" velocity="1.0"/>
  </joint>
  <joint independent="false" name="link_44_to_link_45" type="revolute">
    <parent link="link_44"/>
    <child link="link_45"/>
    <origin xyz="0.5 0.0 0.0"/>
    <axis xyz="0 0 1"/>
    <limit effort="30" lower="-10" upper="10" velocity="1.0"/>
  </joint>
  <loop name="constraint_43" type="revolute">
    <predecessor link="link_43">
      <origin xyz="0.5 0.0 0.0"/>
    </predecessor>
    <successor link="link_45">
      <origin xyz="1.0 0.0 0.0"/>
    </successor>
    <axis xyz="0 0 1"/>
  </loop>
  <link name="link_46">
    <inertial>
      <mass value="3.3"/>
      <origin xyz="0.0 0.0 0.0"/>
      <inertia ixx="0.011253" ixy="0" ixz="0" iyy="0.036203" iyz="0" izz="0.042673"/>
    </inertial>
    <visual>
      <origin rpy="0 0 0" xyz="0.25 0 0"/>
      <geometry>
        <box size="0.5 0.05 0.05"/>
      </geometry>
      <material name="Blue">
        <color rgba="0.1 0 0.8 1.0"/>
      </material>
    </visual>
  </link>
  <link name="link_47">
    <inertial>
      <mass value="3.3"/>
      <origin xyz="0.0 0.0 0.0"/>
      <inertia ixx="0.011253" ixy="0" ixz="0" iyy="0.036203" iyz="0" izz="0.042673"/>
    </inertial>
    <visual>
      <origin rpy="0 0 0" xyz="0.25 0 0"/>
      <geometry>
        <box size="0.5 0.05 0.05"/>
      </geometry>
      <material name="Red">
        <color rgba="0.8 0.1 0.1 1.0"/>
      </material>
    </visual>
  </link>
  <link name="link_48">
    <inertial>
      <mass value="3.3"/>
      <origin xyz="0.0 0.0 0.0"/>
      <inertia ixx="0.011253" ixy="0" ixz="0" iyy="0.036203" iyz="0" izz="0.042673"/>
    </inertial>
    <visual>
      <origin rpy="0 0 0" xyz="0.5 0 0"/>
      <geometry>
        <box size="1.0 0.05 0.05"/>
      </geometry>
      <material name="Green2">
        <color rgba="0.1 0.8 0 1.0"/>
      </material>
    </visual>
  </link>
  <joint independent="false" name="link_43_to_link_46" type="revolute">
    <parent link="link_43"/>
    <child link="link_46"/>
    <origin xyz="1.0 0.0 0.0"/>
    <axis xyz="0 0 1"/>
    <limit effort="30" lower="-10" upper="10" velocity="1.0"/>
  </joint>
  <joint independent="true" name="link_43_to_link_47" type="revolute">
    <parent link="link_43"/>
    <child link="link_47"/>
    <origin xyz="0.0 0.0 0.0"/>
    <axis xyz="0 0 1"/>
    <limit effort="30" lower="-10" upper="10" velocity="1.0"/>
  </joint>
  <joint independent="false" name="link_47_to_link_48" type="revolute">
    <parent link="link_47"/>
    <child link="link_48"/>
    <origin xyz="0.5 0.0 0.0"/>
    <axis xyz="0 0 1"/>
    <limit effort="30" lower="-10" upper="10" velocity="1.0"/>
  </joint>
  <loop name="constraint_46" type="revolute">
    <predecessor link="link_46">
      <origin xyz="0.5 0.0 0.0"/>
    </predecessor>
    <successor link="link_48">
      <origin xyz="1.0 0.0 0.0"/>
    </successor>
    <axis xyz="0 0 1"/>
  </loop>
  <link name="link_49">
    <inertial>
      <mass value="3.3"/>
      <origin xyz="0.0 0.0 0.0"/>
      <inertia ixx="0.011253" ixy="0" ixz="0" iyy="0.036203" iyz="0" izz="0.042673"/>
    </inertial>
    <visual>
      <origin rpy="0 0 0" xyz="0.25 0 0"/>
      <geometry>
        <box size="0.5 0.05 0.05"/>
      </geometry>
      <material name="Blue">
        <color rgba="0.1 0 0.8 1.0"/>
      </material>
    </visual>
  </link>
  <link name="link_50">
    <inertial>
      <mass value="3.3"/>
      <origin xyz="0.0 0.0 0.0"/>
      <inertia ixx="0.011253" ixy="0" ixz="0" iyy="0.036203" iyz="0" izz="0.042673"/>
    </inertial>
    <visual>
      <origin rpy="0 0 0" xyz="0.25 0 0"/>
      <geometry>
        <box size="0.5 0.05 0.05"/>
      </geometry>
      <material name="Red">
        <color rgba="0.8 0.1 0.1 1.0"/>
      </material>
    </visual>
  </link>
  <link name="link_51">
    <inertial>
      <mass value="3.3"/>
      <origin xyz="0.0 0.0 0.0"/>
      <inertia ixx="0.011253" ixy="0" ixz="0" iyy="0.036203" iyz="0" izz="0.042673"/>
    </inertial>
    <visual>
      <origin rpy="0 0 0" xyz="0.5 0 0"/>
      <geometry>
        <box size="1.0 0.05 0.05"/>
      </geometry>
      <material name="Green2">
        <color rgba="0.1 0.8 0 1.0"/>
      </material>
    </visual>
  </link>
  <joint independent="false" name="link_46_to_link_49" type="revolute">
    <parent link="link_46"/>
    <child link="link_49"/>
    <origin xyz="1.0 0.0 0.0"/>
    <axis xyz="0 0 1"/>
    <limit effort="30" lower="-10" upper="10" velocity="1.0"/>
  </joint>
  <joint independent="true" name="link_46_to_link_50" type="revolute">
    <parent link="link_46"/>
    <child link="link_50"/>
    <origin xyz="0.0 0.0 0.0"/>
    <axis xyz="0 0 1"/>
    <limit effort="30" lower="-10" upper="10" velocity="1.0"/>
  </joint>
  <joint independent="false" name="link_50_to_link_51" type="revolute">
    <parent link="link_50"/>
    <child link="link_51"/>
    <origin xyz="0.5 0.0 0.0"/>
    <axis xyz="0 0 1"/>
    <limit effort="30" lower="-10" upper="10" velocity="1.0"/>
  </joint>
  <loop name="constraint_49" type="revolute">
    <predecessor link="link_49">
      <origin xyz="0.5 0.0 0.0"/>
    </predecessor>
    <successor link="link_51">
      <origin xyz="1.0 0.0 0.0"/>
    </successor>
    <axis xyz="0 0 1"/>
  </loop>
  <link name="link_52">
    <inertial>
      <mass value="3.3"/>
      <origin xyz="0.0 0.0 0.0"/>
      <inertia ixx="0.011253" ixy="0" ixz="0" iyy="0.036203" iyz="0" izz="0.042673"/>
    </inertial>
    <visual>
      <origin rpy="0 0 0" xyz="0.25 0 0"/>
      <geometry>
        <box size="0.5 0.05 0.05"/>
      </geometry>
      <material name="Blue">
        <color rgba="0.1 0 0.8 1.0"/>
      </material>
    </visual>
  </link>
  <link name="link_53">
    <inertial>
      <mass value="3.3"/>
      <origin xyz="0.0 0.0 0.0"/>
      <inertia ixx="0.011253" ixy="0" ixz="0" iyy="0.036203" iyz="0" izz="0.042673"/>
    </inertial>
    <visual>
      <origin rpy="0 0 0" xyz="0.25 0 0"/>
      <geometry>
        <box size="0.5 0.05 0.05"/>
      </geometry>
      <material name="Red">
        <color rgba="0.8 0.1 0.1 1.0"/>
      </material>
    </visual>
  </link>
  <link name="link_54">
    <inertial>
      <mass value="3.3"/>
      <origin xyz="0.0 0.0 0.0"/>
      <inertia ixx="0.011253" ixy="0" ixz="0" iyy="0.036203" iyz="0" izz="0.042673"/>
    </inertial>
    <visual>
      <origin rpy="0 0 0" xyz="0.5 0 0"/>
      <geometry>
        <box size="1.0 0.05 0.05"/>
      </geometry>
      <material name="Green2">
        <color rgba="0.1 0.8 0 1.0"/>
      </material>
    </visual>
  </link>
  <joint independent="false" name="link_49_to_link_52" type="revolute">
    <parent link="link_49"/>
    <child link="link_52"/>
    <origin xyz="1.0 0.0 0.0"/>
    <axis xyz="0 0 1"/>
    <limit effort="30" lower="-10" upper="10" velocity="1.0"/>
  </joint>
  <joint independent="true" name="link_49_to_link_53" type="revolute">
    <parent link="link_49"/>
    <child link="link_53"/>
    <origin xyz="0.0 0.0 0.0"/>
    <axis xyz="0 0 1"/>
    <limit effort="30" lower="-10" upper="10" velocity="1.0"/>
  </joint>
  <joint independent="false" name="link_53_to_link_54" type="revolute">
    <parent link="link_53"/>
    <child link="link_54"/>
    <origin xyz="0.5 0.0 0.0"/>
    <axis xyz="0 0 1"/>
    <limit effort="30" lower="-10" upper="10" velocity="1.0"/>
  </joint>
  <loop name="constraint_52" type="revolute">
    <predecessor link="link_52">
      <origin xyz="0.5 0.0 0.0"/>
    </predecessor>
    <successor link="link_54">
      <origin xyz="1.0 0.0 0.0"/>
    </successor>
    <axis xyz="0 0 1"/>
  </loop>
  <link name="link_7">
    <inertial>
      <mass value="3.3"/>
      <origin xyz="0.0 0.0 0.0"/>
      <inertia ixx="0.011253" ixy="0" ixz="0" iyy="0.036203" iyz="0" izz="0.042673"/>
    </inertial>
    <visual>
      <origin rpy="0 0 0" xyz="0.25 0 0"/>
      <geometry>
        <box size="0.5 0.05 0.05"/>
      </geometry>
      <material name="Blue">
        <color rgba="0.1 0 0.8 1.0"/>
      </material>
    </visual>
  </link>
  <link name="link_8">
    <inertial>
      <mass value="3.3"/>
      <origin xyz="0.0 0.0 0.0"/>
      <inertia ixx="0.011253" ixy="0" ixz="0" iyy="0.036203" iyz="0" izz="0.042673"/>
    </inertial>
    <visual>
      <origin rpy="0 0 0" xyz="0.25 0 0"/>
      <geometry>
        <box size="0.5 0.05 0.05"/>
      </geometry>
      <material name="Red">
        <color rgba="0.8 0.1 0.1 1.0"/>
      </material>
    </visual>
  </link>
  <link name="link_9">
    <inertial>
      <mass value="3.3"/>
      <origin xyz="0.0 0.0 0.0"/>
      <inertia ixx="0.011253" ixy="0" ixz="0" iyy="0.036203" iyz="0" izz="0.042673"/>
    </inertial>
    <visual>
      <origin rpy="0 0 0" xyz="0.5 0 0"/>
      <geometry>
        <box size="1.0 0.05 0.05"/>
      </geometry>
      <material name="Green2">
        <color rgba="0.1 0.8 0 1.0"/>
      </material>
    </visual>
  </link>
  <joint independent="false" name="link_1_to_link_7" type="revolute">
    <parent link="link_1"/>
    <child link="link_7"/>
    <origin xyz="1.0 0.0 0.0"/>
    <axis xyz="0 0 1"/>
    <limit effort="30" lower="-10" upper="10" velocity="1.0"/>
  </joint>
  <joint independent="true" name="link_1_to_link_8" type="revolute">
    <parent link="link_1"/>
    <child link="link_8"/>
    <origin xyz="0.0 0.0 0.0"/>
    <axis xyz="0 0 1"/>
    <limit effort="30" lower="-10" upper="10" velocity="1.0"/>
  </joint>
  <joint independent="false" name="link_8_to_link_9" type="revolute">
    <parent link="link_8"/>
    <child link="link_9"/>
    <origin xyz="0.5 0.0 0.0"/>
    <axis xyz="0 0 1"/>
    <limit effort="30" lower="-10" upper="10" velocity="1.0"/>
  </joint>
  <loop name="constraint_7" type="revolute">
    <predecessor link="link_7">
      <origin xyz="0.5 0.0 0.0"/>
    </predecessor>
    <successor link="link_9">
      <origin xyz="1.0 0.0 0.0"/>
    </successor>
    <axis xyz="0 0 1"/>
  </loop>
  <link name="link_10">
    <inertial>
      <mass value="3.3"/>
      <origin xyz="0.0 0.0 0.0"/>
      <inertia ixx="0.011253" ixy="0" ixz="0" iyy="0.036203" iyz="0" izz="0.042673"/>
    </inertial>
    <visual>
      <origin rpy="0 0 0" xyz="0.25 0 0"/>
      <geometry>
        <box size="0.5 0.05 0.05"/>
      </geometry>
      <material name="Blue">
        <color rgba="0.1 0 0.8 1.0"/>
      </material>
    </visual>
  </link>
  <link name="link_11">
    <inertial>
      <mass value="3.3"/>
      <origin xyz="0.0 0.0 0.0"/>
      <inertia ixx="0.011253" ixy="0" ixz="0" iyy="0.036203" iyz="0" izz="0.042673"/>
    </inertial>
    <visual>
      <origin rpy="0 0 0" xyz="0.25 0 0"/>
      <geometry>
        <box size="0.5 0.05 0.05"/>
      </geometry>
      <material name="Red">
        <color rgba="0.8 0.1 0.1 1.0"/>
      </material>
    </visual>
  </link>
  <link name="link_12">
    <inertial>
      <mass value="3.3"/>
      <origin xyz="0.0 0.0 0.0"/>
      <inertia ixx="0.011253" ixy="0" ixz="0" iyy="0.036203" iyz="0" izz="0.042673"/>
    </inertial>
    <visual>
      <origin rpy="0 0 0" xyz="0.5 0 0"/>
      <geometry>
        <box size="1.0 0.05 0.05"/>
      </geometry>
      <material name="Green2">
        <color rgba="0.1 0.8 0 1.0"/>
      </material>
    </visual>
  </link>
  <joint independent="false" name="link_7_to_link_10" type="revolute">
    <parent link="link_7"/>
    <child link="link_10"/>
    <origin xyz="1.0 0.0 0.0"/>
    <axis xyz="0 0 1"/>
    <limit effort="30" lower="-10" upper="10" velocity="1.0"/>
  </joint>
  <joint independent="true" name="link_7_to_link_11" type="revolute">
    <parent link="link_7"/>
    <child link="link_11"/>
    <origin xyz="0.0 0.0 0.0"/>
    <axis xyz="0 0 1"/>
    <limit effort="30" lower="-10" upper="10" velocity="1.0"/>
  </joint>
  <joint independent="false" name="link_11_to_link_12" type="revolute">
    <parent link="link_11"/>
    <child link="link_12"/>
    <origin xyz="0.5 0.0 0.0"/>
    <axis xyz="0 0 1"/>
    <limit effort="30" lower="-10" upper="10" velocity="1.0"/>
  </joint>
  <loop name="constraint_10" type="revolute">
    <predecessor link="link_10">
      <origin xyz="0.5 0.0 0.0"/>
    </predecessor>
    <successor link="link_12">
      <origin xyz="1.0 0.0 0.0"/>
    </successor>
    <axis xyz="0 0 1"/>
  </loop>
  <link name="link_13">
    <inertial>
      <mass value="3.3"/>
      <origin xyz="0.0 0.0 0.0"/>
      <inertia ixx="0.011253" ixy="0" ixz="0" iyy="0.036203" iyz="0" izz="0.042673"/>
    </inertial>
    <visual>
      <origin rpy="0 0 0" xyz="0.25 0 0"/>
      <geometry>
        <box size="0.5 0.05 0.05"/>
      </geometry>
      <material name="Blue">
        <color rgba="0.1 0 0.8 1.0"/>
      </material>
    </visual>
  </link>
  <link name="link_14">
    <inertial>
      <mass value="3.3"/>
      <origin xyz="0.0 0.0 0.0"/>
      <inertia ixx="0.011253" ixy="0" ixz="0" iyy="0.036203" iyz="0" izz="0.042673"/>
    </inertial>
    <visual>
      <origin rpy="0 0 0" xyz="0.25 0 0"/>
      <geometry>
        <box size="0.5 0.05 0.05"/>
      </geometry>
      <material name="Red">
        <color rgba="0.8 0.1 0.1 1.0"/>
      </material>
    </visual>
  </link>
  <link name="link_15">
    <inertial>
      <mass value="3.3"/>
      <origin xyz="0.0 0.0 0.0"/>
      <inertia ixx="0.011253" ixy="0" ixz="0" iyy="0.036203" iyz="0" izz="0.042673"/>
    </inertial>
    <visual>
      <origin rpy="0 0 0" xyz="0.5 0 0"/>
      <geometry>
        <box size="1.0 0.05 0.05"/>
      </geometry>
      <material name="Green2">
        <color rgba="0.1 0.8 0 1.0"/>
      </material>
    </visual>
  </link>
  <joint independent="false" name="link_10_to_link_13" type="revolute">
    <parent link="link_10"/>
    <child link="link_13"/>
    <origin xyz="1.0 0.0 0.0"/>
    <axis xyz="0 0 1"/>
    <limit effort="30" lower="-10" upper="10" velocity="1.0"/>
  </joint>
  <joint independent="true" name="link_10_to_link_14" type="revolute">
    <parent link="link_10"/>
    <child link="link_14"/>
    <origin xyz="0.0 0.0 0.0"/>
    <axis xyz="0 0 1"/>
    <limit effort="30" lower="-10" upper="10" velocity="1.0"/>
  </joint>
  <joint independent="false" name="link_14_to_link_15" type="revolute">
    <parent link="link_14"/>
    <child link="link_15"/>
    <origin xyz="0.5 0.0 0.0"/>
    <axis xyz="0 0 1"/>
    <limit effort="30" lower="-10" upper="10" velocity="1.0"/>
  </joint>
  <loop name="constraint_13" type="revolute">
    <predecessor link="link_13">
      <origin xyz="0.5 0.0 0.0"/>
    </predecessor>
    <successor link="link_15">
      <origin xyz="1.0 0.0 0.0"/>
    </successor>
    <axis xyz="0 0 1"/>
  </loop>
  <link name="link_16">
    <inertial>
      <mass value="3.3"/>
      <origin xyz="0.0 0.0 0.0"/>
      <inertia ixx="0.011253" ixy="0" ixz="0" iyy="0.036203" iyz="0" izz="0.042673"/>
    </inertial>
    <visual>
      <origin rpy="0 0 0" xyz="0.25 0 0"/>
      <geometry>
        <box size="0.5 0.05 0.05"/>
      </geometry>
      <material name="Blue">
        <color rgba="0.1 0 0.8 1.0"/>
      </material>
    </visual>
  </link>
  <link name="link_17">
    <inertial>
      <mass value="3.3"/>
      <origin xyz="0.0 0.0 0.0"/>
      <inertia ixx="0.011253" ixy="0" ixz="0" iyy="0.036203" iyz="0" izz="0.042673"/>
    </inertial>
    <visual>
      <origin rpy="0 0 0" xyz="0.25 0 0"/>
      <geometry>
        <box size="0.5 0.05 0.05"/>
      </geometry>
      <material name="Red">
        <color rgba="0.8 0.1 0.1 1.0"/>
      </material>
    </visual>
  </link>
  <link name="link_18">
    <inertial>
      <mass value="3.3"/>
      <origin xyz="0.0 0.0 0.0"/>
      <inertia ixx="0.011253" ixy="0" ixz="0" iyy="0.036203" iyz="0" izz="0.042673"/>
    </inertial>
    <visual>
      <origin rpy="0 0 0" xyz="0.5 0 0"/>
      <geometry>
        <box size="1.0 0.05 0.05"/>
      </geometry>
      <material name="Green2">
        <color rgba="0.1 0.8 0 1.0"/>
      </material>
    </visual>
  </link>
  <joint independent="false" name="link_13_to_link_16" type="revolute">
    <parent link="link_13"/>
    <child link="link_16"/>
    <origin xyz="1.0 0.0 0.0"/>
    <axis xyz="0 0 1"/>
    <limit effort="30" lower="-10" upper="10" velocity="1.0"/>
  </joint>
  <joint independent="true" name="link_13_to_link_17" type="revolute">
    <parent link="link_13"/>
    <child link="link_17"/>
    <origin xyz="0.0 0.0 0.0"/>
    <axis xyz="0 0 1"/>
    <limit effort="30" lower="-10" upper="10" velocity="1.0"/>
  </joint>
  <joint independent="false" name="link_17_to_link_18" type="revolute">
    <parent link="link_17"/>
    <child link="link_18"/>
    <origin xyz="0.5 0.0 0.0"/>
    <axis xyz="0 0 1"/>
    <limit effort="30" lower="-10" upper="10" velocity="1.0"/>
  </joint>
  <loop name="constraint_16" type="revolute">
    <predecessor link="link_16">
      <origin xyz="0.5 0.0 0.0"/>
    </predecessor>
    <successor link="link_18">
      <origin xyz="1.0 0.0 0.0"/>
    </successor>
    <axis xyz="0 0 1"/>
  </loop>
  <link name="link_19">
    <inertial>
      <mass value="3.3"/>
      <origin xyz="0.0 0.0 0.0"/>
      <inertia ixx="0.011253" ixy="0" ixz="0" iyy="0.036203" iyz="0" izz="0.042673"/>
    </inertial>
    <visual>
      <origin rpy="0 0 0" xyz="0.25 0 0"/>
      <geometry>
        <box size="0.5 0.05 0.05"/>
      </geometry>
      <material name="Blue">
        <color rgba="0.1 0 0.8 1.0"/>
      </material>
    </visual>
  </link>
  <link name="link_20">
    <inertial>
      <mass value="3.3"/>
      <origin xyz="0.0 0.0 0.0"/>
      <inertia ixx="0.011253" ixy="0" ixz="0" iyy="0.036203" iyz="0" izz="0.042673"/>
    </inertial>
    <visual>
      <origin rpy="0 0 0" xyz="0.25 0 0"/>
      <geometry>
        <box size="0.5 0.05 0.05"/>
      </geometry>
      <material name="Red">
        <color rgba="0.8 0.1 0.1 1.0"/>
      </material>
    </visual>
  </link>
  <link name="link_21">
    <inertial>
      <mass value="3.3"/>
      <origin xyz="0.0 0.0 0.0"/>
      <inertia ixx="0.011253" ixy="0" ixz="0" iyy="0.036203" iyz="0" izz="0.042673"/>
    </inertial>
    <visual>
      <origin rpy="0 0 0" xyz="0.5 0 0"/>
      <geometry>
        <box size="1.0 0.05 0.05"/>
      </geometry>
      <material name="Green2">
        <color rgba="0.1 0.8 0 1.0"/>
      </material>
    </visual>
  </link>
  <joint independent="false" name="link_16_to_link_19" type="revolute">
    <parent link="link_16"/>
    <child link="link_19"/>
    <origin xyz="1.0 0.0 0.0"/>
    <axis xyz="0 0 1"/>
    <limit effort="30" lower="-10" upper="10" velocity="1.0"/>
  </joint>
  <joint independent="true" name="link_16_to_link_20" type="revolute">
    <parent link="link_16"/>
    <child link="link_20"/>
    <origin xyz="0.0 0.0 0.0"/>
    <axis xyz="0 0 1"/>
    <limit effort="30" lower="-10" upper="10" velocity="1.0"/>
  </joint>
  <joint independent="false" name="link_20_to_link_21" type="revolute">
    <parent link="link_20"/>
    <child link="link_21"/>
    <origin xyz="0.5 0.0 0.0"/>
    <axis xyz="0 0 1"/>
    <limit effort="30" lower="-10" upper="10" velocity="1.0"/>
  </joint>
  <loop name="constraint_19" type="revolute">
    <predecessor link="link_19">
      <origin xyz="0.5 0.0 0.0"/>
    </predecessor>
    <successor link="link_21">
      <origin xyz="1.0 0.0 0.0"/>
    </successor>
    <axis xyz="0 0 1"/>
  </loop>
  <link name="link_22">
    <inertial>
      <mass value="3.3"/>
      <origin xyz="0.0 0.0 0.0"/>
      <inertia ixx="0.011253" ixy="0" ixz="0" iyy="0.036203" iyz="0" izz="0.042673"/>
    </inertial>
    <visual>
      <origin rpy="0 0 0" xyz="0.25 0 0"/>
      <geometry>
        <box size="0.5 0.05 0.05"/>
      </geometry>
      <material name="Blue">
        <color rgba="0.1 0 0.8 1.0"/>
      </material>
    </visual>
  </link>
  <link name="link_23">
    <inertial>
      <mass value="3.3"/>
      <origin xyz="0.0 0.0 0.0"/>
      <inertia ixx="0.011253" ixy="0" ixz="0" iyy="0.036203" iyz="0" izz="0.042673"/>
    </inertial>
    <visual>
      <origin rpy="0 0 0" xyz="0.25 0 0"/>
      <geometry>
        <box size="0.5 0.05 0.05"/>
      </geometry>
      <material name="Red">
        <color rgba="0.8 0.1 0.1 1.0"/>
      </material>
    </visual>
  </link>
  <link name="link_24">
    <inertial>
      <mass value="3.3"/>
      <origin xyz="0.0 0.0 0.0"/>
      <inertia ixx="0.011253" ixy="0" ixz="0" iyy="0.036203" iyz="0" izz="0.042673"/>
    </inertial>
    <visual>
      <origin rpy="0 0 0" xyz="0.5 0 0"/>
      <geometry>
        <box size="1.0 0.05 0.05"/>
      </geometry>
      <material name="Green2">
        <color rgba="0.1 0.8 0 1.0"/>
      </material>
    </visual>
  </link>
  <joint independent="false" name="link_19_to_link_22" type="revolute">
    <parent link="link_19"/>
    <child link="link_22"/>
    <origin xyz="1.0 0.0 0.0"/>
    <axis xyz="0 0 1"/>
    <limit effort="30" lower="-10" upper="10" velocity="1.0"/>
  </joint>
  <joint independent="true" name="link_19_to_link_23" type="revolute">
    <parent link="link_19"/>
    <child link="link_23"/>
    <origin xyz="0.0 0.0 0.0"/>
    <axis xyz="0 0 1"/>
    <limit effort="30" lower="-10" upper="10" velocity="1.0"/>
  </joint>
  <joint independent="false" name="link_23_to_link_24" type="revolute">
    <parent link="link_23"/>
    <child link="link_24"/>
    <origin xyz="0.5 0.0 0.0"/>
    <axis xyz="0 0 1"/>
    <limit effort="30" lower="-10" upper="10" velocity="1.0"/>
  </joint>
  <loop name="constraint_22" type="revolute">
    <predecessor link="link_22">
      <origin xyz="0.5 0.0 0.0"/>
    </predecessor>
    <successor link="link_24">
      <origin xyz="1.0 0.0 0.0"/>
    </successor>
    <axis xyz="0 0 1"/>
  </loop>
  <link name="link_25">
    <inertial>
      <mass value="3.3"/>
      <origin xyz="0.0 0.0 0.0"/>
      <inertia ixx="0.011253" ixy="0" ixz="0" iyy="0.036203" iyz="0" izz="0.042673"/>
    </inertial>
    <visual>
      <origin rpy="0 0 0" xyz="0.25 0 0"/>
      <geometry>
        <box size="0.5 0.05 0.05"/>
      </geometry>
      <material name="Blue">
        <color rgba="0.1 0 0.8 1.0"/>
      </material>
    </visual>
  </link>
  <link name="link_26">
    <inertial>
      <mass value="3.3"/>
      <origin xyz="0.0 0.0 0.0"/>
      <inertia ixx="0.011253" ixy="0" ixz="0" iyy="0.036203" iyz="0" izz="0.042673"/>
    </inertial>
    <visual>
      <origin rpy="0 0 0" xyz="0.25 0 0"/>
      <geometry>
        <box size="0.5 0.05 0.05"/>
      </geometry>
      <material name="Red">
        <color rgba="0.8 0.1 0.1 1.0"/>
      </material>
    </visual>
  </link>
  <link name="link_27">
    <inertial>
      <mass value="3.3"/>
      <origin xyz="0.0 0.0 0.0"/>
      <inertia ixx="0.011253" ixy="0" ixz="0" iyy="0.036203" iyz="0" izz="0.042673"/>
    </inertial>
    <visual>
      <origin rpy="0 0 0" xyz="0.5 0 0"/>
      <geometry>
        <box size="1.0 0.05 0.05"/>
      </geometry>
      <material name="Green2">
        <color rgba="0.1 0.8 0 1.0"/>
      </material>
    </visual>
  </link>
  <joint independent="false" name="link_22_to_link_25" type="revolute">
    <parent link="link_22"/>
    <child link="link_25"/>
    <origin xyz="1.0 0.0 0.0"/>
    <axis xyz="0 0 1"/>
    <limit effort="30" lower="-10" upper="10" velocity="1.0"/>
  </joint>
  <joint independent="true" name="link_22_to_link_26" type="revolute">
    <parent link="link_22"/>
    <child link="link_26"/>
    <origin xyz="0.0 0.0 0.0"/>
    <axis xyz="0 0 1"/>
    <limit effort="30" lower="-10" upper="10" velocity="1.0"/>
  </joint>
  <joint independent="false" name="link_26_to_link_27" type="revolute">
    <parent link="link_26"/>
    <child link="link_27"/>
    <origin xyz="0.5 0.0 0.0"/>
    <axis xyz="0 0 1"/>
    <limit effort="30" lower="-10" upper="10" velocity="1.0"/>
  </joint>
  <loop name="constraint_25" type="revolute">
    <predecessor link="link_25">
      <origin xyz="0.5 0.0 0.0"/>
    </predecessor>
    <successor link="link_27">
      <origin xyz="1.0 0.0 0.0"/>
    </successor>
    <axis xyz="0 0 1"/>
  </loop>
  <link name="link_28">
    <inertial>
      <mass value="3.3"/>
      <origin xyz="0.0 0.0 0.0"/>
      <inertia ixx="0.011253" ixy="0" ixz="0" iyy="0.036203" iyz="0" izz="0.042673"/>
    </inertial>
    <visual>
      <origin rpy="0 0 0" xyz="0.25 0 0"/>
      <geometry>
        <box size="0.5 0.05 0.05"/>
      </geometry>
      <material name="Blue">
        <color rgba="0.1 0 0.8 1.0"/>
      </material>
    </visual>
  </link>
  <link name="link_29">
    <inertial>
      <mass value="3.3"/>
      <origin xyz="0.0 0.0 0.0"/>
      <inertia ixx="0.011253" ixy="0" ixz="0" iyy="0.036203" iyz="0" izz="0.042673"/>
    </inertial>
    <visual>
      <origin rpy="0 0 0" xyz="0.25 0 0"/>
      <geometry>
        <box size="0.5 0.05 0.05"/>
      </geometry>
      <material name="Red">
        <color rgba="0.8 0.1 0.1 1.0"/>
      </material>
    </visual>
  </link>
  <link name="link_30">
    <inertial>
      <mass value="3.3"/>
      <origin xyz="0.0 0.0 0.0"/>
      <inertia ixx="0.011253" ixy="0" ixz="0" iyy="0.036203" iyz="0" izz="0.042673"/>
    </inertial>
    <visual>
      <origin rpy="0 0 0" xyz="0.5 0 0"/>
      <geometry>
        <box size="1.0 0.05 0.05"/>
      </geometry>
      <material name="Green2">
        <color rgba="0.1 0.8 0 1.0"/>
      </material>
    </visual>
  </link>
  <joint independent="false" name="link_25_to_link_28" type="revolute">
    <parent link="link_25"/>
    <child link="link_28"/>
    <origin xyz="1.0 0.0 0.0"/>
    <axis xyz="0 0 1"/>
    <limit effort="30" lower="-10" upper="10" velocity="1.0"/>
  </joint>
  <joint independent="true" name="link_25_to_link_29" type="revolute">
    <parent link="link_25"/>
    <child link="link_29"/>
    <origin xyz="0.0 0.0 0.0"/>
    <axis xyz="0 0 1"/>
    <limit effort="30" lower="-10" upper="10" velocity="1.0"/>
  </joint>
  <joint independent="false" name="link_29_to_link_30" type="revolute">
    <parent link="link_29"/>
    <child link="link_30"/>
    <origin xyz="0.5 0.0 0.0"/>
    <axis xyz="0 0 1"/>
    <limit effort="30" lower="-10" upper="10" velocity="1.0"/>
  </joint>
  <loop name="constraint_28" type="revolute">
    <predecessor link="link_28">
      <origin xyz="0.5 0.0 0.0"/>
    </predecessor>
    <successor link="link_30">
      <origin xyz="1.0 0.0 0.0"/>
    </successor>
    <axis xyz="0 0 1"/>
  </loop>
</robot>
