<?xml version="1.0" ?>
<!-- =================================================================================== -->
<!-- |    This document was autogenerated by xacro from loop_size40.xacro              | -->
<!-- |    EDITING THIS FILE BY HAND IS NOT RECOMMENDED                                 | -->
<!-- =================================================================================== -->
<robot name="parallel_chain_exp_d40_l40">
  <link name="base"/>
  <link name="link_1_1">
    <inertial>
      <mass value="0.25"/>
      <origin rpy="0 0 0" xyz="0 0.5 0"/>
      <inertia ixx="0.01" ixy="0" ixz="0" iyy="0.1" iyz="0" izz="0.01"/>
    </inertial>
  </link>
  <joint independent="True" name="joint_1_1" type="revolute">
    <parent link="base"/>
    <child link="link_1_1"/>
    <origin xyz="0 0 0"/>
    <axis xyz="0 0 1"/>
    <limit effort="30" lower="-10" upper="10" velocity="1.0"/>
  </joint>
  <link name="link_2_1">
    <inertial>
      <mass value="0.25"/>
      <origin rpy="0 0 0" xyz="0 0.5 0"/>
      <inertia ixx="0.01" ixy="0" ixz="0" iyy="0.1" iyz="0" izz="0.01"/>
    </inertial>
  </link>
  <joint independent="True" name="joint_2_1" type="revolute">
    <parent link="base"/>
    <child link="link_2_1"/>
    <origin xyz="0 0 0"/>
    <axis xyz="0 0 1"/>
    <limit effort="30" lower="-10" upper="10" velocity="1.0"/>
  </joint>
  <link name="link_1_2">
    <inertial>
      <mass value="0.25"/>
      <origin rpy="0 0 0" xyz="0 0.5 0"/>
      <inertia ixx="0.01" ixy="0" ixz="0" iyy="0.1" iyz="0" izz="0.01"/>
    </inertial>
  </link>
  <joint independent="True" name="joint_1_2" type="revolute">
    <parent link="link_1_1"/>
    <child link="link_1_2"/>
    <origin xyz="0 1.0 0"/>
    <axis xyz="0 0 1"/>
    <limit effort="30" lower="-10" upper="10" velocity="1.0"/>
  </joint>
  <link name="link_2_2">
    <inertial>
      <mass value="0.25"/>
      <origin rpy="0 0 0" xyz="0 0.5 0"/>
      <inertia ixx="0.01" ixy="0" ixz="0" iyy="0.1" iyz="0" izz="0.01"/>
    </inertial>
  </link>
  <joint independent="True" name="joint_2_2" type="revolute">
    <parent link="link_2_1"/>
    <child link="link_2_2"/>
    <origin xyz="0 1.0 0"/>
    <axis xyz="0 0 1"/>
    <limit effort="30" lower="-10" upper="10" velocity="1.0"/>
  </joint>
  <link name="link_1_3">
    <inertial>
      <mass value="0.25"/>
      <origin rpy="0 0 0" xyz="0 0.5 0"/>
      <inertia ixx="0.01" ixy="0" ixz="0" iyy="0.1" iyz="0" izz="0.01"/>
    </inertial>
  </link>
  <joint independent="True" name="joint_1_3" type="revolute">
    <parent link="link_1_2"/>
    <child link="link_1_3"/>
    <origin xyz="0 1.0 0"/>
    <axis xyz="0 0 1"/>
    <limit effort="30" lower="-10" upper="10" velocity="1.0"/>
  </joint>
  <link name="link_2_3">
    <inertial>
      <mass value="0.25"/>
      <origin rpy="0 0 0" xyz="0 0.5 0"/>
      <inertia ixx="0.01" ixy="0" ixz="0" iyy="0.1" iyz="0" izz="0.01"/>
    </inertial>
  </link>
  <joint independent="True" name="joint_2_3" type="revolute">
    <parent link="link_2_2"/>
    <child link="link_2_3"/>
    <origin xyz="0 1.0 0"/>
    <axis xyz="0 0 1"/>
    <limit effort="30" lower="-10" upper="10" velocity="1.0"/>
  </joint>
  <link name="link_1_4">
    <inertial>
      <mass value="0.25"/>
      <origin rpy="0 0 0" xyz="0 0.5 0"/>
      <inertia ixx="0.01" ixy="0" ixz="0" iyy="0.1" iyz="0" izz="0.01"/>
    </inertial>
  </link>
  <joint independent="True" name="joint_1_4" type="revolute">
    <parent link="link_1_3"/>
    <child link="link_1_4"/>
    <origin xyz="0 1.0 0"/>
    <axis xyz="0 0 1"/>
    <limit effort="30" lower="-10" upper="10" velocity="1.0"/>
  </joint>
  <link name="link_2_4">
    <inertial>
      <mass value="0.25"/>
      <origin rpy="0 0 0" xyz="0 0.5 0"/>
      <inertia ixx="0.01" ixy="0" ixz="0" iyy="0.1" iyz="0" izz="0.01"/>
    </inertial>
  </link>
  <joint independent="True" name="joint_2_4" type="revolute">
    <parent link="link_2_3"/>
    <child link="link_2_4"/>
    <origin xyz="0 1.0 0"/>
    <axis xyz="0 0 1"/>
    <limit effort="30" lower="-10" upper="10" velocity="1.0"/>
  </joint>
  <link name="link_1_5">
    <inertial>
      <mass value="0.25"/>
      <origin rpy="0 0 0" xyz="0 0.5 0"/>
      <inertia ixx="0.01" ixy="0" ixz="0" iyy="0.1" iyz="0" izz="0.01"/>
    </inertial>
  </link>
  <joint independent="True" name="joint_1_5" type="revolute">
    <parent link="link_1_4"/>
    <child link="link_1_5"/>
    <origin xyz="0 1.0 0"/>
    <axis xyz="0 0 1"/>
    <limit effort="30" lower="-10" upper="10" velocity="1.0"/>
  </joint>
  <link name="link_2_5">
    <inertial>
      <mass value="0.25"/>
      <origin rpy="0 0 0" xyz="0 0.5 0"/>
      <inertia ixx="0.01" ixy="0" ixz="0" iyy="0.1" iyz="0" izz="0.01"/>
    </inertial>
  </link>
  <joint independent="True" name="joint_2_5" type="revolute">
    <parent link="link_2_4"/>
    <child link="link_2_5"/>
    <origin xyz="0 1.0 0"/>
    <axis xyz="0 0 1"/>
    <limit effort="30" lower="-10" upper="10" velocity="1.0"/>
  </joint>
  <link name="link_1_6">
    <inertial>
      <mass value="0.25"/>
      <origin rpy="0 0 0" xyz="0 0.5 0"/>
      <inertia ixx="0.01" ixy="0" ixz="0" iyy="0.1" iyz="0" izz="0.01"/>
    </inertial>
  </link>
  <joint independent="True" name="joint_1_6" type="revolute">
    <parent link="link_1_5"/>
    <child link="link_1_6"/>
    <origin xyz="0 1.0 0"/>
    <axis xyz="0 0 1"/>
    <limit effort="30" lower="-10" upper="10" velocity="1.0"/>
  </joint>
  <link name="link_2_6">
    <inertial>
      <mass value="0.25"/>
      <origin rpy="0 0 0" xyz="0 0.5 0"/>
      <inertia ixx="0.01" ixy="0" ixz="0" iyy="0.1" iyz="0" izz="0.01"/>
    </inertial>
  </link>
  <joint independent="True" name="joint_2_6" type="revolute">
    <parent link="link_2_5"/>
    <child link="link_2_6"/>
    <origin xyz="0 1.0 0"/>
    <axis xyz="0 0 1"/>
    <limit effort="30" lower="-10" upper="10" velocity="1.0"/>
  </joint>
  <link name="link_1_7">
    <inertial>
      <mass value="0.25"/>
      <origin rpy="0 0 0" xyz="0 0.5 0"/>
      <inertia ixx="0.01" ixy="0" ixz="0" iyy="0.1" iyz="0" izz="0.01"/>
    </inertial>
  </link>
  <joint independent="True" name="joint_1_7" type="revolute">
    <parent link="link_1_6"/>
    <child link="link_1_7"/>
    <origin xyz="0 1.0 0"/>
    <axis xyz="0 0 1"/>
    <limit effort="30" lower="-10" upper="10" velocity="1.0"/>
  </joint>
  <link name="link_2_7">
    <inertial>
      <mass value="0.25"/>
      <origin rpy="0 0 0" xyz="0 0.5 0"/>
      <inertia ixx="0.01" ixy="0" ixz="0" iyy="0.1" iyz="0" izz="0.01"/>
    </inertial>
  </link>
  <joint independent="True" name="joint_2_7" type="revolute">
    <parent link="link_2_6"/>
    <child link="link_2_7"/>
    <origin xyz="0 1.0 0"/>
    <axis xyz="0 0 1"/>
    <limit effort="30" lower="-10" upper="10" velocity="1.0"/>
  </joint>
  <link name="link_1_8">
    <inertial>
      <mass value="0.25"/>
      <origin rpy="0 0 0" xyz="0 0.5 0"/>
      <inertia ixx="0.01" ixy="0" ixz="0" iyy="0.1" iyz="0" izz="0.01"/>
    </inertial>
  </link>
  <joint independent="True" name="joint_1_8" type="revolute">
    <parent link="link_1_7"/>
    <child link="link_1_8"/>
    <origin xyz="0 1.0 0"/>
    <axis xyz="0 0 1"/>
    <limit effort="30" lower="-10" upper="10" velocity="1.0"/>
  </joint>
  <link name="link_2_8">
    <inertial>
      <mass value="0.25"/>
      <origin rpy="0 0 0" xyz="0 0.5 0"/>
      <inertia ixx="0.01" ixy="0" ixz="0" iyy="0.1" iyz="0" izz="0.01"/>
    </inertial>
  </link>
  <joint independent="True" name="joint_2_8" type="revolute">
    <parent link="link_2_7"/>
    <child link="link_2_8"/>
    <origin xyz="0 1.0 0"/>
    <axis xyz="0 0 1"/>
    <limit effort="30" lower="-10" upper="10" velocity="1.0"/>
  </joint>
  <link name="link_1_9">
    <inertial>
      <mass value="0.25"/>
      <origin rpy="0 0 0" xyz="0 0.5 0"/>
      <inertia ixx="0.01" ixy="0" ixz="0" iyy="0.1" iyz="0" izz="0.01"/>
    </inertial>
  </link>
  <joint independent="True" name="joint_1_9" type="revolute">
    <parent link="link_1_8"/>
    <child link="link_1_9"/>
    <origin xyz="0 1.0 0"/>
    <axis xyz="0 0 1"/>
    <limit effort="30" lower="-10" upper="10" velocity="1.0"/>
  </joint>
  <link name="link_2_9">
    <inertial>
      <mass value="0.25"/>
      <origin rpy="0 0 0" xyz="0 0.5 0"/>
      <inertia ixx="0.01" ixy="0" ixz="0" iyy="0.1" iyz="0" izz="0.01"/>
    </inertial>
  </link>
  <joint independent="True" name="joint_2_9" type="revolute">
    <parent link="link_2_8"/>
    <child link="link_2_9"/>
    <origin xyz="0 1.0 0"/>
    <axis xyz="0 0 1"/>
    <limit effort="30" lower="-10" upper="10" velocity="1.0"/>
  </joint>
  <link name="link_1_10">
    <inertial>
      <mass value="0.25"/>
      <origin rpy="0 0 0" xyz="0 0.5 0"/>
      <inertia ixx="0.01" ixy="0" ixz="0" iyy="0.1" iyz="0" izz="0.01"/>
    </inertial>
  </link>
  <joint independent="True" name="joint_1_10" type="revolute">
    <parent link="link_1_9"/>
    <child link="link_1_10"/>
    <origin xyz="0 1.0 0"/>
    <axis xyz="0 0 1"/>
    <limit effort="30" lower="-10" upper="10" velocity="1.0"/>
  </joint>
  <link name="link_2_10">
    <inertial>
      <mass value="0.25"/>
      <origin rpy="0 0 0" xyz="0 0.5 0"/>
      <inertia ixx="0.01" ixy="0" ixz="0" iyy="0.1" iyz="0" izz="0.01"/>
    </inertial>
  </link>
  <joint independent="True" name="joint_2_10" type="revolute">
    <parent link="link_2_9"/>
    <child link="link_2_10"/>
    <origin xyz="0 1.0 0"/>
    <axis xyz="0 0 1"/>
    <limit effort="30" lower="-10" upper="10" velocity="1.0"/>
  </joint>
  <link name="link_1_11">
    <inertial>
      <mass value="0.25"/>
      <origin rpy="0 0 0" xyz="0 0.5 0"/>
      <inertia ixx="0.01" ixy="0" ixz="0" iyy="0.1" iyz="0" izz="0.01"/>
    </inertial>
  </link>
  <joint independent="True" name="joint_1_11" type="revolute">
    <parent link="link_1_10"/>
    <child link="link_1_11"/>
    <origin xyz="0 1.0 0"/>
    <axis xyz="0 0 1"/>
    <limit effort="30" lower="-10" upper="10" velocity="1.0"/>
  </joint>
  <link name="link_2_11">
    <inertial>
      <mass value="0.25"/>
      <origin rpy="0 0 0" xyz="0 0.5 0"/>
      <inertia ixx="0.01" ixy="0" ixz="0" iyy="0.1" iyz="0" izz="0.01"/>
    </inertial>
  </link>
  <joint independent="True" name="joint_2_11" type="revolute">
    <parent link="link_2_10"/>
    <child link="link_2_11"/>
    <origin xyz="0 1.0 0"/>
    <axis xyz="0 0 1"/>
    <limit effort="30" lower="-10" upper="10" velocity="1.0"/>
  </joint>
  <link name="link_1_12">
    <inertial>
      <mass value="0.25"/>
      <origin rpy="0 0 0" xyz="0 0.5 0"/>
      <inertia ixx="0.01" ixy="0" ixz="0" iyy="0.1" iyz="0" izz="0.01"/>
    </inertial>
  </link>
  <joint independent="True" name="joint_1_12" type="revolute">
    <parent link="link_1_11"/>
    <child link="link_1_12"/>
    <origin xyz="0 1.0 0"/>
    <axis xyz="0 0 1"/>
    <limit effort="30" lower="-10" upper="10" velocity="1.0"/>
  </joint>
  <link name="link_2_12">
    <inertial>
      <mass value="0.25"/>
      <origin rpy="0 0 0" xyz="0 0.5 0"/>
      <inertia ixx="0.01" ixy="0" ixz="0" iyy="0.1" iyz="0" izz="0.01"/>
    </inertial>
  </link>
  <joint independent="True" name="joint_2_12" type="revolute">
    <parent link="link_2_11"/>
    <child link="link_2_12"/>
    <origin xyz="0 1.0 0"/>
    <axis xyz="0 0 1"/>
    <limit effort="30" lower="-10" upper="10" velocity="1.0"/>
  </joint>
  <link name="link_1_13">
    <inertial>
      <mass value="0.25"/>
      <origin rpy="0 0 0" xyz="0 0.5 0"/>
      <inertia ixx="0.01" ixy="0" ixz="0" iyy="0.1" iyz="0" izz="0.01"/>
    </inertial>
  </link>
  <joint independent="True" name="joint_1_13" type="revolute">
    <parent link="link_1_12"/>
    <child link="link_1_13"/>
    <origin xyz="0 1.0 0"/>
    <axis xyz="0 0 1"/>
    <limit effort="30" lower="-10" upper="10" velocity="1.0"/>
  </joint>
  <link name="link_2_13">
    <inertial>
      <mass value="0.25"/>
      <origin rpy="0 0 0" xyz="0 0.5 0"/>
      <inertia ixx="0.01" ixy="0" ixz="0" iyy="0.1" iyz="0" izz="0.01"/>
    </inertial>
  </link>
  <joint independent="True" name="joint_2_13" type="revolute">
    <parent link="link_2_12"/>
    <child link="link_2_13"/>
    <origin xyz="0 1.0 0"/>
    <axis xyz="0 0 1"/>
    <limit effort="30" lower="-10" upper="10" velocity="1.0"/>
  </joint>
  <link name="link_1_14">
    <inertial>
      <mass value="0.25"/>
      <origin rpy="0 0 0" xyz="0 0.5 0"/>
      <inertia ixx="0.01" ixy="0" ixz="0" iyy="0.1" iyz="0" izz="0.01"/>
    </inertial>
  </link>
  <joint independent="True" name="joint_1_14" type="revolute">
    <parent link="link_1_13"/>
    <child link="link_1_14"/>
    <origin xyz="0 1.0 0"/>
    <axis xyz="0 0 1"/>
    <limit effort="30" lower="-10" upper="10" velocity="1.0"/>
  </joint>
  <link name="link_2_14">
    <inertial>
      <mass value="0.25"/>
      <origin rpy="0 0 0" xyz="0 0.5 0"/>
      <inertia ixx="0.01" ixy="0" ixz="0" iyy="0.1" iyz="0" izz="0.01"/>
    </inertial>
  </link>
  <joint independent="True" name="joint_2_14" type="revolute">
    <parent link="link_2_13"/>
    <child link="link_2_14"/>
    <origin xyz="0 1.0 0"/>
    <axis xyz="0 0 1"/>
    <limit effort="30" lower="-10" upper="10" velocity="1.0"/>
  </joint>
  <link name="link_1_15">
    <inertial>
      <mass value="0.25"/>
      <origin rpy="0 0 0" xyz="0 0.5 0"/>
      <inertia ixx="0.01" ixy="0" ixz="0" iyy="0.1" iyz="0" izz="0.01"/>
    </inertial>
  </link>
  <joint independent="True" name="joint_1_15" type="revolute">
    <parent link="link_1_14"/>
    <child link="link_1_15"/>
    <origin xyz="0 1.0 0"/>
    <axis xyz="0 0 1"/>
    <limit effort="30" lower="-10" upper="10" velocity="1.0"/>
  </joint>
  <link name="link_2_15">
    <inertial>
      <mass value="0.25"/>
      <origin rpy="0 0 0" xyz="0 0.5 0"/>
      <inertia ixx="0.01" ixy="0" ixz="0" iyy="0.1" iyz="0" izz="0.01"/>
    </inertial>
  </link>
  <joint independent="True" name="joint_2_15" type="revolute">
    <parent link="link_2_14"/>
    <child link="link_2_15"/>
    <origin xyz="0 1.0 0"/>
    <axis xyz="0 0 1"/>
    <limit effort="30" lower="-10" upper="10" velocity="1.0"/>
  </joint>
  <link name="link_1_16">
    <inertial>
      <mass value="0.25"/>
      <origin rpy="0 0 0" xyz="0 0.5 0"/>
      <inertia ixx="0.01" ixy="0" ixz="0" iyy="0.1" iyz="0" izz="0.01"/>
    </inertial>
  </link>
  <joint independent="True" name="joint_1_16" type="revolute">
    <parent link="link_1_15"/>
    <child link="link_1_16"/>
    <origin xyz="0 1.0 0"/>
    <axis xyz="0 0 1"/>
    <limit effort="30" lower="-10" upper="10" velocity="1.0"/>
  </joint>
  <link name="link_2_16">
    <inertial>
      <mass value="0.25"/>
      <origin rpy="0 0 0" xyz="0 0.5 0"/>
      <inertia ixx="0.01" ixy="0" ixz="0" iyy="0.1" iyz="0" izz="0.01"/>
    </inertial>
  </link>
  <joint independent="True" name="joint_2_16" type="revolute">
    <parent link="link_2_15"/>
    <child link="link_2_16"/>
    <origin xyz="0 1.0 0"/>
    <axis xyz="0 0 1"/>
    <limit effort="30" lower="-10" upper="10" velocity="1.0"/>
  </joint>
  <link name="link_1_17">
    <inertial>
      <mass value="0.25"/>
      <origin rpy="0 0 0" xyz="0 0.5 0"/>
      <inertia ixx="0.01" ixy="0" ixz="0" iyy="0.1" iyz="0" izz="0.01"/>
    </inertial>
  </link>
  <joint independent="True" name="joint_1_17" type="revolute">
    <parent link="link_1_16"/>
    <child link="link_1_17"/>
    <origin xyz="0 1.0 0"/>
    <axis xyz="0 0 1"/>
    <limit effort="30" lower="-10" upper="10" velocity="1.0"/>
  </joint>
  <link name="link_2_17">
    <inertial>
      <mass value="0.25"/>
      <origin rpy="0 0 0" xyz="0 0.5 0"/>
      <inertia ixx="0.01" ixy="0" ixz="0" iyy="0.1" iyz="0" izz="0.01"/>
    </inertial>
  </link>
  <joint independent="True" name="joint_2_17" type="revolute">
    <parent link="link_2_16"/>
    <child link="link_2_17"/>
    <origin xyz="0 1.0 0"/>
    <axis xyz="0 0 1"/>
    <limit effort="30" lower="-10" upper="10" velocity="1.0"/>
  </joint>
  <link name="link_1_18">
    <inertial>
      <mass value="0.25"/>
      <origin rpy="0 0 0" xyz="0 0.5 0"/>
      <inertia ixx="0.01" ixy="0" ixz="0" iyy="0.1" iyz="0" izz="0.01"/>
    </inertial>
  </link>
  <joint independent="True" name="joint_1_18" type="revolute">
    <parent link="link_1_17"/>
    <child link="link_1_18"/>
    <origin xyz="0 1.0 0"/>
    <axis xyz="0 0 1"/>
    <limit effort="30" lower="-10" upper="10" velocity="1.0"/>
  </joint>
  <link name="link_2_18">
    <inertial>
      <mass value="0.25"/>
      <origin rpy="0 0 0" xyz="0 0.5 0"/>
      <inertia ixx="0.01" ixy="0" ixz="0" iyy="0.1" iyz="0" izz="0.01"/>
    </inertial>
  </link>
  <joint independent="True" name="joint_2_18" type="revolute">
    <parent link="link_2_17"/>
    <child link="link_2_18"/>
    <origin xyz="0 1.0 0"/>
    <axis xyz="0 0 1"/>
    <limit effort="30" lower="-10" upper="10" velocity="1.0"/>
  </joint>
  <link name="link_1_19">
    <inertial>
      <mass value="0.25"/>
      <origin rpy="0 0 0" xyz="0 0.5 0"/>
      <inertia ixx="0.01" ixy="0" ixz="0" iyy="0.1" iyz="0" izz="0.01"/>
    </inertial>
  </link>
  <joint independent="True" name="joint_1_19" type="revolute">
    <parent link="link_1_18"/>
    <child link="link_1_19"/>
    <origin xyz="0 1.0 0"/>
    <axis xyz="0 0 1"/>
    <limit effort="30" lower="-10" upper="10" velocity="1.0"/>
  </joint>
  <link name="link_2_19">
    <inertial>
      <mass value="0.25"/>
      <origin rpy="0 0 0" xyz="0 0.5 0"/>
      <inertia ixx="0.01" ixy="0" ixz="0" iyy="0.1" iyz="0" izz="0.01"/>
    </inertial>
  </link>
  <joint independent="True" name="joint_2_19" type="revolute">
    <parent link="link_2_18"/>
    <child link="link_2_19"/>
    <origin xyz="0 1.0 0"/>
    <axis xyz="0 0 1"/>
    <limit effort="30" lower="-10" upper="10" velocity="1.0"/>
  </joint>
  <link name="link_1_20">
    <inertial>
      <mass value="0.25"/>
      <origin rpy="0 0 0" xyz="0 0.5 0"/>
      <inertia ixx="0.01" ixy="0" ixz="0" iyy="0.1" iyz="0" izz="0.01"/>
    </inertial>
  </link>
  <joint independent="True" name="joint_1_20" type="revolute">
    <parent link="link_1_19"/>
    <child link="link_1_20"/>
    <origin xyz="0 1.0 0"/>
    <axis xyz="0 0 1"/>
    <limit effort="30" lower="-10" upper="10" velocity="1.0"/>
  </joint>
  <link name="link_2_20">
    <inertial>
      <mass value="0.25"/>
      <origin rpy="0 0 0" xyz="0 0.5 0"/>
      <inertia ixx="0.01" ixy="0" ixz="0" iyy="0.1" iyz="0" izz="0.01"/>
    </inertial>
  </link>
  <joint independent="False" name="joint_2_20" type="revolute">
    <parent link="link_2_19"/>
    <child link="link_2_20"/>
    <origin xyz="0 1.0 0"/>
    <axis xyz="0 0 1"/>
    <limit effort="30" lower="-10" upper="10" velocity="1.0"/>
  </joint>
  <coupling name="coupling_20">
    <predecessor link="link_1_20"/>
    <successor link="link_2_20"/>
    <ratio value="1"/>
  </coupling>
  <link name="link_1_21">
    <inertial>
      <mass value="0.25"/>
      <origin rpy="0 0 0" xyz="0 0.5 0"/>
      <inertia ixx="0.01" ixy="0" ixz="0" iyy="0.1" iyz="0" izz="0.01"/>
    </inertial>
  </link>
  <joint independent="True" name="joint_1_21" type="revolute">
    <parent link="link_1_20"/>
    <child link="link_1_21"/>
    <origin xyz="0 1.0 0"/>
    <axis xyz="0 0 1"/>
    <limit effort="30" lower="-10" upper="10" velocity="1.0"/>
  </joint>
  <link name="link_2_21">
    <inertial>
      <mass value="0.25"/>
      <origin rpy="0 0 0" xyz="0 0.5 0"/>
      <inertia ixx="0.01" ixy="0" ixz="0" iyy="0.1" iyz="0" izz="0.01"/>
    </inertial>
  </link>
  <joint independent="True" name="joint_2_21" type="revolute">
    <parent link="link_2_20"/>
    <child link="link_2_21"/>
    <origin xyz="0 1.0 0"/>
    <axis xyz="0 0 1"/>
    <limit effort="30" lower="-10" upper="10" velocity="1.0"/>
  </joint>
  <link name="link_1_22">
    <inertial>
      <mass value="0.25"/>
      <origin rpy="0 0 0" xyz="0 0.5 0"/>
      <inertia ixx="0.01" ixy="0" ixz="0" iyy="0.1" iyz="0" izz="0.01"/>
    </inertial>
  </link>
  <joint independent="True" name="joint_1_22" type="revolute">
    <parent link="link_1_21"/>
    <child link="link_1_22"/>
    <origin xyz="0 1.0 0"/>
    <axis xyz="0 0 1"/>
    <limit effort="30" lower="-10" upper="10" velocity="1.0"/>
  </joint>
  <link name="link_2_22">
    <inertial>
      <mass value="0.25"/>
      <origin rpy="0 0 0" xyz="0 0.5 0"/>
      <inertia ixx="0.01" ixy="0" ixz="0" iyy="0.1" iyz="0" izz="0.01"/>
    </inertial>
  </link>
  <joint independent="True" name="joint_2_22" type="revolute">
    <parent link="link_2_21"/>
    <child link="link_2_22"/>
    <origin xyz="0 1.0 0"/>
    <axis xyz="0 0 1"/>
    <limit effort="30" lower="-10" upper="10" velocity="1.0"/>
  </joint>
  <link name="link_1_23">
    <inertial>
      <mass value="0.25"/>
      <origin rpy="0 0 0" xyz="0 0.5 0"/>
      <inertia ixx="0.01" ixy="0" ixz="0" iyy="0.1" iyz="0" izz="0.01"/>
    </inertial>
  </link>
  <joint independent="True" name="joint_1_23" type="revolute">
    <parent link="link_1_22"/>
    <child link="link_1_23"/>
    <origin xyz="0 1.0 0"/>
    <axis xyz="0 0 1"/>
    <limit effort="30" lower="-10" upper="10" velocity="1.0"/>
  </joint>
  <link name="link_2_23">
    <inertial>
      <mass value="0.25"/>
      <origin rpy="0 0 0" xyz="0 0.5 0"/>
      <inertia ixx="0.01" ixy="0" ixz="0" iyy="0.1" iyz="0" izz="0.01"/>
    </inertial>
  </link>
  <joint independent="True" name="joint_2_23" type="revolute">
    <parent link="link_2_22"/>
    <child link="link_2_23"/>
    <origin xyz="0 1.0 0"/>
    <axis xyz="0 0 1"/>
    <limit effort="30" lower="-10" upper="10" velocity="1.0"/>
  </joint>
  <link name="link_1_24">
    <inertial>
      <mass value="0.25"/>
      <origin rpy="0 0 0" xyz="0 0.5 0"/>
      <inertia ixx="0.01" ixy="0" ixz="0" iyy="0.1" iyz="0" izz="0.01"/>
    </inertial>
  </link>
  <joint independent="True" name="joint_1_24" type="revolute">
    <parent link="link_1_23"/>
    <child link="link_1_24"/>
    <origin xyz="0 1.0 0"/>
    <axis xyz="0 0 1"/>
    <limit effort="30" lower="-10" upper="10" velocity="1.0"/>
  </joint>
  <link name="link_2_24">
    <inertial>
      <mass value="0.25"/>
      <origin rpy="0 0 0" xyz="0 0.5 0"/>
      <inertia ixx="0.01" ixy="0" ixz="0" iyy="0.1" iyz="0" izz="0.01"/>
    </inertial>
  </link>
  <joint independent="True" name="joint_2_24" type="revolute">
    <parent link="link_2_23"/>
    <child link="link_2_24"/>
    <origin xyz="0 1.0 0"/>
    <axis xyz="0 0 1"/>
    <limit effort="30" lower="-10" upper="10" velocity="1.0"/>
  </joint>
  <link name="link_1_25">
    <inertial>
      <mass value="0.25"/>
      <origin rpy="0 0 0" xyz="0 0.5 0"/>
      <inertia ixx="0.01" ixy="0" ixz="0" iyy="0.1" iyz="0" izz="0.01"/>
    </inertial>
  </link>
  <joint independent="True" name="joint_1_25" type="revolute">
    <parent link="link_1_24"/>
    <child link="link_1_25"/>
    <origin xyz="0 1.0 0"/>
    <axis xyz="0 0 1"/>
    <limit effort="30" lower="-10" upper="10" velocity="1.0"/>
  </joint>
  <link name="link_2_25">
    <inertial>
      <mass value="0.25"/>
      <origin rpy="0 0 0" xyz="0 0.5 0"/>
      <inertia ixx="0.01" ixy="0" ixz="0" iyy="0.1" iyz="0" izz="0.01"/>
    </inertial>
  </link>
  <joint independent="True" name="joint_2_25" type="revolute">
    <parent link="link_2_24"/>
    <child link="link_2_25"/>
    <origin xyz="0 1.0 0"/>
    <axis xyz="0 0 1"/>
    <limit effort="30" lower="-10" upper="10" velocity="1.0"/>
  </joint>
  <link name="link_1_26">
    <inertial>
      <mass value="0.25"/>
      <origin rpy="0 0 0" xyz="0 0.5 0"/>
      <inertia ixx="0.01" ixy="0" ixz="0" iyy="0.1" iyz="0" izz="0.01"/>
    </inertial>
  </link>
  <joint independent="True" name="joint_1_26" type="revolute">
    <parent link="link_1_25"/>
    <child link="link_1_26"/>
    <origin xyz="0 1.0 0"/>
    <axis xyz="0 0 1"/>
    <limit effort="30" lower="-10" upper="10" velocity="1.0"/>
  </joint>
  <link name="link_2_26">
    <inertial>
      <mass value="0.25"/>
      <origin rpy="0 0 0" xyz="0 0.5 0"/>
      <inertia ixx="0.01" ixy="0" ixz="0" iyy="0.1" iyz="0" izz="0.01"/>
    </inertial>
  </link>
  <joint independent="True" name="joint_2_26" type="revolute">
    <parent link="link_2_25"/>
    <child link="link_2_26"/>
    <origin xyz="0 1.0 0"/>
    <axis xyz="0 0 1"/>
    <limit effort="30" lower="-10" upper="10" velocity="1.0"/>
  </joint>
  <link name="link_1_27">
    <inertial>
      <mass value="0.25"/>
      <origin rpy="0 0 0" xyz="0 0.5 0"/>
      <inertia ixx="0.01" ixy="0" ixz="0" iyy="0.1" iyz="0" izz="0.01"/>
    </inertial>
  </link>
  <joint independent="True" name="joint_1_27" type="revolute">
    <parent link="link_1_26"/>
    <child link="link_1_27"/>
    <origin xyz="0 1.0 0"/>
    <axis xyz="0 0 1"/>
    <limit effort="30" lower="-10" upper="10" velocity="1.0"/>
  </joint>
  <link name="link_2_27">
    <inertial>
      <mass value="0.25"/>
      <origin rpy="0 0 0" xyz="0 0.5 0"/>
      <inertia ixx="0.01" ixy="0" ixz="0" iyy="0.1" iyz="0" izz="0.01"/>
    </inertial>
  </link>
  <joint independent="True" name="joint_2_27" type="revolute">
    <parent link="link_2_26"/>
    <child link="link_2_27"/>
    <origin xyz="0 1.0 0"/>
    <axis xyz="0 0 1"/>
    <limit effort="30" lower="-10" upper="10" velocity="1.0"/>
  </joint>
  <link name="link_1_28">
    <inertial>
      <mass value="0.25"/>
      <origin rpy="0 0 0" xyz="0 0.5 0"/>
      <inertia ixx="0.01" ixy="0" ixz="0" iyy="0.1" iyz="0" izz="0.01"/>
    </inertial>
  </link>
  <joint independent="True" name="joint_1_28" type="revolute">
    <parent link="link_1_27"/>
    <child link="link_1_28"/>
    <origin xyz="0 1.0 0"/>
    <axis xyz="0 0 1"/>
    <limit effort="30" lower="-10" upper="10" velocity="1.0"/>
  </joint>
  <link name="link_2_28">
    <inertial>
      <mass value="0.25"/>
      <origin rpy="0 0 0" xyz="0 0.5 0"/>
      <inertia ixx="0.01" ixy="0" ixz="0" iyy="0.1" iyz="0" izz="0.01"/>
    </inertial>
  </link>
  <joint independent="True" name="joint_2_28" type="revolute">
    <parent link="link_2_27"/>
    <child link="link_2_28"/>
    <origin xyz="0 1.0 0"/>
    <axis xyz="0 0 1"/>
    <limit effort="30" lower="-10" upper="10" velocity="1.0"/>
  </joint>
  <link name="link_1_29">
    <inertial>
      <mass value="0.25"/>
      <origin rpy="0 0 0" xyz="0 0.5 0"/>
      <inertia ixx="0.01" ixy="0" ixz="0" iyy="0.1" iyz="0" izz="0.01"/>
    </inertial>
  </link>
  <joint independent="True" name="joint_1_29" type="revolute">
    <parent link="link_1_28"/>
    <child link="link_1_29"/>
    <origin xyz="0 1.0 0"/>
    <axis xyz="0 0 1"/>
    <limit effort="30" lower="-10" upper="10" velocity="1.0"/>
  </joint>
  <link name="link_2_29">
    <inertial>
      <mass value="0.25"/>
      <origin rpy="0 0 0" xyz="0 0.5 0"/>
      <inertia ixx="0.01" ixy="0" ixz="0" iyy="0.1" iyz="0" izz="0.01"/>
    </inertial>
  </link>
  <joint independent="True" name="joint_2_29" type="revolute">
    <parent link="link_2_28"/>
    <child link="link_2_29"/>
    <origin xyz="0 1.0 0"/>
    <axis xyz="0 0 1"/>
    <limit effort="30" lower="-10" upper="10" velocity="1.0"/>
  </joint>
  <link name="link_1_30">
    <inertial>
      <mass value="0.25"/>
      <origin rpy="0 0 0" xyz="0 0.5 0"/>
      <inertia ixx="0.01" ixy="0" ixz="0" iyy="0.1" iyz="0" izz="0.01"/>
    </inertial>
  </link>
  <joint independent="True" name="joint_1_30" type="revolute">
    <parent link="link_1_29"/>
    <child link="link_1_30"/>
    <origin xyz="0 1.0 0"/>
    <axis xyz="0 0 1"/>
    <limit effort="30" lower="-10" upper="10" velocity="1.0"/>
  </joint>
  <link name="link_2_30">
    <inertial>
      <mass value="0.25"/>
      <origin rpy="0 0 0" xyz="0 0.5 0"/>
      <inertia ixx="0.01" ixy="0" ixz="0" iyy="0.1" iyz="0" izz="0.01"/>
    </inertial>
  </link>
  <joint independent="True" name="joint_2_30" type="revolute">
    <parent link="link_2_29"/>
    <child link="link_2_30"/>
    <origin xyz="0 1.0 0"/>
    <axis xyz="0 0 1"/>
    <limit effort="30" lower="-10" upper="10" velocity="1.0"/>
  </joint>
  <link name="link_1_31">
    <inertial>
      <mass value="0.25"/>
      <origin rpy="0 0 0" xyz="0 0.5 0"/>
      <inertia ixx="0.01" ixy="0" ixz="0" iyy="0.1" iyz="0" izz="0.01"/>
    </inertial>
  </link>
  <joint independent="True" name="joint_1_31" type="revolute">
    <parent link="link_1_30"/>
    <child link="link_1_31"/>
    <origin xyz="0 1.0 0"/>
    <axis xyz="0 0 1"/>
    <limit effort="30" lower="-10" upper="10" velocity="1.0"/>
  </joint>
  <link name="link_2_31">
    <inertial>
      <mass value="0.25"/>
      <origin rpy="0 0 0" xyz="0 0.5 0"/>
      <inertia ixx="0.01" ixy="0" ixz="0" iyy="0.1" iyz="0" izz="0.01"/>
    </inertial>
  </link>
  <joint independent="True" name="joint_2_31" type="revolute">
    <parent link="link_2_30"/>
    <child link="link_2_31"/>
    <origin xyz="0 1.0 0"/>
    <axis xyz="0 0 1"/>
    <limit effort="30" lower="-10" upper="10" velocity="1.0"/>
  </joint>
  <link name="link_1_32">
    <inertial>
      <mass value="0.25"/>
      <origin rpy="0 0 0" xyz="0 0.5 0"/>
      <inertia ixx="0.01" ixy="0" ixz="0" iyy="0.1" iyz="0" izz="0.01"/>
    </inertial>
  </link>
  <joint independent="True" name="joint_1_32" type="revolute">
    <parent link="link_1_31"/>
    <child link="link_1_32"/>
    <origin xyz="0 1.0 0"/>
    <axis xyz="0 0 1"/>
    <limit effort="30" lower="-10" upper="10" velocity="1.0"/>
  </joint>
  <link name="link_2_32">
    <inertial>
      <mass value="0.25"/>
      <origin rpy="0 0 0" xyz="0 0.5 0"/>
      <inertia ixx="0.01" ixy="0" ixz="0" iyy="0.1" iyz="0" izz="0.01"/>
    </inertial>
  </link>
  <joint independent="True" name="joint_2_32" type="revolute">
    <parent link="link_2_31"/>
    <child link="link_2_32"/>
    <origin xyz="0 1.0 0"/>
    <axis xyz="0 0 1"/>
    <limit effort="30" lower="-10" upper="10" velocity="1.0"/>
  </joint>
  <link name="link_1_33">
    <inertial>
      <mass value="0.25"/>
      <origin rpy="0 0 0" xyz="0 0.5 0"/>
      <inertia ixx="0.01" ixy="0" ixz="0" iyy="0.1" iyz="0" izz="0.01"/>
    </inertial>
  </link>
  <joint independent="True" name="joint_1_33" type="revolute">
    <parent link="link_1_32"/>
    <child link="link_1_33"/>
    <origin xyz="0 1.0 0"/>
    <axis xyz="0 0 1"/>
    <limit effort="30" lower="-10" upper="10" velocity="1.0"/>
  </joint>
  <link name="link_2_33">
    <inertial>
      <mass value="0.25"/>
      <origin rpy="0 0 0" xyz="0 0.5 0"/>
      <inertia ixx="0.01" ixy="0" ixz="0" iyy="0.1" iyz="0" izz="0.01"/>
    </inertial>
  </link>
  <joint independent="True" name="joint_2_33" type="revolute">
    <parent link="link_2_32"/>
    <child link="link_2_33"/>
    <origin xyz="0 1.0 0"/>
    <axis xyz="0 0 1"/>
    <limit effort="30" lower="-10" upper="10" velocity="1.0"/>
  </joint>
  <link name="link_1_34">
    <inertial>
      <mass value="0.25"/>
      <origin rpy="0 0 0" xyz="0 0.5 0"/>
      <inertia ixx="0.01" ixy="0" ixz="0" iyy="0.1" iyz="0" izz="0.01"/>
    </inertial>
  </link>
  <joint independent="True" name="joint_1_34" type="revolute">
    <parent link="link_1_33"/>
    <child link="link_1_34"/>
    <origin xyz="0 1.0 0"/>
    <axis xyz="0 0 1"/>
    <limit effort="30" lower="-10" upper="10" velocity="1.0"/>
  </joint>
  <link name="link_2_34">
    <inertial>
      <mass value="0.25"/>
      <origin rpy="0 0 0" xyz="0 0.5 0"/>
      <inertia ixx="0.01" ixy="0" ixz="0" iyy="0.1" iyz="0" izz="0.01"/>
    </inertial>
  </link>
  <joint independent="True" name="joint_2_34" type="revolute">
    <parent link="link_2_33"/>
    <child link="link_2_34"/>
    <origin xyz="0 1.0 0"/>
    <axis xyz="0 0 1"/>
    <limit effort="30" lower="-10" upper="10" velocity="1.0"/>
  </joint>
  <link name="link_1_35">
    <inertial>
      <mass value="0.25"/>
      <origin rpy="0 0 0" xyz="0 0.5 0"/>
      <inertia ixx="0.01" ixy="0" ixz="0" iyy="0.1" iyz="0" izz="0.01"/>
    </inertial>
  </link>
  <joint independent="True" name="joint_1_35" type="revolute">
    <parent link="link_1_34"/>
    <child link="link_1_35"/>
    <origin xyz="0 1.0 0"/>
    <axis xyz="0 0 1"/>
    <limit effort="30" lower="-10" upper="10" velocity="1.0"/>
  </joint>
  <link name="link_2_35">
    <inertial>
      <mass value="0.25"/>
      <origin rpy="0 0 0" xyz="0 0.5 0"/>
      <inertia ixx="0.01" ixy="0" ixz="0" iyy="0.1" iyz="0" izz="0.01"/>
    </inertial>
  </link>
  <joint independent="True" name="joint_2_35" type="revolute">
    <parent link="link_2_34"/>
    <child link="link_2_35"/>
    <origin xyz="0 1.0 0"/>
    <axis xyz="0 0 1"/>
    <limit effort="30" lower="-10" upper="10" velocity="1.0"/>
  </joint>
  <link name="link_1_36">
    <inertial>
      <mass value="0.25"/>
      <origin rpy="0 0 0" xyz="0 0.5 0"/>
      <inertia ixx="0.01" ixy="0" ixz="0" iyy="0.1" iyz="0" izz="0.01"/>
    </inertial>
  </link>
  <joint independent="True" name="joint_1_36" type="revolute">
    <parent link="link_1_35"/>
    <child link="link_1_36"/>
    <origin xyz="0 1.0 0"/>
    <axis xyz="0 0 1"/>
    <limit effort="30" lower="-10" upper="10" velocity="1.0"/>
  </joint>
  <link name="link_2_36">
    <inertial>
      <mass value="0.25"/>
      <origin rpy="0 0 0" xyz="0 0.5 0"/>
      <inertia ixx="0.01" ixy="0" ixz="0" iyy="0.1" iyz="0" izz="0.01"/>
    </inertial>
  </link>
  <joint independent="True" name="joint_2_36" type="revolute">
    <parent link="link_2_35"/>
    <child link="link_2_36"/>
    <origin xyz="0 1.0 0"/>
    <axis xyz="0 0 1"/>
    <limit effort="30" lower="-10" upper="10" velocity="1.0"/>
  </joint>
  <link name="link_1_37">
    <inertial>
      <mass value="0.25"/>
      <origin rpy="0 0 0" xyz="0 0.5 0"/>
      <inertia ixx="0.01" ixy="0" ixz="0" iyy="0.1" iyz="0" izz="0.01"/>
    </inertial>
  </link>
  <joint independent="True" name="joint_1_37" type="revolute">
    <parent link="link_1_36"/>
    <child link="link_1_37"/>
    <origin xyz="0 1.0 0"/>
    <axis xyz="0 0 1"/>
    <limit effort="30" lower="-10" upper="10" velocity="1.0"/>
  </joint>
  <link name="link_2_37">
    <inertial>
      <mass value="0.25"/>
      <origin rpy="0 0 0" xyz="0 0.5 0"/>
      <inertia ixx="0.01" ixy="0" ixz="0" iyy="0.1" iyz="0" izz="0.01"/>
    </inertial>
  </link>
  <joint independent="True" name="joint_2_37" type="revolute">
    <parent link="link_2_36"/>
    <child link="link_2_37"/>
    <origin xyz="0 1.0 0"/>
    <axis xyz="0 0 1"/>
    <limit effort="30" lower="-10" upper="10" velocity="1.0"/>
  </joint>
  <link name="link_1_38">
    <inertial>
      <mass value="0.25"/>
      <origin rpy="0 0 0" xyz="0 0.5 0"/>
      <inertia ixx="0.01" ixy="0" ixz="0" iyy="0.1" iyz="0" izz="0.01"/>
    </inertial>
  </link>
  <joint independent="True" name="joint_1_38" type="revolute">
    <parent link="link_1_37"/>
    <child link="link_1_38"/>
    <origin xyz="0 1.0 0"/>
    <axis xyz="0 0 1"/>
    <limit effort="30" lower="-10" upper="10" velocity="1.0"/>
  </joint>
  <link name="link_2_38">
    <inertial>
      <mass value="0.25"/>
      <origin rpy="0 0 0" xyz="0 0.5 0"/>
      <inertia ixx="0.01" ixy="0" ixz="0" iyy="0.1" iyz="0" izz="0.01"/>
    </inertial>
  </link>
  <joint independent="True" name="joint_2_38" type="revolute">
    <parent link="link_2_37"/>
    <child link="link_2_38"/>
    <origin xyz="0 1.0 0"/>
    <axis xyz="0 0 1"/>
    <limit effort="30" lower="-10" upper="10" velocity="1.0"/>
  </joint>
  <link name="link_1_39">
    <inertial>
      <mass value="0.25"/>
      <origin rpy="0 0 0" xyz="0 0.5 0"/>
      <inertia ixx="0.01" ixy="0" ixz="0" iyy="0.1" iyz="0" izz="0.01"/>
    </inertial>
  </link>
  <joint independent="True" name="joint_1_39" type="revolute">
    <parent link="link_1_38"/>
    <child link="link_1_39"/>
    <origin xyz="0 1.0 0"/>
    <axis xyz="0 0 1"/>
    <limit effort="30" lower="-10" upper="10" velocity="1.0"/>
  </joint>
  <link name="link_2_39">
    <inertial>
      <mass value="0.25"/>
      <origin rpy="0 0 0" xyz="0 0.5 0"/>
      <inertia ixx="0.01" ixy="0" ixz="0" iyy="0.1" iyz="0" izz="0.01"/>
    </inertial>
  </link>
  <joint independent="True" name="joint_2_39" type="revolute">
    <parent link="link_2_38"/>
    <child link="link_2_39"/>
    <origin xyz="0 1.0 0"/>
    <axis xyz="0 0 1"/>
    <limit effort="30" lower="-10" upper="10" velocity="1.0"/>
  </joint>
  <link name="link_1_40">
    <inertial>
      <mass value="0.25"/>
      <origin rpy="0 0 0" xyz="0 0.5 0"/>
      <inertia ixx="0.01" ixy="0" ixz="0" iyy="0.1" iyz="0" izz="0.01"/>
    </inertial>
  </link>
  <joint independent="True" name="joint_1_40" type="revolute">
    <parent link="link_1_39"/>
    <child link="link_1_40"/>
    <origin xyz="0 1.0 0"/>
    <axis xyz="0 0 1"/>
    <limit effort="30" lower="-10" upper="10" velocity="1.0"/>
  </joint>
  <link name="link_2_40">
    <inertial>
      <mass value="0.25"/>
      <origin rpy="0 0 0" xyz="0 0.5 0"/>
      <inertia ixx="0.01" ixy="0" ixz="0" iyy="0.1" iyz="0" izz="0.01"/>
    </inertial>
  </link>
  <joint independent="True" name="joint_2_40" type="revolute">
    <parent link="link_2_39"/>
    <child link="link_2_40"/>
    <origin xyz="0 1.0 0"/>
    <axis xyz="0 0 1"/>
    <limit effort="30" lower="-10" upper="10" velocity="1.0"/>
  </joint>
</robot>
