<?xml version="1.0" ?>
<robot name="Openchain">
  <link name="body">
    <inertial>
      <mass value="10.0"/> 
      <origin xyz="0. 0. 0."/>
      <inertia ixx="0.3006167" ixy="0" ixz="0" iyy="0.23837" iyz="0" izz="0.09690467"/>
    </inertial>
  </link>

  <joint name="q1" type="continuous">
    <axis xyz="1 0 0"/>
    <origin rpy="0 0 0" xyz="0.0 0.0 0.0"/>
    <parent link="body"/>
    <child link="link1"/>
  </joint>
  <link name="link1">
    <inertial>
      <mass value="2.1656"/>
      <origin xyz="-0.03416 -0.00075 0.04293"/>
      <inertia ixx="0.003735" ixy="0.0" ixz="0.0" iyy="0.01391" iyz="0.0" izz="0.01355"/>
    </inertial>
    <visual>
      <origin xyz="0 0 0" rpy="0 0 0" />
      <geometry>
        <box size = " 0.6 0.1 0.2" />
      </geometry>
      <material name="">
        <color rgba="0.752941176470588 0.752941176470588 0.752941176470588 1" />
      </material>
    </visual>
  </link>

  <joint name="q2" type="continuous">
    <axis xyz="1 0 0"/>
    <origin rpy="0 0 0" xyz="0.0 0.0 -0.3"/>
    <parent link="link1"/>
    <child link="link2"/>
  </joint>
  <link name="link2">
    <inertial>
      <mass value="2.1656"/>
      <origin xyz="-0.03416 -0.00075 0.04293"/>
      <inertia ixx="0.003735" ixy="0.0" ixz="0.0" iyy="0.01391" iyz="0.0" izz="0.01355"/>
    </inertial>
    <visual>
      <origin xyz="0 0 0" rpy="0 0 0" />
      <geometry>
        <box size = " 0.26 0.1 0.2" />
      </geometry>
      <material name="">
        <color rgba="0.752941176470588 0.752941176470588 0.752941176470588 1" />
      </material>
    </visual>  
  </link>
</robot>
