<?xml version="1.0" ?>
<!-- =================================================================================== -->
<!-- |    This document was autogenerated by xacro from jvrc1_humanoid.xacro           | -->
<!-- |    EDITING THIS FILE BY HAND IS NOT RECOMMENDED                                 | -->
<!-- =================================================================================== -->
<robot name="jvrc1_humanoid" xmlns:xacro="http://ros.org/wiki/xacro">
  <link name="base"/>
  <link name="pelvis">
    <inertial>
      <mass value="10"/>
      <origin xyz="-0.01 0.0 0.034"/>
      <inertia ixx="0.089583" ixy="0.0" ixz="0.0" iyy="0.089583" iyz="0.0" izz="0.1125"/>
    </inertial>
  </link>
  <joint name="base_to_pelvis" type="floating">
    <origin rpy="0 0 0" xyz="0 0 0"/>
    <parent link="base"/>
    <child link="pelvis"/>
  </joint>
  <joint independent="true" name="pelvis-to-waist-yaw" type="revolute">
    <axis xyz="0 0 1"/>
    <origin rpy="0.0 0.0 0.0" xyz="0.0 0.0 0.192"/>
    <parent link="pelvis"/>
    <child link="waist-yaw"/>
    <limit effort="150" lower="-10" upper="10" velocity="100"/>
  </joint>
  <link name="waist-yaw">
    <inertial>
      <mass value="1.0"/>
      <origin xyz="0.0 0.0 -0.07"/>
      <inertia ixx="0.00173" ixy="0.0" ixz="0.0" iyy="0.00173" iyz="0.0" izz="0.0032"/>
    </inertial>
  </link>
  <joint independent="false" name="pelvis-to-waist-yaw-rotor" type="revolute">
    <axis xyz="0 0 1"/>
    <origin rpy="0.0 0.0 0.0" xyz="0.0 0.0 0.192"/>
    <parent link="pelvis"/>
    <child link="waist-yaw-rotor"/>
    <limit effort="150" lower="-10" upper="10" velocity="100"/>
  </joint>
  <link name="waist-yaw-rotor">
    <inertial>
      <mass value="0.07"/>
      <origin xyz="0.0 0.0 0.0"/>
      <inertia ixx="2e-05" ixy="0.0" ixz="0.0" iyy="2e-05" iyz="0.0" izz="5e-05"/>
    </inertial>
  </link>
  <constraint name="waist-yaw-transmission" type="rolling">
    <predecessor link="waist-yaw"/>
    <successor link="waist-yaw-rotor"/>
    <ratio value="6.0"/>
  </constraint>
  <joint independent="true" name="waist-yaw-to-waist-pitch" type="revolute">
    <axis xyz="0 1 0"/>
    <origin rpy="0.0 0.0 0.0" xyz="0.0 0.0 -1.11e-16"/>
    <parent link="waist-yaw"/>
    <child link="waist-pitch"/>
    <limit effort="150" lower="-10" upper="10" velocity="100"/>
  </joint>
  <link name="waist-pitch">
    <inertial>
      <mass value="1.0"/>
      <origin xyz="0.0 0.0 0.0"/>
      <inertia ixx="0.002425" ixy="0.0" ixz="0.0" iyy="0.002425" iyz="0.0" izz="0.002425"/>
    </inertial>
  </link>
  <joint independent="false" name="waist-yaw-to-waist-pitch-rotor" type="revolute">
    <axis xyz="0 1 0"/>
    <origin rpy="0.0 0.0 0.0" xyz="0.0 0.0 -1.11e-16"/>
    <parent link="waist-yaw"/>
    <child link="waist-pitch-rotor"/>
    <limit effort="150" lower="-10" upper="10" velocity="100"/>
  </joint>
  <link name="waist-pitch-rotor">
    <inertial>
      <mass value="0.07"/>
      <origin xyz="0.0 0.0 0.0"/>
      <inertia ixx="2e-05" ixy="0.0" ixz="0.0" iyy="2e-05" iyz="0.0" izz="5e-05"/>
    </inertial>
  </link>
  <constraint name="waist-pitch-transmission" type="rolling">
    <predecessor link="waist-pitch"/>
    <successor link="waist-pitch-rotor"/>
    <ratio value="6.0"/>
  </constraint>
  <joint independent="true" name="waist-pitch-to-waist-roll" type="revolute">
    <axis xyz="1 0 0"/>
    <origin rpy="0.0 0.0 0.0" xyz="0.0 0.0 -1.11e-16"/>
    <parent link="waist-pitch"/>
    <child link="waist-roll"/>
    <limit effort="150" lower="-10" upper="10" velocity="100"/>
  </joint>
  <link name="waist-roll">
    <inertial>
      <mass value="10.0"/>
      <origin xyz="0.02 0.0 0.24"/>
      <inertia ixx="0.157083" ixy="0.0" ixz="0.0" iyy="0.101083" iyz="0." izz="0.1367"/>
    </inertial>
  </link>
  <joint independent="false" name="waist-pitch-to-waist-roll-rotor" type="revolute">
    <axis xyz="1 0 0"/>
    <origin rpy="0.0 0.0 0.0" xyz="0.0 0.0 -1.11e-16"/>
    <parent link="waist-pitch"/>
    <child link="waist-roll-rotor"/>
    <limit effort="150" lower="-10" upper="10" velocity="100"/>
  </joint>
  <link name="waist-roll-rotor">
    <inertial>
      <mass value="0.07"/>
      <origin xyz="0.0 0.0 0.0"/>
      <inertia ixx="2e-05" ixy="0.0" ixz="0.0" iyy="2e-05" iyz="0.0" izz="5e-05"/>
    </inertial>
  </link>
  <constraint name="waist-roll-transmission" type="rolling">
    <predecessor link="waist-roll"/>
    <successor link="waist-roll-rotor"/>
    <ratio value="6.0"/>
  </constraint>
  <joint independent="true" name="waist-roll-to-neck-yaw" type="revolute">
    <axis xyz="0 0 1"/>
    <origin rpy="0.0 0.0 0.0" xyz="-0.003 0.0 0.453"/>
    <parent link="waist-roll"/>
    <child link="neck-yaw"/>
    <limit effort="150" lower="-10" upper="10" velocity="100"/>
  </joint>
  <link name="neck-yaw">
    <inertial>
      <mass value="0.5"/>
      <origin xyz="0.0 0.0 -0.05"/>
      <inertia ixx="0.000729167" ixy="0.0" ixz="0.0" iyy="0.000729167" iyz="0.0" izz="0.000625"/>
    </inertial>
  </link>
  <!-- <xacro:dependent_neck_yaw_rotor_joint parent="waist-roll"/>
    <xacro:neck_yaw_rotor/>
    <xacro:trans_constraint name="neck-yaw-transmission"
                            predecessor="neck-yaw"
                            successor="neck-yaw-rotor"/> -->
  <joint independent="true" name="neck-yaw-to-neck-roll" type="revolute">
    <axis xyz="1 0 0"/>
    <origin rpy="0.0 0.0 0.0" xyz="8.24e-18 0.0 2.22e-16"/>
    <parent link="neck-yaw"/>
    <child link="neck-roll"/>
    <limit effort="150" lower="-10" upper="10" velocity="100"/>
  </joint>
  <link name="neck-roll">
    <inertial>
      <mass value="0.5"/>
      <origin xyz="0.0 0.0 0.0"/>
      <inertia ixx="0.0005" ixy="0.0" ixz="0.0" iyy="0.0005" iyz="0.0" izz="0.0005"/>
    </inertial>
  </link>
  <!-- <xacro:dependent_neck_roll_rotor_joint parent="neck-yaw"/>
    <xacro:neck_roll_rotor/>
    <xacro:trans_constraint name="neck-roll-transmission"
                            predecessor="neck-roll"
                            successor="neck-roll-rotor"/> -->
  <joint independent="true" name="neck-roll-to-neck-pitch" type="revolute">
    <axis xyz="0 1 0"/>
    <origin rpy="0.0 0.0 0.0" xyz="8.24e-18 0.0 2.22e-16"/>
    <parent link="neck-roll"/>
    <child link="neck-pitch"/>
    <limit effort="150" lower="-10" upper="10" velocity="100"/>
  </joint>
  <link name="neck-pitch">
    <inertial>
      <mass value="2.0"/>
      <origin xyz="0.01 0.0 0.11"/>
      <inertia ixx="0.00968" ixy="0.0" ixz="0.0" iyy="0.00968" iyz="0.0" izz="0.00968"/>
    </inertial>
  </link>
  <!-- <xacro:dependent_neck_pitch_rotor_joint parent="neck-roll"/>
    <xacro:neck_pitch_rotor/>
    <xacro:trans_constraint name="neck-pitch-transmission"
                            predecessor="neck-pitch"
                            successor="neck-pitch-rotor"/> -->
  <!-- Left Leg -->
  <joint independent="true" name="pelvis-to-left-hip-pitch" type="revolute">
    <axis xyz="0 1 0"/>
    <origin rpy="0.0 0.0 0.0" xyz="0.0 0.096 0.0"/>
    <parent link="pelvis"/>
    <child link="left-hip-pitch"/>
    <limit effort="150" lower="-10" upper="10" velocity="100"/>
  </joint>
  <link name="left-hip-pitch">
    <inertial>
      <mass value="1.0"/>
      <origin xyz="0.0 0.0 0.0"/>
      <inertia ixx="0.00196" ixy="0.0" ixz="0.0" iyy="0.00196" iyz="0.0" izz="0.00196"/>
    </inertial>
  </link>
  <joint independent="false" name="pelvis-to-left-hip-pitch-rotor" type="revolute">
    <axis xyz="0 1 0"/>
    <origin rpy="0.0 0.0 0.0" xyz="0.0 0.096 0.0"/>
    <parent link="pelvis"/>
    <child link="left-hip-pitch-rotor"/>
    <limit effort="150" lower="-10" upper="10" velocity="100"/>
  </joint>
  <link name="left-hip-pitch-rotor">
    <inertial>
      <mass value="0.07"/>
      <origin xyz="0.0 0.0 0.0"/>
      <inertia ixx="2e-05" ixy="0.0" ixz="0.0" iyy="2e-05" iyz="0.0" izz="5e-05"/>
    </inertial>
  </link>
  <constraint name="left-hip-pitch-transmission" type="rolling">
    <predecessor link="left-hip-pitch"/>
    <successor link="left-hip-pitch-rotor"/>
    <ratio value="6.0"/>
  </constraint>
  <joint independent="true" name="left-hip-pitch-to-hip-roll" type="revolute">
    <axis xyz="1 0 0"/>
    <origin rpy="0.0 0.0 0.0" xyz="0.0 -2.77e-17 0.0"/>
    <parent link="left-hip-pitch"/>
    <child link="left-hip-roll"/>
    <limit effort="150" lower="-10" upper="10" velocity="100"/>
  </joint>
  <link name="left-hip-roll">
    <inertial>
      <mass value="1.0"/>
      <origin xyz="0.0 0.0 0.0"/>
      <inertia ixx="0.00196" ixy="0.0" ixz="0.0" iyy="0.00196" iyz="0.0" izz="0.00196"/>
    </inertial>
  </link>
  <joint independent="false" name="left-hip-pitch-to-hip-roll-rotor" type="revolute">
    <axis xyz="1 0 0"/>
    <origin rpy="0.0 0.0 0.0" xyz="0.0 -2.77e-17 0.0"/>
    <parent link="left-hip-pitch"/>
    <child link="left-hip-roll-rotor"/>
    <limit effort="150" lower="-10" upper="10" velocity="100"/>
  </joint>
  <link name="left-hip-roll-rotor">
    <inertial>
      <mass value="0.07"/>
      <origin xyz="0.0 0.0 0.0"/>
      <inertia ixx="2e-05" ixy="0.0" ixz="0.0" iyy="2e-05" iyz="0.0" izz="5e-05"/>
    </inertial>
  </link>
  <constraint name="left-hip-roll-transmission" type="rolling">
    <predecessor link="left-hip-roll"/>
    <successor link="left-hip-roll-rotor"/>
    <ratio value="6.0"/>
  </constraint>
  <joint independent="true" name="left-hip-roll-to-hip-yaw" type="revolute">
    <axis xyz="0 0 1"/>
    <origin rpy="0.0 0.0 0.0" xyz="0.0 -2.77e-17 0.0"/>
    <parent link="left-hip-roll"/>
    <child link="left-hip-yaw"/>
    <limit effort="150" lower="-10" upper="10" velocity="100"/>
  </joint>
  <link name="left-hip-yaw">
    <inertial>
      <mass value="3.0"/>
      <origin xyz="0.01 0.0 -0.22"/>
      <inertia ixx="0.031925" ixy="0.0" ixz="0.0" iyy="0.034525" iyz="0.0" izz="0.00865"/>
    </inertial>
  </link>
  <joint independent="false" name="left-hip-roll-to-hip-yaw-rotor" type="revolute">
    <axis xyz="0 0 1"/>
    <origin rpy="0.0 0.0 0.0" xyz="0.0 -2.77e-17 0.0"/>
    <parent link="left-hip-roll"/>
    <child link="left-hip-yaw-rotor"/>
    <limit effort="150" lower="-10" upper="10" velocity="100"/>
  </joint>
  <link name="left-hip-yaw-rotor">
    <inertial>
      <mass value="0.07"/>
      <origin xyz="0.0 0.0 0.0"/>
      <inertia ixx="2e-05" ixy="0.0" ixz="0.0" iyy="2e-05" iyz="0.0" izz="5e-05"/>
    </inertial>
  </link>
  <constraint name="left-hip-yaw-transmission" type="rolling">
    <predecessor link="left-hip-yaw"/>
    <successor link="left-hip-yaw-rotor"/>
    <ratio value="6.0"/>
  </constraint>
  <joint independent="true" name="left-hip-yaw-to-knee" type="revolute">
    <axis xyz="0 1 0"/>
    <origin rpy="0.0 0.0 0.0" xyz="-0.02 -2.77e-17 -0.389"/>
    <parent link="left-hip-yaw"/>
    <child link="left-knee"/>
    <limit effort="150" lower="-10" upper="10" velocity="100"/>
  </joint>
  <link name="left-knee">
    <inertial>
      <mass value="3.0"/>
      <origin xyz="0.04 0.0 -0.16"/>
      <inertia ixx="0.031925" ixy="0.0" ixz="0.0" iyy="0.034525" iyz="0.0" izz="0.00865"/>
    </inertial>
  </link>
  <joint independent="false" name="left-hip-yaw-to-knee-rotor" type="revolute">
    <axis xyz="0 1 0"/>
    <origin rpy="0.0 0.0 0.0" xyz="-0.02 -2.77e-17 -0.389"/>
    <parent link="left-hip-yaw"/>
    <child link="left-knee-rotor"/>
    <limit effort="150" lower="-10" upper="10" velocity="100"/>
  </joint>
  <link name="left-knee-rotor">
    <inertial>
      <mass value="0.07"/>
      <origin xyz="0.0 0.0 0.0"/>
      <inertia ixx="2e-05" ixy="0.0" ixz="0.0" iyy="2e-05" iyz="0.0" izz="5e-05"/>
    </inertial>
  </link>
  <constraint name="left-knee-transmission" type="rolling">
    <predecessor link="left-knee"/>
    <successor link="left-knee-rotor"/>
    <ratio value="6.0"/>
  </constraint>
  <joint independent="true" name="left-knee-to-ankle-roll" type="revolute">
    <axis xyz="1 0 0"/>
    <origin rpy="0.0 0.0 0.0" xyz="0.04 1.52e-16 -0.357"/>
    <parent link="left-knee"/>
    <child link="left-ankle-roll"/>
    <limit effort="150" lower="-10" upper="10" velocity="100"/>
  </joint>
  <link name="left-ankle-roll">
    <inertial>
      <mass value="1.0"/>
      <origin xyz="0.0 0.0 0.0"/>
      <inertia ixx="0.00064" ixy="0.0" ixz="0.0" iyy="0.00064" iyz="0.0" izz="0.00064"/>
    </inertial>
  </link>
  <joint independent="false" name="left-knee-to-ankle-roll-rotor" type="revolute">
    <axis xyz="1 0 0"/>
    <origin rpy="0.0 0.0 0.0" xyz="0.04 1.52e-16 -0.357"/>
    <parent link="left-knee"/>
    <child link="left-ankle-roll-rotor"/>
    <limit effort="150" lower="-10" upper="10" velocity="100"/>
  </joint>
  <link name="left-ankle-roll-rotor">
    <inertial>
      <mass value="0.07"/>
      <origin xyz="0.0 0.0 0.0"/>
      <inertia ixx="2e-05" ixy="0.0" ixz="0.0" iyy="2e-05" iyz="0.0" izz="5e-05"/>
    </inertial>
  </link>
  <constraint name="left-ankle-roll-transmission" type="rolling">
    <predecessor link="left-ankle-roll"/>
    <successor link="left-ankle-roll-rotor"/>
    <ratio value="6.0"/>
  </constraint>
  <joint independent="true" name="left-ankle-roll-to-ankle-pitch" type="revolute">
    <axis xyz="0 1 0"/>
    <origin rpy="0.0 0.0 0.0" xyz="-4.86e-17 3.61e-16 -2.22e-16"/>
    <parent link="left-ankle-roll"/>
    <child link="left-ankle-pitch"/>
    <limit effort="150" lower="-10" upper="10" velocity="100"/>
  </joint>
  <link name="left-ankle-pitch">
    <inertial>
      <mass value="1.5"/>
      <origin xyz="0.03 0.0 -0.07"/>
      <inertia ixx="0.001417" ixy="0.0" ixz="0.0" iyy="0.005617" iyz="0.0" izz="0.006217"/>
    </inertial>
  </link>
  <joint independent="false" name="left-ankle-roll-to-ankle-pitch-rotor" type="revolute">
    <axis xyz="0 1 0"/>
    <origin rpy="0.0 0.0 0.0" xyz="-4.86e-17 3.61e-16 -2.22e-16"/>
    <parent link="left-ankle-roll"/>
    <child link="left-ankle-pitch-rotor"/>
    <limit effort="150" lower="-10" upper="10" velocity="100"/>
  </joint>
  <link name="left-ankle-pitch-rotor">
    <inertial>
      <mass value="0.07"/>
      <origin xyz="0.0 0.0 0.0"/>
      <inertia ixx="2e-05" ixy="0.0" ixz="0.0" iyy="2e-05" iyz="0.0" izz="5e-05"/>
    </inertial>
  </link>
  <constraint name="left-ankle-pitch-transmission" type="rolling">
    <predecessor link="left-ankle-pitch"/>
    <successor link="left-ankle-pitch-rotor"/>
    <ratio value="6.0"/>
  </constraint>
  <!-- Right Leg -->
  <joint independent="true" name="pelvis-to-right-hip-pitch" type="revolute">
    <axis xyz="0 1 0"/>
    <origin rpy="0.0 0.0 0.0" xyz="0.0 -0.096 -87e-03"/>
    <parent link="pelvis"/>
    <child link="right-hip-pitch"/>
    <limit effort="150" lower="-10" upper="10" velocity="100"/>
  </joint>
  <link name="right-hip-pitch">
    <inertial>
      <mass value="1.0"/>
      <origin xyz="0.0 0.0 0.0"/>
      <inertia ixx="0.00196" ixy="0.0" ixz="0.0" iyy="0.00196" iyz="0.0" izz="0.00196"/>
    </inertial>
  </link>
  <joint independent="false" name="pelvis-to-right-hip-pitch-rotor" type="revolute">
    <axis xyz="0 1 0"/>
    <origin rpy="0.0 0.0 0.0" xyz="0.0 -0.096 -87e-03"/>
    <parent link="pelvis"/>
    <child link="right-hip-pitch-rotor"/>
    <limit effort="150" lower="-10" upper="10" velocity="100"/>
  </joint>
  <link name="right-hip-pitch-rotor">
    <inertial>
      <mass value="0.07"/>
      <origin xyz="0.0 0.0 0.0"/>
      <inertia ixx="2e-05" ixy="0.0" ixz="0.0" iyy="2e-05" iyz="0.0" izz="5e-05"/>
    </inertial>
  </link>
  <constraint name="right-hip-pitch-transmission" type="rolling">
    <predecessor link="right-hip-pitch"/>
    <successor link="right-hip-pitch-rotor"/>
    <ratio value="6.0"/>
  </constraint>
  <joint independent="true" name="right-hip-pitch-to-hip-roll" type="revolute">
    <axis xyz="1 0 0"/>
    <origin rpy="0.0 0.0 0.0" xyz="0.0 2.77e-17 0.0"/>
    <parent link="right-hip-pitch"/>
    <child link="right-hip-roll"/>
    <limit effort="150" lower="-10" upper="10" velocity="100"/>
  </joint>
  <link name="right-hip-roll">
    <inertial>
      <mass value="1.0"/>
      <origin xyz="0.0 0.0 0.0"/>
      <inertia ixx="0.00196" ixy="0.0" ixz="0.0" iyy="0.00196" iyz="0.0" izz="0.00196"/>
    </inertial>
  </link>
  <joint independent="false" name="right-hip-pitch-to-hip-roll-rotor" type="revolute">
    <axis xyz="1 0 0"/>
    <origin rpy="0.0 0.0 0.0" xyz="0.0 2.77e-17 0.0"/>
    <parent link="right-hip-pitch"/>
    <child link="right-hip-roll-rotor"/>
    <limit effort="150" lower="-10" upper="10" velocity="100"/>
  </joint>
  <link name="right-hip-roll-rotor">
    <inertial>
      <mass value="0.07"/>
      <origin xyz="0.0 0.0 0.0"/>
      <inertia ixx="2e-05" ixy="0.0" ixz="0.0" iyy="2e-05" iyz="0.0" izz="5e-05"/>
    </inertial>
  </link>
  <constraint name="right-hip-roll-transmission" type="rolling">
    <predecessor link="right-hip-roll"/>
    <successor link="right-hip-roll-rotor"/>
    <ratio value="6.0"/>
  </constraint>
  <joint independent="true" name="right-hip-roll-to-hip-yaw" type="revolute">
    <axis xyz="0 0 1"/>
    <origin rpy="0.0 0.0 0.0" xyz="0.0 2.77e-17 0.0"/>
    <parent link="right-hip-roll"/>
    <child link="right-hip-yaw"/>
    <limit effort="150" lower="-10" upper="10" velocity="100"/>
  </joint>
  <link name="right-hip-yaw">
    <inertial>
      <mass value="3.0"/>
      <origin xyz="0.01 0.0 -0.22"/>
      <inertia ixx="0.031925" ixy="0.0" ixz="0.0" iyy="0.034525" iyz="0.0" izz="0.00865"/>
    </inertial>
  </link>
  <joint independent="false" name="right-hip-roll-to-hip-yaw-rotor" type="revolute">
    <axis xyz="0 0 1"/>
    <origin rpy="0.0 0.0 0.0" xyz="0.0 2.77e-17 0.0"/>
    <parent link="right-hip-roll"/>
    <child link="right-hip-yaw-rotor"/>
    <limit effort="150" lower="-10" upper="10" velocity="100"/>
  </joint>
  <link name="right-hip-yaw-rotor">
    <inertial>
      <mass value="0.07"/>
      <origin xyz="0.0 0.0 0.0"/>
      <inertia ixx="2e-05" ixy="0.0" ixz="0.0" iyy="2e-05" iyz="0.0" izz="5e-05"/>
    </inertial>
  </link>
  <constraint name="right-hip-yaw-transmission" type="rolling">
    <predecessor link="right-hip-yaw"/>
    <successor link="right-hip-yaw-rotor"/>
    <ratio value="6.0"/>
  </constraint>
  <joint independent="true" name="right-hip-yaw-to-knee" type="revolute">
    <axis xyz="0 1 0"/>
    <origin rpy="0.0 0.0 0.0" xyz="-0.02 2.77e-17 -0.389"/>
    <parent link="right-hip-yaw"/>
    <child link="right-knee"/>
    <limit effort="150" lower="-10" upper="10" velocity="100"/>
  </joint>
  <link name="right-knee">
    <inertial>
      <mass value="3.0"/>
      <origin xyz="0.04 0.0 -0.16"/>
      <inertia ixx="0.031925" ixy="0.0" ixz="0.0" iyy="0.034525" iyz="0.0" izz="0.00865"/>
    </inertial>
  </link>
  <joint independent="false" name="right-hip-yaw-to-knee-rotor" type="revolute">
    <axis xyz="0 1 0"/>
    <origin rpy="0.0 0.0 0.0" xyz="-0.02 2.77e-17 -0.389"/>
    <parent link="right-hip-yaw"/>
    <child link="right-knee-rotor"/>
    <limit effort="150" lower="-10" upper="10" velocity="100"/>
  </joint>
  <link name="right-knee-rotor">
    <inertial>
      <mass value="0.07"/>
      <origin xyz="0.0 0.0 0.0"/>
      <inertia ixx="2e-05" ixy="0.0" ixz="0.0" iyy="2e-05" iyz="0.0" izz="5e-05"/>
    </inertial>
  </link>
  <constraint name="right-knee-transmission" type="rolling">
    <predecessor link="right-knee"/>
    <successor link="right-knee-rotor"/>
    <ratio value="6.0"/>
  </constraint>
  <joint independent="true" name="right-knee-to-ankle-roll" type="revolute">
    <axis xyz="1 0 0"/>
    <origin rpy="0.0 0.0 0.0" xyz="0.04 1.11e-16 -0.357"/>
    <parent link="right-knee"/>
    <child link="right-ankle-roll"/>
    <limit effort="150" lower="-10" upper="10" velocity="100"/>
  </joint>
  <link name="right-ankle-roll">
    <inertial>
      <mass value="1.0"/>
      <origin xyz="0.0 0.0 0.0"/>
      <inertia ixx="0.00064" ixy="0.0" ixz="0.0" iyy="0.00064" iyz="0.0" izz="0.00064"/>
    </inertial>
  </link>
  <joint independent="false" name="right-knee-to-ankle-roll-rotor" type="revolute">
    <axis xyz="1 0 0"/>
    <origin rpy="0.0 0.0 0.0" xyz="0.04 1.11e-16 -0.357"/>
    <parent link="right-knee"/>
    <child link="right-ankle-roll-rotor"/>
    <limit effort="150" lower="-10" upper="10" velocity="100"/>
  </joint>
  <link name="right-ankle-roll-rotor">
    <inertial>
      <mass value="0.07"/>
      <origin xyz="0.0 0.0 0.0"/>
      <inertia ixx="2e-05" ixy="0.0" ixz="0.0" iyy="2e-05" iyz="0.0" izz="5e-05"/>
    </inertial>
  </link>
  <constraint name="right-ankle-roll-transmission" type="rolling">
    <predecessor link="right-ankle-roll"/>
    <successor link="right-ankle-roll-rotor"/>
    <ratio value="6.0"/>
  </constraint>
  <joint independent="true" name="right-ankle-roll-to-ankle-pitch" type="revolute">
    <axis xyz="0 1 0"/>
    <origin rpy="0.0 0.0 0.0" xyz="-1.734e-17 -4.44e-16 -1.11e-16"/>
    <parent link="right-ankle-roll"/>
    <child link="right-ankle-pitch"/>
    <limit effort="150" lower="-10" upper="10" velocity="100"/>
  </joint>
  <link name="right-ankle-pitch">
    <inertial>
      <mass value="1.5"/>
      <origin xyz="0.03 0.0 -0.07"/>
      <inertia ixx="0.001417" ixy="0.0" ixz="0.0" iyy="0.005617" iyz="0.0" izz="0.006217"/>
    </inertial>
  </link>
  <joint independent="false" name="right-ankle-roll-to-ankle-pitch-rotor" type="revolute">
    <axis xyz="0 1 0"/>
    <origin rpy="0.0 0.0 0.0" xyz="-1.734e-17 -4.44e-16 -1.11e-16"/>
    <parent link="right-ankle-roll"/>
    <child link="right-ankle-pitch-rotor"/>
    <limit effort="150" lower="-10" upper="10" velocity="100"/>
  </joint>
  <link name="right-ankle-pitch-rotor">
    <inertial>
      <mass value="0.07"/>
      <origin xyz="0.0 0.0 0.0"/>
      <inertia ixx="2e-05" ixy="0.0" ixz="0.0" iyy="2e-05" iyz="0.0" izz="5e-05"/>
    </inertial>
  </link>
  <constraint name="right-ankle-pitch-transmission" type="rolling">
    <predecessor link="right-ankle-pitch"/>
    <successor link="right-ankle-pitch-rotor"/>
    <ratio value="6.0"/>
  </constraint>
  <!-- Left Arm -->
  <joint independent="true" name="waist-roll-to-left-shoulder-pitch" type="revolute">
    <axis xyz="0 1 0"/>
    <origin rpy="0.0 0.0 0.0" xyz="0.0 0.24 0.33"/>
    <parent link="waist-roll"/>
    <child link="left-shoulder-pitch"/>
    <limit effort="150" lower="-10" upper="10" velocity="100"/>
  </joint>
  <link name="left-shoulder-pitch">
    <inertial>
      <mass value="1.0"/>
      <origin xyz="0.0 0.0 0.0"/>
      <inertia ixx="0.00196" ixy="0.0" ixz="0.0" iyy="0.00196" iyz="0.0" izz="0.00196"/>
    </inertial>
  </link>
  <joint independent="false" name="waist-roll-to-left-shoulder-pitch-rotor" type="revolute">
    <axis xyz="0 1 0"/>
    <origin rpy="0.0 0.0 0.0" xyz="0.0 0.24 0.33"/>
    <parent link="waist-roll"/>
    <child link="left-shoulder-pitch-rotor"/>
    <limit effort="150" lower="-10" upper="10" velocity="100"/>
  </joint>
  <link name="left-shoulder-pitch-rotor">
    <inertial>
      <mass value="0.07"/>
      <origin xyz="0.0 0.0 0.0"/>
      <inertia ixx="2e-05" ixy="0.0" ixz="0.0" iyy="2e-05" iyz="0.0" izz="5e-05"/>
    </inertial>
  </link>
  <constraint name="left-shoulder-pitch-transmission" type="rolling">
    <predecessor link="left-shoulder-pitch"/>
    <successor link="left-shoulder-pitch-rotor"/>
    <ratio value="6.0"/>
  </constraint>
  <joint independent="true" name="left-shoulder-pitch-to-shoulder-roll" type="revolute">
    <axis xyz="1 0 0"/>
    <origin rpy="0.0 0.0 0.0" xyz="0.0 2.78e-17 -5.55e-16"/>
    <parent link="left-shoulder-pitch"/>
    <child link="left-shoulder-roll"/>
    <limit effort="150" lower="-10" upper="10" velocity="100"/>
  </joint>
  <link name="left-shoulder-roll">
    <inertial>
      <mass value="1.0"/>
      <origin xyz="0.0 0.0 0.0"/>
      <inertia ixx="0.00196" ixy="0.0" ixz="0.0" iyy="0.00196" iyz="0.0" izz="0.00196"/>
    </inertial>
  </link>
  <joint independent="false" name="left-shoulder-pitch-to-shoulder-roll-rotor" type="revolute">
    <axis xyz="1 0 0"/>
    <origin rpy="0.0 0.0 0.0" xyz="0.0 2.78e-17 -5.55e-16"/>
    <parent link="left-shoulder-pitch"/>
    <child link="left-shoulder-roll-rotor"/>
    <limit effort="150" lower="-10" upper="10" velocity="100"/>
  </joint>
  <link name="left-shoulder-roll-rotor">
    <inertial>
      <mass value="0.07"/>
      <origin xyz="0.0 0.0 0.0"/>
      <inertia ixx="2e-05" ixy="0.0" ixz="0.0" iyy="2e-05" iyz="0.0" izz="5e-05"/>
    </inertial>
  </link>
  <constraint name="left-shoulder-roll-transmission" type="rolling">
    <predecessor link="left-shoulder-roll"/>
    <successor link="left-shoulder-roll-rotor"/>
    <ratio value="6.0"/>
  </constraint>
  <joint independent="true" name="left-shoulder-roll-to-shoulder-yaw" type="revolute">
    <axis xyz="0 0 1"/>
    <origin rpy="0.0 0.0 0.0" xyz="0.0 2.78e-17 -5.55e-16"/>
    <parent link="left-shoulder-roll"/>
    <child link="left-shoulder-yaw"/>
    <limit effort="150" lower="-10" upper="10" velocity="100"/>
  </joint>
  <link name="left-shoulder-yaw">
    <inertial>
      <mass value="2.0"/>
      <origin xyz="-0.01 0.0 -0.19"/>
      <inertia ixx="0.01365" ixy="0.0" ixz="0.0" iyy="0.0146" iyz="0.0" izz="0.00635"/>
    </inertial>
  </link>
  <joint independent="false" name="left-shoulder-roll-to-shoulder-yaw-rotor" type="revolute">
    <axis xyz="0 0 1"/>
    <origin rpy="0.0 0.0 0.0" xyz="0.0 2.78e-17 -5.55e-16"/>
    <parent link="left-shoulder-roll"/>
    <child link="left-shoulder-yaw-rotor"/>
    <limit effort="150" lower="-10" upper="10" velocity="100"/>
  </joint>
  <link name="left-shoulder-yaw-rotor">
    <inertial>
      <mass value="0.07"/>
      <origin xyz="0.0 0.0 0.0"/>
      <inertia ixx="2e-05" ixy="0.0" ixz="0.0" iyy="2e-05" iyz="0.0" izz="5e-05"/>
    </inertial>
  </link>
  <constraint name="left-shoulder-yaw-transmission" type="rolling">
    <predecessor link="left-shoulder-yaw"/>
    <successor link="left-shoulder-yaw-rotor"/>
    <ratio value="6.0"/>
  </constraint>
  <joint independent="true" name="left-shoulder-yaw-to-elbow-pitch" type="revolute">
    <axis xyz="0 1 0"/>
    <origin rpy="0.0 0.0 0.0" xyz="0.004 -2.78e-17 -0.305"/>
    <parent link="left-shoulder-yaw"/>
    <child link="left-elbow-pitch"/>
    <limit effort="150" lower="-10" upper="10" velocity="100"/>
  </joint>
  <link name="left-elbow-pitch">
    <inertial>
      <mass value="1.0"/>
      <origin xyz="-0.02 0.0 -0.1"/>
      <inertia ixx="0.010675" ixy="0.0" ixz="0.0" iyy="0.010675" iyz="0.0" izz="0.0027"/>
    </inertial>
  </link>
  <joint independent="false" name="left-shoulder-yaw-to-elbow-pitch-rotor" type="revolute">
    <axis xyz="0 1 0"/>
    <origin rpy="0.0 0.0 0.0" xyz="0.004 -2.78e-17 -0.305"/>
    <parent link="left-shoulder-yaw"/>
    <child link="left-elbow-pitch-rotor"/>
    <limit effort="150" lower="-10" upper="10" velocity="100"/>
  </joint>
  <link name="left-elbow-pitch-rotor">
    <inertial>
      <mass value="0.07"/>
      <origin xyz="0.0 0.0 0.0"/>
      <inertia ixx="2e-05" ixy="0.0" ixz="0.0" iyy="2e-05" iyz="0.0" izz="5e-05"/>
    </inertial>
  </link>
  <constraint name="left-elbow-pitch-transmission" type="rolling">
    <predecessor link="left-elbow-pitch"/>
    <successor link="left-elbow-pitch-rotor"/>
    <ratio value="6.0"/>
  </constraint>
  <joint independent="true" name="left-elbow-pitch-to-elbow-yaw" type="revolute">
    <axis xyz="0 0 1"/>
    <origin rpy="0.0 0.0 0.0" xyz="-0.004 3.89e-16 -0.239"/>
    <parent link="left-elbow-pitch"/>
    <child link="left-elbow-yaw"/>
    <limit effort="150" lower="-10" upper="10" velocity="100"/>
  </joint>
  <link name="left-elbow-yaw">
    <inertial>
      <mass value="1.0"/>
      <origin xyz="0.0 0.0 0.0"/>
      <inertia ixx="0.00064" ixy="0.0" ixz="0.0" iyy="0.00064" iyz="0.0" izz="0.00064"/>
    </inertial>
  </link>
  <joint independent="false" name="left-elbow-pitch-to-elbow-yaw-rotor" type="revolute">
    <axis xyz="0 0 1"/>
    <origin rpy="0.0 0.0 0.0" xyz="-0.004 3.89e-16 -0.239"/>
    <parent link="left-elbow-pitch"/>
    <child link="left-elbow-yaw-rotor"/>
    <limit effort="150" lower="-10" upper="10" velocity="100"/>
  </joint>
  <link name="left-elbow-yaw-rotor">
    <inertial>
      <mass value="0.07"/>
      <origin xyz="0.0 0.0 0.0"/>
      <inertia ixx="2e-05" ixy="0.0" ixz="0.0" iyy="2e-05" iyz="0.0" izz="5e-05"/>
    </inertial>
  </link>
  <constraint name="left-elbow-yaw-transmission" type="rolling">
    <predecessor link="left-elbow-yaw"/>
    <successor link="left-elbow-yaw-rotor"/>
    <ratio value="6.0"/>
  </constraint>
  <joint independent="true" name="left-elbow-yaw-to-wrist-roll" type="revolute">
    <axis xyz="1 0 0"/>
    <origin rpy="0.0 0.0 0.0" xyz="0.0 -2.78e-16 -1.80e-16"/>
    <parent link="left-elbow-yaw"/>
    <child link="left-wrist-roll"/>
    <limit effort="150" lower="-10" upper="10" velocity="100"/>
  </joint>
  <link name="left-wrist-roll">
    <inertial>
      <mass value="0.5"/>
      <origin xyz="0.0 0.0 0.0"/>
      <inertia ixx="0.00032" ixy="0.0" ixz="0.0" iyy="0.00032" iyz="0.0" izz="0.00032"/>
    </inertial>
  </link>
  <!-- <xacro:L_dependent_wrist_roll_rotor_joint parent="left-elbow-yaw"/>
    <xacro:wrist_roll_rotor prefix="left-"/>
    <xacro:trans_constraint name="left-wrist-roll-transmission"
                            predecessor="left-wrist-roll"
                            successor="left-wrist-roll-rotor"/> -->
  <joint independent="true" name="left-wrist-roll-to-wrist-yaw" type="revolute">
    <axis xyz="0 0 1"/>
    <origin rpy="0.0 0.0 0.0" xyz="0.0 -2.78e-16 -1.80e-16"/>
    <parent link="left-wrist-roll"/>
    <child link="left-wrist-yaw"/>
    <limit effort="150" lower="-10" upper="10" velocity="100"/>
  </joint>
  <link name="left-wrist-yaw">
    <inertial>
      <mass value="0.5"/>
      <origin xyz="0.0 -0.01 -0.06"/>
      <inertia ixx="0.0004625" ixy="0.0" ixz="0.0" iyy="0.0007625" iyz="0.0" izz="0.0004625"/>
    </inertial>
  </link>
  <!-- <xacro:L_dependent_wrist_yaw_rotor_joint parent="left-wrist-roll"/>
    <xacro:wrist_yaw_rotor prefix="left-"/>
    <xacro:trans_constraint name="left-wrist-yaw-transmission"
                            predecessor="left-wrist-yaw"
                            successor="left-wrist-yaw-rotor"/> -->
  <!-- Right Arm -->
  <joint independent="true" name="waist-roll-to-right-shoulder-pitch" type="revolute">
    <axis xyz="0 1 0"/>
    <origin rpy="0.0 0.0 0.0" xyz="0.0 -0.24 0.33"/>
    <parent link="waist-roll"/>
    <child link="right-shoulder-pitch"/>
    <limit effort="150" lower="-10" upper="10" velocity="100"/>
  </joint>
  <link name="right-shoulder-pitch">
    <inertial>
      <mass value="1.0"/>
      <origin xyz="0.0 0.0 0.0"/>
      <inertia ixx="0.00196" ixy="0.0" ixz="0.0" iyy="0.00196" iyz="0.0" izz="0.00196"/>
    </inertial>
  </link>
  <joint independent="false" name="waist-roll-to-right-shoulder-pitch-rotor" type="revolute">
    <axis xyz="0 1 0"/>
    <origin rpy="0.0 0.0 0.0" xyz="0.0 -0.24 0.33"/>
    <parent link="waist-roll"/>
    <child link="right-shoulder-pitch-rotor"/>
    <limit effort="150" lower="-10" upper="10" velocity="100"/>
  </joint>
  <link name="right-shoulder-pitch-rotor">
    <inertial>
      <mass value="0.07"/>
      <origin xyz="0.0 0.0 0.0"/>
      <inertia ixx="2e-05" ixy="0.0" ixz="0.0" iyy="2e-05" iyz="0.0" izz="5e-05"/>
    </inertial>
  </link>
  <constraint name="right-shoulder-pitch-transmission" type="rolling">
    <predecessor link="right-shoulder-pitch"/>
    <successor link="right-shoulder-pitch-rotor"/>
    <ratio value="6.0"/>
  </constraint>
  <joint independent="true" name="right-shoulder-pitch-to-shoulder-roll" type="revolute">
    <axis xyz="1 0 0"/>
    <origin rpy="0.0 0.0 0.0" xyz="0.0 -2.78e-17 -7.77e-16"/>
    <parent link="right-shoulder-pitch"/>
    <child link="right-shoulder-roll"/>
    <limit effort="150" lower="-10" upper="10" velocity="100"/>
  </joint>
  <link name="right-shoulder-roll">
    <inertial>
      <mass value="1.0"/>
      <origin xyz="0.0 0.0 0.0"/>
      <inertia ixx="0.00196" ixy="0.0" ixz="0.0" iyy="0.00196" iyz="0.0" izz="0.00196"/>
    </inertial>
  </link>
  <joint independent="false" name="right-shoulder-pitch-to-shoulder-roll-rotor" type="revolute">
    <axis xyz="1 0 0"/>
    <origin rpy="0.0 0.0 0.0" xyz="0.0 -2.78e-17 -7.77e-16"/>
    <parent link="right-shoulder-pitch"/>
    <child link="right-shoulder-roll-rotor"/>
    <limit effort="150" lower="-10" upper="10" velocity="100"/>
  </joint>
  <link name="right-shoulder-roll-rotor">
    <inertial>
      <mass value="0.07"/>
      <origin xyz="0.0 0.0 0.0"/>
      <inertia ixx="2e-05" ixy="0.0" ixz="0.0" iyy="2e-05" iyz="0.0" izz="5e-05"/>
    </inertial>
  </link>
  <constraint name="right-shoulder-roll-transmission" type="rolling">
    <predecessor link="right-shoulder-roll"/>
    <successor link="right-shoulder-roll-rotor"/>
    <ratio value="6.0"/>
  </constraint>
  <joint independent="true" name="right-shoulder-roll-to-shoulder-yaw" type="revolute">
    <axis xyz="0 0 1"/>
    <origin rpy="0.0 0.0 0.0" xyz="0.0 -2.78e-17 -7.77e-16"/>
    <parent link="right-shoulder-roll"/>
    <child link="right-shoulder-yaw"/>
    <limit effort="150" lower="-10" upper="10" velocity="100"/>
  </joint>
  <link name="right-shoulder-yaw">
    <inertial>
      <mass value="2.0"/>
      <origin xyz="-0.01 0.0 -0.19"/>
      <inertia ixx="0.01365" ixy="0.0" ixz="0.0" iyy="0.0146" iyz="0.0" izz="0.00635"/>
    </inertial>
  </link>
  <joint independent="false" name="right-shoulder-roll-to-shoulder-yaw-rotor" type="revolute">
    <axis xyz="0 0 1"/>
    <origin rpy="0.0 0.0 0.0" xyz="0.0 -2.78e-17 -7.77e-16"/>
    <parent link="right-shoulder-roll"/>
    <child link="right-shoulder-yaw-rotor"/>
    <limit effort="150" lower="-10" upper="10" velocity="100"/>
  </joint>
  <link name="right-shoulder-yaw-rotor">
    <inertial>
      <mass value="0.07"/>
      <origin xyz="0.0 0.0 0.0"/>
      <inertia ixx="2e-05" ixy="0.0" ixz="0.0" iyy="2e-05" iyz="0.0" izz="5e-05"/>
    </inertial>
  </link>
  <constraint name="right-shoulder-yaw-transmission" type="rolling">
    <predecessor link="right-shoulder-yaw"/>
    <successor link="right-shoulder-yaw-rotor"/>
    <ratio value="6.0"/>
  </constraint>
  <joint independent="true" name="right-shoulder-yaw-to-elbow-pitch" type="revolute">
    <axis xyz="0 1 0"/>
    <origin rpy="0.0 0.0 0.0" xyz="0.004 2.78e-17 -0.305"/>
    <parent link="right-shoulder-yaw"/>
    <child link="right-elbow-pitch"/>
    <limit effort="150" lower="-10" upper="10" velocity="100"/>
  </joint>
  <link name="right-elbow-pitch">
    <inertial>
      <mass value="1.0"/>
      <origin xyz="-0.02 0.0 -0.1"/>
      <inertia ixx="0.010675" ixy="0.0" ixz="0.0" iyy="0.010675" iyz="0.0" izz="0.0027"/>
    </inertial>
  </link>
  <joint independent="false" name="right-shoulder-yaw-to-elbow-pitch-rotor" type="revolute">
    <axis xyz="0 1 0"/>
    <origin rpy="0.0 0.0 0.0" xyz="0.004 2.78e-17 -0.305"/>
    <parent link="right-shoulder-yaw"/>
    <child link="right-elbow-pitch-rotor"/>
    <limit effort="150" lower="-10" upper="10" velocity="100"/>
  </joint>
  <link name="right-elbow-pitch-rotor">
    <inertial>
      <mass value="0.07"/>
      <origin xyz="0.0 0.0 0.0"/>
      <inertia ixx="2e-05" ixy="0.0" ixz="0.0" iyy="2e-05" iyz="0.0" izz="5e-05"/>
    </inertial>
  </link>
  <constraint name="right-elbow-pitch-transmission" type="rolling">
    <predecessor link="right-elbow-pitch"/>
    <successor link="right-elbow-pitch-rotor"/>
    <ratio value="6.0"/>
  </constraint>
  <joint independent="true" name="right-elbow-pitch-to-elbow-yaw" type="revolute">
    <axis xyz="0 0 1"/>
    <origin rpy="0.0 0.0 0.0" xyz="-0.004 -5e-16 -0.239"/>
    <parent link="right-elbow-pitch"/>
    <child link="right-elbow-yaw"/>
    <limit effort="150" lower="-10" upper="10" velocity="100"/>
  </joint>
  <link name="right-elbow-yaw">
    <inertial>
      <mass value="1.0"/>
      <origin xyz="0.0 0.0 0.0"/>
      <inertia ixx="0.00064" ixy="0.0" ixz="0.0" iyy="0.00064" iyz="0.0" izz="0.00064"/>
    </inertial>
  </link>
  <joint independent="false" name="right-elbow-pitch-to-elbow-yaw-rotor" type="revolute">
    <axis xyz="0 0 1"/>
    <origin rpy="0.0 0.0 0.0" xyz="-0.004 -5e-16 -0.239"/>
    <parent link="right-elbow-pitch"/>
    <child link="right-elbow-yaw-rotor"/>
    <limit effort="150" lower="-10" upper="10" velocity="100"/>
  </joint>
  <link name="right-elbow-yaw-rotor">
    <inertial>
      <mass value="0.07"/>
      <origin xyz="0.0 0.0 0.0"/>
      <inertia ixx="2e-05" ixy="0.0" ixz="0.0" iyy="2e-05" iyz="0.0" izz="5e-05"/>
    </inertial>
  </link>
  <constraint name="right-elbow-yaw-transmission" type="rolling">
    <predecessor link="right-elbow-yaw"/>
    <successor link="right-elbow-yaw-rotor"/>
    <ratio value="6.0"/>
  </constraint>
  <joint independent="true" name="right-elbow-yaw-to-wrist-roll" type="revolute">
    <axis xyz="1 0 0"/>
    <origin rpy="0.0 0.0 0.0" xyz="0.0 2.78e-16 -1.80e-16"/>
    <parent link="right-elbow-yaw"/>
    <child link="right-wrist-roll"/>
    <limit effort="150" lower="-10" upper="10" velocity="100"/>
  </joint>
  <link name="right-wrist-roll">
    <inertial>
      <mass value="0.5"/>
      <origin xyz="0.0 0.0 0.0"/>
      <inertia ixx="0.00032" ixy="0.0" ixz="0.0" iyy="0.00032" iyz="0.0" izz="0.00032"/>
    </inertial>
  </link>
  <!-- <xacro:R_dependent_wrist_roll_rotor_joint parent="right-elbow-yaw"/>
    <xacro:wrist_roll_rotor prefix="right-"/>
    <xacro:trans_constraint name="right-wrist-roll-transmission"
                            predecessor="right-wrist-roll"
                            successor="right-wrist-roll-rotor"/> -->
  <joint independent="true" name="right-wrist-roll-to-wrist-yaw" type="revolute">
    <axis xyz="0 0 1"/>
    <origin rpy="0.0 0.0 0.0" xyz="0.0 2.78e-16 -1.80e-16"/>
    <parent link="right-wrist-roll"/>
    <child link="right-wrist-yaw"/>
    <limit effort="150" lower="-10" upper="10" velocity="100"/>
  </joint>
  <link name="right-wrist-yaw">
    <inertial>
      <mass value="0.5"/>
      <origin xyz="0.0 0.01 -0.06"/>
      <inertia ixx="0.0004625" ixy="0.0" ixz="0.0" iyy="0.0007625" iyz="0.0" izz="0.0004625"/>
    </inertial>
  </link>
  <!-- <xacro:R_dependent_wrist_yaw_rotor_joint parent="right-wrist-roll"/>
    <xacro:wrist_yaw_rotor prefix="right-"/>
    <xacro:trans_constraint name="right-wrist-yaw-transmission"
                            predecessor="right-wrist-yaw"
                            successor="right-wrist-yaw-rotor"/> -->
</robot>

