<?xml version="1.0" encoding="utf-8"?>
<!-- =================================================================================== -->
<!-- |    This document was autogenerated by xacro from mini_cheetah_fr_leg.xacro      | -->
<!-- |    EDITING THIS FILE BY HAND IS NOT RECOMMENDED                                 | -->
<!-- =================================================================================== -->
<robot name="mini_cheetah_fr_leg" xmlns:xacro="http://ros.org/wiki/xacro">
  <link name="Floating Base"/>
  <joint name="torso_to_FR_abad_j" type="continuous">
    <axis xyz="1 0 0"/>
    <origin xyz="0.19 -0.05 0.0"/>
    <parent link="Floating Base"/>
    <child link="FR_abad_link"/>
  </joint>
  <link name="FR_abad_link">
    <inertial>
      <mass value="0.54"/>
      <origin xyz="0.0 -0.036 0."/>
      <inertia ixx="0.000381" ixy="-5.8e-05" ixz="4.5e-07" iyy="0.00056" iyz="-9.5e-07" izz="0.000444"/>
    </inertial>
    <!-- TODO(@MatthewChignoli): Do collision and visual stuff later -->
  </link>
  <joint independent="false" name="torso_to_FR_abad_rotor_j" type="continuous">
    <axis xyz="1 0 0"/>
    <origin xyz="0.125 -0.049 0.0"/>
    <parent link="Floating Base"/>
    <child link="FR_abad_rotor"/>
  </joint>
  <link name="FR_abad_rotor">
    <inertial>
      <mass value="0."/>
      <origin xyz="0. 0. 0."/>
      <inertia ixx="6.3e-05" ixy="0.0" ixz="0.0" iyy="3.3e-05" iyz="0.0" izz="3.3e-05"/>
    </inertial>
  </link>
  <constraint name="FR_abad_tranmission" type="rolling">
    <predecessor link="FR_abad_link"/>
    <successor link="FR_abad_rotor"/>
    <ratio value="6.0"/>
  </constraint>
  <joint name="FR_abad_to_hip_j" type="continuous">
    <axis xyz="0 1 0"/>
    <origin xyz="0 -0.062 0.0"/>
    <parent link="FR_abad_link"/>
    <child link="FR_hip_link"/>
  </joint>
  <link name="FR_hip_link">
    <inertial>
      <mass value="0.634"/>
      <origin xyz="0.0 -0.016 -0.02"/>
      <inertia ixx="0.001983" ixy="-0.000245" ixz="1.3e-05" iyy="0.002103" iyz="-1.5e-06" izz="0.000408"/>
    </inertial>
    <!-- TODO(@MatthewChignoli): Do collision and visual stuff later -->
  </link>
  <joint independent="false" name="FR_abad_to_hip_rotor_j" type="continuous">
    <axis xyz="0 1 0"/>
    <origin rpy="0 0 0" xyz="0.0 -0.04 0.0"/>
    <parent link="FR_abad_link"/>
    <child link="FR_hip_rotor"/>
  </joint>
  <link name="FR_hip_rotor">
    <inertial>
      <mass value="0."/>
      <origin xyz="0. 0. 0."/>
      <inertia ixx="3.3e-05" ixy="0.0" ixz="0.0" iyy="6.3e-05" iyz="0.0" izz="3.3e-05"/>
    </inertial>
  </link>
  <constraint name="FR_hip_tranmission" type="rolling">
    <predecessor link="FR_hip_link"/>
    <successor link="FR_hip_rotor"/>
    <ratio value="6.0"/>
  </constraint>
  <joint name="FR_hip_to_knee_j" type="continuous">
    <axis xyz="0 1 0"/>
    <origin xyz="0.0 0.0 -0.209"/>
    <parent link="FR_hip_link"/>
    <child link="FR_knee_link"/>
  </joint>
  <link name="FR_knee_link">
    <inertial>
      <mass value="0.064"/>
      <origin xyz="0.0 0.0 -0.061"/>
      <inertia ixx="6e-06" ixy="0.0" ixz="0.0" iyy="0.000248" iyz="0.0" izz="0.000245"/>
    </inertial>
    <!-- TODO(@MatthewChignoli): Do collision and visual stuff later -->
  </link>
  <joint independent="false" name="FR_hip_to_knee_rotor_j" type="continuous">
    <axis xyz="0 1 0"/>
    <parent link="FR_hip_link"/>
    <child link="FR_knee_rotor"/>
  </joint>
  <link name="FR_knee_rotor">
    <inertial>
      <mass value="0."/>
      <origin xyz="0. 0. 0."/>
      <inertia ixx="3.3e-05" ixy="0.0" ixz="0.0" iyy="6.3e-05" iyz="0.0" izz="3.3e-05"/>
    </inertial>
  </link>
  <constraint name="FR_knee_tranmission" type="rolling">
    <predecessor link="FR_knee_link"/>
    <successor link="FR_knee_rotor"/>
    <ratio value="9.33"/>
  </constraint>
</robot>

