<?xml version="1.0" ?>
<!-- =================================================================================== -->
<!-- |    This document was autogenerated by xacro from mini_cheetah_approximate.xacro | -->
<!-- |    EDITING THIS FILE BY HAND IS NOT RECOMMENDED                                 | -->
<!-- =================================================================================== -->
<robot name="mini_cheetah" xmlns:xacro="http://ros.org/wiki/xacro">
  <link name="base"/>
  <link name="Floating Base">
    <inertial>
      <mass value="3.3"/>
      <origin xyz="0.0 0.0 0.0"/>
      <inertia ixx="0.011252999999999999" ixy="0" ixz="0" iyy="0.036203" iyz="0" izz="0.042672999999999996"/>
    </inertial>
  </link>
  <joint name="base_to_floating_base" type="floating">
    <origin rpy="0 0 0" xyz="0 0 0"/>
    <parent link="base"/>
    <child link="Floating Base"/>
  </joint>
  <joint name="torso_to_FR_abad_j" type="revolute">
    <axis xyz="1 0 0"/>
    <origin xyz="0.19 -0.049 0.0"/>
    <parent link="Floating Base"/>
    <child link="FR_abad_link"/>
    <limit effort="150" lower="-10" upper="10" velocity="100"/>
  </joint>
  <link name="FR_abad_link">
    <inertial>
      <mass value="0.54"/>
      <origin xyz="0.0 -0.036 0."/>
      <inertia ixx="0.000381" ixy="-5.8e-05" ixz="4.5e-07" iyy="0.00056" iyz="-9.499999999999999e-07" izz="0.000444"/>
    </inertial>
  </link>
  <joint name="FR_abad_to_hip_j" type="revolute">
    <axis xyz="0 1 0"/>
    <origin rpy="0 0 3.141592653589793" xyz="0 -0.062 0.0"/>
    <parent link="FR_abad_link"/>
    <child link="FR_hip_link"/>
    <limit effort="150" lower="-10" upper="10" velocity="100"/>
  </joint>
  <link name="FR_hip_link">
    <inertial>
      <mass value="0.634"/>
      <origin xyz="0.0 -0.016 -0.02"/>
      <inertia ixx="0.001983" ixy="-0.000245" ixz="1.3e-05" iyy="0.002103" iyz="-1.5e-06" izz="0.000408"/>
    </inertial>
  </link>
  <joint name="FR_hip_to_knee_j" type="revolute">
    <axis xyz="0 1 0"/>
    <origin xyz="0.0 0.0 -0.209"/>
    <parent link="FR_hip_link"/>
    <child link="FR_knee_link"/>
    <limit effort="150" lower="-10" upper="10" velocity="100"/>
  </joint>
  <link name="FR_knee_link">
    <inertial>
      <mass value="0.064"/>
      <origin xyz="0.0 0.0 -0.061"/>
      <inertia ixx="6e-06" ixy="0.0" ixz="0.0" iyy="0.000248" iyz="0.0" izz="0.000245"/>
    </inertial>
  </link>
  <joint name="torso_to_FL_abad_j" type="revolute">
    <axis xyz="1 0 0"/>
    <origin xyz="0.19 0.049 0.0"/>
    <parent link="Floating Base"/>
    <child link="FL_abad_link"/>
    <limit effort="150" lower="-10" upper="10" velocity="100"/>
  </joint>
  <link name="FL_abad_link">
    <inertial>
      <mass value="0.54"/>
      <origin xyz="0.0 0.036 0."/>
      <inertia ixx="0.000381" ixy="5.8e-05" ixz="4.5e-07" iyy="0.00056" iyz="9.499999999999999e-07" izz="0.000444"/>
    </inertial>
  </link>
  <joint name="FL_abad_to_hip_j" type="revolute">
    <axis xyz="0 1 0"/>
    <origin rpy="0 0 3.141592653589793" xyz="0 0.062 0.0"/>
    <parent link="FL_abad_link"/>
    <child link="FL_hip_link"/>
    <limit effort="150" lower="-10" upper="10" velocity="100"/>
  </joint>
  <link name="FL_hip_link">
    <inertial>
      <mass value="0.634"/>
      <origin xyz="0.0 0.016 -0.02"/>
      <inertia ixx="0.001983" ixy="0.000245" ixz="1.3e-05" iyy="0.002103" iyz="1.5e-06" izz="0.000408"/>
    </inertial>
  </link>
  <joint name="FL_hip_to_knee_j" type="revolute">
    <axis xyz="0 1 0"/>
    <origin xyz="0.0 0.0 -0.209"/>
    <parent link="FL_hip_link"/>
    <child link="FL_knee_link"/>
    <limit effort="150" lower="-10" upper="10" velocity="100"/>
  </joint>
  <link name="FL_knee_link">
    <inertial>
      <mass value="0.064"/>
      <origin xyz="0.0 0.0 -0.061"/>
      <inertia ixx="6e-06" ixy="0.0" ixz="0.0" iyy="0.000248" iyz="0.0" izz="0.000245"/>
    </inertial>
  </link>
  <joint name="torso_to_HR_abad_j" type="revolute">
    <axis xyz="1 0 0"/>
    <origin xyz="-0.19 -0.049 0.0"/>
    <parent link="Floating Base"/>
    <child link="HR_abad_link"/>
    <limit effort="150" lower="-10" upper="10" velocity="100"/>
  </joint>
  <link name="HR_abad_link">
    <inertial>
      <mass value="0.54"/>
      <origin xyz="0.0 -0.036 0."/>
      <inertia ixx="0.000381" ixy="-5.8e-05" ixz="4.5e-07" iyy="0.00056" iyz="-9.499999999999999e-07" izz="0.000444"/>
    </inertial>
  </link>
  <joint name="HR_abad_to_hip_j" type="revolute">
    <axis xyz="0 1 0"/>
    <origin rpy="0 0 3.141592653589793" xyz="0 -0.062 0.0"/>
    <parent link="HR_abad_link"/>
    <child link="HR_hip_link"/>
    <limit effort="150" lower="-10" upper="10" velocity="100"/>
  </joint>
  <link name="HR_hip_link">
    <inertial>
      <mass value="0.634"/>
      <origin xyz="0.0 -0.016 -0.02"/>
      <inertia ixx="0.001983" ixy="-0.000245" ixz="1.3e-05" iyy="0.002103" iyz="-1.5e-06" izz="0.000408"/>
    </inertial>
  </link>
  <joint name="HR_hip_to_knee_j" type="revolute">
    <axis xyz="0 1 0"/>
    <origin xyz="0.0 0.0 -0.209"/>
    <parent link="HR_hip_link"/>
    <child link="HR_knee_link"/>
    <limit effort="150" lower="-10" upper="10" velocity="100"/>
  </joint>
  <link name="HR_knee_link">
    <inertial>
      <mass value="0.064"/>
      <origin xyz="0.0 0.0 -0.061"/>
      <inertia ixx="6e-06" ixy="0.0" ixz="0.0" iyy="0.000248" iyz="0.0" izz="0.000245"/>
    </inertial>
  </link>
  <joint name="torso_to_HL_abad_j" type="revolute">
    <axis xyz="1 0 0"/>
    <origin xyz="-0.19 0.049 0.0"/>
    <parent link="Floating Base"/>
    <child link="HL_abad_link"/>
    <limit effort="150" lower="-10" upper="10" velocity="100"/>
  </joint>
  <link name="HL_abad_link">
    <inertial>
      <mass value="0.54"/>
      <origin xyz="0.0 0.036 0."/>
      <inertia ixx="0.000381" ixy="5.8e-05" ixz="4.5e-07" iyy="0.00056" iyz="9.499999999999999e-07" izz="0.000444"/>
    </inertial>
  </link>
  <joint name="HL_abad_to_hip_j" type="revolute">
    <axis xyz="0 1 0"/>
    <origin rpy="0 0 3.141592653589793" xyz="0 0.062 0.0"/>
    <parent link="HL_abad_link"/>
    <child link="HL_hip_link"/>
    <limit effort="150" lower="-10" upper="10" velocity="100"/>
  </joint>
  <link name="HL_hip_link">
    <inertial>
      <mass value="0.634"/>
      <origin xyz="0.0 0.016 -0.02"/>
      <inertia ixx="0.001983" ixy="0.000245" ixz="1.3e-05" iyy="0.002103" iyz="1.5e-06" izz="0.000408"/>
    </inertial>
  </link>
  <joint name="HL_hip_to_knee_j" type="revolute">
    <axis xyz="0 1 0"/>
    <origin xyz="0.0 0.0 -0.209"/>
    <parent link="HL_hip_link"/>
    <child link="HL_knee_link"/>
    <limit effort="150" lower="-10" upper="10" velocity="100"/>
  </joint>
  <link name="HL_knee_link">
    <inertial>
      <mass value="0.064"/>
      <origin xyz="0.0 0.0 -0.061"/>
      <inertia ixx="6e-06" ixy="0.0" ixz="0.0" iyy="0.000248" iyz="0.0" izz="0.000245"/>
    </inertial>
  </link>
</robot>

