<?xml version="1.0" ?>

<robot name="mit_humanoid_leg" xmlns:xacro="http://ros.org/wiki/xacro">

    <xacro:property name="effort_limit" value="150"/>
    <xacro:property name="velocity_limit" value="100"/>
    <xacro:property name="joint_lower_limit" value="-10"/>
    <xacro:property name="joint_upper_limit" value="10"/>

    <!-- Hip Yaw Macro -->
    <xacro:property name="hipz_pitch" value="-0.174533"/>
    <xacro:macro name="hipz" params="prefix y_sign">
        <joint name="base_to_${prefix}hipz_link" type="revolute">
            <axis xyz="0 0 1"/>
            <origin xyz="-0.00565 ${y_sign * -0.082} -0.05735" rpy="0 ${hipz_pitch} 0"/>
            <parent link="base"/>
            <child link="${prefix}hip_rz_link"/>
            <limit effort="${effort_limit}" velocity="${velocity_limit}"
                   lower="${joint_lower_limit}" upper="${joint_upper_limit}"/>
        </joint>
        <link name="${prefix}hip_rz_link">
            <inertial>
                <mass value="0.84563"/>
                <origin xyz="-0.064842 ${y_sign * -0.000036} -0.063090"/>
                <inertia ixx="0.0015373" ixy="${y_sign * 0.0000011}" ixz="0.0005578"
                         iyy="0.0014252" iyz="${y_sign * 0.0000024}" izz="0.0012028"/>
            </inertial>
        </link>

        <joint name="${prefix}base_to_hipz_rotor" type="revolute" independent="false">
            <axis xyz="0 0 1"/>
            <origin xyz="-0.00842837 ${y_sign * -0.082} -0.041593" rpy="0 ${hipz_pitch} 0"/>
            <parent link="base"/>
            <child link="${prefix}hip_rz_rotor"/>
            <limit effort="${effort_limit}" velocity="${velocity_limit}"
                   lower="${joint_lower_limit}" upper="${joint_upper_limit}"/>

        </joint>
        <link name="${prefix}hip_rz_rotor">
            <inertial>
                <mass value="0."/>
                <origin xyz="0. 0. 0."/>
                <inertia ixx="1.084e-4" ixy="0.0" ixz="0.0"
                         iyy="1.084e-4" iyz="0.0" izz="1.6841e-4"/>
            </inertial>
        </link>

        <coupling name="hipz_transmission">
            <predecessor link="${prefix}hip_rz_link"/>
            <successor link="${prefix}hip_rz_rotor"/>
            <ratio value="6.0"/>
        </coupling>
    </xacro:macro>

    <!-- Hip Abduction/Adduction -->
    <xacro:property name="hipx_pitch" value="0.436332"/>
    <xacro:macro name="hipx" params="prefix y_sign">
        <joint name="${prefix}hipz_to_hipx_link" type="revolute">
            <axis xyz="1 0 0"/>
            <origin xyz="-0.06435 0.0 -.07499" rpy="0 ${hipx_pitch} 0"/>
            <parent link="${prefix}hip_rz_link"/>
            <child link="${prefix}hip_rx_link"/>
            <limit effort="${effort_limit}" velocity="${velocity_limit}"
                   lower="${joint_lower_limit}" upper="${joint_upper_limit}"/>
        </joint>
        <link name="${prefix}hip_rx_link">
            <inertial>
                <mass value="1.20868"/>
                <origin xyz="0.067232 ${y_sign * -0.013018} 0.0001831"/>
                <inertia ixx="0.0017535" ixy="${y_sign * -0.0000063}" ixz="-0.000080"
                         iyy="0.003338" iyz="${y_sign * -0.000013}" izz="0.0019927"/>
            </inertial>
        </link>

        <joint name="${prefix}hipz_to_hipx_rotor" type="revolute" independent="false">
            <axis xyz="1 0 0"/>
            <origin xyz="-0.0827 0.0 -0.066436" rpy="0 ${hipx_pitch} 0"/>
            <parent link="${prefix}hip_rz_link"/>
            <child link="${prefix}hip_rx_rotor"/>
            <limit effort="${effort_limit}" velocity="${velocity_limit}"
                   lower="${joint_lower_limit}" upper="${joint_upper_limit}"/>
        </joint>
        <link name="${prefix}hip_rx_rotor">
            <inertial>
                <mass value="0."/>
                <origin xyz="0. 0. 0."/>
                <inertia ixx="1.6841e-4" ixy="0.0" ixz="0.0"
                         iyy="1.084e-4" iyz="0.0" izz="1.084e-4"/>
            </inertial>
        </link>

        <coupling name="hipx_transmission">
            <predecessor link="${prefix}hip_rx_link"/>
            <successor link="${prefix}hip_rx_rotor"/>
            <ratio value="6.0"/>
        </coupling>
    </xacro:macro>


    <!-- Hip Flexion/Extension -->
    <xacro:macro name="hipy" params="prefix y_sign">
        <joint name="${prefix}hipx_to_hipy_link" type="revolute">
            <axis xyz="0 1 0"/>
            <origin xyz="0.071 ${y_sign * 0.0018375} 0.0" rpy="0 -${hipz_pitch + hipx_pitch} 0"/>
            <parent link="${prefix}hip_rx_link"/>
            <child link="${prefix}hip_ry_link"/>
            <limit effort="${effort_limit}" velocity="${velocity_limit}"
                   lower="${joint_lower_limit}" upper="${joint_upper_limit}"/>
        </joint>
        <link name="${prefix}hip_ry_link">
            <inertial>
                <mass value="2.64093"/>
                <origin xyz="0.0132054 ${y_sign * 0.0269864} -0.096021"/>
                <inertia ixx="0.0243761" ixy="${y_sign * 0.0000996}" ixz="0.0006548"
                    iyy="0.0259015" iyz="${y_sign * 0.0026713}" izz="0.0038929"/>
            </inertial>
        </link>

        <joint name="${prefix}hipx_to_hipy_rotor" type="revolute" independent="false">
            <axis xyz="0 1 0"/>
            <origin xyz="0.071 ${y_sign * 0.024} 0.0" rpy="0 -${hipz_pitch + hipx_pitch} 0"/>
            <parent link="${prefix}hip_rx_link"/>
            <child link="${prefix}hip_ry_rotor"/>
            <limit effort="${effort_limit}" velocity="${velocity_limit}"
                   lower="${joint_lower_limit}" upper="${joint_upper_limit}"/>
        </joint>
        <link name="${prefix}hip_ry_rotor">
            <inertial>
                <mass value="0."/>
                <origin xyz="0. 0. 0."/>
                <inertia ixx="3.443e-4" ixy="0.0" ixz="0.0"
                         iyy="5.548e-4" iyz="0.0" izz="3.443e-4"/>
            </inertial>
        </link>

        <coupling name="hipy_transmission">
            <predecessor link="${prefix}hip_ry_link"/>
            <successor link="${prefix}hip_ry_rotor"/>
            <ratio value="6.0"/>
        </coupling>
    </xacro:macro>

    <!-- Knee Flexion/Extension -->
    <xacro:macro name="knee" params="prefix y_sign">
        <joint name="${prefix}hipy_to_knee_link" type="revolute">
            <axis xyz="0 1 0"/>
            <origin xyz="0.0 0.0 -0.267"/>
            <parent link="${prefix}hip_ry_link"/>
            <child link="${prefix}knee_link"/>
            <limit effort="${effort_limit}" velocity="${velocity_limit}"
                   lower="${joint_lower_limit}" upper="${joint_upper_limit}"/>
        </joint>
        <link name="${prefix}knee_link">
            <inertial>
                <mass value="0.35435"/>
                <origin xyz="0.00528 ${y_sign * 0.0014762} -0.13201"/>
                <inertia ixx="0.003051" ixy="0.0" ixz="0.0000873"
                         iyy="0.003033" iyz="${y_sign * 0.0000393}" izz="0.0002529"/>
            </inertial>
        </link>

        <joint name="${prefix}hipy_to_knee_rotor" type="revolute" independent="false">
            <axis xyz="0 1 0"/>
            <origin xyz="0.013 ${y_sign * -0.0497} -0.0178"/>
            <parent link="${prefix}hip_ry_link"/>
            <child link="${prefix}knee_rotor"/>
            <limit effort="${effort_limit}" velocity="${velocity_limit}"
                   lower="${joint_lower_limit}" upper="${joint_upper_limit}"/>
        </joint>
        <link name="${prefix}knee_rotor">
            <inertial>
                <mass value="0."/>
                <origin xyz="0. 0. 0."/>
                <inertia ixx="3.443e-4" ixy="0.0" ixz="0.0"
                         iyy="5.548e-4" iyz="0.0" izz="3.443e-4"/>
            </inertial>
        </link>

        <coupling name="knee_transmission">
            <predecessor link="${prefix}knee_link"/>
            <successor link="${prefix}knee_rotor"/>
            <ratio value="12.0"/>
        </coupling>
    </xacro:macro>

    <!-- Ankle Flexion/Extension -->
    <xacro:macro name="ankle" params="prefix y_sign">
        <joint name="${prefix}hipy_to_ankle_rotor" type="revolute" independent="false">
            <axis xyz="0 1 0"/>
            <origin xyz=".01563 ${y_sign * -.0454} -.13354"/>
            <parent link="${prefix}hip_ry_link"/>
            <child link="${prefix}ankle_rotor"/>
            <limit effort="${effort_limit}" velocity="${velocity_limit}"
                   lower="${joint_lower_limit}" upper="${joint_upper_limit}"/>
        </joint>
        <link name="${prefix}ankle_rotor">
            <inertial>
                <mass value="0."/>
                <origin xyz="0. 0. 0."/>
                <inertia ixx="1.084e-4" ixy="0.0" ixz="0.0"
                         iyy="1.6841e-4" iyz="0.0" izz="1.084e-4"/>
            </inertial>
        </link>

        <joint name="${prefix}knee_to_ankle" type="revolute">
            <axis xyz="0 1 0"/>
            <origin xyz="0.0 0.0 -0.2785"/>
            <parent link="${prefix}knee_link"/>
            <child link="${prefix}ankle_link"/>
            <limit effort="${effort_limit}" velocity="${velocity_limit}"
                   lower="${joint_lower_limit}" upper="${joint_upper_limit}"/>
        </joint>
        <link name="${prefix}ankle_link">
            <inertial>
                <mass value="0.280951"/>
                <origin xyz="0.022623 0.0 -0.012826"/>
                <inertia ixx="0.0000842" ixy="0.0" ixz="-0.0000488"
                         iyy="0.0007959" iyz="0.0" izz="0.0007681"/>
            </inertial>
        </link>

        <coupling name="ankle_transmission">
            <predecessor link="${prefix}ankle_link"/>
            <successor link="${prefix}ankle_rotor"/>
            <ratio value="12.0"/>
        </coupling>
    </xacro:macro>

    <link name="base"/>
    <xacro:hipz prefix="" y_sign="1"/>
    <xacro:hipx prefix="" y_sign="1"/>
    <xacro:hipy prefix="" y_sign="1"/>
    <xacro:knee prefix="" y_sign="1"/>
    <xacro:ankle prefix="" y_sign="1"/>

</robot>
