<?xml version="1.0" ?>
<!-- =================================================================================== -->
<!-- |    This document was autogenerated by xacro from mit_humanoid_leg.xacro         | -->
<!-- |    EDITING THIS FILE BY HAND IS NOT RECOMMENDED                                 | -->
<!-- =================================================================================== -->
<robot name="mit_humanoid_leg">
  <link name="base"/>
  <joint name="base_to_hipz_link" type="revolute">
    <axis xyz="0 0 1"/>
    <origin rpy="0 -0.174533 0" xyz="-0.00565 -0.082 -0.05735"/>
    <parent link="base"/>
    <child link="hip_rz_link"/>
    <limit effort="150" lower="-10" upper="10" velocity="100"/>
  </joint>
  <link name="hip_rz_link">
    <inertial>
      <mass value="0.84563"/>
      <origin xyz="-0.064842 -3.6e-05 -0.063090"/>
      <inertia ixx="0.0015373" ixy="1.1e-06" ixz="0.0005578" iyy="0.0014252" iyz="2.4e-06" izz="0.0012028"/>
    </inertial>
  </link>
  <joint independent="false" name="base_to_hipz_rotor" type="revolute">
    <axis xyz="0 0 1"/>
    <origin rpy="0 -0.174533 0" xyz="-0.00842837 -0.082 -0.041593"/>
    <parent link="base"/>
    <child link="hip_rz_rotor"/>
    <limit effort="150" lower="-10" upper="10" velocity="100"/>
  </joint>
  <link name="hip_rz_rotor">
    <inertial>
      <mass value="0."/>
      <origin xyz="0. 0. 0."/>
      <inertia ixx="1.084e-4" ixy="0.0" ixz="0.0" iyy="1.084e-4" iyz="0.0" izz="1.6841e-4"/>
    </inertial>
  </link>
  <coupling name="hipz_transmission">
    <predecessor link="hip_rz_link"/>
    <successor link="hip_rz_rotor"/>
    <ratio value="6.0"/>
  </coupling>
  <joint name="hipz_to_hipx_link" type="revolute">
    <axis xyz="1 0 0"/>
    <origin rpy="0 0.436332 0" xyz="-0.06435 0.0 -.07499"/>
    <parent link="hip_rz_link"/>
    <child link="hip_rx_link"/>
    <limit effort="150" lower="-10" upper="10" velocity="100"/>
  </joint>
  <link name="hip_rx_link">
    <inertial>
      <mass value="1.20868"/>
      <origin xyz="0.067232 -0.013018 0.0001831"/>
      <inertia ixx="0.0017535" ixy="-6.3e-06" ixz="-0.000080" iyy="0.003338" iyz="-1.3e-05" izz="0.0019927"/>
    </inertial>
  </link>
  <joint independent="false" name="hipz_to_hipx_rotor" type="revolute">
    <axis xyz="1 0 0"/>
    <origin rpy="0 0.436332 0" xyz="-0.0827 0.0 -0.066436"/>
    <parent link="hip_rz_link"/>
    <child link="hip_rx_rotor"/>
    <limit effort="150" lower="-10" upper="10" velocity="100"/>
  </joint>
  <link name="hip_rx_rotor">
    <inertial>
      <mass value="0."/>
      <origin xyz="0. 0. 0."/>
      <inertia ixx="1.6841e-4" ixy="0.0" ixz="0.0" iyy="1.084e-4" iyz="0.0" izz="1.084e-4"/>
    </inertial>
  </link>
  <coupling name="hipx_transmission">
    <predecessor link="hip_rx_link"/>
    <successor link="hip_rx_rotor"/>
    <ratio value="6.0"/>
  </coupling>
  <joint name="hipx_to_hipy_link" type="revolute">
    <axis xyz="0 1 0"/>
    <origin rpy="0 -0.261799 0" xyz="0.071 0.0018375 0.0"/>
    <parent link="hip_rx_link"/>
    <child link="hip_ry_link"/>
    <limit effort="150" lower="-10" upper="10" velocity="100"/>
  </joint>
  <link name="hip_ry_link">
    <inertial>
      <mass value="2.64093"/>
      <origin xyz="0.0132054 0.0269864 -0.096021"/>
      <inertia ixx="0.0243761" ixy="9.96e-05" ixz="0.0006548" iyy="0.0259015" iyz="0.0026713" izz="0.0038929"/>
    </inertial>
  </link>
  <joint independent="false" name="hipx_to_hipy_rotor" type="revolute">
    <axis xyz="0 1 0"/>
    <origin rpy="0 -0.261799 0" xyz="0.071 0.024 0.0"/>
    <parent link="hip_rx_link"/>
    <child link="hip_ry_rotor"/>
    <limit effort="150" lower="-10" upper="10" velocity="100"/>
  </joint>
  <link name="hip_ry_rotor">
    <inertial>
      <mass value="0."/>
      <origin xyz="0. 0. 0."/>
      <inertia ixx="3.443e-4" ixy="0.0" ixz="0.0" iyy="5.548e-4" iyz="0.0" izz="3.443e-4"/>
    </inertial>
  </link>
  <coupling name="hipy_transmission">
    <predecessor link="hip_ry_link"/>
    <successor link="hip_ry_rotor"/>
    <ratio value="6.0"/>
  </coupling>
  <joint name="hipy_to_knee_link" type="revolute">
    <axis xyz="0 1 0"/>
    <origin xyz="0.0 0.0 -0.267"/>
    <parent link="hip_ry_link"/>
    <child link="knee_link"/>
    <limit effort="150" lower="-10" upper="10" velocity="100"/>
  </joint>
  <link name="knee_link">
    <inertial>
      <mass value="0.35435"/>
      <origin xyz="0.00528 0.0014762 -0.13201"/>
      <inertia ixx="0.003051" ixy="0.0" ixz="0.0000873" iyy="0.003033" iyz="3.93e-05" izz="0.0002529"/>
    </inertial>
  </link>
  <joint independent="false" name="hipy_to_knee_rotor" type="revolute">
    <axis xyz="0 1 0"/>
    <origin xyz="0.013 -0.0497 -0.0178"/>
    <parent link="hip_ry_link"/>
    <child link="knee_rotor"/>
    <limit effort="150" lower="-10" upper="10" velocity="100"/>
  </joint>
  <link name="knee_rotor">
    <inertial>
      <mass value="0."/>
      <origin xyz="0. 0. 0."/>
      <inertia ixx="3.443e-4" ixy="0.0" ixz="0.0" iyy="5.548e-4" iyz="0.0" izz="3.443e-4"/>
    </inertial>
  </link>
  <coupling name="knee_transmission">
    <predecessor link="knee_link"/>
    <successor link="knee_rotor"/>
    <ratio value="12.0"/>
  </coupling>
  <joint independent="false" name="hipy_to_ankle_rotor" type="revolute">
    <axis xyz="0 1 0"/>
    <origin xyz=".01563 -0.0454 -.13354"/>
    <parent link="hip_ry_link"/>
    <child link="ankle_rotor"/>
    <limit effort="150" lower="-10" upper="10" velocity="100"/>
  </joint>
  <link name="ankle_rotor">
    <inertial>
      <mass value="0."/>
      <origin xyz="0. 0. 0."/>
      <inertia ixx="1.084e-4" ixy="0.0" ixz="0.0" iyy="1.6841e-4" iyz="0.0" izz="1.084e-4"/>
    </inertial>
  </link>
  <joint name="knee_to_ankle" type="revolute">
    <axis xyz="0 1 0"/>
    <origin xyz="0.0 0.0 -0.2785"/>
    <parent link="knee_link"/>
    <child link="ankle_link"/>
    <limit effort="150" lower="-10" upper="10" velocity="100"/>
  </joint>
  <link name="ankle_link">
    <inertial>
      <mass value="0.280951"/>
      <origin xyz="0.022623 0.0 -0.012826"/>
      <inertia ixx="0.0000842" ixy="0.0" ixz="-0.0000488" iyy="0.0007959" iyz="0.0" izz="0.0007681"/>
    </inertial>
  </link>
  <coupling name="ankle_transmission">
    <predecessor link="ankle_link"/>
    <successor link="ankle_rotor"/>
    <ratio value="12.0"/>
  </coupling>
</robot>
