<?xml version="1.0" ?>
<!-- =================================================================================== -->
<!-- |    This document was autogenerated by xacro from mit_humanoid.xacro             | -->
<!-- |    EDITING THIS FILE BY HAND IS NOT RECOMMENDED                                 | -->
<!-- =================================================================================== -->
<robot name="mit_humanoid">
  <!-- End of macro definitions -->
  <link name="Floating Base">
    <inertial>
      <mass value="8.52"/>
      <origin xyz="0.009896 0.004771 0.100522"/>
      <inertia ixx="0.172699" ixy="0.001419" ixz="0.004023" iyy="0.105949" iyz="-0.001672" izz="0.091906"/>
    </inertial>
  </link>
  <joint name="base_to_right_hipz_link" type="revolute">
    <axis xyz="0 0 1"/>
    <origin rpy="0 -0.174533 0" xyz="-0.00565 -0.082 -0.05735"/>
    <parent link="Floating Base"/>
    <child link="right_hip_rz_link"/>
    <limit effort="150" lower="-10" upper="10" velocity="100"/>
  </joint>
  <link name="right_hip_rz_link">
    <inertial>
      <mass value="0.84563"/>
      <origin xyz="-0.064842 3.6e-05 -0.063090"/>
      <inertia ixx="0.0015373" ixy="-1.1e-06" ixz="0.0005578" iyy="0.0014252" iyz="-2.4e-06" izz="0.0012028"/>
    </inertial>
  </link>
  <joint independent="false" name="right_base_to_hipz_rotor" type="revolute">
    <axis xyz="0 0 1"/>
    <origin rpy="0 -0.174533 0" xyz="-0.00842837 -0.082 -0.041593"/>
    <parent link="Floating Base"/>
    <child link="right_hip_rz_rotor"/>
    <limit effort="150" lower="-10" upper="10" velocity="100"/>
  </joint>
  <link name="right_hip_rz_rotor">
    <inertial>
      <mass value="0.05"/>
      <origin xyz="0. 0. 0."/>
      <inertia ixx="1.084e-4" ixy="0.0" ixz="0.0" iyy="1.084e-4" iyz="0.0" izz="1.6841e-4"/>
    </inertial>
  </link>
  <constraint name="right_hipz_transmission" type="rolling">
    <predecessor link="right_hip_rz_link"/>
    <successor link="right_hip_rz_rotor"/>
    <ratio value="6.0"/>
  </constraint>
  <joint name="base_to_left_hipz_link" type="revolute">
    <axis xyz="0 0 1"/>
    <origin rpy="0 -0.174533 0" xyz="-0.00565 0.082 -0.05735"/>
    <parent link="Floating Base"/>
    <child link="left_hip_rz_link"/>
    <limit effort="150" lower="-10" upper="10" velocity="100"/>
  </joint>
  <link name="left_hip_rz_link">
    <inertial>
      <mass value="0.84563"/>
      <origin xyz="-0.064842 -3.6e-05 -0.063090"/>
      <inertia ixx="0.0015373" ixy="1.1e-06" ixz="0.0005578" iyy="0.0014252" iyz="2.4e-06" izz="0.0012028"/>
    </inertial>
  </link>
  <joint independent="false" name="left_base_to_hipz_rotor" type="revolute">
    <axis xyz="0 0 1"/>
    <origin rpy="0 -0.174533 0" xyz="-0.00842837 0.082 -0.041593"/>
    <parent link="Floating Base"/>
    <child link="left_hip_rz_rotor"/>
    <limit effort="150" lower="-10" upper="10" velocity="100"/>
  </joint>
  <link name="left_hip_rz_rotor">
    <inertial>
      <mass value="0.05"/>
      <origin xyz="0. 0. 0."/>
      <inertia ixx="1.084e-4" ixy="0.0" ixz="0.0" iyy="1.084e-4" iyz="0.0" izz="1.6841e-4"/>
    </inertial>
  </link>
  <constraint name="left_hipz_transmission" type="rolling">
    <predecessor link="left_hip_rz_link"/>
    <successor link="left_hip_rz_rotor"/>
    <ratio value="6.0"/>
  </constraint>
  <joint name="right_hipz_to_hipx_link" type="revolute">
    <axis xyz="1 0 0"/>
    <origin rpy="0 0.436332 0" xyz="-0.06435 0.0 -.07499"/>
    <parent link="right_hip_rz_link"/>
    <child link="right_hip_rx_link"/>
    <limit effort="150" lower="-10" upper="10" velocity="100"/>
  </joint>
  <link name="right_hip_rx_link">
    <inertial>
      <mass value="1.20868"/>
      <origin xyz="0.067232 0.013018 0.0001831"/>
      <inertia ixx="0.0017535" ixy="6.3e-06" ixz="-0.000080" iyy="0.003338" iyz="1.3e-05" izz="0.0019927"/>
    </inertial>
  </link>
  <joint independent="false" name="right_hipz_to_hipx_rotor" type="revolute">
    <axis xyz="1 0 0"/>
    <origin rpy="0 0.436332 0" xyz="-0.0827 0.0 -0.066436"/>
    <parent link="right_hip_rz_link"/>
    <child link="right_hip_rx_rotor"/>
    <limit effort="150" lower="-10" upper="10" velocity="100"/>
  </joint>
  <link name="right_hip_rx_rotor">
    <inertial>
      <mass value="0.05"/>
      <origin xyz="0. 0. 0."/>
      <inertia ixx="1.6841e-4" ixy="0.0" ixz="0.0" iyy="1.084e-4" iyz="0.0" izz="1.084e-4"/>
    </inertial>
  </link>
  <constraint name="right_hipx_transmission" type="rolling">
    <predecessor link="right_hip_rx_link"/>
    <successor link="right_hip_rx_rotor"/>
    <ratio value="6.0"/>
  </constraint>
  <joint name="left_hipz_to_hipx_link" type="revolute">
    <axis xyz="1 0 0"/>
    <origin rpy="0 0.436332 0" xyz="-0.06435 0.0 -.07499"/>
    <parent link="left_hip_rz_link"/>
    <child link="left_hip_rx_link"/>
    <limit effort="150" lower="-10" upper="10" velocity="100"/>
  </joint>
  <link name="left_hip_rx_link">
    <inertial>
      <mass value="1.20868"/>
      <origin xyz="0.067232 -0.013018 0.0001831"/>
      <inertia ixx="0.0017535" ixy="-6.3e-06" ixz="-0.000080" iyy="0.003338" iyz="-1.3e-05" izz="0.0019927"/>
    </inertial>
  </link>
  <joint independent="false" name="left_hipz_to_hipx_rotor" type="revolute">
    <axis xyz="1 0 0"/>
    <origin rpy="0 0.436332 0" xyz="-0.0827 0.0 -0.066436"/>
    <parent link="left_hip_rz_link"/>
    <child link="left_hip_rx_rotor"/>
    <limit effort="150" lower="-10" upper="10" velocity="100"/>
  </joint>
  <link name="left_hip_rx_rotor">
    <inertial>
      <mass value="0.05"/>
      <origin xyz="0. 0. 0."/>
      <inertia ixx="1.6841e-4" ixy="0.0" ixz="0.0" iyy="1.084e-4" iyz="0.0" izz="1.084e-4"/>
    </inertial>
  </link>
  <constraint name="left_hipx_transmission" type="rolling">
    <predecessor link="left_hip_rx_link"/>
    <successor link="left_hip_rx_rotor"/>
    <ratio value="6.0"/>
  </constraint>
  <joint name="right_hipx_to_hipy_link" type="revolute">
    <axis xyz="0 1 0"/>
    <origin rpy="0 -0.261799 0" xyz="0.071 0.0018375 0.0"/>
    <parent link="right_hip_rx_link"/>
    <child link="right_hip_ry_link"/>
    <limit effort="150" lower="-10" upper="10" velocity="100"/>
  </joint>
  <link name="right_hip_ry_link">
    <inertial>
      <mass value="2.64093"/>
      <origin xyz="0.0132054 -0.0269864 -0.096021"/>
      <inertia ixx="0.0243761" ixy="-9.96e-05" ixz="0.0006548" iyy="0.0259015" iyz="-0.0026713" izz="0.0038929"/>
    </inertial>
  </link>
  <joint independent="false" name="right_hipx_to_hipy_rotor" type="revolute">
    <axis xyz="0 1 0"/>
    <origin rpy="0 -0.261799 0" xyz="0.071 0.024 0.0"/>
    <parent link="right_hip_rx_link"/>
    <child link="right_hip_ry_rotor"/>
    <limit effort="150" lower="-10" upper="10" velocity="100"/>
  </joint>
  <link name="right_hip_ry_rotor">
    <inertial>
      <mass value="0.1"/>
      <origin xyz="0. 0. 0."/>
      <inertia ixx="3.443e-4" ixy="0.0" ixz="0.0" iyy="5.548e-4" iyz="0.0" izz="3.443e-4"/>
    </inertial>
  </link>
  <constraint name="right_hipy_transmission" type="rolling">
    <predecessor link="right_hip_ry_link"/>
    <successor link="right_hip_ry_rotor"/>
    <ratio value="6.0"/>
  </constraint>
  <joint name="left_hipx_to_hipy_link" type="revolute">
    <axis xyz="0 1 0"/>
    <origin rpy="0 -0.261799 0" xyz="0.071 -0.0018375 0.0"/>
    <parent link="left_hip_rx_link"/>
    <child link="left_hip_ry_link"/>
    <limit effort="150" lower="-10" upper="10" velocity="100"/>
  </joint>
  <link name="left_hip_ry_link">
    <inertial>
      <mass value="2.64093"/>
      <origin xyz="0.0132054 0.0269864 -0.096021"/>
      <inertia ixx="0.0243761" ixy="9.96e-05" ixz="0.0006548" iyy="0.0259015" iyz="0.0026713" izz="0.0038929"/>
    </inertial>
  </link>
  <joint independent="false" name="left_hipx_to_hipy_rotor" type="revolute">
    <axis xyz="0 1 0"/>
    <origin rpy="0 -0.261799 0" xyz="0.071 -0.024 0.0"/>
    <parent link="left_hip_rx_link"/>
    <child link="left_hip_ry_rotor"/>
    <limit effort="150" lower="-10" upper="10" velocity="100"/>
  </joint>
  <link name="left_hip_ry_rotor">
    <inertial>
      <mass value="0.1"/>
      <origin xyz="0. 0. 0."/>
      <inertia ixx="3.443e-4" ixy="0.0" ixz="0.0" iyy="5.548e-4" iyz="0.0" izz="3.443e-4"/>
    </inertial>
  </link>
  <constraint name="left_hipy_transmission" type="rolling">
    <predecessor link="left_hip_ry_link"/>
    <successor link="left_hip_ry_rotor"/>
    <ratio value="6.0"/>
  </constraint>
  <joint name="right_hipy_to_knee_link" type="revolute">
    <axis xyz="0 1 0"/>
    <origin xyz="0.0 0.0 -0.267"/>
    <parent link="right_hip_ry_link"/>
    <child link="right_knee_link"/>
    <limit effort="150" lower="-10" upper="10" velocity="100"/>
  </joint>
  <link name="right_knee_link">
    <inertial>
      <mass value="0.35435"/>
      <origin xyz="0.00528 -0.0014762 -0.13201"/>
      <inertia ixx="0.003051" ixy="0.0" ixz="0.0000873" iyy="0.003033" iyz="-3.93e-05" izz="0.0002529"/>
    </inertial>
  </link>
  <joint independent="false" name="right_hipy_to_knee_rotor" type="revolute">
    <axis xyz="0 1 0"/>
    <origin xyz="0.013 -0.0497 -0.0178"/>
    <parent link="right_hip_ry_link"/>
    <child link="right_knee_rotor"/>
    <limit effort="150" lower="-10" upper="10" velocity="100"/>
  </joint>
  <link name="right_knee_rotor">
    <inertial>
      <mass value="0.1"/>
      <origin xyz="0. 0. 0."/>
      <inertia ixx="3.443e-4" ixy="0.0" ixz="0.0" iyy="5.548e-4" iyz="0.0" izz="3.443e-4"/>
    </inertial>
  </link>
  <constraint name="right_knee_transmission" type="rolling">
    <predecessor link="right_knee_link"/>
    <successor link="right_knee_rotor"/>
    <ratio value="12.0"/>
  </constraint>
  <joint name="left_hipy_to_knee_link" type="revolute">
    <axis xyz="0 1 0"/>
    <origin xyz="0.0 0.0 -0.267"/>
    <parent link="left_hip_ry_link"/>
    <child link="left_knee_link"/>
    <limit effort="150" lower="-10" upper="10" velocity="100"/>
  </joint>
  <link name="left_knee_link">
    <inertial>
      <mass value="0.35435"/>
      <origin xyz="0.00528 0.0014762 -0.13201"/>
      <inertia ixx="0.003051" ixy="0.0" ixz="0.0000873" iyy="0.003033" iyz="3.93e-05" izz="0.0002529"/>
    </inertial>
  </link>
  <joint independent="false" name="left_hipy_to_knee_rotor" type="revolute">
    <axis xyz="0 1 0"/>
    <origin xyz="0.013 0.0497 -0.0178"/>
    <parent link="left_hip_ry_link"/>
    <child link="left_knee_rotor"/>
    <limit effort="150" lower="-10" upper="10" velocity="100"/>
  </joint>
  <link name="left_knee_rotor">
    <inertial>
      <mass value="0.1"/>
      <origin xyz="0. 0. 0."/>
      <inertia ixx="3.443e-4" ixy="0.0" ixz="0.0" iyy="5.548e-4" iyz="0.0" izz="3.443e-4"/>
    </inertial>
  </link>
  <constraint name="left_knee_transmission" type="rolling">
    <predecessor link="left_knee_link"/>
    <successor link="left_knee_rotor"/>
    <ratio value="12.0"/>
  </constraint>
  <joint independent="false" name="right_hipy_to_ankle_rotor" type="revolute">
    <axis xyz="0 1 0"/>
    <origin xyz=".01563 -0.0454 -.13354"/>
    <parent link="right_hip_ry_link"/>
    <child link="right_ankle_rotor"/>
    <limit effort="150" lower="-10" upper="10" velocity="100"/>
  </joint>
  <link name="right_ankle_rotor">
    <inertial>
      <mass value="0.05"/>
      <origin xyz="0. 0. 0."/>
      <inertia ixx="1.084e-4" ixy="0.0" ixz="0.0" iyy="1.6841e-4" iyz="0.0" izz="1.084e-4"/>
    </inertial>
  </link>
  <joint name="right_knee_to_ankle" type="revolute">
    <axis xyz="0 1 0"/>
    <origin xyz="0.0 0.0 -0.2785"/>
    <parent link="right_knee_link"/>
    <child link="right_ankle_link"/>
    <limit effort="150" lower="-10" upper="10" velocity="100"/>
  </joint>
  <link name="right_ankle_link">
    <inertial>
      <mass value="0.280951"/>
      <origin xyz="0.022623 0.0 -0.012826"/>
      <inertia ixx="0.0000842" ixy="0.0" ixz="-0.0000488" iyy="0.0007959" iyz="0.0" izz="0.0007681"/>
    </inertial>
  </link>
  <constraint name="right_ankle_transmission" type="rolling">
    <predecessor link="right_ankle_link"/>
    <successor link="right_ankle_rotor"/>
    <ratio value="12.0"/>
  </constraint>
  <joint independent="false" name="left_hipy_to_ankle_rotor" type="revolute">
    <axis xyz="0 1 0"/>
    <origin xyz=".01563 0.0454 -.13354"/>
    <parent link="left_hip_ry_link"/>
    <child link="left_ankle_rotor"/>
    <limit effort="150" lower="-10" upper="10" velocity="100"/>
  </joint>
  <link name="left_ankle_rotor">
    <inertial>
      <mass value="0.05"/>
      <origin xyz="0. 0. 0."/>
      <inertia ixx="1.084e-4" ixy="0.0" ixz="0.0" iyy="1.6841e-4" iyz="0.0" izz="1.084e-4"/>
    </inertial>
  </link>
  <joint name="left_knee_to_ankle" type="revolute">
    <axis xyz="0 1 0"/>
    <origin xyz="0.0 0.0 -0.2785"/>
    <parent link="left_knee_link"/>
    <child link="left_ankle_link"/>
    <limit effort="150" lower="-10" upper="10" velocity="100"/>
  </joint>
  <link name="left_ankle_link">
    <inertial>
      <mass value="0.280951"/>
      <origin xyz="0.022623 0.0 -0.012826"/>
      <inertia ixx="0.0000842" ixy="0.0" ixz="-0.0000488" iyy="0.0007959" iyz="0.0" izz="0.0007681"/>
    </inertial>
  </link>
  <constraint name="left_ankle_transmission" type="rolling">
    <predecessor link="left_ankle_link"/>
    <successor link="left_ankle_rotor"/>
    <ratio value="12.0"/>
  </constraint>
  <joint name="base_to_right_shouldery_link" type="revolute">
    <axis xyz="0 1 0"/>
    <origin xyz="0.01346 -0.17608 0.24657"/>
    <parent link="Floating Base"/>
    <child link="right_shoulder_ry_link"/>
    <limit effort="150" lower="-10" upper="10" velocity="100"/>
  </joint>
  <link name="right_shoulder_ry_link">
    <inertial>
      <mass value="0.788506"/>
      <origin xyz="0.009265 -0.052623 -0.0001249"/>
      <inertia ixx="0.0013678" ixy="-2.66e-05" ixz="0.0000021" iyy="0.0007392" iyz="1.2e-06" izz="0.000884"/>
    </inertial>
  </link>
  <joint independent="false" name="base_to_right_shouldery_rotor" type="revolute">
    <axis xyz="0 1 0"/>
    <origin xyz="0.01346 -0.16 0.24657"/>
    <parent link="Floating Base"/>
    <child link="right_shoulder_ry_rotor"/>
    <limit effort="150" lower="-10" upper="10" velocity="100"/>
  </joint>
  <link name="right_shoulder_ry_rotor">
    <inertial>
      <mass value="0.05"/>
      <origin xyz="0. 0. 0."/>
      <inertia ixx="1.084e-4" ixy="0.0" ixz="0.0" iyy="1.6841e-4" iyz="0.0" izz="1.084e-4"/>
    </inertial>
  </link>
  <constraint name="right_shouldery_transmission" type="rolling">
    <predecessor link="right_shoulder_ry_link"/>
    <successor link="right_shoulder_ry_rotor"/>
    <ratio value="6.0"/>
  </constraint>
  <joint name="base_to_left_shouldery_link" type="revolute">
    <axis xyz="0 1 0"/>
    <origin xyz="0.01346 0.17608 0.24657"/>
    <parent link="Floating Base"/>
    <child link="left_shoulder_ry_link"/>
    <limit effort="150" lower="-10" upper="10" velocity="100"/>
  </joint>
  <link name="left_shoulder_ry_link">
    <inertial>
      <mass value="0.788506"/>
      <origin xyz="0.009265 0.052623 -0.0001249"/>
      <inertia ixx="0.0013678" ixy="2.66e-05" ixz="0.0000021" iyy="0.0007392" iyz="-1.2e-06" izz="0.000884"/>
    </inertial>
  </link>
  <joint independent="false" name="base_to_left_shouldery_rotor" type="revolute">
    <axis xyz="0 1 0"/>
    <origin xyz="0.01346 0.16 0.24657"/>
    <parent link="Floating Base"/>
    <child link="left_shoulder_ry_rotor"/>
    <limit effort="150" lower="-10" upper="10" velocity="100"/>
  </joint>
  <link name="left_shoulder_ry_rotor">
    <inertial>
      <mass value="0.05"/>
      <origin xyz="0. 0. 0."/>
      <inertia ixx="1.084e-4" ixy="0.0" ixz="0.0" iyy="1.6841e-4" iyz="0.0" izz="1.084e-4"/>
    </inertial>
  </link>
  <constraint name="left_shouldery_transmission" type="rolling">
    <predecessor link="left_shoulder_ry_link"/>
    <successor link="left_shoulder_ry_rotor"/>
    <ratio value="6.0"/>
  </constraint>
  <joint name="right_shouldery_shoulderx_link" type="revolute">
    <axis xyz="1 0 0"/>
    <origin xyz="0. -0.0575 0."/>
    <parent link="right_shoulder_ry_link"/>
    <child link="right_shoulder_rx_link"/>
    <limit effort="150" lower="-10" upper="10" velocity="100"/>
  </joint>
  <link name="right_shoulder_rx_link">
    <inertial>
      <mass value="0.80125"/>
      <origin xyz="0.0006041 -0.0001221 -0.082361"/>
      <inertia ixx="0.0011524" ixy="-7e-07" ixz="0.0000396" iyy="0.0011921" iyz="-1.4e-06" izz="0.0012386"/>
    </inertial>
  </link>
  <joint independent="false" name="right_shouldery_to_shoulderx_rotor" type="revolute">
    <axis xyz="1 0 0"/>
    <origin xyz="0. -0.0575 0."/>
    <parent link="right_shoulder_ry_link"/>
    <child link="right_shoulder_rx_rotor"/>
    <limit effort="150" lower="-10" upper="10" velocity="100"/>
  </joint>
  <link name="right_shoulder_rx_rotor">
    <inertial>
      <mass value="0.05"/>
      <origin xyz="0. 0. 0."/>
      <inertia ixx="1.6841e-4" ixy="0.0" ixz="0.0" iyy="1.084e-4" iyz="0.0" izz="1.084e-4"/>
    </inertial>
  </link>
  <constraint name="right_shoulderx_transmission" type="rolling">
    <predecessor link="right_shoulder_rx_link"/>
    <successor link="right_shoulder_rx_rotor"/>
    <ratio value="6.0"/>
  </constraint>
  <joint name="left_shouldery_shoulderx_link" type="revolute">
    <axis xyz="1 0 0"/>
    <origin xyz="0. 0.0575 0."/>
    <parent link="left_shoulder_ry_link"/>
    <child link="left_shoulder_rx_link"/>
    <limit effort="150" lower="-10" upper="10" velocity="100"/>
  </joint>
  <link name="left_shoulder_rx_link">
    <inertial>
      <mass value="0.80125"/>
      <origin xyz="0.0006041 0.0001221 -0.082361"/>
      <inertia ixx="0.0011524" ixy="7e-07" ixz="0.0000396" iyy="0.0011921" iyz="1.4e-06" izz="0.0012386"/>
    </inertial>
  </link>
  <joint independent="false" name="left_shouldery_to_shoulderx_rotor" type="revolute">
    <axis xyz="1 0 0"/>
    <origin xyz="0. 0.0575 0."/>
    <parent link="left_shoulder_ry_link"/>
    <child link="left_shoulder_rx_rotor"/>
    <limit effort="150" lower="-10" upper="10" velocity="100"/>
  </joint>
  <link name="left_shoulder_rx_rotor">
    <inertial>
      <mass value="0.05"/>
      <origin xyz="0. 0. 0."/>
      <inertia ixx="1.6841e-4" ixy="0.0" ixz="0.0" iyy="1.084e-4" iyz="0.0" izz="1.084e-4"/>
    </inertial>
  </link>
  <constraint name="left_shoulderx_transmission" type="rolling">
    <predecessor link="left_shoulder_rx_link"/>
    <successor link="left_shoulder_rx_rotor"/>
    <ratio value="6.0"/>
  </constraint>
  <joint name="right_shoulderx_shoulderz_link" type="revolute">
    <axis xyz="0 0 1"/>
    <origin xyz="0. 0.0 -0.10250"/>
    <parent link="right_shoulder_rx_link"/>
    <child link="right_shoulder_rz_link"/>
    <limit effort="150" lower="-10" upper="10" velocity="100"/>
  </joint>
  <link name="right_shoulder_rz_link">
    <inertial>
      <mass value="0.905588"/>
      <origin xyz="0.0001703 0.016797 -0.060"/>
      <inertia ixx="0.0012713" ixy="-1e-06" ixz="-0.000008" iyy="0.0017477" iyz="2.25e-05" izz="0.0008191"/>
    </inertial>
  </link>
  <joint independent="false" name="right_shoulderx_to_shoulderz_rotor" type="revolute">
    <axis xyz="0 0 1"/>
    <origin xyz="0. 0.0 -0.10250"/>
    <parent link="right_shoulder_rx_link"/>
    <child link="right_shoulder_rz_rotor"/>
    <limit effort="150" lower="-10" upper="10" velocity="100"/>
  </joint>
  <link name="right_shoulder_rz_rotor">
    <inertial>
      <mass value="0.05"/>
      <origin xyz="0. 0. 0."/>
      <inertia ixx="1.084e-4" ixy="0.0" ixz="0.0" iyy="1.084e-4" iyz="0.0" izz="1.6841e-4"/>
    </inertial>
  </link>
  <constraint name="right_shoulderz_transmission" type="rolling">
    <predecessor link="right_shoulder_rz_link"/>
    <successor link="right_shoulder_rz_rotor"/>
    <ratio value="6.0"/>
  </constraint>
  <joint name="left_shoulderx_shoulderz_link" type="revolute">
    <axis xyz="0 0 1"/>
    <origin xyz="0. -0.0 -0.10250"/>
    <parent link="left_shoulder_rx_link"/>
    <child link="left_shoulder_rz_link"/>
    <limit effort="150" lower="-10" upper="10" velocity="100"/>
  </joint>
  <link name="left_shoulder_rz_link">
    <inertial>
      <mass value="0.905588"/>
      <origin xyz="0.0001703 -0.016797 -0.060"/>
      <inertia ixx="0.0012713" ixy="1e-06" ixz="-0.000008" iyy="0.0017477" iyz="-2.25e-05" izz="0.0008191"/>
    </inertial>
  </link>
  <joint independent="false" name="left_shoulderx_to_shoulderz_rotor" type="revolute">
    <axis xyz="0 0 1"/>
    <origin xyz="0. -0.0 -0.10250"/>
    <parent link="left_shoulder_rx_link"/>
    <child link="left_shoulder_rz_rotor"/>
    <limit effort="150" lower="-10" upper="10" velocity="100"/>
  </joint>
  <link name="left_shoulder_rz_rotor">
    <inertial>
      <mass value="0.05"/>
      <origin xyz="0. 0. 0."/>
      <inertia ixx="1.084e-4" ixy="0.0" ixz="0.0" iyy="1.084e-4" iyz="0.0" izz="1.6841e-4"/>
    </inertial>
  </link>
  <constraint name="left_shoulderz_transmission" type="rolling">
    <predecessor link="left_shoulder_rz_link"/>
    <successor link="left_shoulder_rz_rotor"/>
    <ratio value="6.0"/>
  </constraint>
  <joint name="right_shoulderz_elbow_link" type="revolute">
    <axis xyz="0 1 0"/>
    <origin xyz="0. 0.0 -0.1455"/>
    <parent link="right_shoulder_rz_link"/>
    <child link="right_elbow_link"/>
    <limit effort="150" lower="-10" upper="10" velocity="100"/>
  </joint>
  <link name="right_elbow_link">
    <inertial>
      <mass value="0.34839"/>
      <origin xyz="-0.0059578 -0.000111 -0.0426735"/>
      <inertia ixx="0.001570" ixy="-2e-07" ixz="0.0000335" iyy="0.0016167" iyz="-3e-06" izz="0.0000619"/>
    </inertial>
  </link>
  <joint independent="false" name="right_shoulderz_to_elbow_rotor" type="revolute">
    <axis xyz="0 1 0"/>
    <origin xyz="0. 0.0325 -0.06"/>
    <parent link="right_shoulder_rz_link"/>
    <child link="right_elbow_rotor"/>
    <limit effort="150" lower="-10" upper="10" velocity="100"/>
  </joint>
  <link name="right_elbow_rotor">
    <inertial>
      <mass value="0.05"/>
      <origin xyz="0. 0. 0."/>
      <inertia ixx="1.084e-4" ixy="0.0" ixz="0.0" iyy="1.6841e-4" iyz="0.0" izz="1.084e-4"/>
    </inertial>
  </link>
  <constraint name="right_elbow_transmission" type="rolling">
    <predecessor link="right_elbow_link"/>
    <successor link="right_elbow_rotor"/>
    <ratio value="9.0"/>
  </constraint>
  <joint name="left_shoulderz_elbow_link" type="revolute">
    <axis xyz="0 1 0"/>
    <origin xyz="0. -0.0 -0.1455"/>
    <parent link="left_shoulder_rz_link"/>
    <child link="left_elbow_link"/>
    <limit effort="150" lower="-10" upper="10" velocity="100"/>
  </joint>
  <link name="left_elbow_link">
    <inertial>
      <mass value="0.34839"/>
      <origin xyz="-0.0059578 0.000111 -0.0426735"/>
      <inertia ixx="0.001570" ixy="2e-07" ixz="0.0000335" iyy="0.0016167" iyz="3e-06" izz="0.0000619"/>
    </inertial>
  </link>
  <joint independent="false" name="left_shoulderz_to_elbow_rotor" type="revolute">
    <axis xyz="0 1 0"/>
    <origin xyz="0. -0.0325 -0.06"/>
    <parent link="left_shoulder_rz_link"/>
    <child link="left_elbow_rotor"/>
    <limit effort="150" lower="-10" upper="10" velocity="100"/>
  </joint>
  <link name="left_elbow_rotor">
    <inertial>
      <mass value="0.05"/>
      <origin xyz="0. 0. 0."/>
      <inertia ixx="1.084e-4" ixy="0.0" ixz="0.0" iyy="1.6841e-4" iyz="0.0" izz="1.084e-4"/>
    </inertial>
  </link>
  <constraint name="left_elbow_transmission" type="rolling">
    <predecessor link="left_elbow_link"/>
    <successor link="left_elbow_rotor"/>
    <ratio value="9.0"/>
  </constraint>
</robot>

