<?xml version="1.0" ?>
<!-- =================================================================================== -->
<!-- |    This document was autogenerated by xacro from parallel_chains.xacro          | -->
<!-- |    EDITING THIS FILE BY HAND IS NOT RECOMMENDED                                 | -->
<!-- =================================================================================== -->
<robot name="parallel_chain" xmlns:xacro="http://ros.org/wiki/xacro">
  <!-- <xacro:include filename="revolute_rotor_properties.xacro"/> -->
  <link name="base"/>
  <link name="link_1_1">
    <inertial>
      <mass value="0.25"/>
      <origin rpy="0 0 0" xyz="0 0.5 0"/>
      <inertia ixx="0.01" ixy="0" ixz="0" iyy="0.1" iyz="0" izz="0.01"/>
    </inertial>
  </link>
  <joint name="joint_1_1" type="revolute">
    <parent link="base"/>
    <child link="link_1_1"/>
    <origin xyz="0 0 0"/>
    <axis xyz="0 0 1"/>
    <limit effort="30" lower="-10" upper="10" velocity="1.0"/>
  </joint>
  <link name="link_2_1">
    <inertial>
      <mass value="0.25"/>
      <origin rpy="0 0 0" xyz="0 0.5 0"/>
      <inertia ixx="0.01" ixy="0" ixz="0" iyy="0.1" iyz="0" izz="0.01"/>
    </inertial>
  </link>
  <joint name="joint_2_1" type="revolute">
    <parent link="base"/>
    <child link="link_2_1"/>
    <origin xyz="0.25 0 0"/>
    <axis xyz="0 0 1"/>
    <limit effort="30" lower="-10" upper="10" velocity="1.0"/>
  </joint>
  <link name="link_1_2">
    <inertial>
      <mass value="0.25"/>
      <origin rpy="0 0 0" xyz="0 0.5 0"/>
      <inertia ixx="0.01" ixy="0" ixz="0" iyy="0.1" iyz="0" izz="0.01"/>
    </inertial>
  </link>
  <link name="link_2_2">
    <inertial>
      <mass value="0.25"/>
      <origin rpy="0 0 0" xyz="0 0.5 0"/>
      <inertia ixx="0.01" ixy="0" ixz="0" iyy="0.1" iyz="0" izz="0.01"/>
    </inertial>
  </link>
  <link name="link_1_3">
    <inertial>
      <mass value="0.25"/>
      <origin rpy="0 0 0" xyz="0 0.5 0"/>
      <inertia ixx="0.01" ixy="0" ixz="0" iyy="0.1" iyz="0" izz="0.01"/>
    </inertial>
  </link>
  <link name="link_2_3">
    <inertial>
      <mass value="0.25"/>
      <origin rpy="0 0 0" xyz="0 0.5 0"/>
      <inertia ixx="0.01" ixy="0" ixz="0" iyy="0.1" iyz="0" izz="0.01"/>
    </inertial>
  </link>
  <link name="link_1_4">
    <inertial>
      <mass value="0.25"/>
      <origin rpy="0 0 0" xyz="0 0.5 0"/>
      <inertia ixx="0.01" ixy="0" ixz="0" iyy="0.1" iyz="0" izz="0.01"/>
    </inertial>
  </link>
  <link name="link_2_4">
    <inertial>
      <mass value="0.25"/>
      <origin rpy="0 0 0" xyz="0 0.5 0"/>
      <inertia ixx="0.01" ixy="0" ixz="0" iyy="0.1" iyz="0" izz="0.01"/>
    </inertial>
  </link>
  <link name="link_1_5">
    <inertial>
      <mass value="0.25"/>
      <origin rpy="0 0 0" xyz="0 0.5 0"/>
      <inertia ixx="0.01" ixy="0" ixz="0" iyy="0.1" iyz="0" izz="0.01"/>
    </inertial>
  </link>
  <link name="link_2_5">
    <inertial>
      <mass value="0.25"/>
      <origin rpy="0 0 0" xyz="0 0.5 0"/>
      <inertia ixx="0.01" ixy="0" ixz="0" iyy="0.1" iyz="0" izz="0.01"/>
    </inertial>
  </link>
  <constraint name="rolling_1" type="rolling">
    <predecessor link="link_1_1"/>
    <successor link="link_2_1"/>
    <ratio value="1"/>
  </constraint>
</robot>

