<?xml version="1.0" ?>
<!-- =================================================================================== -->
<!-- |    This document was autogenerated by xacro from tello_humanoid_approximate.xacro | -->
<!-- |    EDITING THIS FILE BY HAND IS NOT RECOMMENDED                                 | -->
<!-- =================================================================================== -->
<robot name="tello_humanoid_approximate">
  <!-- Torso -->
  <link name="base">
    <inertial>
      <mass value="2.3008"/>
      <origin xyz="0.0073 -0.0013 -0.0023"/>
      <inertia ixx="0.0366" ixy="0." ixz="-0.0006" iyy="0.0142" iyz="-0.0002" izz="0.0291"/>
    </inertial>
  </link>
  <!-- Left Hip Clamp -->
  <joint independent="true" name="base-to-left-hip-clamp" type="revolute">
    <axis xyz="0 0 1"/>
    <origin rpy="0.0 0.0 0.0" xyz="0.0 126e-03 -87e-03"/>
    <parent link="base"/>
    <child link="left-hip-clamp"/>
    <limit effort="150" lower="-10" upper="10" velocity="100"/>
  </joint>
  <link name="left-hip-clamp">
    <inertial>
      <mass value="1.3289"/>
      <origin xyz="-0.001 0.0 -0.0069"/>
      <inertia ixx="0.0032" ixy="0." ixz="0.0001" iyy="0.0033" iyz="0." izz="0.0027"/>
    </inertial>
  </link>
  <!-- Left Gimbal, Thigh -->
  <joint independent="true" name="left-hip-clamp-to-gimbal" type="revolute">
    <axis xyz="1 0 0"/>
    <origin rpy="0.0 0.0 0.0" xyz="0.0 0.0 -142.5e-03"/>
    <parent link="left-hip-clamp"/>
    <child link="left-gimbal"/>
    <limit effort="150" lower="-10" upper="10" velocity="100"/>
  </joint>
  <link name="left-gimbal">
    <inertial>
      <mass value="0.4433"/>
      <origin xyz="-0.0027 0.0 0.0258"/>
      <inertia ixx="0.0018" ixy="0.0" ixz="0.0" iyy="0.0017" iyz="0.0" izz="0.0015"/>
    </inertial>
  </link>
  <joint independent="true" name="left-gimbal-to-thigh" type="revolute">
    <axis xyz="0 1 0"/>
    <origin rpy="0.0 0.0 0.0" xyz="0.0 0.0 0.0"/>
    <parent link="left-gimbal"/>
    <child link="left-thigh"/>
    <limit effort="150" lower="-10" upper="10" velocity="100"/>
  </joint>
  <link name="left-thigh">
    <inertial>
      <mass value="1.5424"/>
      <origin xyz="0.003 -0.0001 -0.0323"/>
      <inertia ixx="0.0103" ixy="0.0" ixz="-0.0005" iyy="0.0097" iyz="0.0" izz="0.0027"/>
    </inertial>
  </link>
  <!-- Left Shin, Foot -->
  <joint independent="true" name="left-thigh-to-shin" type="revolute">
    <axis xyz="0 1 0"/>
    <origin rpy="0.0 0.0 0.0" xyz="0.0 0.0 -226.8e-03"/>
    <parent link="left-thigh"/>
    <child link="left-shin"/>
    <limit effort="150" lower="-10" upper="10" velocity="100"/>
  </joint>
  <link name="left-shin">
    <inertial>
      <mass value="0.3072"/>
      <origin xyz="0.0047 -0.0003 -0.1043"/>
      <inertia ixx="0.0054" ixy="0.0" ixz="-0.0002" iyy="0.0054" iyz="0.0" izz="0.0001"/>
    </inertial>
  </link>
  <joint independent="true" name="left-shin-to-foot" type="revolute">
    <axis xyz="0 1 0"/>
    <origin rpy="0.0 0.0 0.0" xyz="0.0 0.0 -260e-03"/>
    <parent link="left-shin"/>
    <child link="left-foot"/>
    <limit effort="150" lower="-10" upper="10" velocity="100"/>
  </joint>
  <link name="left-foot">
    <inertial>
      <mass value="0.1025"/>
      <origin xyz="0.0042 0.0 -0.0251"/>
      <inertia ixx="0.094e-03" ixy="0.0" ixz="-0.0038e-03" iyy="0.1773e-03" iyz="0.0" izz="0.0901e-03"/>
    </inertial>
  </link>
  <!-- Right Hip Clamp -->
  <joint independent="true" name="base-to-right-hip-clamp" type="revolute">
    <axis xyz="0 0 1"/>
    <origin rpy="0.0 0.0 0.0" xyz="0.0 -126e-03 -87e-03"/>
    <parent link="base"/>
    <child link="right-hip-clamp"/>
    <limit effort="150" lower="-10" upper="10" velocity="100"/>
  </joint>
  <link name="right-hip-clamp">
    <inertial>
      <mass value="1.3289"/>
      <origin xyz="-0.001 0.0 -0.0069"/>
      <inertia ixx="0.0032" ixy="0." ixz="0.0001" iyy="0.0033" iyz="0." izz="0.0027"/>
    </inertial>
  </link>
  <!-- Right Gimbal, Thigh -->
  <joint independent="true" name="right-hip-clamp-to-gimbal" type="revolute">
    <axis xyz="1 0 0"/>
    <origin rpy="0.0 0.0 0.0" xyz="0.0 0.0 -142.5e-03"/>
    <parent link="right-hip-clamp"/>
    <child link="right-gimbal"/>
    <limit effort="150" lower="-10" upper="10" velocity="100"/>
  </joint>
  <link name="right-gimbal">
    <inertial>
      <mass value="0.4433"/>
      <origin xyz="-0.0027 0.0 0.0258"/>
      <inertia ixx="0.0018" ixy="0.0" ixz="0.0" iyy="0.0017" iyz="0.0" izz="0.0015"/>
    </inertial>
  </link>
  <joint independent="true" name="right-gimbal-to-thigh" type="revolute">
    <axis xyz="0 1 0"/>
    <origin rpy="0.0 0.0 0.0" xyz="0.0 0.0 0.0"/>
    <parent link="right-gimbal"/>
    <child link="right-thigh"/>
    <limit effort="150" lower="-10" upper="10" velocity="100"/>
  </joint>
  <link name="right-thigh">
    <inertial>
      <mass value="1.5424"/>
      <origin xyz="0.003 -0.0001 -0.0323"/>
      <inertia ixx="0.0103" ixy="0.0" ixz="-0.0005" iyy="0.0097" iyz="0.0" izz="0.0027"/>
    </inertial>
  </link>
  <!-- Right Shin, Foot -->
  <joint independent="true" name="right-thigh-to-shin" type="revolute">
    <axis xyz="0 1 0"/>
    <origin rpy="0.0 0.0 0.0" xyz="0.0 0.0 -226.8e-03"/>
    <parent link="right-thigh"/>
    <child link="right-shin"/>
    <limit effort="150" lower="-10" upper="10" velocity="100"/>
  </joint>
  <link name="right-shin">
    <inertial>
      <mass value="0.3072"/>
      <origin xyz="0.0047 -0.0003 -0.1043"/>
      <inertia ixx="0.0054" ixy="0.0" ixz="-0.0002" iyy="0.0054" iyz="0.0" izz="0.0001"/>
    </inertial>
  </link>
  <joint independent="true" name="right-shin-to-foot" type="revolute">
    <axis xyz="0 1 0"/>
    <origin rpy="0.0 0.0 0.0" xyz="0.0 0.0 -260e-03"/>
    <parent link="right-shin"/>
    <child link="right-foot"/>
    <limit effort="150" lower="-10" upper="10" velocity="100"/>
  </joint>
  <link name="right-foot">
    <inertial>
      <mass value="0.1025"/>
      <origin xyz="0.0042 0.0 -0.0251"/>
      <inertia ixx="0.094e-03" ixy="0.0" ixz="-0.0038e-03" iyy="0.1773e-03" iyz="0.0" izz="0.0901e-03"/>
    </inertial>
  </link>
  <!-- Left Shoulder RY -->
  <joint independent="true" name="base-to-left-shoulder-ry" type="revolute">
    <axis xyz="0 1 0"/>
    <origin rpy="0.0 0.0 0.0" xyz="0.01346 0.17608 0.24657"/>
    <parent link="base"/>
    <child link="left-shoulder-ry"/>
    <limit effort="150" lower="-10" upper="10" velocity="100"/>
  </joint>
  <link name="left-shoulder-ry">
    <inertial>
      <mass value="0.788506"/>
      <origin xyz="0.009265 0.052623 -0.0001249"/>
      <inertia ixx="0.0013678" ixy="0.0000266" ixz="0.0000021" iyy="0.0007392" iyz="-0.0000012" izz="0.000884"/>
    </inertial>
  </link>
  <!-- Left Shoulder RX -->
  <joint independent="true" name="left-shoulder-ry-to-shoulder-rx" type="revolute">
    <axis xyz="1 0 0"/>
    <origin rpy="0.0 0.0 0.0" xyz="0.0 0.0575 0.0"/>
    <parent link="left-shoulder-ry"/>
    <child link="left-shoulder-rx"/>
    <limit effort="150" lower="-10" upper="10" velocity="100"/>
  </joint>
  <link name="left-shoulder-rx">
    <inertial>
      <mass value="0.80125"/>
      <origin xyz="0.0006041 0.0001221 -0.082361"/>
      <inertia ixx="0.0011524" ixy="0.0000007" ixz="0.0000396" iyy="0.0011921" iyz="0.0000014" izz="0.0012386"/>
    </inertial>
  </link>
  <!-- Left Shoulder RZ -->
  <joint independent="true" name="left-shoulder-rx-to-shoulder-rz" type="revolute">
    <axis xyz="0 0 1"/>
    <origin rpy="0.0 0.0 0.0" xyz="0.0 0.0 -0.1025"/>
    <parent link="left-shoulder-rx"/>
    <child link="left-shoulder-rz"/>
    <limit effort="150" lower="-10" upper="10" velocity="100"/>
  </joint>
  <link name="left-shoulder-rz">
    <inertial>
      <mass value="0.905588"/>
      <origin xyz="0.0001703 -0.016797 -0.060"/>
      <inertia ixx="0.0012713" ixy="0.000001" ixz="-0.000008" iyy="0.0017477" iyz="-0.0000225" izz="0.0008191"/>
    </inertial>
  </link>
  <!-- Left Elbow -->
  <joint independent="true" name="left-shoulder-rz-to-elbow" type="revolute">
    <axis xyz="0 1 0"/>
    <origin rpy="0.0 0.0 0.0" xyz="0.0 0.0 -0.1455"/>
    <parent link="left-shoulder-rz"/>
    <child link="left-elbow"/>
    <limit effort="150" lower="-10" upper="10" velocity="100"/>
  </joint>
  <link name="left-elbow">
    <inertial>
      <mass value="0.34839"/>
      <origin xyz="-0.0059578 0.000111 -0.0426735"/>
      <inertia ixx="0.001570" ixy="0.0000002" ixz="0.0000335" iyy="0.0016167" iyz="0.000003" izz="0.0000619"/>
    </inertial>
  </link>
  <!-- Right Shoulder RY -->
  <joint independent="true" name="base-to-right-shoulder-ry" type="revolute">
    <axis xyz="0 1 0"/>
    <origin rpy="0.0 0.0 0.0" xyz="0.01346 -0.17608 0.24657"/>
    <parent link="base"/>
    <child link="right-shoulder-ry"/>
    <limit effort="150" lower="-10" upper="10" velocity="100"/>
  </joint>
  <link name="right-shoulder-ry">
    <inertial>
      <mass value="0.788506"/>
      <origin xyz="0.009265 -0.052623 -0.0001249"/>
      <inertia ixx="0.0013678" ixy="-0.0000266" ixz="0.0000021" iyy="0.0007392" iyz="0.0000012" izz="0.000884"/>
    </inertial>
  </link>
  <!-- Right Shoulder RX -->
  <joint independent="true" name="right-shoulder-ry-to-shoulder-rx" type="revolute">
    <axis xyz="1 0 0"/>
    <origin rpy="0.0 0.0 0.0" xyz="0.0 -0.0575 0.0"/>
    <parent link="right-shoulder-ry"/>
    <child link="right-shoulder-rx"/>
    <limit effort="150" lower="-10" upper="10" velocity="100"/>
  </joint>
  <link name="right-shoulder-rx">
    <inertial>
      <mass value="0.80125"/>
      <origin xyz="0.0006041 -0.0001221 -0.082361"/>
      <inertia ixx="0.0011524" ixy="-0.0000007" ixz="0.0000396" iyy="0.0011921" iyz="-0.0000014" izz="0.0012386"/>
    </inertial>
  </link>
  <!-- Right Shoulder RZ -->
  <joint independent="true" name="right-shoulder-rx-to-shoulder-rz" type="revolute">
    <axis xyz="0 0 1"/>
    <origin rpy="0.0 0.0 0.0" xyz="0.0 0.0 -0.1025"/>
    <parent link="right-shoulder-rx"/>
    <child link="right-shoulder-rz"/>
    <limit effort="150" lower="-10" upper="10" velocity="100"/>
  </joint>
  <link name="right-shoulder-rz">
    <inertial>
      <mass value="0.905588"/>
      <origin xyz="0.0001703 0.016797 -0.060"/>
      <inertia ixx="0.0012713" ixy="-0.000001" ixz="-0.000008" iyy="0.0017477" iyz="0.0000225" izz="0.0008191"/>
    </inertial>
  </link>
  <!-- Right Elbow -->
  <joint independent="true" name="right-shoulder-rz-to-elbow" type="revolute">
    <axis xyz="0 1 0"/>
    <origin rpy="0.0 0.0 0.0" xyz="0.0 0.0 -0.1455"/>
    <parent link="right-shoulder-rz"/>
    <child link="right-elbow"/>
    <limit effort="150" lower="-10" upper="10" velocity="100"/>
  </joint>
  <link name="right-elbow">
    <inertial>
      <mass value="0.34839"/>
      <origin xyz="-0.0059578 -0.000111 -0.0426735"/>
      <inertia ixx="0.001570" ixy="-0.0000002" ixz="0.0000335" iyy="0.0016167" iyz="-0.000003" izz="0.0000619"/>
    </inertial>
  </link>
</robot>

