<?xml version="1.0" ?>
<!-- =================================================================================== -->
<!-- |    This document was autogenerated by xacro from tello_legs.xacro               | -->
<!-- |    EDITING THIS FILE BY HAND IS NOT RECOMMENDED                                 | -->
<!-- =================================================================================== -->
<robot name="tello_legs">
  <link name="ground"/>
  <!-- Left Hip Cluster -->
  <joint independent="true" name="ground-to-left-hip-clamp-rotor" type="revolute">
    <axis xyz="0 0 1"/>
    <origin rpy="3.1415927 0.0 0.0" xyz="0.0 126e-03 -26e-03"/>
    <parent link="ground"/>
    <child link="left-hip-clamp-rotor"/>
    <limit effort="150" lower="-10" upper="10" velocity="100"/>
  </joint>
  <link name="left-hip-clamp-rotor">
    <inertial>
      <mass value="0.07"/>
      <origin xyz="0.0 0.0 0.0"/>
      <inertia ixx="2.5984e-05" ixy="0.0" ixz="0.0" iyy="2.5984e-05" iyz="0.0" izz="5.1512e-05"/>
    </inertial>
  </link>
  <joint independent="false" name="ground-to-left-hip-clamp" type="revolute">
    <axis xyz="0 0 1"/>
    <origin rpy="0.0 0.0 0.0" xyz="0.0 126e-03 -87e-03"/>
    <parent link="ground"/>
    <child link="left-hip-clamp"/>
    <limit effort="150" lower="-10" upper="10" velocity="100"/>
  </joint>
  <link name="left-hip-clamp">
    <inertial>
      <mass value="1.3289"/>
      <origin xyz="-0.001 0.0 -0.0069"/>
      <inertia ixx="0.0032" ixy="0." ixz="0.0001" iyy="0.0033" iyz="0." izz="0.0027"/>
    </inertial>
  </link>
  <!-- Left Hip Differentials -->
  <joint independent="true" name="left-hip-clamp-to-hip-rotor-1" type="revolute">
    <axis xyz="0 0 1"/>
    <origin rpy="-1.5707963 3.1415927 0.0" xyz="0.0 0.04 0.0"/>
    <parent link="left-hip-clamp"/>
    <child link="left-hip-rotor-1"/>
    <limit effort="150" lower="-10" upper="10" velocity="100"/>
  </joint>
  <link name="left-hip-rotor-1">
    <inertial>
      <mass value="0.07"/>
      <origin xyz="0.0 0.0 0.0"/>
      <inertia ixx="2.5984e-05" ixy="0.0" ixz="0.0" iyy="2.5984e-05" iyz="0.0" izz="5.1512e-05"/>
    </inertial>
  </link>
  <joint independent="true" name="left-hip-clamp-to-hip-rotor-2" type="revolute">
    <axis xyz="0 0 1"/>
    <origin rpy="1.5707963 0.0 0.0" xyz="0.0 -0.04 0.0"/>
    <parent link="left-hip-clamp"/>
    <child link="left-hip-rotor-2"/>
    <limit effort="150" lower="-10" upper="10" velocity="100"/>
  </joint>
  <link name="left-hip-rotor-2">
    <inertial>
      <mass value="0.07"/>
      <origin xyz="0.0 0.0 0.0"/>
      <inertia ixx="2.5984e-05" ixy="0.0" ixz="0.0" iyy="2.5984e-05" iyz="0.0" izz="5.1512e-05"/>
    </inertial>
  </link>
  <joint independent="false" name="left-hip-clamp-to-gimbal" type="revolute">
    <axis xyz="1 0 0"/>
    <origin rpy="0.0 0.0 0.0" xyz="0.0 0.0 -142.5e-03"/>
    <parent link="left-hip-clamp"/>
    <child link="left-gimbal"/>
    <limit effort="150" lower="-10" upper="10" velocity="100"/>
  </joint>
  <link name="left-gimbal">
    <inertial>
      <mass value="0.4433"/>
      <origin xyz="-0.0027 0.0 0.0258"/>
      <inertia ixx="0.0018" ixy="0.0" ixz="0.0" iyy="0.0017" iyz="0.0" izz="0.0015"/>
    </inertial>
  </link>
  <joint independent="false" name="left-gimbal-to-thigh" type="revolute">
    <axis xyz="0 1 0"/>
    <origin rpy="0.0 0.0 0.0" xyz="0.0 0.0 0.0"/>
    <parent link="left-gimbal"/>
    <child link="left-thigh"/>
    <limit effort="150" lower="-10" upper="10" velocity="100"/>
  </joint>
  <link name="left-thigh">
    <inertial>
      <mass value="1.5424"/>
      <origin xyz="0.003 -0.0001 -0.0323"/>
      <inertia ixx="0.0103" ixy="0.0" ixz="-0.0005" iyy="0.0097" iyz="0.0" izz="0.0027"/>
    </inertial>
  </link>
  <!-- Left Knee-Ankle Differentials -->
  <joint independent="true" name="left-thigh-to-knee-ankle-rotor-1" type="revolute">
    <axis xyz="0 0 1"/>
    <origin rpy="1.5707963 0.0 0.0" xyz="0.0 26.55e-03 0.0"/>
    <parent link="left-thigh"/>
    <child link="left-knee-ankle-rotor-1"/>
    <limit effort="150" lower="-10" upper="10" velocity="100"/>
  </joint>
  <link name="left-knee-ankle-rotor-1">
    <inertial>
      <mass value="0.07"/>
      <origin xyz="0.0 0.0 0.0"/>
      <inertia ixx="2.5984e-05" ixy="0.0" ixz="0.0" iyy="2.5984e-05" iyz="0.0" izz="5.1512e-05"/>
    </inertial>
  </link>
  <joint independent="true" name="left-thigh-to-knee-ankle-rotor-2" type="revolute">
    <axis xyz="0 0 1"/>
    <origin rpy="-1.5707963 3.1415927 0.0" xyz="0.0 -26.55e-03 0.0"/>
    <parent link="left-thigh"/>
    <child link="left-knee-ankle-rotor-2"/>
    <limit effort="150" lower="-10" upper="10" velocity="100"/>
  </joint>
  <link name="left-knee-ankle-rotor-2">
    <inertial>
      <mass value="0.07"/>
      <origin xyz="0.0 0.0 0.0"/>
      <inertia ixx="2.5984e-05" ixy="0.0" ixz="0.0" iyy="2.5984e-05" iyz="0.0" izz="5.1512e-05"/>
    </inertial>
  </link>
  <joint independent="false" name="left-thigh-to-shin" type="revolute">
    <axis xyz="0 1 0"/>
    <origin rpy="0.0 0.0 0.0" xyz="0.0 0.0 -226.8e-03"/>
    <parent link="left-thigh"/>
    <child link="left-shin"/>
    <limit effort="150" lower="-10" upper="10" velocity="100"/>
  </joint>
  <link name="left-shin">
    <inertial>
      <mass value="0.3072"/>
      <origin xyz="0.0047 -0.0003 -0.1043"/>
      <inertia ixx="0.0054" ixy="0.0" ixz="-0.0002" iyy="0.0054" iyz="0.0" izz="0.0001"/>
    </inertial>
  </link>
  <joint independent="false" name="left-shin-to-foot" type="revolute">
    <axis xyz="0 1 0"/>
    <origin rpy="0.0 0.0 0.0" xyz="0.0 0.0 -260e-03"/>
    <parent link="left-shin"/>
    <child link="left-foot"/>
    <limit effort="150" lower="-10" upper="10" velocity="100"/>
  </joint>
  <link name="left-foot">
    <inertial>
      <mass value="0.1025"/>
      <origin xyz="0.0042 0.0 -0.0251"/>
      <inertia ixx="0.094e-03" ixy="0.0" ixz="-0.0038e-03" iyy="0.1773e-03" iyz="0.0" izz="0.0901e-03"/>
    </inertial>
  </link>
  <!-- Right Hip Cluster -->
  <joint independent="true" name="ground-to-right-hip-clamp-rotor" type="revolute">
    <axis xyz="0 0 1"/>
    <origin rpy="0.0 0.0 0.0" xyz="0.0 -126e-03 -26e-03"/>
    <parent link="ground"/>
    <child link="right-hip-clamp-rotor"/>
    <limit effort="150" lower="-10" upper="10" velocity="100"/>
  </joint>
  <link name="right-hip-clamp-rotor">
    <inertial>
      <mass value="0.07"/>
      <origin xyz="0.0 0.0 0.0"/>
      <inertia ixx="2.5984e-05" ixy="0.0" ixz="0.0" iyy="2.5984e-05" iyz="0.0" izz="5.1512e-05"/>
    </inertial>
  </link>
  <joint independent="false" name="ground-to-right-hip-clamp" type="revolute">
    <axis xyz="0 0 1"/>
    <origin rpy="0.0 0.0 0.0" xyz="0.0 -126e-03 -87e-03"/>
    <parent link="ground"/>
    <child link="right-hip-clamp"/>
    <limit effort="150" lower="-10" upper="10" velocity="100"/>
  </joint>
  <link name="right-hip-clamp">
    <inertial>
      <mass value="1.3289"/>
      <origin xyz="-0.001 0.0 -0.0069"/>
      <inertia ixx="0.0032" ixy="0." ixz="0.0001" iyy="0.0033" iyz="0." izz="0.0027"/>
    </inertial>
  </link>
  <!-- Right Hip Differentials -->
  <joint independent="true" name="right-hip-clamp-to-hip-rotor-1" type="revolute">
    <axis xyz="0 0 1"/>
    <origin rpy="-1.5707963 3.1415927 0.0" xyz="0.0 0.04 0.0"/>
    <parent link="right-hip-clamp"/>
    <child link="right-hip-rotor-1"/>
    <limit effort="150" lower="-10" upper="10" velocity="100"/>
  </joint>
  <link name="right-hip-rotor-1">
    <inertial>
      <mass value="0.07"/>
      <origin xyz="0.0 0.0 0.0"/>
      <inertia ixx="2.5984e-05" ixy="0.0" ixz="0.0" iyy="2.5984e-05" iyz="0.0" izz="5.1512e-05"/>
    </inertial>
  </link>
  <joint independent="true" name="right-hip-clamp-to-hip-rotor-2" type="revolute">
    <axis xyz="0 0 1"/>
    <origin rpy="1.5707963 0.0 0.0" xyz="0.0 -0.04 0.0"/>
    <parent link="right-hip-clamp"/>
    <child link="right-hip-rotor-2"/>
    <limit effort="150" lower="-10" upper="10" velocity="100"/>
  </joint>
  <link name="right-hip-rotor-2">
    <inertial>
      <mass value="0.07"/>
      <origin xyz="0.0 0.0 0.0"/>
      <inertia ixx="2.5984e-05" ixy="0.0" ixz="0.0" iyy="2.5984e-05" iyz="0.0" izz="5.1512e-05"/>
    </inertial>
  </link>
  <joint independent="false" name="right-hip-clamp-to-gimbal" type="revolute">
    <axis xyz="1 0 0"/>
    <origin rpy="0.0 0.0 0.0" xyz="0.0 0.0 -142.5e-03"/>
    <parent link="right-hip-clamp"/>
    <child link="right-gimbal"/>
    <limit effort="150" lower="-10" upper="10" velocity="100"/>
  </joint>
  <link name="right-gimbal">
    <inertial>
      <mass value="0.4433"/>
      <origin xyz="-0.0027 0.0 0.0258"/>
      <inertia ixx="0.0018" ixy="0.0" ixz="0.0" iyy="0.0017" iyz="0.0" izz="0.0015"/>
    </inertial>
  </link>
  <joint independent="false" name="right-gimbal-to-thigh" type="revolute">
    <axis xyz="0 1 0"/>
    <origin rpy="0.0 0.0 0.0" xyz="0.0 0.0 0.0"/>
    <parent link="right-gimbal"/>
    <child link="right-thigh"/>
    <limit effort="150" lower="-10" upper="10" velocity="100"/>
  </joint>
  <link name="right-thigh">
    <inertial>
      <mass value="1.5424"/>
      <origin xyz="0.003 -0.0001 -0.0323"/>
      <inertia ixx="0.0103" ixy="0.0" ixz="-0.0005" iyy="0.0097" iyz="0.0" izz="0.0027"/>
    </inertial>
  </link>
  <!-- Right Knee-Ankle Differentials -->
  <joint independent="true" name="right-thigh-to-knee-ankle-rotor-1" type="revolute">
    <axis xyz="0 0 1"/>
    <origin rpy="1.5707963 0.0 0.0" xyz="0.0 26.55e-03 0.0"/>
    <parent link="right-thigh"/>
    <child link="right-knee-ankle-rotor-1"/>
    <limit effort="150" lower="-10" upper="10" velocity="100"/>
  </joint>
  <link name="right-knee-ankle-rotor-1">
    <inertial>
      <mass value="0.07"/>
      <origin xyz="0.0 0.0 0.0"/>
      <inertia ixx="2.5984e-05" ixy="0.0" ixz="0.0" iyy="2.5984e-05" iyz="0.0" izz="5.1512e-05"/>
    </inertial>
  </link>
  <joint independent="true" name="right-thigh-to-knee-ankle-rotor-2" type="revolute">
    <axis xyz="0 0 1"/>
    <origin rpy="-1.5707963 3.1415927 0.0" xyz="0.0 -26.55e-03 0.0"/>
    <parent link="right-thigh"/>
    <child link="right-knee-ankle-rotor-2"/>
    <limit effort="150" lower="-10" upper="10" velocity="100"/>
  </joint>
  <link name="right-knee-ankle-rotor-2">
    <inertial>
      <mass value="0.07"/>
      <origin xyz="0.0 0.0 0.0"/>
      <inertia ixx="2.5984e-05" ixy="0.0" ixz="0.0" iyy="2.5984e-05" iyz="0.0" izz="5.1512e-05"/>
    </inertial>
  </link>
  <joint independent="false" name="right-thigh-to-shin" type="revolute">
    <axis xyz="0 1 0"/>
    <origin rpy="0.0 0.0 0.0" xyz="0.0 0.0 -226.8e-03"/>
    <parent link="right-thigh"/>
    <child link="right-shin"/>
    <limit effort="150" lower="-10" upper="10" velocity="100"/>
  </joint>
  <link name="right-shin">
    <inertial>
      <mass value="0.3072"/>
      <origin xyz="0.0047 -0.0003 -0.1043"/>
      <inertia ixx="0.0054" ixy="0.0" ixz="-0.0002" iyy="0.0054" iyz="0.0" izz="0.0001"/>
    </inertial>
  </link>
  <joint independent="false" name="right-shin-to-foot" type="revolute">
    <axis xyz="0 1 0"/>
    <origin rpy="0.0 0.0 0.0" xyz="0.0 0.0 -260e-03"/>
    <parent link="right-shin"/>
    <child link="right-foot"/>
    <limit effort="150" lower="-10" upper="10" velocity="100"/>
  </joint>
  <link name="right-foot">
    <inertial>
      <mass value="0.1025"/>
      <origin xyz="0.0042 0.0 -0.0251"/>
      <inertia ixx="0.094e-03" ixy="0.0" ixz="-0.0038e-03" iyy="0.1773e-03" iyz="0.0" izz="0.0901e-03"/>
    </inertial>
  </link>
</robot>

