<?xml version="1.0" ?>

<robot name="tello_humanoid_approximate" xmlns:xacro="http://ros.org/wiki/xacro">
    
    <xacro:include filename="tello_properties.xacro"/>
    <xacro:property name="base" value="ground"/>

    <!-- Torso -->

    <link name="${base}" />
    <xacro:torso name="torso"/>
    <joint name="torso-to-${base}" type="floating">
        <origin xyz="0 0 0" rpy="0 0 0"/>
        <parent link="${base}"/>
        <child link="torso"/>
    </joint>

    <!-- Left Hip Clamp -->
    
    <xacro:L_independent_hip_clamp_joint parent="torso"/>
    <xacro:hip_clamp prefix="left-"/>
    
    <!-- Left Gimbal, Thigh -->

    <xacro:L_independent_gimbal_joint parent="left-hip-clamp"/>
    <xacro:gimbal prefix="left-"/>
    <xacro:L_independent_thigh_joint parent="left-gimbal"/>
    <xacro:thigh prefix="left-"/>

    <!-- Left Shin, Foot -->

    <xacro:L_independent_shin_joint parent="left-thigh"/>
    <xacro:shin prefix="left-"/>
    <xacro:L_independent_foot_joint parent="left-shin"/>
    <xacro:foot prefix="left-"/>

    <!-- Right Hip Clamp -->

    <xacro:R_independent_hip_clamp_joint parent="torso"/>
    <xacro:hip_clamp prefix="right-"/>
    
    <!-- Right Gimbal, Thigh -->

    <xacro:R_independent_gimbal_joint parent="right-hip-clamp"/>
    <xacro:gimbal prefix="right-"/>
    <xacro:R_independent_thigh_joint parent="right-gimbal"/>
    <xacro:thigh prefix="right-"/>

    <!-- Right Shin, Foot -->

    <xacro:R_independent_shin_joint parent="right-thigh"/>
    <xacro:shin prefix="right-"/>
    <xacro:R_independent_foot_joint parent="right-shin"/>
    <xacro:foot prefix="right-"/>

    <!-- Left Shoulder RY -->

    <xacro:L_independent_shoulder_ry_joint parent="torso"/>
    <xacro:left_shoulder_ry/>

    <!-- Left Shoulder RX -->

    <xacro:L_independent_shoulder_rx_joint parent="left-shoulder-ry"/>
    <xacro:left_shoulder_rx/>

    <!-- Left Shoulder RZ -->

    <xacro:L_independent_shoulder_rz_joint parent="left-shoulder-rx"/>
    <xacro:left_shoulder_rz/>

    <!-- Left Elbow -->

    <xacro:L_independent_elbow_joint parent="left-shoulder-rz"/>
    <xacro:left_elbow/>

    <!-- Right Shoulder RY -->

    <xacro:R_independent_shoulder_ry_joint parent="torso"/>
    <xacro:right_shoulder_ry/>

    <!-- Right Shoulder RX -->

    <xacro:R_independent_shoulder_rx_joint parent="right-shoulder-ry"/>
    <xacro:right_shoulder_rx/>

    <!-- Right Shoulder RZ -->

    <xacro:R_independent_shoulder_rz_joint parent="right-shoulder-rx"/>
    <xacro:right_shoulder_rz/>

    <!-- Right Elbow -->

    <xacro:R_independent_elbow_joint parent="right-shoulder-rz"/>
    <xacro:right_elbow/>

</robot>
