<?xml version="1.0" ?>
<!-- =================================================================================== -->
<!-- |    This document was autogenerated by xacro from revolute_rotor_branch.xacro    | -->
<!-- |    EDITING THIS FILE BY HAND IS NOT RECOMMENDED                                 | -->
<!-- =================================================================================== -->
<robot name="variable_revolute_rotor_branch">
  <link name="base"/>
  <joint independent="true" name="base_to_link_6" type="revolute">
    <parent link="base"/>
    <child link="link_6"/>
    <axis xyz="0 0 1"/>
    <origin xyz="1.0 0.0 0.0"/>
    <limit effort="30" lower="-10" upper="10" velocity="1.0"/>
  </joint>
  <link name="link_6">
    <inertial>
      <mass value="1"/>
      <origin rpy="0 0 0" xyz="0.5 0 0"/>
      <inertia ixx="1" ixy="0" ixz="0" iyy="1" iyz="0" izz="1"/>
    </inertial>
  </link>
  <joint independent="false" name="base_to_rotor_6" type="revolute">
    <parent link="base"/>
    <child link="rotor_6"/>
    <axis xyz="0 0 1"/>
    <origin xyz="1.0 0.0 0.0"/>
    <limit effort="30" lower="-10" upper="10" velocity="1.0"/>
  </joint>
  <link name="rotor_6">
    <inertial>
      <mass value="0"/>
      <origin rpy="0 0 0" xyz="0 0 0"/>
      <inertia ixx="1e-4" ixy="0" ixz="0" iyy="1e-4" iyz="0" izz="1e-4"/>
    </inertial>
  </link>
  <constraint name="transmission_6" type="rolling">
    <predecessor link="link_6"/>
    <successor link="rotor_6"/>
    <ratio value="6.0"/>
  </constraint>
  <joint independent="true" name="base_to_link_5" type="revolute">
    <parent link="base"/>
    <child link="link_5"/>
    <axis xyz="0 0 1"/>
    <origin xyz="1.0 0.0 0.0"/>
    <limit effort="30" lower="-10" upper="10" velocity="1.0"/>
  </joint>
  <link name="link_5">
    <inertial>
      <mass value="1"/>
      <origin rpy="0 0 0" xyz="0.5 0 0"/>
      <inertia ixx="1" ixy="0" ixz="0" iyy="1" iyz="0" izz="1"/>
    </inertial>
  </link>
  <joint independent="false" name="base_to_rotor_5" type="revolute">
    <parent link="base"/>
    <child link="rotor_5"/>
    <axis xyz="0 0 1"/>
    <origin xyz="1.0 0.0 0.0"/>
    <limit effort="30" lower="-10" upper="10" velocity="1.0"/>
  </joint>
  <link name="rotor_5">
    <inertial>
      <mass value="0"/>
      <origin rpy="0 0 0" xyz="0 0 0"/>
      <inertia ixx="1e-4" ixy="0" ixz="0" iyy="1e-4" iyz="0" izz="1e-4"/>
    </inertial>
  </link>
  <constraint name="transmission_5" type="rolling">
    <predecessor link="link_5"/>
    <successor link="rotor_5"/>
    <ratio value="6.0"/>
  </constraint>
  <joint independent="true" name="base_to_link_4" type="revolute">
    <parent link="base"/>
    <child link="link_4"/>
    <axis xyz="0 0 1"/>
    <origin xyz="1.0 0.0 0.0"/>
    <limit effort="30" lower="-10" upper="10" velocity="1.0"/>
  </joint>
  <link name="link_4">
    <inertial>
      <mass value="1"/>
      <origin rpy="0 0 0" xyz="0.5 0 0"/>
      <inertia ixx="1" ixy="0" ixz="0" iyy="1" iyz="0" izz="1"/>
    </inertial>
  </link>
  <joint independent="false" name="base_to_rotor_4" type="revolute">
    <parent link="base"/>
    <child link="rotor_4"/>
    <axis xyz="0 0 1"/>
    <origin xyz="1.0 0.0 0.0"/>
    <limit effort="30" lower="-10" upper="10" velocity="1.0"/>
  </joint>
  <link name="rotor_4">
    <inertial>
      <mass value="0"/>
      <origin rpy="0 0 0" xyz="0 0 0"/>
      <inertia ixx="1e-4" ixy="0" ixz="0" iyy="1e-4" iyz="0" izz="1e-4"/>
    </inertial>
  </link>
  <constraint name="transmission_4" type="rolling">
    <predecessor link="link_4"/>
    <successor link="rotor_4"/>
    <ratio value="6.0"/>
  </constraint>
  <joint independent="true" name="base_to_link_3" type="revolute">
    <parent link="base"/>
    <child link="link_3"/>
    <axis xyz="0 0 1"/>
    <origin xyz="1.0 0.0 0.0"/>
    <limit effort="30" lower="-10" upper="10" velocity="1.0"/>
  </joint>
  <link name="link_3">
    <inertial>
      <mass value="1"/>
      <origin rpy="0 0 0" xyz="0.5 0 0"/>
      <inertia ixx="1" ixy="0" ixz="0" iyy="1" iyz="0" izz="1"/>
    </inertial>
  </link>
  <joint independent="false" name="base_to_rotor_3" type="revolute">
    <parent link="base"/>
    <child link="rotor_3"/>
    <axis xyz="0 0 1"/>
    <origin xyz="1.0 0.0 0.0"/>
    <limit effort="30" lower="-10" upper="10" velocity="1.0"/>
  </joint>
  <link name="rotor_3">
    <inertial>
      <mass value="0"/>
      <origin rpy="0 0 0" xyz="0 0 0"/>
      <inertia ixx="1e-4" ixy="0" ixz="0" iyy="1e-4" iyz="0" izz="1e-4"/>
    </inertial>
  </link>
  <constraint name="transmission_3" type="rolling">
    <predecessor link="link_3"/>
    <successor link="rotor_3"/>
    <ratio value="6.0"/>
  </constraint>
  <joint independent="true" name="base_to_link_2" type="revolute">
    <parent link="base"/>
    <child link="link_2"/>
    <axis xyz="0 0 1"/>
    <origin xyz="1.0 0.0 0.0"/>
    <limit effort="30" lower="-10" upper="10" velocity="1.0"/>
  </joint>
  <link name="link_2">
    <inertial>
      <mass value="1"/>
      <origin rpy="0 0 0" xyz="0.5 0 0"/>
      <inertia ixx="1" ixy="0" ixz="0" iyy="1" iyz="0" izz="1"/>
    </inertial>
  </link>
  <joint independent="false" name="base_to_rotor_2" type="revolute">
    <parent link="base"/>
    <child link="rotor_2"/>
    <axis xyz="0 0 1"/>
    <origin xyz="1.0 0.0 0.0"/>
    <limit effort="30" lower="-10" upper="10" velocity="1.0"/>
  </joint>
  <link name="rotor_2">
    <inertial>
      <mass value="0"/>
      <origin rpy="0 0 0" xyz="0 0 0"/>
      <inertia ixx="1e-4" ixy="0" ixz="0" iyy="1e-4" iyz="0" izz="1e-4"/>
    </inertial>
  </link>
  <constraint name="transmission_2" type="rolling">
    <predecessor link="link_2"/>
    <successor link="rotor_2"/>
    <ratio value="6.0"/>
  </constraint>
  <joint independent="true" name="base_to_link_1" type="revolute">
    <parent link="base"/>
    <child link="link_1"/>
    <axis xyz="0 0 1"/>
    <origin xyz="1.0 0.0 0.0"/>
    <limit effort="30" lower="-10" upper="10" velocity="1.0"/>
  </joint>
  <link name="link_1">
    <inertial>
      <mass value="1"/>
      <origin rpy="0 0 0" xyz="0.5 0 0"/>
      <inertia ixx="1" ixy="0" ixz="0" iyy="1" iyz="0" izz="1"/>
    </inertial>
  </link>
  <joint independent="false" name="base_to_rotor_1" type="revolute">
    <parent link="base"/>
    <child link="rotor_1"/>
    <axis xyz="0 0 1"/>
    <origin xyz="1.0 0.0 0.0"/>
    <limit effort="30" lower="-10" upper="10" velocity="1.0"/>
  </joint>
  <link name="rotor_1">
    <inertial>
      <mass value="0"/>
      <origin rpy="0 0 0" xyz="0 0 0"/>
      <inertia ixx="1e-4" ixy="0" ixz="0" iyy="1e-4" iyz="0" izz="1e-4"/>
    </inertial>
  </link>
  <constraint name="transmission_1" type="rolling">
    <predecessor link="link_1"/>
    <successor link="rotor_1"/>
    <ratio value="6.0"/>
  </constraint>
  <joint independent="true" name="link_6_to_link_17" type="revolute">
    <parent link="link_6"/>
    <child link="link_17"/>
    <axis xyz="0 0 1"/>
    <origin xyz="1.0 0.0 0.0"/>
    <limit effort="30" lower="-10" upper="10" velocity="1.0"/>
  </joint>
  <link name="link_17">
    <inertial>
      <mass value="1"/>
      <origin rpy="0 0 0" xyz="0.5 0 0"/>
      <inertia ixx="1" ixy="0" ixz="0" iyy="1" iyz="0" izz="1"/>
    </inertial>
  </link>
  <joint independent="false" name="link_6_to_rotor_17" type="revolute">
    <parent link="link_6"/>
    <child link="rotor_17"/>
    <axis xyz="0 0 1"/>
    <origin xyz="1.0 0.0 0.0"/>
    <limit effort="30" lower="-10" upper="10" velocity="1.0"/>
  </joint>
  <link name="rotor_17">
    <inertial>
      <mass value="0"/>
      <origin rpy="0 0 0" xyz="0 0 0"/>
      <inertia ixx="1e-4" ixy="0" ixz="0" iyy="1e-4" iyz="0" izz="1e-4"/>
    </inertial>
  </link>
  <constraint name="transmission_17" type="rolling">
    <predecessor link="link_17"/>
    <successor link="rotor_17"/>
    <ratio value="6.0"/>
  </constraint>
  <joint independent="true" name="link_17_to_link_18" type="revolute">
    <parent link="link_17"/>
    <child link="link_18"/>
    <axis xyz="0 0 1"/>
    <origin xyz="1.0 0.0 0.0"/>
    <limit effort="30" lower="-10" upper="10" velocity="1.0"/>
  </joint>
  <link name="link_18">
    <inertial>
      <mass value="1"/>
      <origin rpy="0 0 0" xyz="0.5 0 0"/>
      <inertia ixx="1" ixy="0" ixz="0" iyy="1" iyz="0" izz="1"/>
    </inertial>
  </link>
  <joint independent="false" name="link_17_to_rotor_18" type="revolute">
    <parent link="link_17"/>
    <child link="rotor_18"/>
    <axis xyz="0 0 1"/>
    <origin xyz="1.0 0.0 0.0"/>
    <limit effort="30" lower="-10" upper="10" velocity="1.0"/>
  </joint>
  <link name="rotor_18">
    <inertial>
      <mass value="0"/>
      <origin rpy="0 0 0" xyz="0 0 0"/>
      <inertia ixx="1e-4" ixy="0" ixz="0" iyy="1e-4" iyz="0" izz="1e-4"/>
    </inertial>
  </link>
  <constraint name="transmission_18" type="rolling">
    <predecessor link="link_18"/>
    <successor link="rotor_18"/>
    <ratio value="6.0"/>
  </constraint>
  <joint independent="true" name="link_5_to_link_15" type="revolute">
    <parent link="link_5"/>
    <child link="link_15"/>
    <axis xyz="0 0 1"/>
    <origin xyz="1.0 0.0 0.0"/>
    <limit effort="30" lower="-10" upper="10" velocity="1.0"/>
  </joint>
  <link name="link_15">
    <inertial>
      <mass value="1"/>
      <origin rpy="0 0 0" xyz="0.5 0 0"/>
      <inertia ixx="1" ixy="0" ixz="0" iyy="1" iyz="0" izz="1"/>
    </inertial>
  </link>
  <joint independent="false" name="link_5_to_rotor_15" type="revolute">
    <parent link="link_5"/>
    <child link="rotor_15"/>
    <axis xyz="0 0 1"/>
    <origin xyz="1.0 0.0 0.0"/>
    <limit effort="30" lower="-10" upper="10" velocity="1.0"/>
  </joint>
  <link name="rotor_15">
    <inertial>
      <mass value="0"/>
      <origin rpy="0 0 0" xyz="0 0 0"/>
      <inertia ixx="1e-4" ixy="0" ixz="0" iyy="1e-4" iyz="0" izz="1e-4"/>
    </inertial>
  </link>
  <constraint name="transmission_15" type="rolling">
    <predecessor link="link_15"/>
    <successor link="rotor_15"/>
    <ratio value="6.0"/>
  </constraint>
  <joint independent="true" name="link_15_to_link_16" type="revolute">
    <parent link="link_15"/>
    <child link="link_16"/>
    <axis xyz="0 0 1"/>
    <origin xyz="1.0 0.0 0.0"/>
    <limit effort="30" lower="-10" upper="10" velocity="1.0"/>
  </joint>
  <link name="link_16">
    <inertial>
      <mass value="1"/>
      <origin rpy="0 0 0" xyz="0.5 0 0"/>
      <inertia ixx="1" ixy="0" ixz="0" iyy="1" iyz="0" izz="1"/>
    </inertial>
  </link>
  <joint independent="false" name="link_15_to_rotor_16" type="revolute">
    <parent link="link_15"/>
    <child link="rotor_16"/>
    <axis xyz="0 0 1"/>
    <origin xyz="1.0 0.0 0.0"/>
    <limit effort="30" lower="-10" upper="10" velocity="1.0"/>
  </joint>
  <link name="rotor_16">
    <inertial>
      <mass value="0"/>
      <origin rpy="0 0 0" xyz="0 0 0"/>
      <inertia ixx="1e-4" ixy="0" ixz="0" iyy="1e-4" iyz="0" izz="1e-4"/>
    </inertial>
  </link>
  <constraint name="transmission_16" type="rolling">
    <predecessor link="link_16"/>
    <successor link="rotor_16"/>
    <ratio value="6.0"/>
  </constraint>
  <joint independent="true" name="link_4_to_link_13" type="revolute">
    <parent link="link_4"/>
    <child link="link_13"/>
    <axis xyz="0 0 1"/>
    <origin xyz="1.0 0.0 0.0"/>
    <limit effort="30" lower="-10" upper="10" velocity="1.0"/>
  </joint>
  <link name="link_13">
    <inertial>
      <mass value="1"/>
      <origin rpy="0 0 0" xyz="0.5 0 0"/>
      <inertia ixx="1" ixy="0" ixz="0" iyy="1" iyz="0" izz="1"/>
    </inertial>
  </link>
  <joint independent="false" name="link_4_to_rotor_13" type="revolute">
    <parent link="link_4"/>
    <child link="rotor_13"/>
    <axis xyz="0 0 1"/>
    <origin xyz="1.0 0.0 0.0"/>
    <limit effort="30" lower="-10" upper="10" velocity="1.0"/>
  </joint>
  <link name="rotor_13">
    <inertial>
      <mass value="0"/>
      <origin rpy="0 0 0" xyz="0 0 0"/>
      <inertia ixx="1e-4" ixy="0" ixz="0" iyy="1e-4" iyz="0" izz="1e-4"/>
    </inertial>
  </link>
  <constraint name="transmission_13" type="rolling">
    <predecessor link="link_13"/>
    <successor link="rotor_13"/>
    <ratio value="6.0"/>
  </constraint>
  <joint independent="true" name="link_13_to_link_14" type="revolute">
    <parent link="link_13"/>
    <child link="link_14"/>
    <axis xyz="0 0 1"/>
    <origin xyz="1.0 0.0 0.0"/>
    <limit effort="30" lower="-10" upper="10" velocity="1.0"/>
  </joint>
  <link name="link_14">
    <inertial>
      <mass value="1"/>
      <origin rpy="0 0 0" xyz="0.5 0 0"/>
      <inertia ixx="1" ixy="0" ixz="0" iyy="1" iyz="0" izz="1"/>
    </inertial>
  </link>
  <joint independent="false" name="link_13_to_rotor_14" type="revolute">
    <parent link="link_13"/>
    <child link="rotor_14"/>
    <axis xyz="0 0 1"/>
    <origin xyz="1.0 0.0 0.0"/>
    <limit effort="30" lower="-10" upper="10" velocity="1.0"/>
  </joint>
  <link name="rotor_14">
    <inertial>
      <mass value="0"/>
      <origin rpy="0 0 0" xyz="0 0 0"/>
      <inertia ixx="1e-4" ixy="0" ixz="0" iyy="1e-4" iyz="0" izz="1e-4"/>
    </inertial>
  </link>
  <constraint name="transmission_14" type="rolling">
    <predecessor link="link_14"/>
    <successor link="rotor_14"/>
    <ratio value="6.0"/>
  </constraint>
  <joint independent="true" name="link_3_to_link_11" type="revolute">
    <parent link="link_3"/>
    <child link="link_11"/>
    <axis xyz="0 0 1"/>
    <origin xyz="1.0 0.0 0.0"/>
    <limit effort="30" lower="-10" upper="10" velocity="1.0"/>
  </joint>
  <link name="link_11">
    <inertial>
      <mass value="1"/>
      <origin rpy="0 0 0" xyz="0.5 0 0"/>
      <inertia ixx="1" ixy="0" ixz="0" iyy="1" iyz="0" izz="1"/>
    </inertial>
  </link>
  <joint independent="false" name="link_3_to_rotor_11" type="revolute">
    <parent link="link_3"/>
    <child link="rotor_11"/>
    <axis xyz="0 0 1"/>
    <origin xyz="1.0 0.0 0.0"/>
    <limit effort="30" lower="-10" upper="10" velocity="1.0"/>
  </joint>
  <link name="rotor_11">
    <inertial>
      <mass value="0"/>
      <origin rpy="0 0 0" xyz="0 0 0"/>
      <inertia ixx="1e-4" ixy="0" ixz="0" iyy="1e-4" iyz="0" izz="1e-4"/>
    </inertial>
  </link>
  <constraint name="transmission_11" type="rolling">
    <predecessor link="link_11"/>
    <successor link="rotor_11"/>
    <ratio value="6.0"/>
  </constraint>
  <joint independent="true" name="link_11_to_link_12" type="revolute">
    <parent link="link_11"/>
    <child link="link_12"/>
    <axis xyz="0 0 1"/>
    <origin xyz="1.0 0.0 0.0"/>
    <limit effort="30" lower="-10" upper="10" velocity="1.0"/>
  </joint>
  <link name="link_12">
    <inertial>
      <mass value="1"/>
      <origin rpy="0 0 0" xyz="0.5 0 0"/>
      <inertia ixx="1" ixy="0" ixz="0" iyy="1" iyz="0" izz="1"/>
    </inertial>
  </link>
  <joint independent="false" name="link_11_to_rotor_12" type="revolute">
    <parent link="link_11"/>
    <child link="rotor_12"/>
    <axis xyz="0 0 1"/>
    <origin xyz="1.0 0.0 0.0"/>
    <limit effort="30" lower="-10" upper="10" velocity="1.0"/>
  </joint>
  <link name="rotor_12">
    <inertial>
      <mass value="0"/>
      <origin rpy="0 0 0" xyz="0 0 0"/>
      <inertia ixx="1e-4" ixy="0" ixz="0" iyy="1e-4" iyz="0" izz="1e-4"/>
    </inertial>
  </link>
  <constraint name="transmission_12" type="rolling">
    <predecessor link="link_12"/>
    <successor link="rotor_12"/>
    <ratio value="6.0"/>
  </constraint>
  <joint independent="true" name="link_2_to_link_9" type="revolute">
    <parent link="link_2"/>
    <child link="link_9"/>
    <axis xyz="0 0 1"/>
    <origin xyz="1.0 0.0 0.0"/>
    <limit effort="30" lower="-10" upper="10" velocity="1.0"/>
  </joint>
  <link name="link_9">
    <inertial>
      <mass value="1"/>
      <origin rpy="0 0 0" xyz="0.5 0 0"/>
      <inertia ixx="1" ixy="0" ixz="0" iyy="1" iyz="0" izz="1"/>
    </inertial>
  </link>
  <joint independent="false" name="link_2_to_rotor_9" type="revolute">
    <parent link="link_2"/>
    <child link="rotor_9"/>
    <axis xyz="0 0 1"/>
    <origin xyz="1.0 0.0 0.0"/>
    <limit effort="30" lower="-10" upper="10" velocity="1.0"/>
  </joint>
  <link name="rotor_9">
    <inertial>
      <mass value="0"/>
      <origin rpy="0 0 0" xyz="0 0 0"/>
      <inertia ixx="1e-4" ixy="0" ixz="0" iyy="1e-4" iyz="0" izz="1e-4"/>
    </inertial>
  </link>
  <constraint name="transmission_9" type="rolling">
    <predecessor link="link_9"/>
    <successor link="rotor_9"/>
    <ratio value="6.0"/>
  </constraint>
  <joint independent="true" name="link_9_to_link_10" type="revolute">
    <parent link="link_9"/>
    <child link="link_10"/>
    <axis xyz="0 0 1"/>
    <origin xyz="1.0 0.0 0.0"/>
    <limit effort="30" lower="-10" upper="10" velocity="1.0"/>
  </joint>
  <link name="link_10">
    <inertial>
      <mass value="1"/>
      <origin rpy="0 0 0" xyz="0.5 0 0"/>
      <inertia ixx="1" ixy="0" ixz="0" iyy="1" iyz="0" izz="1"/>
    </inertial>
  </link>
  <joint independent="false" name="link_9_to_rotor_10" type="revolute">
    <parent link="link_9"/>
    <child link="rotor_10"/>
    <axis xyz="0 0 1"/>
    <origin xyz="1.0 0.0 0.0"/>
    <limit effort="30" lower="-10" upper="10" velocity="1.0"/>
  </joint>
  <link name="rotor_10">
    <inertial>
      <mass value="0"/>
      <origin rpy="0 0 0" xyz="0 0 0"/>
      <inertia ixx="1e-4" ixy="0" ixz="0" iyy="1e-4" iyz="0" izz="1e-4"/>
    </inertial>
  </link>
  <constraint name="transmission_10" type="rolling">
    <predecessor link="link_10"/>
    <successor link="rotor_10"/>
    <ratio value="6.0"/>
  </constraint>
  <joint independent="true" name="link_1_to_link_7" type="revolute">
    <parent link="link_1"/>
    <child link="link_7"/>
    <axis xyz="0 0 1"/>
    <origin xyz="1.0 0.0 0.0"/>
    <limit effort="30" lower="-10" upper="10" velocity="1.0"/>
  </joint>
  <link name="link_7">
    <inertial>
      <mass value="1"/>
      <origin rpy="0 0 0" xyz="0.5 0 0"/>
      <inertia ixx="1" ixy="0" ixz="0" iyy="1" iyz="0" izz="1"/>
    </inertial>
  </link>
  <joint independent="false" name="link_1_to_rotor_7" type="revolute">
    <parent link="link_1"/>
    <child link="rotor_7"/>
    <axis xyz="0 0 1"/>
    <origin xyz="1.0 0.0 0.0"/>
    <limit effort="30" lower="-10" upper="10" velocity="1.0"/>
  </joint>
  <link name="rotor_7">
    <inertial>
      <mass value="0"/>
      <origin rpy="0 0 0" xyz="0 0 0"/>
      <inertia ixx="1e-4" ixy="0" ixz="0" iyy="1e-4" iyz="0" izz="1e-4"/>
    </inertial>
  </link>
  <constraint name="transmission_7" type="rolling">
    <predecessor link="link_7"/>
    <successor link="rotor_7"/>
    <ratio value="6.0"/>
  </constraint>
  <joint independent="true" name="link_7_to_link_8" type="revolute">
    <parent link="link_7"/>
    <child link="link_8"/>
    <axis xyz="0 0 1"/>
    <origin xyz="1.0 0.0 0.0"/>
    <limit effort="30" lower="-10" upper="10" velocity="1.0"/>
  </joint>
  <link name="link_8">
    <inertial>
      <mass value="1"/>
      <origin rpy="0 0 0" xyz="0.5 0 0"/>
      <inertia ixx="1" ixy="0" ixz="0" iyy="1" iyz="0" izz="1"/>
    </inertial>
  </link>
  <joint independent="false" name="link_7_to_rotor_8" type="revolute">
    <parent link="link_7"/>
    <child link="rotor_8"/>
    <axis xyz="0 0 1"/>
    <origin xyz="1.0 0.0 0.0"/>
    <limit effort="30" lower="-10" upper="10" velocity="1.0"/>
  </joint>
  <link name="rotor_8">
    <inertial>
      <mass value="0"/>
      <origin rpy="0 0 0" xyz="0 0 0"/>
      <inertia ixx="1e-4" ixy="0" ixz="0" iyy="1e-4" iyz="0" izz="1e-4"/>
    </inertial>
  </link>
  <constraint name="transmission_8" type="rolling">
    <predecessor link="link_8"/>
    <successor link="rotor_8"/>
    <ratio value="6.0"/>
  </constraint>
</robot>

