<?xml version="1.0" ?>
<!-- =================================================================================== -->
<!-- |    This document was autogenerated by xacro from revolute_rotor_branch.xacro    | -->
<!-- |    EDITING THIS FILE BY HAND IS NOT RECOMMENDED                                 | -->
<!-- =================================================================================== -->
<robot name="variable_revolute_rotor_branch">
  <link name="ground"/>
  <link name="Floating Base">
    <inertial>
      <mass value="5.0"/>
      <origin xyz="0. 0. 0."/>
      <inertia ixx="0.1" ixy="0." ixz="0." iyy="0.1" iyz="0." izz="0.1"/>
    </inertial>
  </link>
  <joint name="world_to_base" type="floating">
    <origin rpy="0 0 0" xyz="0 0 0"/>
    <parent link="ground"/>
    <child link="Floating Base"/>
  </joint>
  <joint independent="true" name="base_to_link_1" type="revolute">
    <parent link="Floating Base"/>
    <child link="link_1"/>
    <axis xyz="0 0 1"/>
    <origin xyz="1.0 0.0 0.0"/>
    <limit effort="30" lower="-10" upper="10" velocity="1.0"/>
  </joint>
  <link name="link_1">
    <inertial>
      <mass value="1"/>
      <origin rpy="0 0 0" xyz="0.5 0 0"/>
      <inertia ixx="1" ixy="0" ixz="0" iyy="1" iyz="0" izz="1"/>
    </inertial>
  </link>
  <joint independent="false" name="base_to_rotor_1" type="revolute">
    <parent link="Floating Base"/>
    <child link="rotor_1"/>
    <axis xyz="0 0 1"/>
    <origin xyz="1.0 0.0 0.0"/>
    <limit effort="30" lower="-10" upper="10" velocity="1.0"/>
  </joint>
  <link name="rotor_1">
    <inertial>
      <mass value="0"/>
      <origin rpy="0 0 0" xyz="0 0 0"/>
      <inertia ixx="1e-4" ixy="0" ixz="0" iyy="1e-4" iyz="0" izz="1e-4"/>
    </inertial>
  </link>
  <coupling name="transmission_1">
    <predecessor link="link_1"/>
    <successor link="rotor_1"/>
    <ratio value="6.0"/>
  </coupling>
  <joint independent="true" name="link_1_to_link_2" type="revolute">
    <parent link="link_1"/>
    <child link="link_2"/>
    <axis xyz="0 0 1"/>
    <origin xyz="1.0 0.0 0.0"/>
    <limit effort="30" lower="-10" upper="10" velocity="1.0"/>
  </joint>
  <link name="link_2">
    <inertial>
      <mass value="1"/>
      <origin rpy="0 0 0" xyz="0.5 0 0"/>
      <inertia ixx="1" ixy="0" ixz="0" iyy="1" iyz="0" izz="1"/>
    </inertial>
  </link>
  <joint independent="false" name="link_1_to_rotor_2" type="revolute">
    <parent link="link_1"/>
    <child link="rotor_2"/>
    <axis xyz="0 0 1"/>
    <origin xyz="1.0 0.0 0.0"/>
    <limit effort="30" lower="-10" upper="10" velocity="1.0"/>
  </joint>
  <link name="rotor_2">
    <inertial>
      <mass value="0"/>
      <origin rpy="0 0 0" xyz="0 0 0"/>
      <inertia ixx="1e-4" ixy="0" ixz="0" iyy="1e-4" iyz="0" izz="1e-4"/>
    </inertial>
  </link>
  <coupling name="transmission_2">
    <predecessor link="link_2"/>
    <successor link="rotor_2"/>
    <ratio value="6.0"/>
  </coupling>
  <joint independent="true" name="link_2_to_link_3" type="revolute">
    <parent link="link_2"/>
    <child link="link_3"/>
    <axis xyz="0 0 1"/>
    <origin xyz="1.0 0.0 0.0"/>
    <limit effort="30" lower="-10" upper="10" velocity="1.0"/>
  </joint>
  <link name="link_3">
    <inertial>
      <mass value="1"/>
      <origin rpy="0 0 0" xyz="0.5 0 0"/>
      <inertia ixx="1" ixy="0" ixz="0" iyy="1" iyz="0" izz="1"/>
    </inertial>
  </link>
  <joint independent="false" name="link_2_to_rotor_3" type="revolute">
    <parent link="link_2"/>
    <child link="rotor_3"/>
    <axis xyz="0 0 1"/>
    <origin xyz="1.0 0.0 0.0"/>
    <limit effort="30" lower="-10" upper="10" velocity="1.0"/>
  </joint>
  <link name="rotor_3">
    <inertial>
      <mass value="0"/>
      <origin rpy="0 0 0" xyz="0 0 0"/>
      <inertia ixx="1e-4" ixy="0" ixz="0" iyy="1e-4" iyz="0" izz="1e-4"/>
    </inertial>
  </link>
  <coupling name="transmission_3">
    <predecessor link="link_3"/>
    <successor link="rotor_3"/>
    <ratio value="6.0"/>
  </coupling>
  <joint independent="true" name="link_3_to_link_4" type="revolute">
    <parent link="link_3"/>
    <child link="link_4"/>
    <axis xyz="0 0 1"/>
    <origin xyz="1.0 0.0 0.0"/>
    <limit effort="30" lower="-10" upper="10" velocity="1.0"/>
  </joint>
  <link name="link_4">
    <inertial>
      <mass value="1"/>
      <origin rpy="0 0 0" xyz="0.5 0 0"/>
      <inertia ixx="1" ixy="0" ixz="0" iyy="1" iyz="0" izz="1"/>
    </inertial>
  </link>
  <joint independent="false" name="link_3_to_rotor_4" type="revolute">
    <parent link="link_3"/>
    <child link="rotor_4"/>
    <axis xyz="0 0 1"/>
    <origin xyz="1.0 0.0 0.0"/>
    <limit effort="30" lower="-10" upper="10" velocity="1.0"/>
  </joint>
  <link name="rotor_4">
    <inertial>
      <mass value="0"/>
      <origin rpy="0 0 0" xyz="0 0 0"/>
      <inertia ixx="1e-4" ixy="0" ixz="0" iyy="1e-4" iyz="0" izz="1e-4"/>
    </inertial>
  </link>
  <coupling name="transmission_4">
    <predecessor link="link_4"/>
    <successor link="rotor_4"/>
    <ratio value="6.0"/>
  </coupling>
  <joint independent="true" name="link_4_to_link_5" type="revolute">
    <parent link="link_4"/>
    <child link="link_5"/>
    <axis xyz="0 0 1"/>
    <origin xyz="1.0 0.0 0.0"/>
    <limit effort="30" lower="-10" upper="10" velocity="1.0"/>
  </joint>
  <link name="link_5">
    <inertial>
      <mass value="1"/>
      <origin rpy="0 0 0" xyz="0.5 0 0"/>
      <inertia ixx="1" ixy="0" ixz="0" iyy="1" iyz="0" izz="1"/>
    </inertial>
  </link>
  <joint independent="false" name="link_4_to_rotor_5" type="revolute">
    <parent link="link_4"/>
    <child link="rotor_5"/>
    <axis xyz="0 0 1"/>
    <origin xyz="1.0 0.0 0.0"/>
    <limit effort="30" lower="-10" upper="10" velocity="1.0"/>
  </joint>
  <link name="rotor_5">
    <inertial>
      <mass value="0"/>
      <origin rpy="0 0 0" xyz="0 0 0"/>
      <inertia ixx="1e-4" ixy="0" ixz="0" iyy="1e-4" iyz="0" izz="1e-4"/>
    </inertial>
  </link>
  <coupling name="transmission_5">
    <predecessor link="link_5"/>
    <successor link="rotor_5"/>
    <ratio value="6.0"/>
  </coupling>
  <joint independent="true" name="link_5_to_link_6" type="revolute">
    <parent link="link_5"/>
    <child link="link_6"/>
    <axis xyz="0 0 1"/>
    <origin xyz="1.0 0.0 0.0"/>
    <limit effort="30" lower="-10" upper="10" velocity="1.0"/>
  </joint>
  <link name="link_6">
    <inertial>
      <mass value="1"/>
      <origin rpy="0 0 0" xyz="0.5 0 0"/>
      <inertia ixx="1" ixy="0" ixz="0" iyy="1" iyz="0" izz="1"/>
    </inertial>
  </link>
  <joint independent="false" name="link_5_to_rotor_6" type="revolute">
    <parent link="link_5"/>
    <child link="rotor_6"/>
    <axis xyz="0 0 1"/>
    <origin xyz="1.0 0.0 0.0"/>
    <limit effort="30" lower="-10" upper="10" velocity="1.0"/>
  </joint>
  <link name="rotor_6">
    <inertial>
      <mass value="0"/>
      <origin rpy="0 0 0" xyz="0 0 0"/>
      <inertia ixx="1e-4" ixy="0" ixz="0" iyy="1e-4" iyz="0" izz="1e-4"/>
    </inertial>
  </link>
  <coupling name="transmission_6">
    <predecessor link="link_6"/>
    <successor link="rotor_6"/>
    <ratio value="6.0"/>
  </coupling>
  <joint independent="true" name="link_6_to_link_7" type="revolute">
    <parent link="link_6"/>
    <child link="link_7"/>
    <axis xyz="0 0 1"/>
    <origin xyz="1.0 0.0 0.0"/>
    <limit effort="30" lower="-10" upper="10" velocity="1.0"/>
  </joint>
  <link name="link_7">
    <inertial>
      <mass value="1"/>
      <origin rpy="0 0 0" xyz="0.5 0 0"/>
      <inertia ixx="1" ixy="0" ixz="0" iyy="1" iyz="0" izz="1"/>
    </inertial>
  </link>
  <joint independent="false" name="link_6_to_rotor_7" type="revolute">
    <parent link="link_6"/>
    <child link="rotor_7"/>
    <axis xyz="0 0 1"/>
    <origin xyz="1.0 0.0 0.0"/>
    <limit effort="30" lower="-10" upper="10" velocity="1.0"/>
  </joint>
  <link name="rotor_7">
    <inertial>
      <mass value="0"/>
      <origin rpy="0 0 0" xyz="0 0 0"/>
      <inertia ixx="1e-4" ixy="0" ixz="0" iyy="1e-4" iyz="0" izz="1e-4"/>
    </inertial>
  </link>
  <coupling name="transmission_7">
    <predecessor link="link_7"/>
    <successor link="rotor_7"/>
    <ratio value="6.0"/>
  </coupling>
  <joint independent="true" name="link_7_to_link_8" type="revolute">
    <parent link="link_7"/>
    <child link="link_8"/>
    <axis xyz="0 0 1"/>
    <origin xyz="1.0 0.0 0.0"/>
    <limit effort="30" lower="-10" upper="10" velocity="1.0"/>
  </joint>
  <link name="link_8">
    <inertial>
      <mass value="1"/>
      <origin rpy="0 0 0" xyz="0.5 0 0"/>
      <inertia ixx="1" ixy="0" ixz="0" iyy="1" iyz="0" izz="1"/>
    </inertial>
  </link>
  <joint independent="false" name="link_7_to_rotor_8" type="revolute">
    <parent link="link_7"/>
    <child link="rotor_8"/>
    <axis xyz="0 0 1"/>
    <origin xyz="1.0 0.0 0.0"/>
    <limit effort="30" lower="-10" upper="10" velocity="1.0"/>
  </joint>
  <link name="rotor_8">
    <inertial>
      <mass value="0"/>
      <origin rpy="0 0 0" xyz="0 0 0"/>
      <inertia ixx="1e-4" ixy="0" ixz="0" iyy="1e-4" iyz="0" izz="1e-4"/>
    </inertial>
  </link>
  <coupling name="transmission_8">
    <predecessor link="link_8"/>
    <successor link="rotor_8"/>
    <ratio value="6.0"/>
  </coupling>
</robot>
